2021-07-07 17:58:31,939 [werkzeug] [28712:MainThread] _internal.py:_internal:_log in 113] [INFO]:  * Running on http://127.0.0.1:5000/ (Press CTRL+C to quit)
2021-07-07 18:00:38,690 [werkzeug] [4056:MainThread] _internal.py:_internal:_log in 113] [INFO]:  * Running on http://127.0.0.1:5000/ (Press CTRL+C to quit)
2021-07-07 18:00:42,594 [werkzeug] [27408:Thread-1] _internal.py:_internal:_log in 113] [INFO]: 127.0.0.1 - - [07/Jul/2021 18:00:42] "[33mGET / HTTP/1.1[0m" 404 -
2021-07-07 18:00:42,755 [werkzeug] [2412:Thread-2] _internal.py:_internal:_log in 113] [INFO]: 127.0.0.1 - - [07/Jul/2021 18:00:42] "[33mGET /favicon.ico HTTP/1.1[0m" 404 -
2021-07-07 18:02:43,754 [werkzeug] [30196:Thread-3] _internal.py:_internal:_log in 113] [INFO]: 127.0.0.1 - - [07/Jul/2021 18:02:43] "[31m[1mPOST /element/henkins/check HTTP/1.1[0m" 405 -
2021-07-07 18:03:00,737 [werkzeug] [30688:MainThread] _internal.py:_internal:_log in 113] [INFO]:  * Running on http://127.0.0.1:5000/ (Press CTRL+C to quit)
2021-07-07 18:03:33,448 [werkzeug] [28832:MainThread] _internal.py:_internal:_log in 113] [INFO]:  * Running on http://127.0.0.1:5000/ (Press CTRL+C to quit)
2021-07-07 18:05:01,453 [werkzeug] [11912:MainThread] _internal.py:_internal:_log in 113] [INFO]:  * Running on http://127.0.0.1:5000/ (Press CTRL+C to quit)
2021-07-07 18:05:56,114 [werkzeug] [23896:MainThread] _internal.py:_internal:_log in 113] [INFO]:  * Running on http://127.0.0.1:5000/ (Press CTRL+C to quit)
2021-07-07 18:08:46,792 [erybjp] [29260:Thread-1] app.py:app:log_exception in 1891] [ERROR]: Exception on /element/henkins/check [GET]
Traceback (most recent call last):
  File "D:\AutoTest\erybjp\venv\lib\site-packages\flask\app.py", line 2447, in wsgi_app
    response = self.full_dispatch_request()
  File "D:\AutoTest\erybjp\venv\lib\site-packages\flask\app.py", line 1952, in full_dispatch_request
    rv = self.handle_user_exception(e)
  File "D:\AutoTest\erybjp\venv\lib\site-packages\flask_restful\__init__.py", line 271, in error_router
    return original_handler(e)
  File "D:\AutoTest\erybjp\venv\lib\site-packages\flask_cors\extension.py", line 165, in wrapped_function
    return cors_after_request(app.make_response(f(*args, **kwargs)))
  File "D:\AutoTest\erybjp\venv\lib\site-packages\flask\app.py", line 1821, in handle_user_exception
    reraise(exc_type, exc_value, tb)
  File "D:\AutoTest\erybjp\venv\lib\site-packages\flask\_compat.py", line 39, in reraise
    raise value
  File "D:\AutoTest\erybjp\venv\lib\site-packages\flask\app.py", line 1950, in full_dispatch_request
    rv = self.dispatch_request()
  File "D:\AutoTest\erybjp\venv\lib\site-packages\flask\app.py", line 1936, in dispatch_request
    return self.view_functions[rule.endpoint](**req.view_args)
  File "D:\AutoTest\erybjp\uiplatform\router\runtestcase.py", line 87, in jenkins_check
    jen.aliding_jenkins(arg, num)
  File "D:\AutoTest\erybjp\uiplatform\utils\business\cycle_check\test_jenkins_stage_production.py", line 91, in aliding_jenkins
    DingtalkRobot().send_markdown("jenkinsÊúçÂä°Âç†Áî®Ê£ÄÊµãÁªìÊûúÈÄöÁü•", text, [])
  File "D:\AutoTest\erybjp\uiplatform\services\ali_dingtalk.py", line 87, in send_markdown
    return self.__post(data)
  File "D:\AutoTest\erybjp\uiplatform\services\ali_dingtalk.py", line 104, in __post
    response = requests.post(self.__spliceUrl(), headers=self.headers, data=post_data)
  File "D:\AutoTest\erybjp\venv\lib\site-packages\requests\api.py", line 119, in post
    return request('post', url, data=data, json=json, **kwargs)
  File "D:\AutoTest\erybjp\venv\lib\site-packages\requests\api.py", line 61, in request
    return session.request(method=method, url=url, **kwargs)
  File "D:\AutoTest\erybjp\venv\lib\site-packages\requests\sessions.py", line 542, in request
    resp = self.send(prep, **send_kwargs)
  File "D:\AutoTest\erybjp\venv\lib\site-packages\requests\sessions.py", line 655, in send
    r = adapter.send(request, **kwargs)
  File "D:\AutoTest\erybjp\venv\lib\site-packages\requests\adapters.py", line 439, in send
    resp = conn.urlopen(
  File "D:\AutoTest\erybjp\venv\lib\site-packages\urllib3\connectionpool.py", line 696, in urlopen
    self._prepare_proxy(conn)
  File "D:\AutoTest\erybjp\venv\lib\site-packages\urllib3\connectionpool.py", line 964, in _prepare_proxy
    conn.connect()
  File "D:\AutoTest\erybjp\venv\lib\site-packages\urllib3\connection.py", line 359, in connect
    conn = self._connect_tls_proxy(hostname, conn)
  File "D:\AutoTest\erybjp\venv\lib\site-packages\urllib3\connection.py", line 500, in _connect_tls_proxy
    return ssl_wrap_socket(
  File "D:\AutoTest\erybjp\venv\lib\site-packages\urllib3\util\ssl_.py", line 432, in ssl_wrap_socket
    ssl_sock = _ssl_wrap_socket_impl(sock, context, tls_in_tls)
  File "D:\AutoTest\erybjp\venv\lib\site-packages\urllib3\util\ssl_.py", line 474, in _ssl_wrap_socket_impl
    return ssl_context.wrap_socket(sock)
  File "C:\Users\yuanbaojun\AppData\Local\Programs\Python\Python38\lib\ssl.py", line 500, in wrap_socket
    return self.sslsocket_class._create(
  File "C:\Users\yuanbaojun\AppData\Local\Programs\Python\Python38\lib\ssl.py", line 997, in _create
    raise ValueError("check_hostname requires server_hostname")
ValueError: check_hostname requires server_hostname
2021-07-07 18:08:46,810 [werkzeug] [29260:Thread-1] _internal.py:_internal:_log in 113] [INFO]: 127.0.0.1 - - [07/Jul/2021 18:08:46] "[35m[1mGET /element/henkins/check?servername_list=["lbk_activity"] HTTP/1.1[0m" 500 -
2021-07-07 19:16:07,671 [werkzeug] [2412:MainThread] _internal.py:_internal:_log in 113] [INFO]:  * Running on http://127.0.0.1:5000/ (Press CTRL+C to quit)
2021-07-07 19:17:31,799 [werkzeug] [30284:MainThread] _internal.py:_internal:_log in 113] [INFO]:  * Running on http://127.0.0.1:5000/ (Press CTRL+C to quit)
2021-07-07 19:19:25,812 [werkzeug] [6336:MainThread] _internal.py:_internal:_log in 113] [INFO]:  * Running on http://127.0.0.1:5000/ (Press CTRL+C to quit)
2021-07-07 19:19:30,416 [werkzeug] [13580:Thread-6] _internal.py:_internal:_log in 113] [INFO]: 127.0.0.1 - - [07/Jul/2021 19:19:30] "[31m[1mGET /element/henkins/check?servername_list=["lbk_activity","lbk_web_common"] HTTP/1.1[0m" 405 -
2021-07-07 19:19:41,884 [erybjp] [29888:Thread-7] app.py:app:log_exception in 1891] [ERROR]: Exception on /element/henkins/check [POST]
Traceback (most recent call last):
  File "D:\AutoTest\erybjp\venv\lib\site-packages\werkzeug\wrappers\json.py", line 119, in get_json
    rv = self.json_module.loads(data)
  File "D:\AutoTest\erybjp\venv\lib\site-packages\flask\json\__init__.py", line 253, in loads
    return _json.loads(s, **kwargs)
  File "C:\Users\yuanbaojun\AppData\Local\Programs\Python\Python38\lib\json\__init__.py", line 370, in loads
    return cls(**kw).decode(s)
  File "C:\Users\yuanbaojun\AppData\Local\Programs\Python\Python38\lib\json\decoder.py", line 337, in decode
    obj, end = self.raw_decode(s, idx=_w(s, 0).end())
  File "C:\Users\yuanbaojun\AppData\Local\Programs\Python\Python38\lib\json\decoder.py", line 355, in raw_decode
    raise JSONDecodeError("Expecting value", s, err.value) from None
json.decoder.JSONDecodeError: Expecting value: line 1 column 1 (char 0)

During handling of the above exception, another exception occurred:

Traceback (most recent call last):
  File "D:\AutoTest\erybjp\venv\lib\site-packages\flask\app.py", line 1950, in full_dispatch_request
    rv = self.dispatch_request()
  File "D:\AutoTest\erybjp\venv\lib\site-packages\flask\app.py", line 1936, in dispatch_request
    return self.view_functions[rule.endpoint](**req.view_args)
  File "D:\AutoTest\erybjp\uiplatform\router\runtestcase.py", line 84, in jenkins_check
    arg = request.get_json()
  File "D:\AutoTest\erybjp\venv\lib\site-packages\werkzeug\wrappers\json.py", line 128, in get_json
    rv = self.on_json_loading_failed(e)
  File "D:\AutoTest\erybjp\venv\lib\site-packages\flask\wrappers.py", line 27, in on_json_loading_failed
    raise BadRequest()
werkzeug.exceptions.BadRequest: 400 Bad Request: The browser (or proxy) sent a request that this server could not understand.

During handling of the above exception, another exception occurred:

Traceback (most recent call last):
  File "D:\AutoTest\erybjp\venv\lib\site-packages\flask\app.py", line 2447, in wsgi_app
    response = self.full_dispatch_request()
  File "D:\AutoTest\erybjp\venv\lib\site-packages\flask\app.py", line 1952, in full_dispatch_request
    rv = self.handle_user_exception(e)
  File "D:\AutoTest\erybjp\venv\lib\site-packages\flask_restful\__init__.py", line 271, in error_router
    return original_handler(e)
  File "D:\AutoTest\erybjp\venv\lib\site-packages\flask_cors\extension.py", line 165, in wrapped_function
    return cors_after_request(app.make_response(f(*args, **kwargs)))
  File "D:\AutoTest\erybjp\venv\lib\site-packages\flask\app.py", line 2097, in make_response
    raise TypeError(
TypeError: The view function did not return a valid response. The function either returned None or ended without a return statement.
2021-07-07 19:19:41,900 [werkzeug] [29888:Thread-7] _internal.py:_internal:_log in 113] [INFO]: 127.0.0.1 - - [07/Jul/2021 19:19:41] "[35m[1mPOST /element/henkins/check HTTP/1.1[0m" 500 -
2021-07-07 19:20:09,365 [werkzeug] [27520:MainThread] _internal.py:_internal:_log in 113] [INFO]:  * Running on http://127.0.0.1:5000/ (Press CTRL+C to quit)
2021-07-07 19:23:43,104 [werkzeug] [21596:MainThread] _internal.py:_internal:_log in 113] [INFO]:  * Running on http://127.0.0.1:5000/ (Press CTRL+C to quit)
2021-07-07 19:24:43,434 [erybjp] [23660:Thread-1] app.py:app:log_exception in 1891] [ERROR]: Exception on /element/henkins/check [POST]
Traceback (most recent call last):
  File "D:\AutoTest\erybjp\venv\lib\site-packages\flask\app.py", line 2447, in wsgi_app
    response = self.full_dispatch_request()
  File "D:\AutoTest\erybjp\venv\lib\site-packages\flask\app.py", line 1952, in full_dispatch_request
    rv = self.handle_user_exception(e)
  File "D:\AutoTest\erybjp\venv\lib\site-packages\flask_restful\__init__.py", line 271, in error_router
    return original_handler(e)
  File "D:\AutoTest\erybjp\venv\lib\site-packages\flask_cors\extension.py", line 165, in wrapped_function
    return cors_after_request(app.make_response(f(*args, **kwargs)))
  File "D:\AutoTest\erybjp\venv\lib\site-packages\flask\app.py", line 1821, in handle_user_exception
    reraise(exc_type, exc_value, tb)
  File "D:\AutoTest\erybjp\venv\lib\site-packages\flask\_compat.py", line 39, in reraise
    raise value
  File "D:\AutoTest\erybjp\venv\lib\site-packages\flask\app.py", line 1950, in full_dispatch_request
    rv = self.dispatch_request()
  File "D:\AutoTest\erybjp\venv\lib\site-packages\flask\app.py", line 1936, in dispatch_request
    return self.view_functions[rule.endpoint](**req.view_args)
  File "D:\AutoTest\erybjp\uiplatform\router\runtestcase.py", line 88, in jenkins_check
    jen.aliding_jenkins(arg.get("servername_list"), num)
  File "D:\AutoTest\erybjp\uiplatform\utils\business\cycle_check\test_jenkins_stage_production.py", line 89, in aliding_jenkins
    data = jen.test_staging_production_compare(servername_list)
  File "D:\AutoTest\erybjp\uiplatform\utils\business\cycle_check\test_jenkins_stage_production.py", line 76, in test_staging_production_compare
    production_num = self.test_production_server(servername)
  File "D:\AutoTest\erybjp\uiplatform\utils\business\cycle_check\test_jenkins_stage_production.py", line 64, in test_production_server
    self.page.product_para_element.click()
  File "D:\AutoTest\erybjp\uiplatform\utils\common\BasePage.py", line 261, in click
    elem = self.__get_element(self.k, self.v)
  File "D:\AutoTest\erybjp\uiplatform\utils\common\BasePage.py", line 185, in __get_element
    self.__find_element((By.CSS_SELECTOR, value))
  File "D:\AutoTest\erybjp\uiplatform\utils\common\BasePage.py", line 155, in __find_element
    raise NoSuchElementException(error_msg)
selenium.common.exceptions.NoSuchElementException: Message: ‚ùå Find 0 elements through: css selector=a[title='Parameters']

2021-07-07 19:24:43,454 [werkzeug] [23660:Thread-1] _internal.py:_internal:_log in 113] [INFO]: 127.0.0.1 - - [07/Jul/2021 19:24:43] "[35m[1mPOST /element/henkins/check HTTP/1.1[0m" 500 -
2021-07-07 19:43:57,329 [werkzeug] [29016:MainThread] _internal.py:_internal:_log in 113] [INFO]:  * Running on http://127.0.0.1:5000/ (Press CTRL+C to quit)
2021-07-07 19:44:40,566 [erybjp] [31496:Thread-1] app.py:app:log_exception in 1891] [ERROR]: Exception on /element/henkins/check [POST]
Traceback (most recent call last):
  File "D:\AutoTest\erybjp\venv\lib\site-packages\flask\app.py", line 2447, in wsgi_app
    response = self.full_dispatch_request()
  File "D:\AutoTest\erybjp\venv\lib\site-packages\flask\app.py", line 1952, in full_dispatch_request
    rv = self.handle_user_exception(e)
  File "D:\AutoTest\erybjp\venv\lib\site-packages\flask_restful\__init__.py", line 271, in error_router
    return original_handler(e)
  File "D:\AutoTest\erybjp\venv\lib\site-packages\flask_cors\extension.py", line 165, in wrapped_function
    return cors_after_request(app.make_response(f(*args, **kwargs)))
  File "D:\AutoTest\erybjp\venv\lib\site-packages\flask\app.py", line 1821, in handle_user_exception
    reraise(exc_type, exc_value, tb)
  File "D:\AutoTest\erybjp\venv\lib\site-packages\flask\_compat.py", line 39, in reraise
    raise value
  File "D:\AutoTest\erybjp\venv\lib\site-packages\flask\app.py", line 1950, in full_dispatch_request
    rv = self.dispatch_request()
  File "D:\AutoTest\erybjp\venv\lib\site-packages\flask\app.py", line 1936, in dispatch_request
    return self.view_functions[rule.endpoint](**req.view_args)
  File "D:\AutoTest\erybjp\uiplatform\router\runtestcase.py", line 88, in jenkins_check
    jen.aliding_jenkins(arg.get("servername_list"), num)
  File "D:\AutoTest\erybjp\uiplatform\utils\business\cycle_check\test_jenkins_stage_production.py", line 92, in aliding_jenkins
    DingtalkRobot().send_markdown("jenkinsÊúçÂä°Âç†Áî®Ê£ÄÊµãÁªìÊûúÈÄöÁü•", text, [])
  File "D:\AutoTest\erybjp\uiplatform\services\ali_dingtalk.py", line 87, in send_markdown
    return self.__post(data)
  File "D:\AutoTest\erybjp\uiplatform\services\ali_dingtalk.py", line 104, in __post
    response = requests.post(self.__spliceUrl(), headers=self.headers, data=post_data)
  File "D:\AutoTest\erybjp\venv\lib\site-packages\requests\api.py", line 119, in post
    return request('post', url, data=data, json=json, **kwargs)
  File "D:\AutoTest\erybjp\venv\lib\site-packages\requests\api.py", line 61, in request
    return session.request(method=method, url=url, **kwargs)
  File "D:\AutoTest\erybjp\venv\lib\site-packages\requests\sessions.py", line 542, in request
    resp = self.send(prep, **send_kwargs)
  File "D:\AutoTest\erybjp\venv\lib\site-packages\requests\sessions.py", line 655, in send
    r = adapter.send(request, **kwargs)
  File "D:\AutoTest\erybjp\venv\lib\site-packages\requests\adapters.py", line 439, in send
    resp = conn.urlopen(
  File "D:\AutoTest\erybjp\venv\lib\site-packages\urllib3\connectionpool.py", line 696, in urlopen
    self._prepare_proxy(conn)
  File "D:\AutoTest\erybjp\venv\lib\site-packages\urllib3\connectionpool.py", line 964, in _prepare_proxy
    conn.connect()
  File "D:\AutoTest\erybjp\venv\lib\site-packages\urllib3\connection.py", line 359, in connect
    conn = self._connect_tls_proxy(hostname, conn)
  File "D:\AutoTest\erybjp\venv\lib\site-packages\urllib3\connection.py", line 500, in _connect_tls_proxy
    return ssl_wrap_socket(
  File "D:\AutoTest\erybjp\venv\lib\site-packages\urllib3\util\ssl_.py", line 432, in ssl_wrap_socket
    ssl_sock = _ssl_wrap_socket_impl(sock, context, tls_in_tls)
  File "D:\AutoTest\erybjp\venv\lib\site-packages\urllib3\util\ssl_.py", line 474, in _ssl_wrap_socket_impl
    return ssl_context.wrap_socket(sock)
  File "C:\Users\yuanbaojun\AppData\Local\Programs\Python\Python38\lib\ssl.py", line 500, in wrap_socket
    return self.sslsocket_class._create(
  File "C:\Users\yuanbaojun\AppData\Local\Programs\Python\Python38\lib\ssl.py", line 997, in _create
    raise ValueError("check_hostname requires server_hostname")
ValueError: check_hostname requires server_hostname
2021-07-07 19:44:40,577 [werkzeug] [31496:Thread-1] _internal.py:_internal:_log in 113] [INFO]: 127.0.0.1 - - [07/Jul/2021 19:44:40] "[35m[1mPOST /element/henkins/check HTTP/1.1[0m" 500 -
2021-07-07 19:47:54,903 [werkzeug] [27436:Thread-14] _internal.py:_internal:_log in 113] [INFO]: 127.0.0.1 - - [07/Jul/2021 19:47:54] "[37mPOST /element/henkins/check HTTP/1.1[0m" 200 -
2021-07-07 20:21:45,959 [werkzeug] [32708:MainThread] _internal.py:_internal:_log in 113] [INFO]:  * Running on http://127.0.0.1:5000/ (Press CTRL+C to quit)
2021-07-07 20:22:03,808 [werkzeug] [29188:Thread-1] _internal.py:_internal:_log in 113] [INFO]: 127.0.0.1 - - [07/Jul/2021 20:22:03] "[37mPOST /element/henkins/check HTTP/1.1[0m" 200 -
2021-07-07 20:22:39,056 [werkzeug] [27520:Thread-3] _internal.py:_internal:_log in 113] [INFO]: 127.0.0.1 - - [07/Jul/2021 20:22:39] "[37mPOST /element/henkins/check HTTP/1.1[0m" 200 -
2021-07-07 20:25:31,001 [werkzeug] [32604:Thread-5] _internal.py:_internal:_log in 113] [INFO]: 127.0.0.1 - - [07/Jul/2021 20:25:31] "[37mPOST /element/henkins/check HTTP/1.1[0m" 200 -
2021-07-07 20:27:52,658 [werkzeug] [20320:MainThread] _internal.py:_internal:_log in 113] [INFO]:  * Running on http://127.0.0.1:5000/ (Press CTRL+C to quit)
2021-07-07 20:27:56,009 [werkzeug] [20288:Thread-1] _internal.py:_internal:_log in 113] [INFO]: 127.0.0.1 - - [07/Jul/2021 20:27:56] "[37mPOST /element/henkins/check HTTP/1.1[0m" 200 -
2021-07-09 12:01:53,258 [werkzeug] [3208:MainThread] _internal.py:_internal:_log in 113] [INFO]:  * Running on http://127.0.0.1:6851/ (Press CTRL+C to quit)
2021-07-09 13:41:57,236 [werkzeug] [10956:Thread-1] _internal.py:_internal:_log in 113] [INFO]: 127.0.0.1 - - [09/Jul/2021 13:41:57] "[33mPOST /jenkins/check HTTP/1.1[0m" 404 -
2021-07-09 13:42:41,102 [werkzeug] [5980:Thread-2] _internal.py:_internal:_log in 113] [INFO]: 127.0.0.1 - - [09/Jul/2021 13:42:41] "[33mPOST /jenkins/check HTTP/1.1[0m" 404 -
2021-07-09 13:42:42,969 [werkzeug] [13012:Thread-3] _internal.py:_internal:_log in 113] [INFO]: 127.0.0.1 - - [09/Jul/2021 13:42:42] "[33mPOST /jenkins/check HTTP/1.1[0m" 404 -
2021-07-09 13:43:30,920 [werkzeug] [8336:MainThread] _internal.py:_internal:_log in 113] [INFO]:  * Running on http://127.0.0.1:6851/ (Press CTRL+C to quit)
2021-07-09 13:43:46,136 [werkzeug] [15152:Thread-1] _internal.py:_internal:_log in 113] [INFO]: 127.0.0.1 - - [09/Jul/2021 13:43:46] "[33mPOST /jenkins/check HTTP/1.1[0m" 404 -
2021-07-09 13:44:25,651 [erybjp] [4888:Thread-2] app.py:app:log_exception in 1891] [ERROR]: Exception on /element/jenkins/check [POST]
Traceback (most recent call last):
  File "C:\Users\lx\AppData\Local\Programs\Python\Python38\lib\site-packages\werkzeug\wrappers\json.py", line 119, in get_json
    rv = self.json_module.loads(data)
  File "C:\Users\lx\AppData\Local\Programs\Python\Python38\lib\site-packages\flask\json\__init__.py", line 253, in loads
    return _json.loads(s, **kwargs)
  File "C:\Users\lx\AppData\Local\Programs\Python\Python38\lib\json\__init__.py", line 370, in loads
    return cls(**kw).decode(s)
  File "C:\Users\lx\AppData\Local\Programs\Python\Python38\lib\json\decoder.py", line 337, in decode
    obj, end = self.raw_decode(s, idx=_w(s, 0).end())
  File "C:\Users\lx\AppData\Local\Programs\Python\Python38\lib\json\decoder.py", line 355, in raw_decode
    raise JSONDecodeError("Expecting value", s, err.value) from None
json.decoder.JSONDecodeError: Expecting value: line 1 column 1 (char 0)

During handling of the above exception, another exception occurred:

Traceback (most recent call last):
  File "C:\Users\lx\AppData\Local\Programs\Python\Python38\lib\site-packages\flask\app.py", line 1950, in full_dispatch_request
    rv = self.dispatch_request()
  File "C:\Users\lx\AppData\Local\Programs\Python\Python38\lib\site-packages\flask\app.py", line 1936, in dispatch_request
    return self.view_functions[rule.endpoint](**req.view_args)
  File "D:\ÊµãËØïÂ≠¶‰π†ÊñáÊ°£\erybjp-master\uiplatform\router\runtestcase.py", line 83, in jenkins_check
    arg = request.get_json()
  File "C:\Users\lx\AppData\Local\Programs\Python\Python38\lib\site-packages\werkzeug\wrappers\json.py", line 128, in get_json
    rv = self.on_json_loading_failed(e)
  File "C:\Users\lx\AppData\Local\Programs\Python\Python38\lib\site-packages\flask\wrappers.py", line 27, in on_json_loading_failed
    raise BadRequest()
werkzeug.exceptions.BadRequest: 400 Bad Request: The browser (or proxy) sent a request that this server could not understand.

During handling of the above exception, another exception occurred:

Traceback (most recent call last):
  File "C:\Users\lx\AppData\Local\Programs\Python\Python38\lib\site-packages\flask\app.py", line 2447, in wsgi_app
    response = self.full_dispatch_request()
  File "C:\Users\lx\AppData\Local\Programs\Python\Python38\lib\site-packages\flask\app.py", line 1952, in full_dispatch_request
    rv = self.handle_user_exception(e)
  File "C:\Users\lx\AppData\Local\Programs\Python\Python38\lib\site-packages\flask_restful\__init__.py", line 271, in error_router
    return original_handler(e)
  File "C:\Users\lx\AppData\Local\Programs\Python\Python38\lib\site-packages\flask_cors\extension.py", line 165, in wrapped_function
    return cors_after_request(app.make_response(f(*args, **kwargs)))
  File "C:\Users\lx\AppData\Local\Programs\Python\Python38\lib\site-packages\flask\app.py", line 2097, in make_response
    raise TypeError(
TypeError: The view function did not return a valid response. The function either returned None or ended without a return statement.
2021-07-09 13:44:25,735 [werkzeug] [4888:Thread-2] _internal.py:_internal:_log in 113] [INFO]: 127.0.0.1 - - [09/Jul/2021 13:44:25] "[35m[1mPOST /element/jenkins/check HTTP/1.1[0m" 500 -
2021-07-09 13:45:13,930 [erybjp] [2020:Thread-3] app.py:app:log_exception in 1891] [ERROR]: Exception on /element/jenkins/check [POST]
Traceback (most recent call last):
  File "C:\Users\lx\AppData\Local\Programs\Python\Python38\lib\site-packages\werkzeug\wrappers\json.py", line 119, in get_json
    rv = self.json_module.loads(data)
  File "C:\Users\lx\AppData\Local\Programs\Python\Python38\lib\site-packages\flask\json\__init__.py", line 253, in loads
    return _json.loads(s, **kwargs)
  File "C:\Users\lx\AppData\Local\Programs\Python\Python38\lib\json\__init__.py", line 370, in loads
    return cls(**kw).decode(s)
  File "C:\Users\lx\AppData\Local\Programs\Python\Python38\lib\json\decoder.py", line 337, in decode
    obj, end = self.raw_decode(s, idx=_w(s, 0).end())
  File "C:\Users\lx\AppData\Local\Programs\Python\Python38\lib\json\decoder.py", line 355, in raw_decode
    raise JSONDecodeError("Expecting value", s, err.value) from None
json.decoder.JSONDecodeError: Expecting value: line 1 column 1 (char 0)

During handling of the above exception, another exception occurred:

Traceback (most recent call last):
  File "C:\Users\lx\AppData\Local\Programs\Python\Python38\lib\site-packages\flask\app.py", line 1950, in full_dispatch_request
    rv = self.dispatch_request()
  File "C:\Users\lx\AppData\Local\Programs\Python\Python38\lib\site-packages\flask\app.py", line 1936, in dispatch_request
    return self.view_functions[rule.endpoint](**req.view_args)
  File "D:\ÊµãËØïÂ≠¶‰π†ÊñáÊ°£\erybjp-master\uiplatform\router\runtestcase.py", line 83, in jenkins_check
    arg = request.get_json()
  File "C:\Users\lx\AppData\Local\Programs\Python\Python38\lib\site-packages\werkzeug\wrappers\json.py", line 128, in get_json
    rv = self.on_json_loading_failed(e)
  File "C:\Users\lx\AppData\Local\Programs\Python\Python38\lib\site-packages\flask\wrappers.py", line 27, in on_json_loading_failed
    raise BadRequest()
werkzeug.exceptions.BadRequest: 400 Bad Request: The browser (or proxy) sent a request that this server could not understand.

During handling of the above exception, another exception occurred:

Traceback (most recent call last):
  File "C:\Users\lx\AppData\Local\Programs\Python\Python38\lib\site-packages\flask\app.py", line 2447, in wsgi_app
    response = self.full_dispatch_request()
  File "C:\Users\lx\AppData\Local\Programs\Python\Python38\lib\site-packages\flask\app.py", line 1952, in full_dispatch_request
    rv = self.handle_user_exception(e)
  File "C:\Users\lx\AppData\Local\Programs\Python\Python38\lib\site-packages\flask_restful\__init__.py", line 271, in error_router
    return original_handler(e)
  File "C:\Users\lx\AppData\Local\Programs\Python\Python38\lib\site-packages\flask_cors\extension.py", line 165, in wrapped_function
    return cors_after_request(app.make_response(f(*args, **kwargs)))
  File "C:\Users\lx\AppData\Local\Programs\Python\Python38\lib\site-packages\flask\app.py", line 2097, in make_response
    raise TypeError(
TypeError: The view function did not return a valid response. The function either returned None or ended without a return statement.
2021-07-09 13:45:13,931 [werkzeug] [2020:Thread-3] _internal.py:_internal:_log in 113] [INFO]: 127.0.0.1 - - [09/Jul/2021 13:45:13] "[35m[1mPOST /element/jenkins/check HTTP/1.1[0m" 500 -
2021-07-09 13:45:45,457 [werkzeug] [3220:MainThread] _internal.py:_internal:_log in 113] [INFO]:  * Running on http://127.0.0.1:6851/ (Press CTRL+C to quit)
2021-07-09 13:45:49,755 [erybjp] [10108:Thread-1] app.py:app:log_exception in 1891] [ERROR]: Exception on /element/jenkins/check [POST]
Traceback (most recent call last):
  File "C:\Users\lx\AppData\Local\Programs\Python\Python38\lib\site-packages\werkzeug\wrappers\json.py", line 119, in get_json
    rv = self.json_module.loads(data)
  File "C:\Users\lx\AppData\Local\Programs\Python\Python38\lib\site-packages\flask\json\__init__.py", line 253, in loads
    return _json.loads(s, **kwargs)
  File "C:\Users\lx\AppData\Local\Programs\Python\Python38\lib\json\__init__.py", line 370, in loads
    return cls(**kw).decode(s)
  File "C:\Users\lx\AppData\Local\Programs\Python\Python38\lib\json\decoder.py", line 337, in decode
    obj, end = self.raw_decode(s, idx=_w(s, 0).end())
  File "C:\Users\lx\AppData\Local\Programs\Python\Python38\lib\json\decoder.py", line 355, in raw_decode
    raise JSONDecodeError("Expecting value", s, err.value) from None
json.decoder.JSONDecodeError: Expecting value: line 1 column 1 (char 0)

During handling of the above exception, another exception occurred:

Traceback (most recent call last):
  File "C:\Users\lx\AppData\Local\Programs\Python\Python38\lib\site-packages\flask\app.py", line 1950, in full_dispatch_request
    rv = self.dispatch_request()
  File "C:\Users\lx\AppData\Local\Programs\Python\Python38\lib\site-packages\flask\app.py", line 1936, in dispatch_request
    return self.view_functions[rule.endpoint](**req.view_args)
  File "D:\ÊµãËØïÂ≠¶‰π†ÊñáÊ°£\erybjp-master\uiplatform\router\runtestcase.py", line 83, in jenkins_check
    arg = request.get_json()
  File "C:\Users\lx\AppData\Local\Programs\Python\Python38\lib\site-packages\werkzeug\wrappers\json.py", line 128, in get_json
    rv = self.on_json_loading_failed(e)
  File "C:\Users\lx\AppData\Local\Programs\Python\Python38\lib\site-packages\flask\wrappers.py", line 27, in on_json_loading_failed
    raise BadRequest()
werkzeug.exceptions.BadRequest: 400 Bad Request: The browser (or proxy) sent a request that this server could not understand.

During handling of the above exception, another exception occurred:

Traceback (most recent call last):
  File "C:\Users\lx\AppData\Local\Programs\Python\Python38\lib\site-packages\flask\app.py", line 2447, in wsgi_app
    response = self.full_dispatch_request()
  File "C:\Users\lx\AppData\Local\Programs\Python\Python38\lib\site-packages\flask\app.py", line 1952, in full_dispatch_request
    rv = self.handle_user_exception(e)
  File "C:\Users\lx\AppData\Local\Programs\Python\Python38\lib\site-packages\flask_restful\__init__.py", line 271, in error_router
    return original_handler(e)
  File "C:\Users\lx\AppData\Local\Programs\Python\Python38\lib\site-packages\flask_cors\extension.py", line 165, in wrapped_function
    return cors_after_request(app.make_response(f(*args, **kwargs)))
  File "C:\Users\lx\AppData\Local\Programs\Python\Python38\lib\site-packages\flask\app.py", line 2097, in make_response
    raise TypeError(
TypeError: The view function did not return a valid response. The function either returned None or ended without a return statement.
2021-07-09 13:45:49,773 [werkzeug] [10108:Thread-1] _internal.py:_internal:_log in 113] [INFO]: 127.0.0.1 - - [09/Jul/2021 13:45:49] "[35m[1mPOST /element/jenkins/check HTTP/1.1[0m" 500 -
2021-07-09 13:47:38,545 [erybjp] [14308:Thread-2] app.py:app:log_exception in 1891] [ERROR]: Exception on /element/jenkins/check [POST]
Traceback (most recent call last):
  File "C:\Users\lx\AppData\Local\Programs\Python\Python38\lib\site-packages\werkzeug\wrappers\json.py", line 119, in get_json
    rv = self.json_module.loads(data)
  File "C:\Users\lx\AppData\Local\Programs\Python\Python38\lib\site-packages\flask\json\__init__.py", line 253, in loads
    return _json.loads(s, **kwargs)
  File "C:\Users\lx\AppData\Local\Programs\Python\Python38\lib\json\__init__.py", line 370, in loads
    return cls(**kw).decode(s)
  File "C:\Users\lx\AppData\Local\Programs\Python\Python38\lib\json\decoder.py", line 337, in decode
    obj, end = self.raw_decode(s, idx=_w(s, 0).end())
  File "C:\Users\lx\AppData\Local\Programs\Python\Python38\lib\json\decoder.py", line 355, in raw_decode
    raise JSONDecodeError("Expecting value", s, err.value) from None
json.decoder.JSONDecodeError: Expecting value: line 1 column 1 (char 0)

During handling of the above exception, another exception occurred:

Traceback (most recent call last):
  File "C:\Users\lx\AppData\Local\Programs\Python\Python38\lib\site-packages\flask\app.py", line 1950, in full_dispatch_request
    rv = self.dispatch_request()
  File "C:\Users\lx\AppData\Local\Programs\Python\Python38\lib\site-packages\flask\app.py", line 1936, in dispatch_request
    return self.view_functions[rule.endpoint](**req.view_args)
  File "D:\ÊµãËØïÂ≠¶‰π†ÊñáÊ°£\erybjp-master\uiplatform\router\runtestcase.py", line 83, in jenkins_check
    arg = request.get_json()
  File "C:\Users\lx\AppData\Local\Programs\Python\Python38\lib\site-packages\werkzeug\wrappers\json.py", line 128, in get_json
    rv = self.on_json_loading_failed(e)
  File "C:\Users\lx\AppData\Local\Programs\Python\Python38\lib\site-packages\flask\wrappers.py", line 27, in on_json_loading_failed
    raise BadRequest()
werkzeug.exceptions.BadRequest: 400 Bad Request: The browser (or proxy) sent a request that this server could not understand.

During handling of the above exception, another exception occurred:

Traceback (most recent call last):
  File "C:\Users\lx\AppData\Local\Programs\Python\Python38\lib\site-packages\flask\app.py", line 2447, in wsgi_app
    response = self.full_dispatch_request()
  File "C:\Users\lx\AppData\Local\Programs\Python\Python38\lib\site-packages\flask\app.py", line 1952, in full_dispatch_request
    rv = self.handle_user_exception(e)
  File "C:\Users\lx\AppData\Local\Programs\Python\Python38\lib\site-packages\flask_restful\__init__.py", line 271, in error_router
    return original_handler(e)
  File "C:\Users\lx\AppData\Local\Programs\Python\Python38\lib\site-packages\flask_cors\extension.py", line 165, in wrapped_function
    return cors_after_request(app.make_response(f(*args, **kwargs)))
  File "C:\Users\lx\AppData\Local\Programs\Python\Python38\lib\site-packages\flask\app.py", line 2097, in make_response
    raise TypeError(
TypeError: The view function did not return a valid response. The function either returned None or ended without a return statement.
2021-07-09 13:47:38,559 [werkzeug] [14308:Thread-2] _internal.py:_internal:_log in 113] [INFO]: 127.0.0.1 - - [09/Jul/2021 13:47:38] "[35m[1mPOST /element/jenkins/check HTTP/1.1[0m" 500 -
2021-07-09 13:47:48,067 [werkzeug] [7476:MainThread] _internal.py:_internal:_log in 113] [INFO]:  * Running on http://127.0.0.1:6851/ (Press CTRL+C to quit)
2021-07-09 13:47:49,857 [erybjp] [13956:Thread-1] app.py:app:log_exception in 1891] [ERROR]: Exception on /element/jenkins/check [POST]
Traceback (most recent call last):
  File "C:\Users\lx\AppData\Local\Programs\Python\Python38\lib\site-packages\werkzeug\wrappers\json.py", line 119, in get_json
    rv = self.json_module.loads(data)
  File "C:\Users\lx\AppData\Local\Programs\Python\Python38\lib\site-packages\flask\json\__init__.py", line 253, in loads
    return _json.loads(s, **kwargs)
  File "C:\Users\lx\AppData\Local\Programs\Python\Python38\lib\json\__init__.py", line 370, in loads
    return cls(**kw).decode(s)
  File "C:\Users\lx\AppData\Local\Programs\Python\Python38\lib\json\decoder.py", line 337, in decode
    obj, end = self.raw_decode(s, idx=_w(s, 0).end())
  File "C:\Users\lx\AppData\Local\Programs\Python\Python38\lib\json\decoder.py", line 355, in raw_decode
    raise JSONDecodeError("Expecting value", s, err.value) from None
json.decoder.JSONDecodeError: Expecting value: line 1 column 1 (char 0)

During handling of the above exception, another exception occurred:

Traceback (most recent call last):
  File "C:\Users\lx\AppData\Local\Programs\Python\Python38\lib\site-packages\flask\app.py", line 1950, in full_dispatch_request
    rv = self.dispatch_request()
  File "C:\Users\lx\AppData\Local\Programs\Python\Python38\lib\site-packages\flask\app.py", line 1936, in dispatch_request
    return self.view_functions[rule.endpoint](**req.view_args)
  File "D:\ÊµãËØïÂ≠¶‰π†ÊñáÊ°£\erybjp-master\uiplatform\router\runtestcase.py", line 83, in jenkins_check
    arg = request.get_json()
  File "C:\Users\lx\AppData\Local\Programs\Python\Python38\lib\site-packages\werkzeug\wrappers\json.py", line 128, in get_json
    rv = self.on_json_loading_failed(e)
  File "C:\Users\lx\AppData\Local\Programs\Python\Python38\lib\site-packages\flask\wrappers.py", line 27, in on_json_loading_failed
    raise BadRequest()
werkzeug.exceptions.BadRequest: 400 Bad Request: The browser (or proxy) sent a request that this server could not understand.

During handling of the above exception, another exception occurred:

Traceback (most recent call last):
  File "C:\Users\lx\AppData\Local\Programs\Python\Python38\lib\site-packages\flask\app.py", line 2447, in wsgi_app
    response = self.full_dispatch_request()
  File "C:\Users\lx\AppData\Local\Programs\Python\Python38\lib\site-packages\flask\app.py", line 1952, in full_dispatch_request
    rv = self.handle_user_exception(e)
  File "C:\Users\lx\AppData\Local\Programs\Python\Python38\lib\site-packages\flask_restful\__init__.py", line 271, in error_router
    return original_handler(e)
  File "C:\Users\lx\AppData\Local\Programs\Python\Python38\lib\site-packages\flask_cors\extension.py", line 165, in wrapped_function
    return cors_after_request(app.make_response(f(*args, **kwargs)))
  File "C:\Users\lx\AppData\Local\Programs\Python\Python38\lib\site-packages\flask\app.py", line 2097, in make_response
    raise TypeError(
TypeError: The view function did not return a valid response. The function either returned None or ended without a return statement.
2021-07-09 13:47:49,862 [werkzeug] [13956:Thread-1] _internal.py:_internal:_log in 113] [INFO]: 127.0.0.1 - - [09/Jul/2021 13:47:49] "[35m[1mPOST /element/jenkins/check HTTP/1.1[0m" 500 -
2021-07-09 13:48:32,725 [werkzeug] [9928:MainThread] _internal.py:_internal:_log in 113] [INFO]:  * Running on http://127.0.0.1:6851/ (Press CTRL+C to quit)
2021-07-09 13:48:34,233 [erybjp] [12868:Thread-1] app.py:app:log_exception in 1891] [ERROR]: Exception on /element/jenkins/check [POST]
Traceback (most recent call last):
  File "C:\Users\lx\AppData\Local\Programs\Python\Python38\lib\site-packages\werkzeug\wrappers\json.py", line 119, in get_json
    rv = self.json_module.loads(data)
  File "C:\Users\lx\AppData\Local\Programs\Python\Python38\lib\site-packages\flask\json\__init__.py", line 253, in loads
    return _json.loads(s, **kwargs)
  File "C:\Users\lx\AppData\Local\Programs\Python\Python38\lib\json\__init__.py", line 370, in loads
    return cls(**kw).decode(s)
  File "C:\Users\lx\AppData\Local\Programs\Python\Python38\lib\json\decoder.py", line 337, in decode
    obj, end = self.raw_decode(s, idx=_w(s, 0).end())
  File "C:\Users\lx\AppData\Local\Programs\Python\Python38\lib\json\decoder.py", line 355, in raw_decode
    raise JSONDecodeError("Expecting value", s, err.value) from None
json.decoder.JSONDecodeError: Expecting value: line 1 column 1 (char 0)

During handling of the above exception, another exception occurred:

Traceback (most recent call last):
  File "C:\Users\lx\AppData\Local\Programs\Python\Python38\lib\site-packages\flask\app.py", line 1950, in full_dispatch_request
    rv = self.dispatch_request()
  File "C:\Users\lx\AppData\Local\Programs\Python\Python38\lib\site-packages\flask\app.py", line 1936, in dispatch_request
    return self.view_functions[rule.endpoint](**req.view_args)
  File "D:\ÊµãËØïÂ≠¶‰π†ÊñáÊ°£\erybjp-master\uiplatform\router\runtestcase.py", line 84, in jenkins_check
    arg = request.get_json()
  File "C:\Users\lx\AppData\Local\Programs\Python\Python38\lib\site-packages\werkzeug\wrappers\json.py", line 128, in get_json
    rv = self.on_json_loading_failed(e)
  File "C:\Users\lx\AppData\Local\Programs\Python\Python38\lib\site-packages\flask\wrappers.py", line 27, in on_json_loading_failed
    raise BadRequest()
werkzeug.exceptions.BadRequest: 400 Bad Request: The browser (or proxy) sent a request that this server could not understand.

During handling of the above exception, another exception occurred:

Traceback (most recent call last):
  File "C:\Users\lx\AppData\Local\Programs\Python\Python38\lib\site-packages\flask\app.py", line 2447, in wsgi_app
    response = self.full_dispatch_request()
  File "C:\Users\lx\AppData\Local\Programs\Python\Python38\lib\site-packages\flask\app.py", line 1952, in full_dispatch_request
    rv = self.handle_user_exception(e)
  File "C:\Users\lx\AppData\Local\Programs\Python\Python38\lib\site-packages\flask_restful\__init__.py", line 271, in error_router
    return original_handler(e)
  File "C:\Users\lx\AppData\Local\Programs\Python\Python38\lib\site-packages\flask_cors\extension.py", line 165, in wrapped_function
    return cors_after_request(app.make_response(f(*args, **kwargs)))
  File "C:\Users\lx\AppData\Local\Programs\Python\Python38\lib\site-packages\flask\app.py", line 2097, in make_response
    raise TypeError(
TypeError: The view function did not return a valid response. The function either returned None or ended without a return statement.
2021-07-09 13:48:34,247 [werkzeug] [12868:Thread-1] _internal.py:_internal:_log in 113] [INFO]: 127.0.0.1 - - [09/Jul/2021 13:48:34] "[35m[1mPOST /element/jenkins/check HTTP/1.1[0m" 500 -
2021-07-09 13:50:03,462 [werkzeug] [7032:MainThread] _internal.py:_internal:_log in 113] [INFO]:  * Running on http://127.0.0.1:6851/ (Press CTRL+C to quit)
2021-07-09 13:50:10,103 [werkzeug] [10120:Thread-1] _internal.py:_internal:_log in 113] [INFO]: 127.0.0.1 - - [09/Jul/2021 13:50:10] "[33mPOST /element/jenkins/check HTTP/1.1[0m" 404 -
2021-07-09 13:50:42,538 [erybjp] [16212:Thread-2] app.py:app:log_exception in 1891] [ERROR]: Exception on /element/henkins/check [POST]
Traceback (most recent call last):
  File "C:\Users\lx\AppData\Local\Programs\Python\Python38\lib\site-packages\werkzeug\wrappers\json.py", line 119, in get_json
    rv = self.json_module.loads(data)
  File "C:\Users\lx\AppData\Local\Programs\Python\Python38\lib\site-packages\flask\json\__init__.py", line 253, in loads
    return _json.loads(s, **kwargs)
  File "C:\Users\lx\AppData\Local\Programs\Python\Python38\lib\json\__init__.py", line 370, in loads
    return cls(**kw).decode(s)
  File "C:\Users\lx\AppData\Local\Programs\Python\Python38\lib\json\decoder.py", line 337, in decode
    obj, end = self.raw_decode(s, idx=_w(s, 0).end())
  File "C:\Users\lx\AppData\Local\Programs\Python\Python38\lib\json\decoder.py", line 355, in raw_decode
    raise JSONDecodeError("Expecting value", s, err.value) from None
json.decoder.JSONDecodeError: Expecting value: line 1 column 1 (char 0)

During handling of the above exception, another exception occurred:

Traceback (most recent call last):
  File "C:\Users\lx\AppData\Local\Programs\Python\Python38\lib\site-packages\flask\app.py", line 1950, in full_dispatch_request
    rv = self.dispatch_request()
  File "C:\Users\lx\AppData\Local\Programs\Python\Python38\lib\site-packages\flask\app.py", line 1936, in dispatch_request
    return self.view_functions[rule.endpoint](**req.view_args)
  File "D:\ÊµãËØïÂ≠¶‰π†ÊñáÊ°£\erybjp-master\uiplatform\router\runtestcase.py", line 83, in jenkins_check
    arg = request.get_json()
  File "C:\Users\lx\AppData\Local\Programs\Python\Python38\lib\site-packages\werkzeug\wrappers\json.py", line 128, in get_json
    rv = self.on_json_loading_failed(e)
  File "C:\Users\lx\AppData\Local\Programs\Python\Python38\lib\site-packages\flask\wrappers.py", line 27, in on_json_loading_failed
    raise BadRequest()
werkzeug.exceptions.BadRequest: 400 Bad Request: The browser (or proxy) sent a request that this server could not understand.

During handling of the above exception, another exception occurred:

Traceback (most recent call last):
  File "C:\Users\lx\AppData\Local\Programs\Python\Python38\lib\site-packages\flask\app.py", line 2447, in wsgi_app
    response = self.full_dispatch_request()
  File "C:\Users\lx\AppData\Local\Programs\Python\Python38\lib\site-packages\flask\app.py", line 1952, in full_dispatch_request
    rv = self.handle_user_exception(e)
  File "C:\Users\lx\AppData\Local\Programs\Python\Python38\lib\site-packages\flask_restful\__init__.py", line 271, in error_router
    return original_handler(e)
  File "C:\Users\lx\AppData\Local\Programs\Python\Python38\lib\site-packages\flask_cors\extension.py", line 165, in wrapped_function
    return cors_after_request(app.make_response(f(*args, **kwargs)))
  File "C:\Users\lx\AppData\Local\Programs\Python\Python38\lib\site-packages\flask\app.py", line 2097, in make_response
    raise TypeError(
TypeError: The view function did not return a valid response. The function either returned None or ended without a return statement.
2021-07-09 13:50:42,543 [werkzeug] [16212:Thread-2] _internal.py:_internal:_log in 113] [INFO]: 127.0.0.1 - - [09/Jul/2021 13:50:42] "[35m[1mPOST //element/henkins/check HTTP/1.1[0m" 500 -
2021-07-09 13:51:07,780 [erybjp] [5176:Thread-3] app.py:app:log_exception in 1891] [ERROR]: Exception on /element/henkins/check [POST]
Traceback (most recent call last):
  File "C:\Users\lx\AppData\Local\Programs\Python\Python38\lib\site-packages\werkzeug\wrappers\json.py", line 119, in get_json
    rv = self.json_module.loads(data)
  File "C:\Users\lx\AppData\Local\Programs\Python\Python38\lib\site-packages\flask\json\__init__.py", line 253, in loads
    return _json.loads(s, **kwargs)
  File "C:\Users\lx\AppData\Local\Programs\Python\Python38\lib\json\__init__.py", line 370, in loads
    return cls(**kw).decode(s)
  File "C:\Users\lx\AppData\Local\Programs\Python\Python38\lib\json\decoder.py", line 337, in decode
    obj, end = self.raw_decode(s, idx=_w(s, 0).end())
  File "C:\Users\lx\AppData\Local\Programs\Python\Python38\lib\json\decoder.py", line 355, in raw_decode
    raise JSONDecodeError("Expecting value", s, err.value) from None
json.decoder.JSONDecodeError: Expecting value: line 1 column 1 (char 0)

During handling of the above exception, another exception occurred:

Traceback (most recent call last):
  File "C:\Users\lx\AppData\Local\Programs\Python\Python38\lib\site-packages\flask\app.py", line 1950, in full_dispatch_request
    rv = self.dispatch_request()
  File "C:\Users\lx\AppData\Local\Programs\Python\Python38\lib\site-packages\flask\app.py", line 1936, in dispatch_request
    return self.view_functions[rule.endpoint](**req.view_args)
  File "D:\ÊµãËØïÂ≠¶‰π†ÊñáÊ°£\erybjp-master\uiplatform\router\runtestcase.py", line 83, in jenkins_check
    arg = request.get_json()
  File "C:\Users\lx\AppData\Local\Programs\Python\Python38\lib\site-packages\werkzeug\wrappers\json.py", line 128, in get_json
    rv = self.on_json_loading_failed(e)
  File "C:\Users\lx\AppData\Local\Programs\Python\Python38\lib\site-packages\flask\wrappers.py", line 27, in on_json_loading_failed
    raise BadRequest()
werkzeug.exceptions.BadRequest: 400 Bad Request: The browser (or proxy) sent a request that this server could not understand.

During handling of the above exception, another exception occurred:

Traceback (most recent call last):
  File "C:\Users\lx\AppData\Local\Programs\Python\Python38\lib\site-packages\flask\app.py", line 2447, in wsgi_app
    response = self.full_dispatch_request()
  File "C:\Users\lx\AppData\Local\Programs\Python\Python38\lib\site-packages\flask\app.py", line 1952, in full_dispatch_request
    rv = self.handle_user_exception(e)
  File "C:\Users\lx\AppData\Local\Programs\Python\Python38\lib\site-packages\flask_restful\__init__.py", line 271, in error_router
    return original_handler(e)
  File "C:\Users\lx\AppData\Local\Programs\Python\Python38\lib\site-packages\flask_cors\extension.py", line 165, in wrapped_function
    return cors_after_request(app.make_response(f(*args, **kwargs)))
  File "C:\Users\lx\AppData\Local\Programs\Python\Python38\lib\site-packages\flask\app.py", line 2097, in make_response
    raise TypeError(
TypeError: The view function did not return a valid response. The function either returned None or ended without a return statement.
2021-07-09 13:51:07,786 [werkzeug] [5176:Thread-3] _internal.py:_internal:_log in 113] [INFO]: 127.0.0.1 - - [09/Jul/2021 13:51:07] "[35m[1mPOST /element/henkins/check HTTP/1.1[0m" 500 -
2021-07-09 13:55:33,050 [werkzeug] [13788:Thread-4] _internal.py:_internal:_log in 113] [INFO]: 127.0.0.1 - - [09/Jul/2021 13:55:33] "[37mOPTIONS /element/henkins/check HTTP/1.1[0m" 200 -
2021-07-09 13:55:37,540 [erybjp] [9320:Thread-5] app.py:app:log_exception in 1891] [ERROR]: Exception on /element/henkins/check [POST]
Traceback (most recent call last):
  File "C:\Users\lx\AppData\Local\Programs\Python\Python38\lib\site-packages\werkzeug\wrappers\json.py", line 119, in get_json
    rv = self.json_module.loads(data)
  File "C:\Users\lx\AppData\Local\Programs\Python\Python38\lib\site-packages\flask\json\__init__.py", line 253, in loads
    return _json.loads(s, **kwargs)
  File "C:\Users\lx\AppData\Local\Programs\Python\Python38\lib\json\__init__.py", line 370, in loads
    return cls(**kw).decode(s)
  File "C:\Users\lx\AppData\Local\Programs\Python\Python38\lib\json\decoder.py", line 337, in decode
    obj, end = self.raw_decode(s, idx=_w(s, 0).end())
  File "C:\Users\lx\AppData\Local\Programs\Python\Python38\lib\json\decoder.py", line 355, in raw_decode
    raise JSONDecodeError("Expecting value", s, err.value) from None
json.decoder.JSONDecodeError: Expecting value: line 1 column 1 (char 0)

During handling of the above exception, another exception occurred:

Traceback (most recent call last):
  File "C:\Users\lx\AppData\Local\Programs\Python\Python38\lib\site-packages\flask\app.py", line 1950, in full_dispatch_request
    rv = self.dispatch_request()
  File "C:\Users\lx\AppData\Local\Programs\Python\Python38\lib\site-packages\flask\app.py", line 1936, in dispatch_request
    return self.view_functions[rule.endpoint](**req.view_args)
  File "D:\ÊµãËØïÂ≠¶‰π†ÊñáÊ°£\erybjp-master\uiplatform\router\runtestcase.py", line 83, in jenkins_check
    arg = request.get_json()
  File "C:\Users\lx\AppData\Local\Programs\Python\Python38\lib\site-packages\werkzeug\wrappers\json.py", line 128, in get_json
    rv = self.on_json_loading_failed(e)
  File "C:\Users\lx\AppData\Local\Programs\Python\Python38\lib\site-packages\flask\wrappers.py", line 27, in on_json_loading_failed
    raise BadRequest()
werkzeug.exceptions.BadRequest: 400 Bad Request: The browser (or proxy) sent a request that this server could not understand.

During handling of the above exception, another exception occurred:

Traceback (most recent call last):
  File "C:\Users\lx\AppData\Local\Programs\Python\Python38\lib\site-packages\flask\app.py", line 2447, in wsgi_app
    response = self.full_dispatch_request()
  File "C:\Users\lx\AppData\Local\Programs\Python\Python38\lib\site-packages\flask\app.py", line 1952, in full_dispatch_request
    rv = self.handle_user_exception(e)
  File "C:\Users\lx\AppData\Local\Programs\Python\Python38\lib\site-packages\flask_restful\__init__.py", line 271, in error_router
    return original_handler(e)
  File "C:\Users\lx\AppData\Local\Programs\Python\Python38\lib\site-packages\flask_cors\extension.py", line 165, in wrapped_function
    return cors_after_request(app.make_response(f(*args, **kwargs)))
  File "C:\Users\lx\AppData\Local\Programs\Python\Python38\lib\site-packages\flask\app.py", line 2097, in make_response
    raise TypeError(
TypeError: The view function did not return a valid response. The function either returned None or ended without a return statement.
2021-07-09 13:55:37,554 [werkzeug] [9320:Thread-5] _internal.py:_internal:_log in 113] [INFO]: 127.0.0.1 - - [09/Jul/2021 13:55:37] "[35m[1mPOST /element/henkins/check HTTP/1.1[0m" 500 -
2021-07-09 13:56:59,528 [werkzeug] [3708:Thread-6] _internal.py:_internal:_log in 113] [INFO]: 127.0.0.1 - - [09/Jul/2021 13:56:59] "[37mGET /element/auto/run HTTP/1.1[0m" 200 -
2021-07-09 13:57:52,355 [erybjp] [9268:Thread-7] app.py:app:log_exception in 1891] [ERROR]: Exception on /element/henkins/check [POST]
Traceback (most recent call last):
  File "C:\Users\lx\AppData\Local\Programs\Python\Python38\lib\site-packages\werkzeug\wrappers\json.py", line 119, in get_json
    rv = self.json_module.loads(data)
  File "C:\Users\lx\AppData\Local\Programs\Python\Python38\lib\site-packages\flask\json\__init__.py", line 253, in loads
    return _json.loads(s, **kwargs)
  File "C:\Users\lx\AppData\Local\Programs\Python\Python38\lib\json\__init__.py", line 370, in loads
    return cls(**kw).decode(s)
  File "C:\Users\lx\AppData\Local\Programs\Python\Python38\lib\json\decoder.py", line 337, in decode
    obj, end = self.raw_decode(s, idx=_w(s, 0).end())
  File "C:\Users\lx\AppData\Local\Programs\Python\Python38\lib\json\decoder.py", line 355, in raw_decode
    raise JSONDecodeError("Expecting value", s, err.value) from None
json.decoder.JSONDecodeError: Expecting value: line 1 column 1 (char 0)

During handling of the above exception, another exception occurred:

Traceback (most recent call last):
  File "C:\Users\lx\AppData\Local\Programs\Python\Python38\lib\site-packages\flask\app.py", line 1950, in full_dispatch_request
    rv = self.dispatch_request()
  File "C:\Users\lx\AppData\Local\Programs\Python\Python38\lib\site-packages\flask\app.py", line 1936, in dispatch_request
    return self.view_functions[rule.endpoint](**req.view_args)
  File "D:\ÊµãËØïÂ≠¶‰π†ÊñáÊ°£\erybjp-master\uiplatform\router\runtestcase.py", line 83, in jenkins_check
    arg = request.get_json()
  File "C:\Users\lx\AppData\Local\Programs\Python\Python38\lib\site-packages\werkzeug\wrappers\json.py", line 128, in get_json
    rv = self.on_json_loading_failed(e)
  File "C:\Users\lx\AppData\Local\Programs\Python\Python38\lib\site-packages\flask\wrappers.py", line 27, in on_json_loading_failed
    raise BadRequest()
werkzeug.exceptions.BadRequest: 400 Bad Request: The browser (or proxy) sent a request that this server could not understand.

During handling of the above exception, another exception occurred:

Traceback (most recent call last):
  File "C:\Users\lx\AppData\Local\Programs\Python\Python38\lib\site-packages\flask\app.py", line 2447, in wsgi_app
    response = self.full_dispatch_request()
  File "C:\Users\lx\AppData\Local\Programs\Python\Python38\lib\site-packages\flask\app.py", line 1952, in full_dispatch_request
    rv = self.handle_user_exception(e)
  File "C:\Users\lx\AppData\Local\Programs\Python\Python38\lib\site-packages\flask_restful\__init__.py", line 271, in error_router
    return original_handler(e)
  File "C:\Users\lx\AppData\Local\Programs\Python\Python38\lib\site-packages\flask_cors\extension.py", line 165, in wrapped_function
    return cors_after_request(app.make_response(f(*args, **kwargs)))
  File "C:\Users\lx\AppData\Local\Programs\Python\Python38\lib\site-packages\flask\app.py", line 2097, in make_response
    raise TypeError(
TypeError: The view function did not return a valid response. The function either returned None or ended without a return statement.
2021-07-09 13:57:52,368 [werkzeug] [9268:Thread-7] _internal.py:_internal:_log in 113] [INFO]: 127.0.0.1 - - [09/Jul/2021 13:57:52] "[35m[1mPOST /element/henkins/check HTTP/1.1[0m" 500 -
2021-07-09 13:58:03,066 [erybjp] [15976:Thread-8] app.py:app:log_exception in 1891] [ERROR]: Exception on /element/henkins/check [POST]
Traceback (most recent call last):
  File "C:\Users\lx\AppData\Local\Programs\Python\Python38\lib\site-packages\werkzeug\wrappers\json.py", line 119, in get_json
    rv = self.json_module.loads(data)
  File "C:\Users\lx\AppData\Local\Programs\Python\Python38\lib\site-packages\flask\json\__init__.py", line 253, in loads
    return _json.loads(s, **kwargs)
  File "C:\Users\lx\AppData\Local\Programs\Python\Python38\lib\json\__init__.py", line 370, in loads
    return cls(**kw).decode(s)
  File "C:\Users\lx\AppData\Local\Programs\Python\Python38\lib\json\decoder.py", line 337, in decode
    obj, end = self.raw_decode(s, idx=_w(s, 0).end())
  File "C:\Users\lx\AppData\Local\Programs\Python\Python38\lib\json\decoder.py", line 355, in raw_decode
    raise JSONDecodeError("Expecting value", s, err.value) from None
json.decoder.JSONDecodeError: Expecting value: line 1 column 1 (char 0)

During handling of the above exception, another exception occurred:

Traceback (most recent call last):
  File "C:\Users\lx\AppData\Local\Programs\Python\Python38\lib\site-packages\flask\app.py", line 1950, in full_dispatch_request
    rv = self.dispatch_request()
  File "C:\Users\lx\AppData\Local\Programs\Python\Python38\lib\site-packages\flask\app.py", line 1936, in dispatch_request
    return self.view_functions[rule.endpoint](**req.view_args)
  File "D:\ÊµãËØïÂ≠¶‰π†ÊñáÊ°£\erybjp-master\uiplatform\router\runtestcase.py", line 83, in jenkins_check
    arg = request.get_json()
  File "C:\Users\lx\AppData\Local\Programs\Python\Python38\lib\site-packages\werkzeug\wrappers\json.py", line 128, in get_json
    rv = self.on_json_loading_failed(e)
  File "C:\Users\lx\AppData\Local\Programs\Python\Python38\lib\site-packages\flask\wrappers.py", line 27, in on_json_loading_failed
    raise BadRequest()
werkzeug.exceptions.BadRequest: 400 Bad Request: The browser (or proxy) sent a request that this server could not understand.

During handling of the above exception, another exception occurred:

Traceback (most recent call last):
  File "C:\Users\lx\AppData\Local\Programs\Python\Python38\lib\site-packages\flask\app.py", line 2447, in wsgi_app
    response = self.full_dispatch_request()
  File "C:\Users\lx\AppData\Local\Programs\Python\Python38\lib\site-packages\flask\app.py", line 1952, in full_dispatch_request
    rv = self.handle_user_exception(e)
  File "C:\Users\lx\AppData\Local\Programs\Python\Python38\lib\site-packages\flask_restful\__init__.py", line 271, in error_router
    return original_handler(e)
  File "C:\Users\lx\AppData\Local\Programs\Python\Python38\lib\site-packages\flask_cors\extension.py", line 165, in wrapped_function
    return cors_after_request(app.make_response(f(*args, **kwargs)))
  File "C:\Users\lx\AppData\Local\Programs\Python\Python38\lib\site-packages\flask\app.py", line 2097, in make_response
    raise TypeError(
TypeError: The view function did not return a valid response. The function either returned None or ended without a return statement.
2021-07-09 13:58:03,072 [werkzeug] [15976:Thread-8] _internal.py:_internal:_log in 113] [INFO]: 127.0.0.1 - - [09/Jul/2021 13:58:03] "[35m[1mPOST /element/henkins/check HTTP/1.1[0m" 500 -
2021-07-09 13:58:03,971 [erybjp] [1920:Thread-9] app.py:app:log_exception in 1891] [ERROR]: Exception on /element/henkins/check [POST]
Traceback (most recent call last):
  File "C:\Users\lx\AppData\Local\Programs\Python\Python38\lib\site-packages\werkzeug\wrappers\json.py", line 119, in get_json
    rv = self.json_module.loads(data)
  File "C:\Users\lx\AppData\Local\Programs\Python\Python38\lib\site-packages\flask\json\__init__.py", line 253, in loads
    return _json.loads(s, **kwargs)
  File "C:\Users\lx\AppData\Local\Programs\Python\Python38\lib\json\__init__.py", line 370, in loads
    return cls(**kw).decode(s)
  File "C:\Users\lx\AppData\Local\Programs\Python\Python38\lib\json\decoder.py", line 337, in decode
    obj, end = self.raw_decode(s, idx=_w(s, 0).end())
  File "C:\Users\lx\AppData\Local\Programs\Python\Python38\lib\json\decoder.py", line 355, in raw_decode
    raise JSONDecodeError("Expecting value", s, err.value) from None
json.decoder.JSONDecodeError: Expecting value: line 1 column 1 (char 0)

During handling of the above exception, another exception occurred:

Traceback (most recent call last):
  File "C:\Users\lx\AppData\Local\Programs\Python\Python38\lib\site-packages\flask\app.py", line 1950, in full_dispatch_request
    rv = self.dispatch_request()
  File "C:\Users\lx\AppData\Local\Programs\Python\Python38\lib\site-packages\flask\app.py", line 1936, in dispatch_request
    return self.view_functions[rule.endpoint](**req.view_args)
  File "D:\ÊµãËØïÂ≠¶‰π†ÊñáÊ°£\erybjp-master\uiplatform\router\runtestcase.py", line 83, in jenkins_check
    arg = request.get_json()
  File "C:\Users\lx\AppData\Local\Programs\Python\Python38\lib\site-packages\werkzeug\wrappers\json.py", line 128, in get_json
    rv = self.on_json_loading_failed(e)
  File "C:\Users\lx\AppData\Local\Programs\Python\Python38\lib\site-packages\flask\wrappers.py", line 27, in on_json_loading_failed
    raise BadRequest()
werkzeug.exceptions.BadRequest: 400 Bad Request: The browser (or proxy) sent a request that this server could not understand.

During handling of the above exception, another exception occurred:

Traceback (most recent call last):
  File "C:\Users\lx\AppData\Local\Programs\Python\Python38\lib\site-packages\flask\app.py", line 2447, in wsgi_app
    response = self.full_dispatch_request()
  File "C:\Users\lx\AppData\Local\Programs\Python\Python38\lib\site-packages\flask\app.py", line 1952, in full_dispatch_request
    rv = self.handle_user_exception(e)
  File "C:\Users\lx\AppData\Local\Programs\Python\Python38\lib\site-packages\flask_restful\__init__.py", line 271, in error_router
    return original_handler(e)
  File "C:\Users\lx\AppData\Local\Programs\Python\Python38\lib\site-packages\flask_cors\extension.py", line 165, in wrapped_function
    return cors_after_request(app.make_response(f(*args, **kwargs)))
  File "C:\Users\lx\AppData\Local\Programs\Python\Python38\lib\site-packages\flask\app.py", line 2097, in make_response
    raise TypeError(
TypeError: The view function did not return a valid response. The function either returned None or ended without a return statement.
2021-07-09 13:58:03,984 [werkzeug] [1920:Thread-9] _internal.py:_internal:_log in 113] [INFO]: 127.0.0.1 - - [09/Jul/2021 13:58:03] "[35m[1mPOST /element/henkins/check HTTP/1.1[0m" 500 -
2021-07-09 13:58:08,585 [erybjp] [9040:Thread-10] app.py:app:log_exception in 1891] [ERROR]: Exception on /element/henkins/check [POST]
Traceback (most recent call last):
  File "C:\Users\lx\AppData\Local\Programs\Python\Python38\lib\site-packages\werkzeug\wrappers\json.py", line 119, in get_json
    rv = self.json_module.loads(data)
  File "C:\Users\lx\AppData\Local\Programs\Python\Python38\lib\site-packages\flask\json\__init__.py", line 253, in loads
    return _json.loads(s, **kwargs)
  File "C:\Users\lx\AppData\Local\Programs\Python\Python38\lib\json\__init__.py", line 370, in loads
    return cls(**kw).decode(s)
  File "C:\Users\lx\AppData\Local\Programs\Python\Python38\lib\json\decoder.py", line 337, in decode
    obj, end = self.raw_decode(s, idx=_w(s, 0).end())
  File "C:\Users\lx\AppData\Local\Programs\Python\Python38\lib\json\decoder.py", line 355, in raw_decode
    raise JSONDecodeError("Expecting value", s, err.value) from None
json.decoder.JSONDecodeError: Expecting value: line 1 column 1 (char 0)

During handling of the above exception, another exception occurred:

Traceback (most recent call last):
  File "C:\Users\lx\AppData\Local\Programs\Python\Python38\lib\site-packages\flask\app.py", line 1950, in full_dispatch_request
    rv = self.dispatch_request()
  File "C:\Users\lx\AppData\Local\Programs\Python\Python38\lib\site-packages\flask\app.py", line 1936, in dispatch_request
    return self.view_functions[rule.endpoint](**req.view_args)
  File "D:\ÊµãËØïÂ≠¶‰π†ÊñáÊ°£\erybjp-master\uiplatform\router\runtestcase.py", line 83, in jenkins_check
    arg = request.get_json()
  File "C:\Users\lx\AppData\Local\Programs\Python\Python38\lib\site-packages\werkzeug\wrappers\json.py", line 128, in get_json
    rv = self.on_json_loading_failed(e)
  File "C:\Users\lx\AppData\Local\Programs\Python\Python38\lib\site-packages\flask\wrappers.py", line 27, in on_json_loading_failed
    raise BadRequest()
werkzeug.exceptions.BadRequest: 400 Bad Request: The browser (or proxy) sent a request that this server could not understand.

During handling of the above exception, another exception occurred:

Traceback (most recent call last):
  File "C:\Users\lx\AppData\Local\Programs\Python\Python38\lib\site-packages\flask\app.py", line 2447, in wsgi_app
    response = self.full_dispatch_request()
  File "C:\Users\lx\AppData\Local\Programs\Python\Python38\lib\site-packages\flask\app.py", line 1952, in full_dispatch_request
    rv = self.handle_user_exception(e)
  File "C:\Users\lx\AppData\Local\Programs\Python\Python38\lib\site-packages\flask_restful\__init__.py", line 271, in error_router
    return original_handler(e)
  File "C:\Users\lx\AppData\Local\Programs\Python\Python38\lib\site-packages\flask_cors\extension.py", line 165, in wrapped_function
    return cors_after_request(app.make_response(f(*args, **kwargs)))
  File "C:\Users\lx\AppData\Local\Programs\Python\Python38\lib\site-packages\flask\app.py", line 2097, in make_response
    raise TypeError(
TypeError: The view function did not return a valid response. The function either returned None or ended without a return statement.
2021-07-09 13:58:08,590 [werkzeug] [9040:Thread-10] _internal.py:_internal:_log in 113] [INFO]: 127.0.0.1 - - [09/Jul/2021 13:58:08] "[35m[1mPOST /element/henkins/check HTTP/1.1[0m" 500 -
2021-07-09 13:58:34,440 [erybjp] [4524:Thread-11] app.py:app:log_exception in 1891] [ERROR]: Exception on /element/henkins/check [POST]
Traceback (most recent call last):
  File "C:\Users\lx\AppData\Local\Programs\Python\Python38\lib\site-packages\werkzeug\wrappers\json.py", line 119, in get_json
    rv = self.json_module.loads(data)
  File "C:\Users\lx\AppData\Local\Programs\Python\Python38\lib\site-packages\flask\json\__init__.py", line 253, in loads
    return _json.loads(s, **kwargs)
  File "C:\Users\lx\AppData\Local\Programs\Python\Python38\lib\json\__init__.py", line 370, in loads
    return cls(**kw).decode(s)
  File "C:\Users\lx\AppData\Local\Programs\Python\Python38\lib\json\decoder.py", line 337, in decode
    obj, end = self.raw_decode(s, idx=_w(s, 0).end())
  File "C:\Users\lx\AppData\Local\Programs\Python\Python38\lib\json\decoder.py", line 355, in raw_decode
    raise JSONDecodeError("Expecting value", s, err.value) from None
json.decoder.JSONDecodeError: Expecting value: line 1 column 1 (char 0)

During handling of the above exception, another exception occurred:

Traceback (most recent call last):
  File "C:\Users\lx\AppData\Local\Programs\Python\Python38\lib\site-packages\flask\app.py", line 1950, in full_dispatch_request
    rv = self.dispatch_request()
  File "C:\Users\lx\AppData\Local\Programs\Python\Python38\lib\site-packages\flask\app.py", line 1936, in dispatch_request
    return self.view_functions[rule.endpoint](**req.view_args)
  File "D:\ÊµãËØïÂ≠¶‰π†ÊñáÊ°£\erybjp-master\uiplatform\router\runtestcase.py", line 83, in jenkins_check
    arg = request.get_json()
  File "C:\Users\lx\AppData\Local\Programs\Python\Python38\lib\site-packages\werkzeug\wrappers\json.py", line 128, in get_json
    rv = self.on_json_loading_failed(e)
  File "C:\Users\lx\AppData\Local\Programs\Python\Python38\lib\site-packages\flask\wrappers.py", line 27, in on_json_loading_failed
    raise BadRequest()
werkzeug.exceptions.BadRequest: 400 Bad Request: The browser (or proxy) sent a request that this server could not understand.

During handling of the above exception, another exception occurred:

Traceback (most recent call last):
  File "C:\Users\lx\AppData\Local\Programs\Python\Python38\lib\site-packages\flask\app.py", line 2447, in wsgi_app
    response = self.full_dispatch_request()
  File "C:\Users\lx\AppData\Local\Programs\Python\Python38\lib\site-packages\flask\app.py", line 1952, in full_dispatch_request
    rv = self.handle_user_exception(e)
  File "C:\Users\lx\AppData\Local\Programs\Python\Python38\lib\site-packages\flask_restful\__init__.py", line 271, in error_router
    return original_handler(e)
  File "C:\Users\lx\AppData\Local\Programs\Python\Python38\lib\site-packages\flask_cors\extension.py", line 165, in wrapped_function
    return cors_after_request(app.make_response(f(*args, **kwargs)))
  File "C:\Users\lx\AppData\Local\Programs\Python\Python38\lib\site-packages\flask\app.py", line 2097, in make_response
    raise TypeError(
TypeError: The view function did not return a valid response. The function either returned None or ended without a return statement.
2021-07-09 13:58:34,451 [werkzeug] [4524:Thread-11] _internal.py:_internal:_log in 113] [INFO]: 127.0.0.1 - - [09/Jul/2021 13:58:34] "[35m[1mPOST /element/henkins/check HTTP/1.1[0m" 500 -
2021-07-09 13:58:57,018 [werkzeug] [6840:MainThread] _internal.py:_internal:_log in 113] [INFO]:  * Running on http://127.0.0.1:6851/ (Press CTRL+C to quit)
2021-07-09 14:00:17,249 [werkzeug] [15312:Thread-1] _internal.py:_internal:_log in 113] [INFO]: 127.0.0.1 - - [09/Jul/2021 14:00:17] "[37mGET /scheduler/jobs HTTP/1.1[0m" 200 -
2021-07-09 14:00:24,762 [erybjp] [15100:Thread-2] app.py:app:log_exception in 1891] [ERROR]: Exception on /element/henkins/check [POST]
Traceback (most recent call last):
  File "C:\Users\lx\AppData\Local\Programs\Python\Python38\lib\site-packages\werkzeug\wrappers\json.py", line 119, in get_json
    rv = self.json_module.loads(data)
  File "C:\Users\lx\AppData\Local\Programs\Python\Python38\lib\site-packages\flask\json\__init__.py", line 253, in loads
    return _json.loads(s, **kwargs)
  File "C:\Users\lx\AppData\Local\Programs\Python\Python38\lib\json\__init__.py", line 370, in loads
    return cls(**kw).decode(s)
  File "C:\Users\lx\AppData\Local\Programs\Python\Python38\lib\json\decoder.py", line 337, in decode
    obj, end = self.raw_decode(s, idx=_w(s, 0).end())
  File "C:\Users\lx\AppData\Local\Programs\Python\Python38\lib\json\decoder.py", line 355, in raw_decode
    raise JSONDecodeError("Expecting value", s, err.value) from None
json.decoder.JSONDecodeError: Expecting value: line 1 column 1 (char 0)

During handling of the above exception, another exception occurred:

Traceback (most recent call last):
  File "C:\Users\lx\AppData\Local\Programs\Python\Python38\lib\site-packages\flask\app.py", line 1950, in full_dispatch_request
    rv = self.dispatch_request()
  File "C:\Users\lx\AppData\Local\Programs\Python\Python38\lib\site-packages\flask\app.py", line 1936, in dispatch_request
    return self.view_functions[rule.endpoint](**req.view_args)
  File "D:\ÊµãËØïÂ≠¶‰π†ÊñáÊ°£\erybjp-master\uiplatform\router\runtestcase.py", line 83, in jenkins_check
    arg = request.get_json()
  File "C:\Users\lx\AppData\Local\Programs\Python\Python38\lib\site-packages\werkzeug\wrappers\json.py", line 128, in get_json
    rv = self.on_json_loading_failed(e)
  File "C:\Users\lx\AppData\Local\Programs\Python\Python38\lib\site-packages\flask\wrappers.py", line 27, in on_json_loading_failed
    raise BadRequest()
werkzeug.exceptions.BadRequest: 400 Bad Request: The browser (or proxy) sent a request that this server could not understand.

During handling of the above exception, another exception occurred:

Traceback (most recent call last):
  File "C:\Users\lx\AppData\Local\Programs\Python\Python38\lib\site-packages\flask\app.py", line 2447, in wsgi_app
    response = self.full_dispatch_request()
  File "C:\Users\lx\AppData\Local\Programs\Python\Python38\lib\site-packages\flask\app.py", line 1952, in full_dispatch_request
    rv = self.handle_user_exception(e)
  File "C:\Users\lx\AppData\Local\Programs\Python\Python38\lib\site-packages\flask_restful\__init__.py", line 271, in error_router
    return original_handler(e)
  File "C:\Users\lx\AppData\Local\Programs\Python\Python38\lib\site-packages\flask_cors\extension.py", line 165, in wrapped_function
    return cors_after_request(app.make_response(f(*args, **kwargs)))
  File "C:\Users\lx\AppData\Local\Programs\Python\Python38\lib\site-packages\flask\app.py", line 2097, in make_response
    raise TypeError(
TypeError: The view function did not return a valid response. The function either returned None or ended without a return statement.
2021-07-09 14:00:24,773 [werkzeug] [15100:Thread-2] _internal.py:_internal:_log in 113] [INFO]: 127.0.0.1 - - [09/Jul/2021 14:00:24] "[35m[1mPOST /element/henkins/check HTTP/1.1[0m" 500 -
2021-07-09 14:00:47,754 [erybjp] [3708:Thread-3] app.py:app:log_exception in 1891] [ERROR]: Exception on /element/henkins/check [POST]
Traceback (most recent call last):
  File "C:\Users\lx\AppData\Local\Programs\Python\Python38\lib\site-packages\werkzeug\wrappers\json.py", line 119, in get_json
    rv = self.json_module.loads(data)
  File "C:\Users\lx\AppData\Local\Programs\Python\Python38\lib\site-packages\flask\json\__init__.py", line 253, in loads
    return _json.loads(s, **kwargs)
  File "C:\Users\lx\AppData\Local\Programs\Python\Python38\lib\json\__init__.py", line 370, in loads
    return cls(**kw).decode(s)
  File "C:\Users\lx\AppData\Local\Programs\Python\Python38\lib\json\decoder.py", line 337, in decode
    obj, end = self.raw_decode(s, idx=_w(s, 0).end())
  File "C:\Users\lx\AppData\Local\Programs\Python\Python38\lib\json\decoder.py", line 355, in raw_decode
    raise JSONDecodeError("Expecting value", s, err.value) from None
json.decoder.JSONDecodeError: Expecting value: line 1 column 1 (char 0)

During handling of the above exception, another exception occurred:

Traceback (most recent call last):
  File "C:\Users\lx\AppData\Local\Programs\Python\Python38\lib\site-packages\flask\app.py", line 1950, in full_dispatch_request
    rv = self.dispatch_request()
  File "C:\Users\lx\AppData\Local\Programs\Python\Python38\lib\site-packages\flask\app.py", line 1936, in dispatch_request
    return self.view_functions[rule.endpoint](**req.view_args)
  File "D:\ÊµãËØïÂ≠¶‰π†ÊñáÊ°£\erybjp-master\uiplatform\router\runtestcase.py", line 83, in jenkins_check
    arg = request.get_json()
  File "C:\Users\lx\AppData\Local\Programs\Python\Python38\lib\site-packages\werkzeug\wrappers\json.py", line 128, in get_json
    rv = self.on_json_loading_failed(e)
  File "C:\Users\lx\AppData\Local\Programs\Python\Python38\lib\site-packages\flask\wrappers.py", line 27, in on_json_loading_failed
    raise BadRequest()
werkzeug.exceptions.BadRequest: 400 Bad Request: The browser (or proxy) sent a request that this server could not understand.

During handling of the above exception, another exception occurred:

Traceback (most recent call last):
  File "C:\Users\lx\AppData\Local\Programs\Python\Python38\lib\site-packages\flask\app.py", line 2447, in wsgi_app
    response = self.full_dispatch_request()
  File "C:\Users\lx\AppData\Local\Programs\Python\Python38\lib\site-packages\flask\app.py", line 1952, in full_dispatch_request
    rv = self.handle_user_exception(e)
  File "C:\Users\lx\AppData\Local\Programs\Python\Python38\lib\site-packages\flask_restful\__init__.py", line 271, in error_router
    return original_handler(e)
  File "C:\Users\lx\AppData\Local\Programs\Python\Python38\lib\site-packages\flask_cors\extension.py", line 165, in wrapped_function
    return cors_after_request(app.make_response(f(*args, **kwargs)))
  File "C:\Users\lx\AppData\Local\Programs\Python\Python38\lib\site-packages\flask\app.py", line 2097, in make_response
    raise TypeError(
TypeError: The view function did not return a valid response. The function either returned None or ended without a return statement.
2021-07-09 14:00:47,761 [werkzeug] [3708:Thread-3] _internal.py:_internal:_log in 113] [INFO]: 127.0.0.1 - - [09/Jul/2021 14:00:47] "[35m[1mPOST /element/henkins/check HTTP/1.1[0m" 500 -
2021-07-09 15:17:02,000 [werkzeug] [14784:MainThread] _internal.py:_internal:_log in 113] [INFO]:  * Running on http://127.0.0.1:6851/ (Press CTRL+C to quit)
2021-07-09 15:17:18,850 [werkzeug] [10056:MainThread] _internal.py:_internal:_log in 113] [INFO]:  * Running on http://127.0.0.1:6851/ (Press CTRL+C to quit)
2021-07-09 15:17:43,771 [erybjp] [15688:Thread-6] app.py:app:log_exception in 1891] [ERROR]: Exception on /element/henkins/check [POST]
Traceback (most recent call last):
  File "C:\Users\lx\AppData\Local\Programs\Python\Python38\lib\site-packages\werkzeug\wrappers\json.py", line 119, in get_json
    rv = self.json_module.loads(data)
  File "C:\Users\lx\AppData\Local\Programs\Python\Python38\lib\site-packages\flask\json\__init__.py", line 253, in loads
    return _json.loads(s, **kwargs)
  File "C:\Users\lx\AppData\Local\Programs\Python\Python38\lib\json\__init__.py", line 370, in loads
    return cls(**kw).decode(s)
  File "C:\Users\lx\AppData\Local\Programs\Python\Python38\lib\json\decoder.py", line 337, in decode
    obj, end = self.raw_decode(s, idx=_w(s, 0).end())
  File "C:\Users\lx\AppData\Local\Programs\Python\Python38\lib\json\decoder.py", line 355, in raw_decode
    raise JSONDecodeError("Expecting value", s, err.value) from None
json.decoder.JSONDecodeError: Expecting value: line 1 column 1 (char 0)

During handling of the above exception, another exception occurred:

Traceback (most recent call last):
  File "C:\Users\lx\AppData\Local\Programs\Python\Python38\lib\site-packages\flask\app.py", line 1950, in full_dispatch_request
    rv = self.dispatch_request()
  File "C:\Users\lx\AppData\Local\Programs\Python\Python38\lib\site-packages\flask\app.py", line 1936, in dispatch_request
    return self.view_functions[rule.endpoint](**req.view_args)
  File "D:\ÊµãËØïÂ≠¶‰π†ÊñáÊ°£\erybjp-master\uiplatform\router\runtestcase.py", line 83, in jenkins_check
    arg = request.get_json()
  File "C:\Users\lx\AppData\Local\Programs\Python\Python38\lib\site-packages\werkzeug\wrappers\json.py", line 128, in get_json
    rv = self.on_json_loading_failed(e)
  File "C:\Users\lx\AppData\Local\Programs\Python\Python38\lib\site-packages\flask\wrappers.py", line 27, in on_json_loading_failed
    raise BadRequest()
werkzeug.exceptions.BadRequest: 400 Bad Request: The browser (or proxy) sent a request that this server could not understand.

During handling of the above exception, another exception occurred:

Traceback (most recent call last):
  File "C:\Users\lx\AppData\Local\Programs\Python\Python38\lib\site-packages\flask\app.py", line 2447, in wsgi_app
    response = self.full_dispatch_request()
  File "C:\Users\lx\AppData\Local\Programs\Python\Python38\lib\site-packages\flask\app.py", line 1952, in full_dispatch_request
    rv = self.handle_user_exception(e)
  File "C:\Users\lx\AppData\Local\Programs\Python\Python38\lib\site-packages\flask_restful\__init__.py", line 271, in error_router
    return original_handler(e)
  File "C:\Users\lx\AppData\Local\Programs\Python\Python38\lib\site-packages\flask_cors\extension.py", line 165, in wrapped_function
    return cors_after_request(app.make_response(f(*args, **kwargs)))
  File "C:\Users\lx\AppData\Local\Programs\Python\Python38\lib\site-packages\flask\app.py", line 2097, in make_response
    raise TypeError(
TypeError: The view function did not return a valid response. The function either returned None or ended without a return statement.
2021-07-09 15:17:43,792 [werkzeug] [15688:Thread-6] _internal.py:_internal:_log in 113] [INFO]: 127.0.0.1 - - [09/Jul/2021 15:17:43] "[35m[1mPOST /element/henkins/check HTTP/1.1[0m" 500 -
2021-07-09 15:18:28,341 [werkzeug] [15240:MainThread] _internal.py:_internal:_log in 113] [INFO]:  * Running on http://127.0.0.1:6851/ (Press CTRL+C to quit)
2021-07-09 15:19:21,745 [werkzeug] [8148:MainThread] _internal.py:_internal:_log in 113] [INFO]:  * Running on http://127.0.0.1:6851/ (Press CTRL+C to quit)
2021-07-09 15:23:26,738 [werkzeug] [16192:MainThread] _internal.py:_internal:_log in 113] [INFO]:  * Running on http://127.0.0.1:6851/ (Press CTRL+C to quit)
2021-07-09 15:23:30,857 [werkzeug] [15320:Thread-1] _internal.py:_internal:_log in 113] [INFO]: 127.0.0.1 - - [09/Jul/2021 15:23:30] "[33mPOST /element/jenkins/check HTTP/1.1[0m" 404 -
2021-07-09 15:24:20,660 [werkzeug] [12836:Thread-2] _internal.py:_internal:_log in 113] [INFO]: 127.0.0.1 - - [09/Jul/2021 15:24:20] "[37mPOST /element/henkins/check HTTP/1.1[0m" 200 -
2021-07-09 15:26:09,976 [werkzeug] [7580:Thread-18] _internal.py:_internal:_log in 113] [INFO]: 127.0.0.1 - - [09/Jul/2021 15:26:09] "[37mPOST /element/henkins/check HTTP/1.1[0m" 200 -
2021-07-09 15:31:17,679 [werkzeug] [7328:MainThread] _internal.py:_internal:_log in 113] [INFO]:  * Running on http://127.0.0.1:6851/ (Press CTRL+C to quit)
2021-07-09 15:31:36,454 [werkzeug] [10232:Thread-1] _internal.py:_internal:_log in 113] [INFO]: 127.0.0.1 - - [09/Jul/2021 15:31:36] "[37mPOST /element/henkins/check HTTP/1.1[0m" 200 -
2021-07-09 15:32:40,542 [werkzeug] [6088:Thread-6] _internal.py:_internal:_log in 113] [INFO]: 127.0.0.1 - - [09/Jul/2021 15:32:40] "[37mPOST /element/henkins/check HTTP/1.1[0m" 200 -
