2021-05-29 10:27:22,987 [werkzeug] [9084:MainThread] _internal.py:_internal:_log in 225] [INFO]:  * Restarting with stat
2021-05-29 10:27:24,860 [werkzeug] [8596:Thread-2] _internal.py:_internal:_log in 225] [INFO]:  * Running on http://127.0.0.1:5000/ (Press CTRL+C to quit)
2021-05-29 10:27:32,245 [werkzeug] [21120:Thread-3] _internal.py:_internal:_log in 225] [INFO]: 127.0.0.1 - - [29/May/2021 10:27:32] "[33mGET / HTTP/1.1[0m" 404 -
2021-05-29 10:27:33,078 [werkzeug] [7380:Thread-4] _internal.py:_internal:_log in 225] [INFO]: 127.0.0.1 - - [29/May/2021 10:27:33] "[33mGET /favicon.ico HTTP/1.1[0m" 404 -
2021-05-29 10:27:46,515 [werkzeug] [20844:Thread-6] _internal.py:_internal:_log in 225] [INFO]: 127.0.0.1 - - [29/May/2021 10:27:46] "[31m[1mGET /auth/ui_test/run HTTP/1.1[0m" 405 -
2021-05-29 10:28:18,063 [werkzeug] [14936:Thread-5] _internal.py:_internal:_log in 225] [INFO]: 127.0.0.1 - - [29/May/2021 10:28:18] "GET /auth/ui_test/test HTTP/1.1" 200 -
2021-05-29 10:30:17,323 [werkzeug] [19244:MainThread] _internal.py:_internal:_log in 225] [INFO]:  * Restarting with stat
2021-05-29 10:30:19,229 [werkzeug] [15832:Thread-2] _internal.py:_internal:_log in 225] [INFO]:  * Running on http://127.0.0.1:5000/ (Press CTRL+C to quit)
2021-05-29 10:30:35,054 [werkzeug] [3896:Thread-3] _internal.py:_internal:_log in 225] [INFO]: 127.0.0.1 - - [29/May/2021 10:30:35] "GET /auth/ui_test/test HTTP/1.1" 200 -
2021-05-29 10:32:11,069 [werkzeug] [11944:MainThread] _internal.py:_internal:_log in 225] [INFO]:  * Restarting with stat
2021-05-29 10:32:12,736 [werkzeug] [1784:Thread-2] _internal.py:_internal:_log in 225] [INFO]:  * Running on http://127.0.0.1:5000/ (Press CTRL+C to quit)
2021-05-29 10:32:25,070 [werkzeug] [10876:Thread-3] _internal.py:_internal:_log in 225] [INFO]: 127.0.0.1 - - [29/May/2021 10:32:25] "GET /auth/ui_test/test HTTP/1.1" 200 -
2021-05-29 10:32:39,599 [werkzeug] [11412:MainThread] _internal.py:_internal:_log in 225] [INFO]:  * Restarting with stat
2021-05-29 10:32:41,277 [werkzeug] [18880:Thread-2] _internal.py:_internal:_log in 225] [INFO]:  * Running on http://127.0.0.1:5000/ (Press CTRL+C to quit)
2021-05-29 10:32:54,489 [werkzeug] [4956:Thread-3] _internal.py:_internal:_log in 225] [INFO]: 127.0.0.1 - - [29/May/2021 10:32:54] "GET /auth/ui_test/test HTTP/1.1" 200 -
2021-05-29 10:33:47,424 [werkzeug] [7912:MainThread] _internal.py:_internal:_log in 225] [INFO]:  * Detected change in 'E:\\Auto_test\\flask\\erybjp\\uiplatform\\utils\\business\\test.py', reloading
2021-05-29 10:33:47,504 [werkzeug] [11412:MainThread] _internal.py:_internal:_log in 225] [INFO]:  * Restarting with stat
2021-05-29 10:33:49,128 [werkzeug] [9040:Thread-2] _internal.py:_internal:_log in 225] [INFO]:  * Running on http://127.0.0.1:5000/ (Press CTRL+C to quit)
2021-05-29 10:36:36,911 [werkzeug] [4692:MainThread] _internal.py:_internal:_log in 225] [INFO]:  * Restarting with stat
2021-05-29 10:36:38,575 [werkzeug] [20612:Thread-2] _internal.py:_internal:_log in 225] [INFO]:  * Running on http://127.0.0.1:5000/ (Press CTRL+C to quit)
2021-05-29 10:36:56,324 [werkzeug] [16784:Thread-3] _internal.py:_internal:_log in 225] [INFO]: 127.0.0.1 - - [29/May/2021 10:36:56] "GET /auth/ui_test/test HTTP/1.1" 200 -
2021-05-29 10:38:32,541 [werkzeug] [17996:MainThread] _internal.py:_internal:_log in 225] [INFO]:  * Restarting with stat
2021-05-29 10:38:34,182 [werkzeug] [10488:Thread-2] _internal.py:_internal:_log in 225] [INFO]:  * Running on http://127.0.0.1:5000/ (Press CTRL+C to quit)
2021-05-29 10:38:48,834 [werkzeug] [20932:Thread-3] _internal.py:_internal:_log in 225] [INFO]: 127.0.0.1 - - [29/May/2021 10:38:48] "GET /auth/ui_test/test HTTP/1.1" 200 -
2021-05-29 10:39:34,775 [werkzeug] [18340:MainThread] _internal.py:_internal:_log in 225] [INFO]:  * Restarting with stat
2021-05-29 10:39:36,452 [werkzeug] [12588:Thread-2] _internal.py:_internal:_log in 225] [INFO]:  * Running on http://127.0.0.1:5000/ (Press CTRL+C to quit)
2021-05-29 10:39:50,376 [werkzeug] [15388:Thread-3] _internal.py:_internal:_log in 225] [INFO]: 127.0.0.1 - - [29/May/2021 10:39:50] "GET /auth/ui_test/test HTTP/1.1" 200 -
2021-05-29 10:45:41,637 [werkzeug] [11948:MainThread] _internal.py:_internal:_log in 225] [INFO]:  * Restarting with stat
2021-05-29 10:45:43,262 [werkzeug] [21184:Thread-2] _internal.py:_internal:_log in 225] [INFO]:  * Running on http://127.0.0.1:5000/ (Press CTRL+C to quit)
2021-05-29 10:46:20,006 [werkzeug] [16616:Thread-3] _internal.py:_internal:_log in 225] [INFO]: 127.0.0.1 - - [29/May/2021 10:46:20] "GET /auth/ui_test/test HTTP/1.1" 200 -
2021-05-29 10:46:57,939 [werkzeug] [20656:MainThread] _internal.py:_internal:_log in 225] [INFO]:  * Restarting with stat
2021-05-29 10:46:59,611 [werkzeug] [12864:Thread-2] _internal.py:_internal:_log in 225] [INFO]:  * Running on http://127.0.0.1:5000/ (Press CTRL+C to quit)
2021-05-29 10:48:10,291 [werkzeug] [19468:Thread-3] _internal.py:_internal:_log in 225] [INFO]: 127.0.0.1 - - [29/May/2021 10:48:10] "GET /auth/ui_test/test HTTP/1.1" 200 -
2021-05-29 11:03:44,546 [werkzeug] [7764:MainThread] _internal.py:_internal:_log in 225] [INFO]:  * Restarting with stat
2021-05-29 11:03:46,226 [werkzeug] [3924:Thread-2] _internal.py:_internal:_log in 225] [INFO]:  * Running on http://127.0.0.1:5000/ (Press CTRL+C to quit)
2021-05-29 11:04:51,960 [werkzeug] [10380:Thread-4] _internal.py:_internal:_log in 225] [INFO]: 127.0.0.1 - - [29/May/2021 11:04:51] "GET /auth/ui_test/test HTTP/1.1" 200 -
2021-05-29 11:04:52,112 [werkzeug] [7604:Thread-3] _internal.py:_internal:_log in 225] [INFO]: 127.0.0.1 - - [29/May/2021 11:04:52] "[35m[1mGET /auth/ui_test/test HTTP/1.1[0m" 500 -
2021-05-29 11:04:52,141 [werkzeug] [20584:Thread-36] _internal.py:_internal:_log in 225] [INFO]: 127.0.0.1 - - [29/May/2021 11:04:52] "GET /auth/ui_test/test?__debugger__=yes&cmd=resource&f=style.css HTTP/1.1" 200 -
2021-05-29 11:04:52,150 [werkzeug] [1652:Thread-37] _internal.py:_internal:_log in 225] [INFO]: 127.0.0.1 - - [29/May/2021 11:04:52] "GET /auth/ui_test/test?__debugger__=yes&cmd=resource&f=debugger.js HTTP/1.1" 200 -
2021-05-29 11:04:52,165 [werkzeug] [7604:Thread-3] _internal.py:_internal:_log in 225] [ERROR]: Error on request:
Traceback (most recent call last):
  File "E:\Auto_test\flask\erybjp\venv\lib\site-packages\werkzeug\debug\__init__.py", line 309, in debug_application
    app_iter = self.app(environ, start_response)
  File "E:\Auto_test\flask\erybjp\venv\lib\site-packages\flask\app.py", line 2069, in __call__
    return self.wsgi_app(environ, start_response)
  File "E:\Auto_test\flask\erybjp\venv\lib\site-packages\flask\app.py", line 2054, in wsgi_app
    response = self.handle_exception(e)
  File "E:\Auto_test\flask\erybjp\venv\lib\site-packages\flask_cors\extension.py", line 165, in wrapped_function
    return cors_after_request(app.make_response(f(*args, **kwargs)))
  File "E:\Auto_test\flask\erybjp\venv\lib\site-packages\flask\app.py", line 2051, in wsgi_app
    response = self.full_dispatch_request()
  File "E:\Auto_test\flask\erybjp\venv\lib\site-packages\flask\app.py", line 1501, in full_dispatch_request
    rv = self.handle_user_exception(e)
  File "E:\Auto_test\flask\erybjp\venv\lib\site-packages\flask_cors\extension.py", line 165, in wrapped_function
    return cors_after_request(app.make_response(f(*args, **kwargs)))
  File "E:\Auto_test\flask\erybjp\venv\lib\site-packages\flask\app.py", line 1499, in full_dispatch_request
    rv = self.dispatch_request()
  File "E:\Auto_test\flask\erybjp\venv\lib\site-packages\flask\app.py", line 1485, in dispatch_request
    return self.ensure_sync(self.view_functions[rule.endpoint])(**req.view_args)
  File "E:\Auto_test\flask\erybjp\uiplatform\router\runtestcase.py", line 49, in run_only_test
    pytest.main(["uiplatform/utils/business/test_check_web.py"])
  File "E:\Auto_test\flask\erybjp\venv\lib\site-packages\_pytest\config\__init__.py", line 163, in main
    config=config
  File "E:\Auto_test\flask\erybjp\venv\lib\site-packages\pluggy\hooks.py", line 286, in __call__
    return self._hookexec(self, self.get_hookimpls(), kwargs)
  File "E:\Auto_test\flask\erybjp\venv\lib\site-packages\pluggy\manager.py", line 93, in _hookexec
    return self._inner_hookexec(hook, methods, kwargs)
  File "E:\Auto_test\flask\erybjp\venv\lib\site-packages\pluggy\manager.py", line 87, in <lambda>
    firstresult=hook.spec.opts.get("firstresult") if hook.spec else False,
  File "E:\Auto_test\flask\erybjp\venv\lib\site-packages\pluggy\callers.py", line 208, in _multicall
    return outcome.get_result()
  File "E:\Auto_test\flask\erybjp\venv\lib\site-packages\pluggy\callers.py", line 80, in get_result
    raise ex[1].with_traceback(ex[2])
  File "E:\Auto_test\flask\erybjp\venv\lib\site-packages\pluggy\callers.py", line 187, in _multicall
    res = hook_impl.function(*args)
  File "E:\Auto_test\flask\erybjp\venv\lib\site-packages\_pytest\main.py", line 316, in pytest_cmdline_main
    return wrap_session(config, _main)
  File "E:\Auto_test\flask\erybjp\venv\lib\site-packages\_pytest\main.py", line 305, in wrap_session
    session=session, exitstatus=session.exitstatus
  File "E:\Auto_test\flask\erybjp\venv\lib\site-packages\pluggy\hooks.py", line 286, in __call__
    return self._hookexec(self, self.get_hookimpls(), kwargs)
  File "E:\Auto_test\flask\erybjp\venv\lib\site-packages\pluggy\manager.py", line 93, in _hookexec
    return self._inner_hookexec(hook, methods, kwargs)
  File "E:\Auto_test\flask\erybjp\venv\lib\site-packages\pluggy\manager.py", line 87, in <lambda>
    firstresult=hook.spec.opts.get("firstresult") if hook.spec else False,
  File "E:\Auto_test\flask\erybjp\venv\lib\site-packages\pluggy\callers.py", line 203, in _multicall
    gen.send(outcome)
  File "E:\Auto_test\flask\erybjp\venv\lib\site-packages\_pytest\terminal.py", line 804, in pytest_sessionfinish
    self._tw.line("")
  File "E:\Auto_test\flask\erybjp\venv\lib\site-packages\_pytest\_io\terminalwriter.py", line 171, in line
    self.write("\n")
  File "E:\Auto_test\flask\erybjp\venv\lib\site-packages\_pytest\_io\terminalwriter.py", line 155, in write
    self._file.write(msg)
ValueError: I/O operation on closed file.

During handling of the above exception, another exception occurred:

Traceback (most recent call last):
  File "E:\Auto_test\flask\erybjp\venv\lib\site-packages\werkzeug\serving.py", line 319, in run_wsgi
    execute(self.server.app)
  File "E:\Auto_test\flask\erybjp\venv\lib\site-packages\werkzeug\serving.py", line 310, in execute
    for data in application_iter:
  File "E:\Auto_test\flask\erybjp\venv\lib\site-packages\werkzeug\debug\__init__.py", line 351, in debug_application
    traceback.log(environ["wsgi.errors"])
  File "E:\Auto_test\flask\erybjp\venv\lib\site-packages\werkzeug\debug\tbtools.py", line 267, in log
    logfile.write(tb)
ValueError: I/O operation on closed file.
2021-05-29 11:04:52,442 [werkzeug] [15292:Thread-38] _internal.py:_internal:_log in 225] [INFO]: 127.0.0.1 - - [29/May/2021 11:04:52] "GET /auth/ui_test/test?__debugger__=yes&cmd=resource&f=console.png HTTP/1.1" 200 -
2021-05-29 11:04:52,464 [werkzeug] [7796:Thread-39] _internal.py:_internal:_log in 225] [INFO]: 127.0.0.1 - - [29/May/2021 11:04:52] "GET /auth/ui_test/test?__debugger__=yes&cmd=resource&f=ubuntu.ttf HTTP/1.1" 200 -
2021-05-29 11:04:52,567 [werkzeug] [20468:Thread-40] _internal.py:_internal:_log in 225] [INFO]: 127.0.0.1 - - [29/May/2021 11:04:52] "GET /auth/ui_test/test?__debugger__=yes&cmd=resource&f=console.png HTTP/1.1" 200 -
2021-05-29 11:07:47,223 [werkzeug] [18200:MainThread] _internal.py:_internal:_log in 225] [INFO]:  * Restarting with stat
2021-05-29 11:07:49,223 [werkzeug] [2396:Thread-2] _internal.py:_internal:_log in 225] [INFO]:  * Running on http://127.0.0.1:5000/ (Press CTRL+C to quit)
2021-05-29 11:09:35,494 [werkzeug] [21468:Thread-3] _internal.py:_internal:_log in 225] [INFO]: 127.0.0.1 - - [29/May/2021 11:09:35] "GET /auth/ui_test/test HTTP/1.1" 200 -
2021-05-29 11:09:36,014 [werkzeug] [16752:Thread-4] _internal.py:_internal:_log in 225] [INFO]: 127.0.0.1 - - [29/May/2021 11:09:36] "[35m[1mGET /auth/ui_test/test HTTP/1.1[0m" 500 -
2021-05-29 11:09:36,028 [werkzeug] [16752:Thread-4] _internal.py:_internal:_log in 225] [ERROR]: Error on request:
Traceback (most recent call last):
  File "E:\Auto_test\flask\erybjp\venv\lib\site-packages\werkzeug\debug\__init__.py", line 309, in debug_application
    app_iter = self.app(environ, start_response)
  File "E:\Auto_test\flask\erybjp\venv\lib\site-packages\flask\app.py", line 2069, in __call__
    return self.wsgi_app(environ, start_response)
  File "E:\Auto_test\flask\erybjp\venv\lib\site-packages\flask\app.py", line 2054, in wsgi_app
    response = self.handle_exception(e)
  File "E:\Auto_test\flask\erybjp\venv\lib\site-packages\flask_cors\extension.py", line 165, in wrapped_function
    return cors_after_request(app.make_response(f(*args, **kwargs)))
  File "E:\Auto_test\flask\erybjp\venv\lib\site-packages\flask\app.py", line 2051, in wsgi_app
    response = self.full_dispatch_request()
  File "E:\Auto_test\flask\erybjp\venv\lib\site-packages\flask\app.py", line 1501, in full_dispatch_request
    rv = self.handle_user_exception(e)
  File "E:\Auto_test\flask\erybjp\venv\lib\site-packages\flask_cors\extension.py", line 165, in wrapped_function
    return cors_after_request(app.make_response(f(*args, **kwargs)))
  File "E:\Auto_test\flask\erybjp\venv\lib\site-packages\flask\app.py", line 1499, in full_dispatch_request
    rv = self.dispatch_request()
  File "E:\Auto_test\flask\erybjp\venv\lib\site-packages\flask\app.py", line 1485, in dispatch_request
    return self.ensure_sync(self.view_functions[rule.endpoint])(**req.view_args)
  File "E:\Auto_test\flask\erybjp\uiplatform\router\runtestcase.py", line 49, in run_only_test
    pytest.main(["uiplatform/utils/business/test_check_web.py"])
  File "E:\Auto_test\flask\erybjp\venv\lib\site-packages\_pytest\config\__init__.py", line 163, in main
    config=config
  File "E:\Auto_test\flask\erybjp\venv\lib\site-packages\pluggy\hooks.py", line 286, in __call__
    return self._hookexec(self, self.get_hookimpls(), kwargs)
  File "E:\Auto_test\flask\erybjp\venv\lib\site-packages\pluggy\manager.py", line 93, in _hookexec
    return self._inner_hookexec(hook, methods, kwargs)
  File "E:\Auto_test\flask\erybjp\venv\lib\site-packages\pluggy\manager.py", line 87, in <lambda>
    firstresult=hook.spec.opts.get("firstresult") if hook.spec else False,
  File "E:\Auto_test\flask\erybjp\venv\lib\site-packages\pluggy\callers.py", line 208, in _multicall
    return outcome.get_result()
  File "E:\Auto_test\flask\erybjp\venv\lib\site-packages\pluggy\callers.py", line 80, in get_result
    raise ex[1].with_traceback(ex[2])
  File "E:\Auto_test\flask\erybjp\venv\lib\site-packages\pluggy\callers.py", line 187, in _multicall
    res = hook_impl.function(*args)
  File "E:\Auto_test\flask\erybjp\venv\lib\site-packages\_pytest\main.py", line 316, in pytest_cmdline_main
    return wrap_session(config, _main)
  File "E:\Auto_test\flask\erybjp\venv\lib\site-packages\_pytest\main.py", line 305, in wrap_session
    session=session, exitstatus=session.exitstatus
  File "E:\Auto_test\flask\erybjp\venv\lib\site-packages\pluggy\hooks.py", line 286, in __call__
    return self._hookexec(self, self.get_hookimpls(), kwargs)
  File "E:\Auto_test\flask\erybjp\venv\lib\site-packages\pluggy\manager.py", line 93, in _hookexec
    return self._inner_hookexec(hook, methods, kwargs)
  File "E:\Auto_test\flask\erybjp\venv\lib\site-packages\pluggy\manager.py", line 87, in <lambda>
    firstresult=hook.spec.opts.get("firstresult") if hook.spec else False,
  File "E:\Auto_test\flask\erybjp\venv\lib\site-packages\pluggy\callers.py", line 203, in _multicall
    gen.send(outcome)
  File "E:\Auto_test\flask\erybjp\venv\lib\site-packages\_pytest\terminal.py", line 804, in pytest_sessionfinish
    self._tw.line("")
  File "E:\Auto_test\flask\erybjp\venv\lib\site-packages\_pytest\_io\terminalwriter.py", line 171, in line
    self.write("\n")
  File "E:\Auto_test\flask\erybjp\venv\lib\site-packages\_pytest\_io\terminalwriter.py", line 155, in write
    self._file.write(msg)
ValueError: I/O operation on closed file.

During handling of the above exception, another exception occurred:

Traceback (most recent call last):
  File "E:\Auto_test\flask\erybjp\venv\lib\site-packages\werkzeug\serving.py", line 319, in run_wsgi
    execute(self.server.app)
  File "E:\Auto_test\flask\erybjp\venv\lib\site-packages\werkzeug\serving.py", line 310, in execute
    for data in application_iter:
  File "E:\Auto_test\flask\erybjp\venv\lib\site-packages\werkzeug\debug\__init__.py", line 351, in debug_application
    traceback.log(environ["wsgi.errors"])
  File "E:\Auto_test\flask\erybjp\venv\lib\site-packages\werkzeug\debug\tbtools.py", line 267, in log
    logfile.write(tb)
ValueError: I/O operation on closed file.
2021-05-29 11:09:36,034 [werkzeug] [16264:Thread-72] _internal.py:_internal:_log in 225] [INFO]: 127.0.0.1 - - [29/May/2021 11:09:36] "GET /auth/ui_test/test?__debugger__=yes&cmd=resource&f=style.css HTTP/1.1" 200 -
2021-05-29 11:09:36,034 [werkzeug] [2188:Thread-73] _internal.py:_internal:_log in 225] [INFO]: 127.0.0.1 - - [29/May/2021 11:09:36] "GET /auth/ui_test/test?__debugger__=yes&cmd=resource&f=debugger.js HTTP/1.1" 200 -
2021-05-29 11:09:36,314 [werkzeug] [8624:Thread-74] _internal.py:_internal:_log in 225] [INFO]: 127.0.0.1 - - [29/May/2021 11:09:36] "GET /auth/ui_test/test?__debugger__=yes&cmd=resource&f=console.png HTTP/1.1" 200 -
2021-05-29 11:09:36,333 [werkzeug] [18244:Thread-75] _internal.py:_internal:_log in 225] [INFO]: 127.0.0.1 - - [29/May/2021 11:09:36] "GET /auth/ui_test/test?__debugger__=yes&cmd=resource&f=ubuntu.ttf HTTP/1.1" 200 -
2021-05-29 11:09:36,430 [werkzeug] [11480:Thread-76] _internal.py:_internal:_log in 225] [INFO]: 127.0.0.1 - - [29/May/2021 11:09:36] "GET /auth/ui_test/test?__debugger__=yes&cmd=resource&f=console.png HTTP/1.1" 200 -
2021-05-29 12:02:55,700 [werkzeug] [12136:Thread-77] _internal.py:_internal:_log in 225] [INFO]: 127.0.0.1 - - [29/May/2021 12:02:55] "GET /auth/ui_test/test HTTP/1.1" 200 -
2021-05-29 12:03:38,531 [werkzeug] [20232:MainThread] _internal.py:_internal:_log in 225] [INFO]:  * Restarting with stat
2021-05-29 12:03:40,231 [werkzeug] [16080:Thread-2] _internal.py:_internal:_log in 225] [INFO]:  * Running on http://127.0.0.1:5000/ (Press CTRL+C to quit)
2021-05-29 12:04:15,532 [werkzeug] [11180:Thread-3] _internal.py:_internal:_log in 225] [INFO]: 127.0.0.1 - - [29/May/2021 12:04:15] "GET /auth/ui_test/test HTTP/1.1" 200 -
2021-05-29 12:13:36,031 [werkzeug] [5536:MainThread] _internal.py:_internal:_log in 225] [INFO]:  * Restarting with stat
2021-05-29 12:13:37,754 [werkzeug] [6192:Thread-2] _internal.py:_internal:_log in 225] [INFO]:  * Running on http://127.0.0.1:5000/ (Press CTRL+C to quit)
2021-05-29 12:20:58,120 [werkzeug] [10032:MainThread] _internal.py:_internal:_log in 225] [INFO]:  * Detected change in 'E:\\Auto_test\\flask\\erybjp\\uiplatform\\utils\\business\\conftest.py', reloading
2021-05-29 12:20:58,208 [werkzeug] [5536:MainThread] _internal.py:_internal:_log in 225] [INFO]:  * Restarting with stat
2021-05-29 12:21:00,002 [werkzeug] [7244:Thread-2] _internal.py:_internal:_log in 225] [INFO]:  * Running on http://127.0.0.1:5000/ (Press CTRL+C to quit)
2021-05-29 12:22:31,363 [werkzeug] [13652:MainThread] _internal.py:_internal:_log in 225] [INFO]:  * Restarting with stat
2021-05-29 12:22:33,151 [werkzeug] [8412:Thread-2] _internal.py:_internal:_log in 225] [INFO]:  * Running on http://127.0.0.1:5000/ (Press CTRL+C to quit)
2021-05-29 12:22:51,746 [werkzeug] [4260:Thread-3] _internal.py:_internal:_log in 225] [INFO]: 127.0.0.1 - - [29/May/2021 12:22:51] "GET /auth/ui_test/test HTTP/1.1" 200 -
2021-05-29 12:25:02,377 [werkzeug] [20324:MainThread] _internal.py:_internal:_log in 225] [INFO]:  * Restarting with stat
2021-05-29 12:25:05,486 [werkzeug] [8548:Thread-7] _internal.py:_internal:_log in 225] [INFO]:  * Running on http://127.0.0.1:5000/ (Press CTRL+C to quit)
2021-05-29 12:25:33,983 [werkzeug] [15844:Thread-8] _internal.py:_internal:_log in 225] [INFO]: 127.0.0.1 - - [29/May/2021 12:25:33] "GET /auth/ui_test/test HTTP/1.1" 200 -
2021-05-29 12:26:16,289 [werkzeug] [4712:MainThread] _internal.py:_internal:_log in 225] [INFO]:  * Detected change in 'E:\\Auto_test\\flask\\erybjp\\uiplatform\\utils\\business\\conftest.py', reloading
2021-05-29 12:26:16,528 [werkzeug] [20324:MainThread] _internal.py:_internal:_log in 225] [INFO]:  * Restarting with stat
2021-05-29 12:26:19,662 [werkzeug] [8708:Thread-7] _internal.py:_internal:_log in 225] [INFO]:  * Running on http://127.0.0.1:5000/ (Press CTRL+C to quit)
2021-05-29 12:27:40,363 [werkzeug] [9608:MainThread] _internal.py:_internal:_log in 225] [INFO]:  * Restarting with stat
2021-05-29 12:27:42,096 [werkzeug] [18636:Thread-2] _internal.py:_internal:_log in 225] [INFO]:  * Running on http://127.0.0.1:5000/ (Press CTRL+C to quit)
2021-05-29 12:28:23,228 [werkzeug] [12532:Thread-3] _internal.py:_internal:_log in 225] [INFO]: 127.0.0.1 - - [29/May/2021 12:28:23] "GET /auth/ui_test/test HTTP/1.1" 200 -
2021-05-29 20:43:38,167 [werkzeug] [19840:MainThread] _internal.py:_internal:_log in 225] [INFO]:  * Restarting with stat
2021-05-29 20:43:39,960 [werkzeug] [6996:Thread-2] _internal.py:_internal:_log in 225] [INFO]:  * Running on http://127.0.0.1:5000/ (Press CTRL+C to quit)
2021-05-29 20:44:00,213 [werkzeug] [1032:MainThread] _internal.py:_internal:_log in 225] [INFO]:  * Restarting with stat
2021-05-29 20:44:01,880 [werkzeug] [9888:Thread-2] _internal.py:_internal:_log in 225] [INFO]:  * Running on http://127.0.0.1:5000/ (Press CTRL+C to quit)
2021-05-29 20:44:09,275 [werkzeug] [17384:Thread-3] _internal.py:_internal:_log in 225] [INFO]: 127.0.0.1 - - [29/May/2021 20:44:09] "GET /auth/ui_test/test HTTP/1.1" 200 -
2021-05-29 20:45:33,616 [werkzeug] [14048:MainThread] _internal.py:_internal:_log in 225] [INFO]:  * Restarting with stat
2021-05-29 20:45:35,379 [werkzeug] [20124:Thread-2] _internal.py:_internal:_log in 225] [INFO]:  * Running on http://127.0.0.1:5000/ (Press CTRL+C to quit)
2021-05-29 20:45:36,837 [werkzeug] [20760:Thread-4] _internal.py:_internal:_log in 225] [INFO]: 127.0.0.1 - - [29/May/2021 20:45:36] "GET /auth/ui_test/test HTTP/1.1" 200 -
2021-05-29 20:47:14,807 [werkzeug] [9072:MainThread] _internal.py:_internal:_log in 225] [INFO]:  * Restarting with stat
2021-05-29 20:47:16,585 [werkzeug] [10684:Thread-2] _internal.py:_internal:_log in 225] [INFO]:  * Running on http://127.0.0.1:5000/ (Press CTRL+C to quit)
2021-05-29 20:47:23,592 [werkzeug] [12416:Thread-3] _internal.py:_internal:_log in 225] [INFO]: 127.0.0.1 - - [29/May/2021 20:47:23] "GET /auth/ui_test/test HTTP/1.1" 200 -
2021-05-29 20:48:07,138 [werkzeug] [1080:MainThread] _internal.py:_internal:_log in 225] [INFO]:  * Restarting with stat
2021-05-29 20:48:09,084 [werkzeug] [9888:Thread-2] _internal.py:_internal:_log in 225] [INFO]:  * Running on http://127.0.0.1:5000/ (Press CTRL+C to quit)
2021-05-29 20:48:38,398 [werkzeug] [17480:Thread-3] _internal.py:_internal:_log in 225] [INFO]: 127.0.0.1 - - [29/May/2021 20:48:38] "GET /auth/ui_test/test HTTP/1.1" 200 -
2021-05-29 20:48:50,001 [werkzeug] [12412:MainThread] _internal.py:_internal:_log in 225] [INFO]:  * Restarting with stat
2021-05-29 20:48:51,764 [werkzeug] [19272:Thread-2] _internal.py:_internal:_log in 225] [INFO]:  * Running on http://127.0.0.1:5000/ (Press CTRL+C to quit)
2021-05-29 20:49:05,379 [werkzeug] [20732:Thread-3] _internal.py:_internal:_log in 225] [INFO]: 127.0.0.1 - - [29/May/2021 20:49:05] "GET /auth/ui_test/test HTTP/1.1" 200 -
2021-05-29 20:51:10,755 [werkzeug] [12436:MainThread] _internal.py:_internal:_log in 225] [INFO]:  * Restarting with stat
2021-05-29 20:51:48,144 [werkzeug] [12468:MainThread] _internal.py:_internal:_log in 225] [INFO]:  * Restarting with stat
2021-05-29 20:51:49,843 [werkzeug] [15460:Thread-2] _internal.py:_internal:_log in 225] [INFO]:  * Running on http://127.0.0.1:5000/ (Press CTRL+C to quit)
2021-05-29 20:52:25,729 [werkzeug] [18660:Thread-3] _internal.py:_internal:_log in 225] [INFO]: 127.0.0.1 - - [29/May/2021 20:52:25] "GET /auth/ui_test/test HTTP/1.1" 200 -
2021-05-29 20:53:11,940 [werkzeug] [15120:MainThread] _internal.py:_internal:_log in 225] [INFO]:  * Restarting with stat
2021-05-29 20:53:13,717 [werkzeug] [13472:Thread-2] _internal.py:_internal:_log in 225] [INFO]:  * Running on http://127.0.0.1:5000/ (Press CTRL+C to quit)
2021-05-29 20:53:32,762 [werkzeug] [7256:Thread-3] _internal.py:_internal:_log in 225] [INFO]: 127.0.0.1 - - [29/May/2021 20:53:32] "GET /auth/ui_test/test HTTP/1.1" 200 -
2021-05-29 20:58:11,804 [werkzeug] [4428:MainThread] _internal.py:_internal:_log in 225] [INFO]:  * Restarting with stat
2021-05-29 20:58:13,683 [werkzeug] [13404:Thread-2] _internal.py:_internal:_log in 225] [INFO]:  * Running on http://127.0.0.1:5000/ (Press CTRL+C to quit)
2021-05-29 20:58:33,775 [werkzeug] [8576:Thread-3] _internal.py:_internal:_log in 225] [INFO]: 127.0.0.1 - - [29/May/2021 20:58:33] "GET /auth/ui_test/test HTTP/1.1" 200 -
2021-05-29 21:03:26,855 [werkzeug] [17952:MainThread] _internal.py:_internal:_log in 225] [INFO]:  * Restarting with stat
2021-05-29 21:03:28,573 [werkzeug] [11008:Thread-2] _internal.py:_internal:_log in 225] [INFO]:  * Running on http://127.0.0.1:5000/ (Press CTRL+C to quit)
2021-05-29 21:04:09,551 [werkzeug] [16960:Thread-3] _internal.py:_internal:_log in 225] [INFO]: 127.0.0.1 - - [29/May/2021 21:04:09] "GET /auth/ui_test/test HTTP/1.1" 200 -
2021-05-29 21:05:33,271 [werkzeug] [16824:MainThread] _internal.py:_internal:_log in 225] [INFO]:  * Detected change in 'E:\\Auto_test\\flask\\erybjp\\uiplatform\\utils\\business\\test_check_web.py', reloading
2021-05-29 21:05:33,347 [werkzeug] [17952:MainThread] _internal.py:_internal:_log in 225] [INFO]:  * Restarting with stat
2021-05-29 21:05:35,154 [werkzeug] [11924:Thread-2] _internal.py:_internal:_log in 225] [INFO]:  * Running on http://127.0.0.1:5000/ (Press CTRL+C to quit)
2021-05-29 21:06:32,887 [werkzeug] [18100:MainThread] _internal.py:_internal:_log in 225] [INFO]:  * Restarting with stat
2021-05-29 21:06:46,727 [werkzeug] [7180:MainThread] _internal.py:_internal:_log in 225] [INFO]:  * Restarting with stat
2021-05-29 21:06:48,549 [werkzeug] [12468:Thread-2] _internal.py:_internal:_log in 225] [INFO]:  * Running on http://127.0.0.1:5000/ (Press CTRL+C to quit)
2021-05-29 21:07:40,535 [werkzeug] [10400:Thread-3] _internal.py:_internal:_log in 225] [INFO]: 127.0.0.1 - - [29/May/2021 21:07:40] "GET /auth/ui_test/test HTTP/1.1" 200 -
2021-05-29 21:14:45,738 [werkzeug] [8800:MainThread] _internal.py:_internal:_log in 225] [INFO]:  * Restarting with stat
2021-05-29 21:14:48,785 [werkzeug] [3040:Thread-7] _internal.py:_internal:_log in 225] [INFO]:  * Running on http://127.0.0.1:5000/ (Press CTRL+C to quit)
2021-05-29 21:14:58,728 [werkzeug] [4988:MainThread] _internal.py:_internal:_log in 225] [INFO]:  * Restarting with stat
2021-05-29 21:15:01,798 [werkzeug] [14100:Thread-7] _internal.py:_internal:_log in 225] [INFO]:  * Running on http://127.0.0.1:5000/ (Press CTRL+C to quit)
2021-05-29 21:15:14,976 [werkzeug] [1044:MainThread] _internal.py:_internal:_log in 225] [INFO]:  * Restarting with stat
2021-05-29 21:15:18,006 [werkzeug] [20936:Thread-7] _internal.py:_internal:_log in 225] [INFO]:  * Running on http://127.0.0.1:5000/ (Press CTRL+C to quit)
2021-05-29 21:18:48,213 [werkzeug] [2832:MainThread] _internal.py:_internal:_log in 225] [INFO]:  * Restarting with stat
2021-05-29 21:18:49,889 [werkzeug] [11208:Thread-2] _internal.py:_internal:_log in 225] [INFO]:  * Running on http://127.0.0.1:5000/ (Press CTRL+C to quit)
2021-05-29 21:19:41,667 [werkzeug] [11060:Thread-3] _internal.py:_internal:_log in 225] [INFO]: 127.0.0.1 - - [29/May/2021 21:19:41] "GET /auth/ui_test/test HTTP/1.1" 200 -
2021-05-29 21:19:51,686 [werkzeug] [11472:MainThread] _internal.py:_internal:_log in 225] [INFO]:  * Restarting with stat
2021-05-29 21:19:53,437 [werkzeug] [21092:Thread-2] _internal.py:_internal:_log in 225] [INFO]:  * Running on http://127.0.0.1:5000/ (Press CTRL+C to quit)
2021-05-29 21:20:29,596 [werkzeug] [14720:Thread-4] _internal.py:_internal:_log in 225] [INFO]: 127.0.0.1 - - [29/May/2021 21:20:29] "GET /auth/ui_test/test HTTP/1.1" 200 -
2021-05-29 21:22:30,336 [werkzeug] [1764:MainThread] _internal.py:_internal:_log in 225] [INFO]:  * Restarting with stat
2021-05-29 21:22:32,093 [werkzeug] [20884:Thread-2] _internal.py:_internal:_log in 225] [INFO]:  * Running on http://127.0.0.1:5000/ (Press CTRL+C to quit)
2021-05-29 21:23:13,966 [werkzeug] [4252:Thread-3] _internal.py:_internal:_log in 225] [INFO]: 127.0.0.1 - - [29/May/2021 21:23:13] "GET /auth/ui_test/test HTTP/1.1" 200 -
2021-05-29 21:53:53,872 [werkzeug] [4676:MainThread] _internal.py:_internal:_log in 225] [INFO]:  * Restarting with stat
2021-05-29 21:53:55,734 [werkzeug] [20504:MainThread] _internal.py:_internal:_log in 225] [WARNING]:  * Debugger is active!
2021-05-29 21:53:55,743 [werkzeug] [20504:MainThread] _internal.py:_internal:_log in 225] [INFO]:  * Debugger PIN: 182-435-572
2021-05-29 21:53:55,865 [werkzeug] [1160:Thread-1] _internal.py:_internal:_log in 225] [WARNING]:  * Running on all addresses.
   WARNING: This is a development server. Do not use it in a production deployment.
2021-05-29 21:53:55,865 [werkzeug] [1160:Thread-1] _internal.py:_internal:_log in 225] [INFO]:  * Running on http://192.168.31.7:6851/ (Press CTRL+C to quit)
2021-05-29 21:54:45,509 [werkzeug] [16804:MainThread] _internal.py:_internal:_log in 225] [INFO]:  * Restarting with stat
2021-05-29 21:54:48,057 [werkzeug] [19116:MainThread] _internal.py:_internal:_log in 225] [WARNING]:  * Debugger is active!
2021-05-29 21:54:48,066 [werkzeug] [19116:MainThread] _internal.py:_internal:_log in 225] [INFO]:  * Debugger PIN: 182-435-572
2021-05-29 21:54:48,184 [werkzeug] [16148:Thread-1] _internal.py:_internal:_log in 225] [WARNING]:  * Running on all addresses.
   WARNING: This is a development server. Do not use it in a production deployment.
2021-05-29 21:54:48,184 [werkzeug] [16148:Thread-1] _internal.py:_internal:_log in 225] [INFO]:  * Running on http://192.168.31.7:6851/ (Press CTRL+C to quit)
2021-05-29 21:55:23,459 [werkzeug] [10948:Thread-2] _internal.py:_internal:_log in 225] [INFO]: 192.168.31.7 - - [29/May/2021 21:55:23] "GET /auth/ui_test/test HTTP/1.1" 200 -
2021-05-29 21:55:24,588 [werkzeug] [14160:Thread-3] _internal.py:_internal:_log in 225] [INFO]: 192.168.31.7 - - [29/May/2021 21:55:24] "GET /auth/ui_test/test HTTP/1.1" 200 -
2021-05-29 21:55:28,138 [werkzeug] [11448:Thread-4] _internal.py:_internal:_log in 225] [INFO]: 192.168.31.7 - - [29/May/2021 21:55:28] "[33mGET /favicon.ico HTTP/1.1[0m" 404 -
2021-05-29 22:18:10,405 [werkzeug] [9120:MainThread] _internal.py:_internal:_log in 225] [INFO]:  * Restarting with stat
2021-05-29 22:18:17,711 [werkzeug] [8976:MainThread] _internal.py:_internal:_log in 225] [WARNING]:  * Debugger is active!
2021-05-29 22:18:17,723 [werkzeug] [8976:MainThread] _internal.py:_internal:_log in 225] [INFO]:  * Debugger PIN: 182-435-572
2021-05-29 22:18:17,904 [werkzeug] [11648:Thread-6] _internal.py:_internal:_log in 225] [WARNING]:  * Running on all addresses.
   WARNING: This is a development server. Do not use it in a production deployment.
2021-05-29 22:18:17,905 [werkzeug] [11648:Thread-6] _internal.py:_internal:_log in 225] [INFO]:  * Running on http://192.168.31.7:6851/ (Press CTRL+C to quit)
2021-05-29 22:19:29,373 [werkzeug] [20916:Thread-7] _internal.py:_internal:_log in 225] [INFO]: 192.168.31.7 - - [29/May/2021 22:19:29] "GET /auth/ui_test/test HTTP/1.1" 200 -
2021-05-29 22:22:08,256 [werkzeug] [3780:MainThread] _internal.py:_internal:_log in 225] [INFO]:  * Restarting with stat
2021-05-29 22:22:12,225 [werkzeug] [7148:MainThread] _internal.py:_internal:_log in 225] [WARNING]:  * Debugger is active!
2021-05-29 22:22:12,234 [werkzeug] [7148:MainThread] _internal.py:_internal:_log in 225] [INFO]:  * Debugger PIN: 182-435-572
2021-05-29 22:22:12,351 [werkzeug] [12748:Thread-1] _internal.py:_internal:_log in 225] [WARNING]:  * Running on all addresses.
   WARNING: This is a development server. Do not use it in a production deployment.
2021-05-29 22:22:12,351 [werkzeug] [12748:Thread-1] _internal.py:_internal:_log in 225] [INFO]:  * Running on http://192.168.31.7:6851/ (Press CTRL+C to quit)
2021-05-29 22:22:54,520 [werkzeug] [16900:Thread-2] _internal.py:_internal:_log in 225] [INFO]: 192.168.31.7 - - [29/May/2021 22:22:54] "GET /auth/ui_test/test HTTP/1.1" 200 -
2021-05-29 22:23:44,292 [werkzeug] [7148:MainThread] _internal.py:_internal:_log in 225] [INFO]:  * Detected change in 'E:\\Auto_test\\flask\\erybjp\\uiplatform\\utils\\business\\conftest.py', reloading
2021-05-29 22:23:44,379 [werkzeug] [3780:MainThread] _internal.py:_internal:_log in 225] [INFO]:  * Restarting with stat
2021-05-29 22:23:47,349 [werkzeug] [10552:MainThread] _internal.py:_internal:_log in 225] [WARNING]:  * Debugger is active!
2021-05-29 22:23:47,359 [werkzeug] [10552:MainThread] _internal.py:_internal:_log in 225] [INFO]:  * Debugger PIN: 182-435-572
2021-05-29 22:23:47,481 [werkzeug] [5376:Thread-1] _internal.py:_internal:_log in 225] [WARNING]:  * Running on all addresses.
   WARNING: This is a development server. Do not use it in a production deployment.
2021-05-29 22:23:47,482 [werkzeug] [5376:Thread-1] _internal.py:_internal:_log in 225] [INFO]:  * Running on http://192.168.31.7:6851/ (Press CTRL+C to quit)
2021-05-29 22:24:00,851 [werkzeug] [10552:MainThread] _internal.py:_internal:_log in 225] [INFO]:  * Detected change in 'E:\\Auto_test\\flask\\erybjp\\uiplatform\\utils\\business\\conftest.py', reloading
2021-05-29 22:24:00,929 [werkzeug] [3780:MainThread] _internal.py:_internal:_log in 225] [INFO]:  * Restarting with stat
2021-05-29 22:24:04,208 [werkzeug] [19884:MainThread] _internal.py:_internal:_log in 225] [WARNING]:  * Debugger is active!
2021-05-29 22:24:04,217 [werkzeug] [19884:MainThread] _internal.py:_internal:_log in 225] [INFO]:  * Debugger PIN: 182-435-572
2021-05-29 22:24:04,339 [werkzeug] [16164:Thread-1] _internal.py:_internal:_log in 225] [WARNING]:  * Running on all addresses.
   WARNING: This is a development server. Do not use it in a production deployment.
2021-05-29 22:24:04,339 [werkzeug] [16164:Thread-1] _internal.py:_internal:_log in 225] [INFO]:  * Running on http://192.168.31.7:6851/ (Press CTRL+C to quit)
2021-05-29 22:24:27,613 [werkzeug] [19884:MainThread] _internal.py:_internal:_log in 225] [INFO]:  * Detected change in 'E:\\Auto_test\\flask\\erybjp\\uiplatform\\utils\\business\\conftest.py', reloading
2021-05-29 22:24:27,678 [werkzeug] [3780:MainThread] _internal.py:_internal:_log in 225] [INFO]:  * Restarting with stat
2021-05-29 22:24:32,616 [werkzeug] [14716:MainThread] _internal.py:_internal:_log in 225] [WARNING]:  * Debugger is active!
2021-05-29 22:24:32,625 [werkzeug] [14716:MainThread] _internal.py:_internal:_log in 225] [INFO]:  * Debugger PIN: 182-435-572
2021-05-29 22:24:32,747 [werkzeug] [15396:Thread-1] _internal.py:_internal:_log in 225] [WARNING]:  * Running on all addresses.
   WARNING: This is a development server. Do not use it in a production deployment.
2021-05-29 22:24:32,747 [werkzeug] [15396:Thread-1] _internal.py:_internal:_log in 225] [INFO]:  * Running on http://192.168.31.7:6851/ (Press CTRL+C to quit)
2021-05-29 22:25:33,462 [werkzeug] [14532:MainThread] _internal.py:_internal:_log in 225] [INFO]:  * Restarting with stat
2021-05-29 22:25:36,473 [werkzeug] [3332:MainThread] _internal.py:_internal:_log in 225] [WARNING]:  * Debugger is active!
2021-05-29 22:25:36,482 [werkzeug] [3332:MainThread] _internal.py:_internal:_log in 225] [INFO]:  * Debugger PIN: 182-435-572
2021-05-29 22:25:36,603 [werkzeug] [15320:Thread-1] _internal.py:_internal:_log in 225] [WARNING]:  * Running on all addresses.
   WARNING: This is a development server. Do not use it in a production deployment.
2021-05-29 22:25:36,603 [werkzeug] [15320:Thread-1] _internal.py:_internal:_log in 225] [INFO]:  * Running on http://192.168.31.7:6851/ (Press CTRL+C to quit)
2021-05-29 22:26:13,318 [werkzeug] [2188:Thread-3] _internal.py:_internal:_log in 225] [INFO]: 192.168.31.7 - - [29/May/2021 22:26:13] "GET /auth/ui_test/test HTTP/1.1" 200 -
2021-05-29 22:28:16,047 [werkzeug] [1012:MainThread] _internal.py:_internal:_log in 225] [INFO]:  * Restarting with stat
2021-05-29 22:28:19,308 [werkzeug] [15312:MainThread] _internal.py:_internal:_log in 225] [WARNING]:  * Debugger is active!
2021-05-29 22:28:19,317 [werkzeug] [15312:MainThread] _internal.py:_internal:_log in 225] [INFO]:  * Debugger PIN: 182-435-572
2021-05-29 22:28:19,442 [werkzeug] [18880:Thread-1] _internal.py:_internal:_log in 225] [WARNING]:  * Running on all addresses.
   WARNING: This is a development server. Do not use it in a production deployment.
2021-05-29 22:28:19,442 [werkzeug] [18880:Thread-1] _internal.py:_internal:_log in 225] [INFO]:  * Running on http://192.168.31.7:6851/ (Press CTRL+C to quit)
2021-05-29 22:28:54,789 [werkzeug] [20472:Thread-2] _internal.py:_internal:_log in 225] [INFO]: 192.168.31.7 - - [29/May/2021 22:28:54] "GET /auth/ui_test/test HTTP/1.1" 200 -
2021-05-29 22:30:11,347 [werkzeug] [17016:MainThread] _internal.py:_internal:_log in 225] [INFO]:  * Restarting with stat
2021-05-29 22:30:15,085 [werkzeug] [12092:MainThread] _internal.py:_internal:_log in 225] [WARNING]:  * Debugger is active!
2021-05-29 22:30:15,095 [werkzeug] [12092:MainThread] _internal.py:_internal:_log in 225] [INFO]:  * Debugger PIN: 182-435-572
2021-05-29 22:30:15,215 [werkzeug] [20516:Thread-1] _internal.py:_internal:_log in 225] [WARNING]:  * Running on all addresses.
   WARNING: This is a development server. Do not use it in a production deployment.
2021-05-29 22:30:15,216 [werkzeug] [20516:Thread-1] _internal.py:_internal:_log in 225] [INFO]:  * Running on http://192.168.31.7:6851/ (Press CTRL+C to quit)
2021-05-29 22:30:57,573 [werkzeug] [15572:Thread-2] _internal.py:_internal:_log in 225] [INFO]: 192.168.31.7 - - [29/May/2021 22:30:57] "GET /auth/ui_test/test HTTP/1.1" 200 -
2021-05-29 22:31:14,862 [werkzeug] [12608:MainThread] _internal.py:_internal:_log in 225] [INFO]:  * Restarting with stat
2021-05-29 22:31:17,086 [werkzeug] [11576:MainThread] _internal.py:_internal:_log in 225] [WARNING]:  * Debugger is active!
2021-05-29 22:31:17,095 [werkzeug] [11576:MainThread] _internal.py:_internal:_log in 225] [INFO]:  * Debugger PIN: 182-435-572
2021-05-29 22:31:17,222 [werkzeug] [20680:Thread-1] _internal.py:_internal:_log in 225] [WARNING]:  * Running on all addresses.
   WARNING: This is a development server. Do not use it in a production deployment.
2021-05-29 22:31:17,222 [werkzeug] [20680:Thread-1] _internal.py:_internal:_log in 225] [INFO]:  * Running on http://192.168.31.7:6851/ (Press CTRL+C to quit)
2021-05-29 22:34:25,787 [werkzeug] [9948:Thread-3] _internal.py:_internal:_log in 225] [INFO]: 192.168.31.7 - - [29/May/2021 22:34:25] "GET /auth/ui_test/test HTTP/1.1" 200 -
2021-05-29 22:34:25,946 [werkzeug] [13424:Thread-2] _internal.py:_internal:_log in 225] [INFO]: 192.168.31.7 - - [29/May/2021 22:34:25] "[35m[1mGET /auth/ui_test/test HTTP/1.1[0m" 500 -
2021-05-29 22:34:25,978 [werkzeug] [10124:Thread-104] _internal.py:_internal:_log in 225] [INFO]: 192.168.31.7 - - [29/May/2021 22:34:25] "GET /auth/ui_test/test?__debugger__=yes&cmd=resource&f=style.css HTTP/1.1" 200 -
2021-05-29 22:34:25,979 [werkzeug] [1080:Thread-105] _internal.py:_internal:_log in 225] [INFO]: 192.168.31.7 - - [29/May/2021 22:34:25] "GET /auth/ui_test/test?__debugger__=yes&cmd=resource&f=debugger.js HTTP/1.1" 200 -
2021-05-29 22:34:25,993 [werkzeug] [13424:Thread-2] _internal.py:_internal:_log in 225] [ERROR]: Error on request:
Traceback (most recent call last):
  File "E:\Auto_test\flask\erybjp\venv\lib\site-packages\werkzeug\debug\__init__.py", line 309, in debug_application
    app_iter = self.app(environ, start_response)
  File "E:\Auto_test\flask\erybjp\venv\lib\site-packages\flask\app.py", line 2069, in __call__
    return self.wsgi_app(environ, start_response)
  File "E:\Auto_test\flask\erybjp\venv\lib\site-packages\flask\app.py", line 2054, in wsgi_app
    response = self.handle_exception(e)
  File "E:\Auto_test\flask\erybjp\venv\lib\site-packages\flask_cors\extension.py", line 165, in wrapped_function
    return cors_after_request(app.make_response(f(*args, **kwargs)))
  File "E:\Auto_test\flask\erybjp\venv\lib\site-packages\flask\app.py", line 2051, in wsgi_app
    response = self.full_dispatch_request()
  File "E:\Auto_test\flask\erybjp\venv\lib\site-packages\flask\app.py", line 1501, in full_dispatch_request
    rv = self.handle_user_exception(e)
  File "E:\Auto_test\flask\erybjp\venv\lib\site-packages\flask_cors\extension.py", line 165, in wrapped_function
    return cors_after_request(app.make_response(f(*args, **kwargs)))
  File "E:\Auto_test\flask\erybjp\venv\lib\site-packages\flask\app.py", line 1499, in full_dispatch_request
    rv = self.dispatch_request()
  File "E:\Auto_test\flask\erybjp\venv\lib\site-packages\flask\app.py", line 1485, in dispatch_request
    return self.ensure_sync(self.view_functions[rule.endpoint])(**req.view_args)
  File "E:\Auto_test\flask\erybjp\uiplatform\router\runtestcase.py", line 49, in run_only_test
    pytest.main(["uiplatform/utils/business/test_check_web.py"])
  File "E:\Auto_test\flask\erybjp\venv\lib\site-packages\_pytest\config\__init__.py", line 163, in main
    config=config
  File "E:\Auto_test\flask\erybjp\venv\lib\site-packages\pluggy\hooks.py", line 286, in __call__
    return self._hookexec(self, self.get_hookimpls(), kwargs)
  File "E:\Auto_test\flask\erybjp\venv\lib\site-packages\pluggy\manager.py", line 93, in _hookexec
    return self._inner_hookexec(hook, methods, kwargs)
  File "E:\Auto_test\flask\erybjp\venv\lib\site-packages\pluggy\manager.py", line 87, in <lambda>
    firstresult=hook.spec.opts.get("firstresult") if hook.spec else False,
  File "E:\Auto_test\flask\erybjp\venv\lib\site-packages\pluggy\callers.py", line 208, in _multicall
    return outcome.get_result()
  File "E:\Auto_test\flask\erybjp\venv\lib\site-packages\pluggy\callers.py", line 80, in get_result
    raise ex[1].with_traceback(ex[2])
  File "E:\Auto_test\flask\erybjp\venv\lib\site-packages\pluggy\callers.py", line 187, in _multicall
    res = hook_impl.function(*args)
  File "E:\Auto_test\flask\erybjp\venv\lib\site-packages\_pytest\main.py", line 316, in pytest_cmdline_main
    return wrap_session(config, _main)
  File "E:\Auto_test\flask\erybjp\venv\lib\site-packages\_pytest\main.py", line 305, in wrap_session
    session=session, exitstatus=session.exitstatus
  File "E:\Auto_test\flask\erybjp\venv\lib\site-packages\pluggy\hooks.py", line 286, in __call__
    return self._hookexec(self, self.get_hookimpls(), kwargs)
  File "E:\Auto_test\flask\erybjp\venv\lib\site-packages\pluggy\manager.py", line 93, in _hookexec
    return self._inner_hookexec(hook, methods, kwargs)
  File "E:\Auto_test\flask\erybjp\venv\lib\site-packages\pluggy\manager.py", line 87, in <lambda>
    firstresult=hook.spec.opts.get("firstresult") if hook.spec else False,
  File "E:\Auto_test\flask\erybjp\venv\lib\site-packages\pluggy\callers.py", line 203, in _multicall
    gen.send(outcome)
  File "E:\Auto_test\flask\erybjp\venv\lib\site-packages\_pytest\terminal.py", line 804, in pytest_sessionfinish
    self._tw.line("")
  File "E:\Auto_test\flask\erybjp\venv\lib\site-packages\_pytest\_io\terminalwriter.py", line 171, in line
    self.write("\n")
  File "E:\Auto_test\flask\erybjp\venv\lib\site-packages\_pytest\_io\terminalwriter.py", line 155, in write
    self._file.write(msg)
ValueError: I/O operation on closed file.

During handling of the above exception, another exception occurred:

Traceback (most recent call last):
  File "E:\Auto_test\flask\erybjp\venv\lib\site-packages\werkzeug\serving.py", line 319, in run_wsgi
    execute(self.server.app)
  File "E:\Auto_test\flask\erybjp\venv\lib\site-packages\werkzeug\serving.py", line 310, in execute
    for data in application_iter:
  File "E:\Auto_test\flask\erybjp\venv\lib\site-packages\werkzeug\debug\__init__.py", line 351, in debug_application
    traceback.log(environ["wsgi.errors"])
  File "E:\Auto_test\flask\erybjp\venv\lib\site-packages\werkzeug\debug\tbtools.py", line 267, in log
    logfile.write(tb)
ValueError: I/O operation on closed file.
2021-05-29 22:34:25,993 [werkzeug] [12172:Thread-24] _internal.py:_internal:_log in 225] [INFO]: 192.168.31.7 - - [29/May/2021 22:34:25] "[35m[1mGET /auth/ui_test/test HTTP/1.1[0m" 500 -
2021-05-29 22:34:26,008 [werkzeug] [19544:Thread-33] _internal.py:_internal:_log in 225] [INFO]: 192.168.31.7 - - [29/May/2021 22:34:26] "[35m[1mGET /auth/ui_test/test HTTP/1.1[0m" 500 -
2021-05-29 22:34:26,021 [werkzeug] [11560:Thread-106] _internal.py:_internal:_log in 225] [INFO]: 192.168.31.7 - - [29/May/2021 22:34:26] "GET /auth/ui_test/test?__debugger__=yes&cmd=resource&f=style.css HTTP/1.1" 200 -
2021-05-29 22:34:26,022 [werkzeug] [7568:Thread-107] _internal.py:_internal:_log in 225] [INFO]: 192.168.31.7 - - [29/May/2021 22:34:26] "GET /auth/ui_test/test?__debugger__=yes&cmd=resource&f=debugger.js HTTP/1.1" 200 -
2021-05-29 22:34:26,056 [werkzeug] [12172:Thread-24] _internal.py:_internal:_log in 225] [ERROR]: Error on request:
Traceback (most recent call last):
  File "E:\Auto_test\flask\erybjp\venv\lib\site-packages\_pytest\main.py", line 269, in wrap_session
    session.exitstatus = doit(config, session) or 0
  File "E:\Auto_test\flask\erybjp\venv\lib\site-packages\_pytest\main.py", line 323, in _main
    config.hook.pytest_runtestloop(session=session)
  File "E:\Auto_test\flask\erybjp\venv\lib\site-packages\pluggy\hooks.py", line 286, in __call__
    return self._hookexec(self, self.get_hookimpls(), kwargs)
  File "E:\Auto_test\flask\erybjp\venv\lib\site-packages\pluggy\manager.py", line 93, in _hookexec
    return self._inner_hookexec(hook, methods, kwargs)
  File "E:\Auto_test\flask\erybjp\venv\lib\site-packages\pluggy\manager.py", line 87, in <lambda>
    firstresult=hook.spec.opts.get("firstresult") if hook.spec else False,
  File "E:\Auto_test\flask\erybjp\venv\lib\site-packages\pluggy\callers.py", line 208, in _multicall
    return outcome.get_result()
  File "E:\Auto_test\flask\erybjp\venv\lib\site-packages\pluggy\callers.py", line 80, in get_result
    raise ex[1].with_traceback(ex[2])
  File "E:\Auto_test\flask\erybjp\venv\lib\site-packages\pluggy\callers.py", line 187, in _multicall
    res = hook_impl.function(*args)
  File "E:\Auto_test\flask\erybjp\venv\lib\site-packages\_pytest\main.py", line 348, in pytest_runtestloop
    item.config.hook.pytest_runtest_protocol(item=item, nextitem=nextitem)
  File "E:\Auto_test\flask\erybjp\venv\lib\site-packages\pluggy\hooks.py", line 286, in __call__
    return self._hookexec(self, self.get_hookimpls(), kwargs)
  File "E:\Auto_test\flask\erybjp\venv\lib\site-packages\pluggy\manager.py", line 93, in _hookexec
    return self._inner_hookexec(hook, methods, kwargs)
  File "E:\Auto_test\flask\erybjp\venv\lib\site-packages\pluggy\manager.py", line 87, in <lambda>
    firstresult=hook.spec.opts.get("firstresult") if hook.spec else False,
  File "E:\Auto_test\flask\erybjp\venv\lib\site-packages\pluggy\callers.py", line 208, in _multicall
    return outcome.get_result()
  File "E:\Auto_test\flask\erybjp\venv\lib\site-packages\pluggy\callers.py", line 80, in get_result
    raise ex[1].with_traceback(ex[2])
  File "E:\Auto_test\flask\erybjp\venv\lib\site-packages\pluggy\callers.py", line 187, in _multicall
    res = hook_impl.function(*args)
  File "E:\Auto_test\flask\erybjp\venv\lib\site-packages\_pytest\runner.py", line 109, in pytest_runtest_protocol
    runtestprotocol(item, nextitem=nextitem)
  File "E:\Auto_test\flask\erybjp\venv\lib\site-packages\_pytest\runner.py", line 126, in runtestprotocol
    reports.append(call_and_report(item, "call", log))
  File "E:\Auto_test\flask\erybjp\venv\lib\site-packages\_pytest\runner.py", line 217, in call_and_report
    report: TestReport = hook.pytest_runtest_makereport(item=item, call=call)
  File "E:\Auto_test\flask\erybjp\venv\lib\site-packages\pluggy\hooks.py", line 286, in __call__
    return self._hookexec(self, self.get_hookimpls(), kwargs)
  File "E:\Auto_test\flask\erybjp\venv\lib\site-packages\pluggy\manager.py", line 93, in _hookexec
    return self._inner_hookexec(hook, methods, kwargs)
  File "E:\Auto_test\flask\erybjp\venv\lib\site-packages\pluggy\manager.py", line 87, in <lambda>
    firstresult=hook.spec.opts.get("firstresult") if hook.spec else False,
  File "E:\Auto_test\flask\erybjp\venv\lib\site-packages\pluggy\callers.py", line 203, in _multicall
    gen.send(outcome)
  File "E:\Auto_test\flask\erybjp\uiplatform\utils\business\conftest.py", line 46, in pytest_runtest_makereport
    model.title = item.funcargs.get("browser").title
  File "E:\Auto_test\flask\erybjp\venv\lib\site-packages\selenium\webdriver\remote\webdriver.py", line 342, in title
    resp = self.execute(Command.GET_TITLE)
  File "E:\Auto_test\flask\erybjp\venv\lib\site-packages\selenium\webdriver\remote\webdriver.py", line 321, in execute
    self.error_handler.check_response(response)
  File "E:\Auto_test\flask\erybjp\venv\lib\site-packages\selenium\webdriver\remote\errorhandler.py", line 242, in check_response
    raise exception_class(message, screen, stacktrace)
selenium.common.exceptions.WebDriverException: Message: no such session
  (Driver info: chromedriver=2.36.540470 (e522d04694c7ebea4ba8821272dbef4f9b818c91),platform=Windows NT 10.0.18363 x86_64)

During handling of the above exception, another exception occurred:

Traceback (most recent call last):
  File "E:\Auto_test\flask\erybjp\venv\lib\site-packages\_pytest\main.py", line 289, in wrap_session
    config.notify_exception(excinfo, config.option)
  File "E:\Auto_test\flask\erybjp\venv\lib\site-packages\_pytest\config\__init__.py", line 1037, in notify_exception
    res = self.hook.pytest_internalerror(excrepr=excrepr, excinfo=excinfo)
  File "E:\Auto_test\flask\erybjp\venv\lib\site-packages\pluggy\hooks.py", line 286, in __call__
    return self._hookexec(self, self.get_hookimpls(), kwargs)
  File "E:\Auto_test\flask\erybjp\venv\lib\site-packages\pluggy\manager.py", line 93, in _hookexec
    return self._inner_hookexec(hook, methods, kwargs)
  File "E:\Auto_test\flask\erybjp\venv\lib\site-packages\pluggy\manager.py", line 87, in <lambda>
    firstresult=hook.spec.opts.get("firstresult") if hook.spec else False,
  File "E:\Auto_test\flask\erybjp\venv\lib\site-packages\pluggy\callers.py", line 208, in _multicall
    return outcome.get_result()
  File "E:\Auto_test\flask\erybjp\venv\lib\site-packages\pluggy\callers.py", line 80, in get_result
    raise ex[1].with_traceback(ex[2])
  File "E:\Auto_test\flask\erybjp\venv\lib\site-packages\pluggy\callers.py", line 187, in _multicall
    res = hook_impl.function(*args)
  File "E:\Auto_test\flask\erybjp\venv\lib\site-packages\_pytest\terminal.py", line 474, in pytest_internalerror
    self.write_line("INTERNALERROR> " + line)
  File "E:\Auto_test\flask\erybjp\venv\lib\site-packages\_pytest\terminal.py", line 430, in write_line
    self._tw.line(line, **markup)
  File "E:\Auto_test\flask\erybjp\venv\lib\site-packages\_pytest\_io\terminalwriter.py", line 170, in line
    self.write(s, **markup)
  File "E:\Auto_test\flask\erybjp\venv\lib\site-packages\_pytest\_io\terminalwriter.py", line 155, in write
    self._file.write(msg)
ValueError: I/O operation on closed file.

During handling of the above exception, another exception occurred:

Traceback (most recent call last):
  File "E:\Auto_test\flask\erybjp\venv\lib\site-packages\werkzeug\debug\__init__.py", line 309, in debug_application
    app_iter = self.app(environ, start_response)
  File "E:\Auto_test\flask\erybjp\venv\lib\site-packages\flask\app.py", line 2069, in __call__
    return self.wsgi_app(environ, start_response)
  File "E:\Auto_test\flask\erybjp\venv\lib\site-packages\flask\app.py", line 2054, in wsgi_app
    response = self.handle_exception(e)
  File "E:\Auto_test\flask\erybjp\venv\lib\site-packages\flask_cors\extension.py", line 165, in wrapped_function
    return cors_after_request(app.make_response(f(*args, **kwargs)))
  File "E:\Auto_test\flask\erybjp\venv\lib\site-packages\flask\app.py", line 2051, in wsgi_app
    response = self.full_dispatch_request()
  File "E:\Auto_test\flask\erybjp\venv\lib\site-packages\flask\app.py", line 1501, in full_dispatch_request
    rv = self.handle_user_exception(e)
  File "E:\Auto_test\flask\erybjp\venv\lib\site-packages\flask_cors\extension.py", line 165, in wrapped_function
    return cors_after_request(app.make_response(f(*args, **kwargs)))
  File "E:\Auto_test\flask\erybjp\venv\lib\site-packages\flask\app.py", line 1499, in full_dispatch_request
    rv = self.dispatch_request()
  File "E:\Auto_test\flask\erybjp\venv\lib\site-packages\flask\app.py", line 1485, in dispatch_request
    return self.ensure_sync(self.view_functions[rule.endpoint])(**req.view_args)
  File "E:\Auto_test\flask\erybjp\uiplatform\router\runtestcase.py", line 49, in run_only_test
    pytest.main(["uiplatform/utils/business/test_check_web.py"])
  File "E:\Auto_test\flask\erybjp\venv\lib\site-packages\_pytest\config\__init__.py", line 163, in main
    config=config
  File "E:\Auto_test\flask\erybjp\venv\lib\site-packages\pluggy\hooks.py", line 286, in __call__
    return self._hookexec(self, self.get_hookimpls(), kwargs)
  File "E:\Auto_test\flask\erybjp\venv\lib\site-packages\pluggy\manager.py", line 93, in _hookexec
    return self._inner_hookexec(hook, methods, kwargs)
  File "E:\Auto_test\flask\erybjp\venv\lib\site-packages\pluggy\manager.py", line 87, in <lambda>
    firstresult=hook.spec.opts.get("firstresult") if hook.spec else False,
  File "E:\Auto_test\flask\erybjp\venv\lib\site-packages\pluggy\callers.py", line 208, in _multicall
    return outcome.get_result()
  File "E:\Auto_test\flask\erybjp\venv\lib\site-packages\pluggy\callers.py", line 80, in get_result
    raise ex[1].with_traceback(ex[2])
  File "E:\Auto_test\flask\erybjp\venv\lib\site-packages\pluggy\callers.py", line 187, in _multicall
    res = hook_impl.function(*args)
  File "E:\Auto_test\flask\erybjp\venv\lib\site-packages\_pytest\main.py", line 316, in pytest_cmdline_main
    return wrap_session(config, _main)
  File "E:\Auto_test\flask\erybjp\venv\lib\site-packages\_pytest\main.py", line 305, in wrap_session
    session=session, exitstatus=session.exitstatus
  File "E:\Auto_test\flask\erybjp\venv\lib\site-packages\pluggy\hooks.py", line 286, in __call__
    return self._hookexec(self, self.get_hookimpls(), kwargs)
  File "E:\Auto_test\flask\erybjp\venv\lib\site-packages\pluggy\manager.py", line 93, in _hookexec
    return self._inner_hookexec(hook, methods, kwargs)
  File "E:\Auto_test\flask\erybjp\venv\lib\site-packages\pluggy\manager.py", line 87, in <lambda>
    firstresult=hook.spec.opts.get("firstresult") if hook.spec else False,
  File "E:\Auto_test\flask\erybjp\venv\lib\site-packages\pluggy\callers.py", line 203, in _multicall
    gen.send(outcome)
  File "E:\Auto_test\flask\erybjp\venv\lib\site-packages\_pytest\terminal.py", line 804, in pytest_sessionfinish
    self._tw.line("")
  File "E:\Auto_test\flask\erybjp\venv\lib\site-packages\_pytest\_io\terminalwriter.py", line 171, in line
    self.write("\n")
  File "E:\Auto_test\flask\erybjp\venv\lib\site-packages\_pytest\_io\terminalwriter.py", line 155, in write
    self._file.write(msg)
ValueError: I/O operation on closed file.

During handling of the above exception, another exception occurred:

Traceback (most recent call last):
  File "E:\Auto_test\flask\erybjp\venv\lib\site-packages\werkzeug\serving.py", line 319, in run_wsgi
    execute(self.server.app)
  File "E:\Auto_test\flask\erybjp\venv\lib\site-packages\werkzeug\serving.py", line 310, in execute
    for data in application_iter:
  File "E:\Auto_test\flask\erybjp\venv\lib\site-packages\werkzeug\debug\__init__.py", line 351, in debug_application
    traceback.log(environ["wsgi.errors"])
  File "E:\Auto_test\flask\erybjp\venv\lib\site-packages\werkzeug\debug\tbtools.py", line 267, in log
    logfile.write(tb)
ValueError: I/O operation on closed file.
2021-05-29 22:34:26,064 [werkzeug] [19544:Thread-33] _internal.py:_internal:_log in 225] [ERROR]: Error on request:
Traceback (most recent call last):
  File "E:\Auto_test\flask\erybjp\venv\lib\site-packages\_pytest\main.py", line 269, in wrap_session
    session.exitstatus = doit(config, session) or 0
  File "E:\Auto_test\flask\erybjp\venv\lib\site-packages\_pytest\main.py", line 323, in _main
    config.hook.pytest_runtestloop(session=session)
  File "E:\Auto_test\flask\erybjp\venv\lib\site-packages\pluggy\hooks.py", line 286, in __call__
    return self._hookexec(self, self.get_hookimpls(), kwargs)
  File "E:\Auto_test\flask\erybjp\venv\lib\site-packages\pluggy\manager.py", line 93, in _hookexec
    return self._inner_hookexec(hook, methods, kwargs)
  File "E:\Auto_test\flask\erybjp\venv\lib\site-packages\pluggy\manager.py", line 87, in <lambda>
    firstresult=hook.spec.opts.get("firstresult") if hook.spec else False,
  File "E:\Auto_test\flask\erybjp\venv\lib\site-packages\pluggy\callers.py", line 208, in _multicall
    return outcome.get_result()
  File "E:\Auto_test\flask\erybjp\venv\lib\site-packages\pluggy\callers.py", line 80, in get_result
    raise ex[1].with_traceback(ex[2])
  File "E:\Auto_test\flask\erybjp\venv\lib\site-packages\pluggy\callers.py", line 187, in _multicall
    res = hook_impl.function(*args)
  File "E:\Auto_test\flask\erybjp\venv\lib\site-packages\_pytest\main.py", line 348, in pytest_runtestloop
    item.config.hook.pytest_runtest_protocol(item=item, nextitem=nextitem)
  File "E:\Auto_test\flask\erybjp\venv\lib\site-packages\pluggy\hooks.py", line 286, in __call__
    return self._hookexec(self, self.get_hookimpls(), kwargs)
  File "E:\Auto_test\flask\erybjp\venv\lib\site-packages\pluggy\manager.py", line 93, in _hookexec
    return self._inner_hookexec(hook, methods, kwargs)
  File "E:\Auto_test\flask\erybjp\venv\lib\site-packages\pluggy\manager.py", line 87, in <lambda>
    firstresult=hook.spec.opts.get("firstresult") if hook.spec else False,
  File "E:\Auto_test\flask\erybjp\venv\lib\site-packages\pluggy\callers.py", line 208, in _multicall
    return outcome.get_result()
  File "E:\Auto_test\flask\erybjp\venv\lib\site-packages\pluggy\callers.py", line 80, in get_result
    raise ex[1].with_traceback(ex[2])
  File "E:\Auto_test\flask\erybjp\venv\lib\site-packages\pluggy\callers.py", line 187, in _multicall
    res = hook_impl.function(*args)
  File "E:\Auto_test\flask\erybjp\venv\lib\site-packages\_pytest\runner.py", line 109, in pytest_runtest_protocol
    runtestprotocol(item, nextitem=nextitem)
  File "E:\Auto_test\flask\erybjp\venv\lib\site-packages\_pytest\runner.py", line 126, in runtestprotocol
    reports.append(call_and_report(item, "call", log))
  File "E:\Auto_test\flask\erybjp\venv\lib\site-packages\_pytest\runner.py", line 217, in call_and_report
    report: TestReport = hook.pytest_runtest_makereport(item=item, call=call)
  File "E:\Auto_test\flask\erybjp\venv\lib\site-packages\pluggy\hooks.py", line 286, in __call__
    return self._hookexec(self, self.get_hookimpls(), kwargs)
  File "E:\Auto_test\flask\erybjp\venv\lib\site-packages\pluggy\manager.py", line 93, in _hookexec
    return self._inner_hookexec(hook, methods, kwargs)
  File "E:\Auto_test\flask\erybjp\venv\lib\site-packages\pluggy\manager.py", line 87, in <lambda>
    firstresult=hook.spec.opts.get("firstresult") if hook.spec else False,
  File "E:\Auto_test\flask\erybjp\venv\lib\site-packages\pluggy\callers.py", line 203, in _multicall
    gen.send(outcome)
  File "E:\Auto_test\flask\erybjp\uiplatform\utils\business\conftest.py", line 46, in pytest_runtest_makereport
    model.title = item.funcargs.get("browser").title
  File "E:\Auto_test\flask\erybjp\venv\lib\site-packages\selenium\webdriver\remote\webdriver.py", line 342, in title
    resp = self.execute(Command.GET_TITLE)
  File "E:\Auto_test\flask\erybjp\venv\lib\site-packages\selenium\webdriver\remote\webdriver.py", line 321, in execute
    self.error_handler.check_response(response)
  File "E:\Auto_test\flask\erybjp\venv\lib\site-packages\selenium\webdriver\remote\errorhandler.py", line 242, in check_response
    raise exception_class(message, screen, stacktrace)
selenium.common.exceptions.WebDriverException: Message: no such session
  (Driver info: chromedriver=2.36.540470 (e522d04694c7ebea4ba8821272dbef4f9b818c91),platform=Windows NT 10.0.18363 x86_64)

During handling of the above exception, another exception occurred:

Traceback (most recent call last):
  File "E:\Auto_test\flask\erybjp\venv\lib\site-packages\_pytest\main.py", line 289, in wrap_session
    config.notify_exception(excinfo, config.option)
  File "E:\Auto_test\flask\erybjp\venv\lib\site-packages\_pytest\config\__init__.py", line 1037, in notify_exception
    res = self.hook.pytest_internalerror(excrepr=excrepr, excinfo=excinfo)
  File "E:\Auto_test\flask\erybjp\venv\lib\site-packages\pluggy\hooks.py", line 286, in __call__
    return self._hookexec(self, self.get_hookimpls(), kwargs)
  File "E:\Auto_test\flask\erybjp\venv\lib\site-packages\pluggy\manager.py", line 93, in _hookexec
    return self._inner_hookexec(hook, methods, kwargs)
  File "E:\Auto_test\flask\erybjp\venv\lib\site-packages\pluggy\manager.py", line 87, in <lambda>
    firstresult=hook.spec.opts.get("firstresult") if hook.spec else False,
  File "E:\Auto_test\flask\erybjp\venv\lib\site-packages\pluggy\callers.py", line 208, in _multicall
    return outcome.get_result()
  File "E:\Auto_test\flask\erybjp\venv\lib\site-packages\pluggy\callers.py", line 80, in get_result
    raise ex[1].with_traceback(ex[2])
  File "E:\Auto_test\flask\erybjp\venv\lib\site-packages\pluggy\callers.py", line 187, in _multicall
    res = hook_impl.function(*args)
  File "E:\Auto_test\flask\erybjp\venv\lib\site-packages\_pytest\terminal.py", line 474, in pytest_internalerror
    self.write_line("INTERNALERROR> " + line)
  File "E:\Auto_test\flask\erybjp\venv\lib\site-packages\_pytest\terminal.py", line 429, in write_line
    self.ensure_newline()
  File "E:\Auto_test\flask\erybjp\venv\lib\site-packages\_pytest\terminal.py", line 417, in ensure_newline
    self._tw.line()
  File "E:\Auto_test\flask\erybjp\venv\lib\site-packages\_pytest\_io\terminalwriter.py", line 171, in line
    self.write("\n")
  File "E:\Auto_test\flask\erybjp\venv\lib\site-packages\_pytest\_io\terminalwriter.py", line 155, in write
    self._file.write(msg)
ValueError: I/O operation on closed file.

During handling of the above exception, another exception occurred:

Traceback (most recent call last):
  File "E:\Auto_test\flask\erybjp\venv\lib\site-packages\werkzeug\debug\__init__.py", line 309, in debug_application
    app_iter = self.app(environ, start_response)
  File "E:\Auto_test\flask\erybjp\venv\lib\site-packages\flask\app.py", line 2069, in __call__
    return self.wsgi_app(environ, start_response)
  File "E:\Auto_test\flask\erybjp\venv\lib\site-packages\flask\app.py", line 2054, in wsgi_app
    response = self.handle_exception(e)
  File "E:\Auto_test\flask\erybjp\venv\lib\site-packages\flask_cors\extension.py", line 165, in wrapped_function
    return cors_after_request(app.make_response(f(*args, **kwargs)))
  File "E:\Auto_test\flask\erybjp\venv\lib\site-packages\flask\app.py", line 2051, in wsgi_app
    response = self.full_dispatch_request()
  File "E:\Auto_test\flask\erybjp\venv\lib\site-packages\flask\app.py", line 1501, in full_dispatch_request
    rv = self.handle_user_exception(e)
  File "E:\Auto_test\flask\erybjp\venv\lib\site-packages\flask_cors\extension.py", line 165, in wrapped_function
    return cors_after_request(app.make_response(f(*args, **kwargs)))
  File "E:\Auto_test\flask\erybjp\venv\lib\site-packages\flask\app.py", line 1499, in full_dispatch_request
    rv = self.dispatch_request()
  File "E:\Auto_test\flask\erybjp\venv\lib\site-packages\flask\app.py", line 1485, in dispatch_request
    return self.ensure_sync(self.view_functions[rule.endpoint])(**req.view_args)
  File "E:\Auto_test\flask\erybjp\uiplatform\router\runtestcase.py", line 49, in run_only_test
    pytest.main(["uiplatform/utils/business/test_check_web.py"])
  File "E:\Auto_test\flask\erybjp\venv\lib\site-packages\_pytest\config\__init__.py", line 163, in main
    config=config
  File "E:\Auto_test\flask\erybjp\venv\lib\site-packages\pluggy\hooks.py", line 286, in __call__
    return self._hookexec(self, self.get_hookimpls(), kwargs)
  File "E:\Auto_test\flask\erybjp\venv\lib\site-packages\pluggy\manager.py", line 93, in _hookexec
    return self._inner_hookexec(hook, methods, kwargs)
  File "E:\Auto_test\flask\erybjp\venv\lib\site-packages\pluggy\manager.py", line 87, in <lambda>
    firstresult=hook.spec.opts.get("firstresult") if hook.spec else False,
  File "E:\Auto_test\flask\erybjp\venv\lib\site-packages\pluggy\callers.py", line 208, in _multicall
    return outcome.get_result()
  File "E:\Auto_test\flask\erybjp\venv\lib\site-packages\pluggy\callers.py", line 80, in get_result
    raise ex[1].with_traceback(ex[2])
  File "E:\Auto_test\flask\erybjp\venv\lib\site-packages\pluggy\callers.py", line 187, in _multicall
    res = hook_impl.function(*args)
  File "E:\Auto_test\flask\erybjp\venv\lib\site-packages\_pytest\main.py", line 316, in pytest_cmdline_main
    return wrap_session(config, _main)
  File "E:\Auto_test\flask\erybjp\venv\lib\site-packages\_pytest\main.py", line 305, in wrap_session
    session=session, exitstatus=session.exitstatus
  File "E:\Auto_test\flask\erybjp\venv\lib\site-packages\pluggy\hooks.py", line 286, in __call__
    return self._hookexec(self, self.get_hookimpls(), kwargs)
  File "E:\Auto_test\flask\erybjp\venv\lib\site-packages\pluggy\manager.py", line 93, in _hookexec
    return self._inner_hookexec(hook, methods, kwargs)
  File "E:\Auto_test\flask\erybjp\venv\lib\site-packages\pluggy\manager.py", line 87, in <lambda>
    firstresult=hook.spec.opts.get("firstresult") if hook.spec else False,
  File "E:\Auto_test\flask\erybjp\venv\lib\site-packages\pluggy\callers.py", line 203, in _multicall
    gen.send(outcome)
  File "E:\Auto_test\flask\erybjp\venv\lib\site-packages\_pytest\terminal.py", line 804, in pytest_sessionfinish
    self._tw.line("")
  File "E:\Auto_test\flask\erybjp\venv\lib\site-packages\_pytest\_io\terminalwriter.py", line 171, in line
    self.write("\n")
  File "E:\Auto_test\flask\erybjp\venv\lib\site-packages\_pytest\_io\terminalwriter.py", line 155, in write
    self._file.write(msg)
ValueError: I/O operation on closed file.

During handling of the above exception, another exception occurred:

Traceback (most recent call last):
  File "E:\Auto_test\flask\erybjp\venv\lib\site-packages\werkzeug\serving.py", line 319, in run_wsgi
    execute(self.server.app)
  File "E:\Auto_test\flask\erybjp\venv\lib\site-packages\werkzeug\serving.py", line 310, in execute
    for data in application_iter:
  File "E:\Auto_test\flask\erybjp\venv\lib\site-packages\werkzeug\debug\__init__.py", line 351, in debug_application
    traceback.log(environ["wsgi.errors"])
  File "E:\Auto_test\flask\erybjp\venv\lib\site-packages\werkzeug\debug\tbtools.py", line 267, in log
    logfile.write(tb)
ValueError: I/O operation on closed file.
2021-05-29 22:34:26,101 [werkzeug] [7552:Thread-108] _internal.py:_internal:_log in 225] [INFO]: 192.168.31.7 - - [29/May/2021 22:34:26] "GET /auth/ui_test/test?__debugger__=yes&cmd=resource&f=style.css HTTP/1.1" 200 -
2021-05-29 22:34:26,103 [werkzeug] [10924:Thread-109] _internal.py:_internal:_log in 225] [INFO]: 192.168.31.7 - - [29/May/2021 22:34:26] "GET /auth/ui_test/test?__debugger__=yes&cmd=resource&f=debugger.js HTTP/1.1" 200 -
2021-05-29 22:34:26,407 [werkzeug] [10104:Thread-110] _internal.py:_internal:_log in 225] [INFO]: 192.168.31.7 - - [29/May/2021 22:34:26] "GET /auth/ui_test/test?__debugger__=yes&cmd=resource&f=console.png HTTP/1.1" 200 -
2021-05-29 22:34:26,420 [werkzeug] [14600:Thread-111] _internal.py:_internal:_log in 225] [INFO]: 192.168.31.7 - - [29/May/2021 22:34:26] "GET /auth/ui_test/test?__debugger__=yes&cmd=resource&f=console.png HTTP/1.1" 200 -
2021-05-29 22:34:26,432 [werkzeug] [10064:Thread-112] _internal.py:_internal:_log in 225] [INFO]: 192.168.31.7 - - [29/May/2021 22:34:26] "GET /auth/ui_test/test?__debugger__=yes&cmd=resource&f=ubuntu.ttf HTTP/1.1" 200 -
2021-05-29 22:34:26,451 [werkzeug] [10160:Thread-113] _internal.py:_internal:_log in 225] [INFO]: 192.168.31.7 - - [29/May/2021 22:34:26] "GET /auth/ui_test/test?__debugger__=yes&cmd=resource&f=ubuntu.ttf HTTP/1.1" 200 -
2021-05-29 22:34:26,507 [werkzeug] [8188:Thread-114] _internal.py:_internal:_log in 225] [INFO]: 192.168.31.7 - - [29/May/2021 22:34:26] "GET /auth/ui_test/test?__debugger__=yes&cmd=resource&f=console.png HTTP/1.1" 200 -
2021-05-29 22:34:26,547 [werkzeug] [1256:Thread-115] _internal.py:_internal:_log in 225] [INFO]: 192.168.31.7 - - [29/May/2021 22:34:26] "GET /auth/ui_test/test?__debugger__=yes&cmd=resource&f=ubuntu.ttf HTTP/1.1" 200 -
2021-05-29 22:34:26,559 [werkzeug] [11720:Thread-116] _internal.py:_internal:_log in 225] [INFO]: 192.168.31.7 - - [29/May/2021 22:34:26] "GET /auth/ui_test/test?__debugger__=yes&cmd=resource&f=console.png HTTP/1.1" 200 -
2021-05-29 22:41:41,719 [werkzeug] [15132:MainThread] _internal.py:_internal:_log in 225] [INFO]:  * Restarting with stat
2021-05-29 22:41:44,599 [werkzeug] [13776:MainThread] _internal.py:_internal:_log in 225] [WARNING]:  * Debugger is active!
2021-05-29 22:41:44,608 [werkzeug] [13776:MainThread] _internal.py:_internal:_log in 225] [INFO]:  * Debugger PIN: 182-435-572
2021-05-29 22:41:44,731 [werkzeug] [5980:Thread-1] _internal.py:_internal:_log in 225] [WARNING]:  * Running on all addresses.
   WARNING: This is a development server. Do not use it in a production deployment.
2021-05-29 22:41:44,731 [werkzeug] [5980:Thread-1] _internal.py:_internal:_log in 225] [INFO]:  * Running on http://192.168.31.7:6851/ (Press CTRL+C to quit)
2021-05-29 22:46:44,278 [werkzeug] [6472:Thread-2] _internal.py:_internal:_log in 225] [INFO]: 192.168.31.7 - - [29/May/2021 22:46:44] "GET /auth/ui_test/test HTTP/1.1" 200 -
2021-05-29 22:46:44,425 [werkzeug] [10804:Thread-3] _internal.py:_internal:_log in 225] [INFO]: 192.168.31.7 - - [29/May/2021 22:46:44] "[35m[1mGET /auth/ui_test/test HTTP/1.1[0m" 500 -
2021-05-29 22:46:44,432 [werkzeug] [11012:Thread-13] _internal.py:_internal:_log in 225] [INFO]: 192.168.31.7 - - [29/May/2021 22:46:44] "[35m[1mGET /auth/ui_test/test HTTP/1.1[0m" 500 -
2021-05-29 22:46:44,445 [werkzeug] [10804:Thread-3] _internal.py:_internal:_log in 225] [ERROR]: Error on request:
Traceback (most recent call last):
  File "E:\Auto_test\flask\erybjp\venv\lib\site-packages\werkzeug\debug\__init__.py", line 309, in debug_application
    app_iter = self.app(environ, start_response)
  File "E:\Auto_test\flask\erybjp\venv\lib\site-packages\flask\app.py", line 2069, in __call__
    return self.wsgi_app(environ, start_response)
  File "E:\Auto_test\flask\erybjp\venv\lib\site-packages\flask\app.py", line 2054, in wsgi_app
    response = self.handle_exception(e)
  File "E:\Auto_test\flask\erybjp\venv\lib\site-packages\flask_cors\extension.py", line 165, in wrapped_function
    return cors_after_request(app.make_response(f(*args, **kwargs)))
  File "E:\Auto_test\flask\erybjp\venv\lib\site-packages\flask\app.py", line 2051, in wsgi_app
    response = self.full_dispatch_request()
  File "E:\Auto_test\flask\erybjp\venv\lib\site-packages\flask\app.py", line 1501, in full_dispatch_request
    rv = self.handle_user_exception(e)
  File "E:\Auto_test\flask\erybjp\venv\lib\site-packages\flask_cors\extension.py", line 165, in wrapped_function
    return cors_after_request(app.make_response(f(*args, **kwargs)))
  File "E:\Auto_test\flask\erybjp\venv\lib\site-packages\flask\app.py", line 1499, in full_dispatch_request
    rv = self.dispatch_request()
  File "E:\Auto_test\flask\erybjp\venv\lib\site-packages\flask\app.py", line 1485, in dispatch_request
    return self.ensure_sync(self.view_functions[rule.endpoint])(**req.view_args)
  File "E:\Auto_test\flask\erybjp\uiplatform\router\runtestcase.py", line 49, in run_only_test
    pytest.main(["uiplatform/utils/business/test_check_web.py"])
  File "E:\Auto_test\flask\erybjp\venv\lib\site-packages\_pytest\config\__init__.py", line 163, in main
    config=config
  File "E:\Auto_test\flask\erybjp\venv\lib\site-packages\pluggy\hooks.py", line 286, in __call__
    return self._hookexec(self, self.get_hookimpls(), kwargs)
  File "E:\Auto_test\flask\erybjp\venv\lib\site-packages\pluggy\manager.py", line 93, in _hookexec
    return self._inner_hookexec(hook, methods, kwargs)
  File "E:\Auto_test\flask\erybjp\venv\lib\site-packages\pluggy\manager.py", line 87, in <lambda>
    firstresult=hook.spec.opts.get("firstresult") if hook.spec else False,
  File "E:\Auto_test\flask\erybjp\venv\lib\site-packages\pluggy\callers.py", line 208, in _multicall
    return outcome.get_result()
  File "E:\Auto_test\flask\erybjp\venv\lib\site-packages\pluggy\callers.py", line 80, in get_result
    raise ex[1].with_traceback(ex[2])
  File "E:\Auto_test\flask\erybjp\venv\lib\site-packages\pluggy\callers.py", line 187, in _multicall
    res = hook_impl.function(*args)
  File "E:\Auto_test\flask\erybjp\venv\lib\site-packages\_pytest\main.py", line 316, in pytest_cmdline_main
    return wrap_session(config, _main)
  File "E:\Auto_test\flask\erybjp\venv\lib\site-packages\_pytest\main.py", line 305, in wrap_session
    session=session, exitstatus=session.exitstatus
  File "E:\Auto_test\flask\erybjp\venv\lib\site-packages\pluggy\hooks.py", line 286, in __call__
    return self._hookexec(self, self.get_hookimpls(), kwargs)
  File "E:\Auto_test\flask\erybjp\venv\lib\site-packages\pluggy\manager.py", line 93, in _hookexec
    return self._inner_hookexec(hook, methods, kwargs)
  File "E:\Auto_test\flask\erybjp\venv\lib\site-packages\pluggy\manager.py", line 87, in <lambda>
    firstresult=hook.spec.opts.get("firstresult") if hook.spec else False,
  File "E:\Auto_test\flask\erybjp\venv\lib\site-packages\pluggy\callers.py", line 203, in _multicall
    gen.send(outcome)
  File "E:\Auto_test\flask\erybjp\venv\lib\site-packages\_pytest\terminal.py", line 804, in pytest_sessionfinish
    self._tw.line("")
  File "E:\Auto_test\flask\erybjp\venv\lib\site-packages\_pytest\_io\terminalwriter.py", line 171, in line
    self.write("\n")
  File "E:\Auto_test\flask\erybjp\venv\lib\site-packages\_pytest\_io\terminalwriter.py", line 155, in write
    self._file.write(msg)
ValueError: I/O operation on closed file.

During handling of the above exception, another exception occurred:

Traceback (most recent call last):
  File "E:\Auto_test\flask\erybjp\venv\lib\site-packages\werkzeug\serving.py", line 319, in run_wsgi
    execute(self.server.app)
  File "E:\Auto_test\flask\erybjp\venv\lib\site-packages\werkzeug\serving.py", line 310, in execute
    for data in application_iter:
  File "E:\Auto_test\flask\erybjp\venv\lib\site-packages\werkzeug\debug\__init__.py", line 351, in debug_application
    traceback.log(environ["wsgi.errors"])
  File "E:\Auto_test\flask\erybjp\venv\lib\site-packages\werkzeug\debug\tbtools.py", line 267, in log
    logfile.write(tb)
ValueError: I/O operation on closed file.
2021-05-29 22:46:44,449 [werkzeug] [3432:Thread-192] _internal.py:_internal:_log in 225] [INFO]: 192.168.31.7 - - [29/May/2021 22:46:44] "GET /auth/ui_test/test?__debugger__=yes&cmd=resource&f=debugger.js HTTP/1.1" 200 -
2021-05-29 22:46:44,449 [werkzeug] [17276:Thread-193] _internal.py:_internal:_log in 225] [INFO]: 192.168.31.7 - - [29/May/2021 22:46:44] "GET /auth/ui_test/test?__debugger__=yes&cmd=resource&f=style.css HTTP/1.1" 200 -
2021-05-29 22:46:44,466 [werkzeug] [19384:Thread-194] _internal.py:_internal:_log in 225] [INFO]: 192.168.31.7 - - [29/May/2021 22:46:44] "GET /auth/ui_test/test?__debugger__=yes&cmd=resource&f=style.css HTTP/1.1" 200 -
2021-05-29 22:46:44,466 [werkzeug] [16560:Thread-195] _internal.py:_internal:_log in 225] [INFO]: 192.168.31.7 - - [29/May/2021 22:46:44] "GET /auth/ui_test/test?__debugger__=yes&cmd=resource&f=debugger.js HTTP/1.1" 200 -
2021-05-29 22:46:44,478 [werkzeug] [11012:Thread-13] _internal.py:_internal:_log in 225] [ERROR]: Error on request:
Traceback (most recent call last):
  File "E:\Auto_test\flask\erybjp\venv\lib\site-packages\_pytest\main.py", line 269, in wrap_session
    session.exitstatus = doit(config, session) or 0
  File "E:\Auto_test\flask\erybjp\venv\lib\site-packages\_pytest\main.py", line 323, in _main
    config.hook.pytest_runtestloop(session=session)
  File "E:\Auto_test\flask\erybjp\venv\lib\site-packages\pluggy\hooks.py", line 286, in __call__
    return self._hookexec(self, self.get_hookimpls(), kwargs)
  File "E:\Auto_test\flask\erybjp\venv\lib\site-packages\pluggy\manager.py", line 93, in _hookexec
    return self._inner_hookexec(hook, methods, kwargs)
  File "E:\Auto_test\flask\erybjp\venv\lib\site-packages\pluggy\manager.py", line 87, in <lambda>
    firstresult=hook.spec.opts.get("firstresult") if hook.spec else False,
  File "E:\Auto_test\flask\erybjp\venv\lib\site-packages\pluggy\callers.py", line 208, in _multicall
    return outcome.get_result()
  File "E:\Auto_test\flask\erybjp\venv\lib\site-packages\pluggy\callers.py", line 80, in get_result
    raise ex[1].with_traceback(ex[2])
  File "E:\Auto_test\flask\erybjp\venv\lib\site-packages\pluggy\callers.py", line 187, in _multicall
    res = hook_impl.function(*args)
  File "E:\Auto_test\flask\erybjp\venv\lib\site-packages\_pytest\main.py", line 348, in pytest_runtestloop
    item.config.hook.pytest_runtest_protocol(item=item, nextitem=nextitem)
  File "E:\Auto_test\flask\erybjp\venv\lib\site-packages\pluggy\hooks.py", line 286, in __call__
    return self._hookexec(self, self.get_hookimpls(), kwargs)
  File "E:\Auto_test\flask\erybjp\venv\lib\site-packages\pluggy\manager.py", line 93, in _hookexec
    return self._inner_hookexec(hook, methods, kwargs)
  File "E:\Auto_test\flask\erybjp\venv\lib\site-packages\pluggy\manager.py", line 87, in <lambda>
    firstresult=hook.spec.opts.get("firstresult") if hook.spec else False,
  File "E:\Auto_test\flask\erybjp\venv\lib\site-packages\pluggy\callers.py", line 208, in _multicall
    return outcome.get_result()
  File "E:\Auto_test\flask\erybjp\venv\lib\site-packages\pluggy\callers.py", line 80, in get_result
    raise ex[1].with_traceback(ex[2])
  File "E:\Auto_test\flask\erybjp\venv\lib\site-packages\pluggy\callers.py", line 187, in _multicall
    res = hook_impl.function(*args)
  File "E:\Auto_test\flask\erybjp\venv\lib\site-packages\_pytest\runner.py", line 109, in pytest_runtest_protocol
    runtestprotocol(item, nextitem=nextitem)
  File "E:\Auto_test\flask\erybjp\venv\lib\site-packages\_pytest\runner.py", line 126, in runtestprotocol
    reports.append(call_and_report(item, "call", log))
  File "E:\Auto_test\flask\erybjp\venv\lib\site-packages\_pytest\runner.py", line 217, in call_and_report
    report: TestReport = hook.pytest_runtest_makereport(item=item, call=call)
  File "E:\Auto_test\flask\erybjp\venv\lib\site-packages\pluggy\hooks.py", line 286, in __call__
    return self._hookexec(self, self.get_hookimpls(), kwargs)
  File "E:\Auto_test\flask\erybjp\venv\lib\site-packages\pluggy\manager.py", line 93, in _hookexec
    return self._inner_hookexec(hook, methods, kwargs)
  File "E:\Auto_test\flask\erybjp\venv\lib\site-packages\pluggy\manager.py", line 87, in <lambda>
    firstresult=hook.spec.opts.get("firstresult") if hook.spec else False,
  File "E:\Auto_test\flask\erybjp\venv\lib\site-packages\pluggy\callers.py", line 203, in _multicall
    gen.send(outcome)
  File "E:\Auto_test\flask\erybjp\uiplatform\utils\business\conftest.py", line 46, in pytest_runtest_makereport
    model.title = item.funcargs.get("browser").title
  File "E:\Auto_test\flask\erybjp\venv\lib\site-packages\selenium\webdriver\remote\webdriver.py", line 342, in title
    resp = self.execute(Command.GET_TITLE)
  File "E:\Auto_test\flask\erybjp\venv\lib\site-packages\selenium\webdriver\remote\webdriver.py", line 321, in execute
    self.error_handler.check_response(response)
  File "E:\Auto_test\flask\erybjp\venv\lib\site-packages\selenium\webdriver\remote\errorhandler.py", line 242, in check_response
    raise exception_class(message, screen, stacktrace)
selenium.common.exceptions.WebDriverException: Message: no such session
  (Driver info: chromedriver=2.36.540470 (e522d04694c7ebea4ba8821272dbef4f9b818c91),platform=Windows NT 10.0.18363 x86_64)

During handling of the above exception, another exception occurred:

Traceback (most recent call last):
  File "E:\Auto_test\flask\erybjp\venv\lib\site-packages\_pytest\main.py", line 289, in wrap_session
    config.notify_exception(excinfo, config.option)
  File "E:\Auto_test\flask\erybjp\venv\lib\site-packages\_pytest\config\__init__.py", line 1037, in notify_exception
    res = self.hook.pytest_internalerror(excrepr=excrepr, excinfo=excinfo)
  File "E:\Auto_test\flask\erybjp\venv\lib\site-packages\pluggy\hooks.py", line 286, in __call__
    return self._hookexec(self, self.get_hookimpls(), kwargs)
  File "E:\Auto_test\flask\erybjp\venv\lib\site-packages\pluggy\manager.py", line 93, in _hookexec
    return self._inner_hookexec(hook, methods, kwargs)
  File "E:\Auto_test\flask\erybjp\venv\lib\site-packages\pluggy\manager.py", line 87, in <lambda>
    firstresult=hook.spec.opts.get("firstresult") if hook.spec else False,
  File "E:\Auto_test\flask\erybjp\venv\lib\site-packages\pluggy\callers.py", line 208, in _multicall
    return outcome.get_result()
  File "E:\Auto_test\flask\erybjp\venv\lib\site-packages\pluggy\callers.py", line 80, in get_result
    raise ex[1].with_traceback(ex[2])
  File "E:\Auto_test\flask\erybjp\venv\lib\site-packages\pluggy\callers.py", line 187, in _multicall
    res = hook_impl.function(*args)
  File "E:\Auto_test\flask\erybjp\venv\lib\site-packages\_pytest\terminal.py", line 474, in pytest_internalerror
    self.write_line("INTERNALERROR> " + line)
  File "E:\Auto_test\flask\erybjp\venv\lib\site-packages\_pytest\terminal.py", line 429, in write_line
    self.ensure_newline()
  File "E:\Auto_test\flask\erybjp\venv\lib\site-packages\_pytest\terminal.py", line 417, in ensure_newline
    self._tw.line()
  File "E:\Auto_test\flask\erybjp\venv\lib\site-packages\_pytest\_io\terminalwriter.py", line 171, in line
    self.write("\n")
  File "E:\Auto_test\flask\erybjp\venv\lib\site-packages\_pytest\_io\terminalwriter.py", line 155, in write
    self._file.write(msg)
ValueError: I/O operation on closed file.

During handling of the above exception, another exception occurred:

Traceback (most recent call last):
  File "E:\Auto_test\flask\erybjp\venv\lib\site-packages\werkzeug\debug\__init__.py", line 309, in debug_application
    app_iter = self.app(environ, start_response)
  File "E:\Auto_test\flask\erybjp\venv\lib\site-packages\flask\app.py", line 2069, in __call__
    return self.wsgi_app(environ, start_response)
  File "E:\Auto_test\flask\erybjp\venv\lib\site-packages\flask\app.py", line 2054, in wsgi_app
    response = self.handle_exception(e)
  File "E:\Auto_test\flask\erybjp\venv\lib\site-packages\flask_cors\extension.py", line 165, in wrapped_function
    return cors_after_request(app.make_response(f(*args, **kwargs)))
  File "E:\Auto_test\flask\erybjp\venv\lib\site-packages\flask\app.py", line 2051, in wsgi_app
    response = self.full_dispatch_request()
  File "E:\Auto_test\flask\erybjp\venv\lib\site-packages\flask\app.py", line 1501, in full_dispatch_request
    rv = self.handle_user_exception(e)
  File "E:\Auto_test\flask\erybjp\venv\lib\site-packages\flask_cors\extension.py", line 165, in wrapped_function
    return cors_after_request(app.make_response(f(*args, **kwargs)))
  File "E:\Auto_test\flask\erybjp\venv\lib\site-packages\flask\app.py", line 1499, in full_dispatch_request
    rv = self.dispatch_request()
  File "E:\Auto_test\flask\erybjp\venv\lib\site-packages\flask\app.py", line 1485, in dispatch_request
    return self.ensure_sync(self.view_functions[rule.endpoint])(**req.view_args)
  File "E:\Auto_test\flask\erybjp\uiplatform\router\runtestcase.py", line 49, in run_only_test
    pytest.main(["uiplatform/utils/business/test_check_web.py"])
  File "E:\Auto_test\flask\erybjp\venv\lib\site-packages\_pytest\config\__init__.py", line 163, in main
    config=config
  File "E:\Auto_test\flask\erybjp\venv\lib\site-packages\pluggy\hooks.py", line 286, in __call__
    return self._hookexec(self, self.get_hookimpls(), kwargs)
  File "E:\Auto_test\flask\erybjp\venv\lib\site-packages\pluggy\manager.py", line 93, in _hookexec
    return self._inner_hookexec(hook, methods, kwargs)
  File "E:\Auto_test\flask\erybjp\venv\lib\site-packages\pluggy\manager.py", line 87, in <lambda>
    firstresult=hook.spec.opts.get("firstresult") if hook.spec else False,
  File "E:\Auto_test\flask\erybjp\venv\lib\site-packages\pluggy\callers.py", line 208, in _multicall
    return outcome.get_result()
  File "E:\Auto_test\flask\erybjp\venv\lib\site-packages\pluggy\callers.py", line 80, in get_result
    raise ex[1].with_traceback(ex[2])
  File "E:\Auto_test\flask\erybjp\venv\lib\site-packages\pluggy\callers.py", line 187, in _multicall
    res = hook_impl.function(*args)
  File "E:\Auto_test\flask\erybjp\venv\lib\site-packages\_pytest\main.py", line 316, in pytest_cmdline_main
    return wrap_session(config, _main)
  File "E:\Auto_test\flask\erybjp\venv\lib\site-packages\_pytest\main.py", line 305, in wrap_session
    session=session, exitstatus=session.exitstatus
  File "E:\Auto_test\flask\erybjp\venv\lib\site-packages\pluggy\hooks.py", line 286, in __call__
    return self._hookexec(self, self.get_hookimpls(), kwargs)
  File "E:\Auto_test\flask\erybjp\venv\lib\site-packages\pluggy\manager.py", line 93, in _hookexec
    return self._inner_hookexec(hook, methods, kwargs)
  File "E:\Auto_test\flask\erybjp\venv\lib\site-packages\pluggy\manager.py", line 87, in <lambda>
    firstresult=hook.spec.opts.get("firstresult") if hook.spec else False,
  File "E:\Auto_test\flask\erybjp\venv\lib\site-packages\pluggy\callers.py", line 203, in _multicall
    gen.send(outcome)
  File "E:\Auto_test\flask\erybjp\venv\lib\site-packages\_pytest\terminal.py", line 804, in pytest_sessionfinish
    self._tw.line("")
  File "E:\Auto_test\flask\erybjp\venv\lib\site-packages\_pytest\_io\terminalwriter.py", line 171, in line
    self.write("\n")
  File "E:\Auto_test\flask\erybjp\venv\lib\site-packages\_pytest\_io\terminalwriter.py", line 155, in write
    self._file.write(msg)
ValueError: I/O operation on closed file.

During handling of the above exception, another exception occurred:

Traceback (most recent call last):
  File "E:\Auto_test\flask\erybjp\venv\lib\site-packages\werkzeug\serving.py", line 319, in run_wsgi
    execute(self.server.app)
  File "E:\Auto_test\flask\erybjp\venv\lib\site-packages\werkzeug\serving.py", line 310, in execute
    for data in application_iter:
  File "E:\Auto_test\flask\erybjp\venv\lib\site-packages\werkzeug\debug\__init__.py", line 351, in debug_application
    traceback.log(environ["wsgi.errors"])
  File "E:\Auto_test\flask\erybjp\venv\lib\site-packages\werkzeug\debug\tbtools.py", line 267, in log
    logfile.write(tb)
ValueError: I/O operation on closed file.
2021-05-29 22:46:44,766 [werkzeug] [9916:Thread-196] _internal.py:_internal:_log in 225] [INFO]: 192.168.31.7 - - [29/May/2021 22:46:44] "GET /auth/ui_test/test?__debugger__=yes&cmd=resource&f=console.png HTTP/1.1" 200 -
2021-05-29 22:46:44,785 [werkzeug] [12012:Thread-197] _internal.py:_internal:_log in 225] [INFO]: 192.168.31.7 - - [29/May/2021 22:46:44] "GET /auth/ui_test/test?__debugger__=yes&cmd=resource&f=ubuntu.ttf HTTP/1.1" 200 -
2021-05-29 22:46:44,808 [werkzeug] [17004:Thread-198] _internal.py:_internal:_log in 225] [INFO]: 192.168.31.7 - - [29/May/2021 22:46:44] "GET /auth/ui_test/test?__debugger__=yes&cmd=resource&f=console.png HTTP/1.1" 200 -
2021-05-29 22:46:44,837 [werkzeug] [7180:Thread-199] _internal.py:_internal:_log in 225] [INFO]: 192.168.31.7 - - [29/May/2021 22:46:44] "GET /auth/ui_test/test?__debugger__=yes&cmd=resource&f=ubuntu.ttf HTTP/1.1" 200 -
2021-05-29 22:46:45,138 [werkzeug] [12652:Thread-200] _internal.py:_internal:_log in 225] [INFO]: 192.168.31.7 - - [29/May/2021 22:46:45] "GET /auth/ui_test/test?__debugger__=yes&cmd=resource&f=console.png HTTP/1.1" 200 -
2021-05-29 22:46:45,139 [werkzeug] [9260:Thread-201] _internal.py:_internal:_log in 225] [INFO]: 192.168.31.7 - - [29/May/2021 22:46:45] "GET /auth/ui_test/test?__debugger__=yes&cmd=resource&f=console.png HTTP/1.1" 200 -
2021-05-30 09:23:17,998 [werkzeug] [17792:MainThread] _internal.py:_internal:_log in 225] [INFO]:  * Restarting with stat
2021-05-30 09:23:19,896 [werkzeug] [1780:MainThread] _internal.py:_internal:_log in 225] [WARNING]:  * Debugger is active!
2021-05-30 09:23:19,927 [werkzeug] [1780:MainThread] _internal.py:_internal:_log in 225] [INFO]:  * Debugger PIN: 182-435-572
2021-05-30 09:23:20,059 [werkzeug] [9884:Thread-1] _internal.py:_internal:_log in 225] [WARNING]:  * Running on all addresses.
   WARNING: This is a development server. Do not use it in a production deployment.
2021-05-30 09:23:20,059 [werkzeug] [9884:Thread-1] _internal.py:_internal:_log in 225] [INFO]:  * Running on http://192.168.31.7:6851/ (Press CTRL+C to quit)
2021-05-30 09:23:51,264 [werkzeug] [17724:Thread-4] _internal.py:_internal:_log in 225] [INFO]: 192.168.31.7 - - [30/May/2021 09:23:51] "GET /auth/ui_test/t HTTP/1.1" 200 -
2021-05-30 09:23:51,681 [werkzeug] [15320:Thread-17] _internal.py:_internal:_log in 225] [INFO]: 192.168.31.7 - - [30/May/2021 09:23:51] "[33mGET /favicon.ico HTTP/1.1[0m" 404 -
2021-05-30 09:24:30,214 [werkzeug] [12880:Thread-2] _internal.py:_internal:_log in 225] [INFO]: 192.168.31.7 - - [30/May/2021 09:24:30] "GET /auth/ui_test/test HTTP/1.1" 200 -
2021-05-30 09:24:30,395 [werkzeug] [13624:Thread-3] _internal.py:_internal:_log in 225] [INFO]: 192.168.31.7 - - [30/May/2021 09:24:30] "[35m[1mGET /auth/ui_test/test HTTP/1.1[0m" 500 -
2021-05-30 09:24:30,430 [werkzeug] [3556:Thread-43] _internal.py:_internal:_log in 225] [INFO]: 192.168.31.7 - - [30/May/2021 09:24:30] "GET /auth/ui_test/test?__debugger__=yes&cmd=resource&f=style.css HTTP/1.1" 200 -
2021-05-30 09:24:30,439 [werkzeug] [19176:Thread-44] _internal.py:_internal:_log in 225] [INFO]: 192.168.31.7 - - [30/May/2021 09:24:30] "GET /auth/ui_test/test?__debugger__=yes&cmd=resource&f=debugger.js HTTP/1.1" 200 -
2021-05-30 09:24:30,439 [werkzeug] [13624:Thread-3] _internal.py:_internal:_log in 225] [ERROR]: Error on request:
Traceback (most recent call last):
  File "E:\Auto_test\flask\erybjp\venv\lib\site-packages\werkzeug\debug\__init__.py", line 309, in debug_application
    app_iter = self.app(environ, start_response)
  File "E:\Auto_test\flask\erybjp\venv\lib\site-packages\flask\app.py", line 2069, in __call__
    return self.wsgi_app(environ, start_response)
  File "E:\Auto_test\flask\erybjp\venv\lib\site-packages\flask\app.py", line 2054, in wsgi_app
    response = self.handle_exception(e)
  File "E:\Auto_test\flask\erybjp\venv\lib\site-packages\flask_cors\extension.py", line 165, in wrapped_function
    return cors_after_request(app.make_response(f(*args, **kwargs)))
  File "E:\Auto_test\flask\erybjp\venv\lib\site-packages\flask\app.py", line 2051, in wsgi_app
    response = self.full_dispatch_request()
  File "E:\Auto_test\flask\erybjp\venv\lib\site-packages\flask\app.py", line 1501, in full_dispatch_request
    rv = self.handle_user_exception(e)
  File "E:\Auto_test\flask\erybjp\venv\lib\site-packages\flask_cors\extension.py", line 165, in wrapped_function
    return cors_after_request(app.make_response(f(*args, **kwargs)))
  File "E:\Auto_test\flask\erybjp\venv\lib\site-packages\flask\app.py", line 1499, in full_dispatch_request
    rv = self.dispatch_request()
  File "E:\Auto_test\flask\erybjp\venv\lib\site-packages\flask\app.py", line 1485, in dispatch_request
    return self.ensure_sync(self.view_functions[rule.endpoint])(**req.view_args)
  File "E:\Auto_test\flask\erybjp\uiplatform\router\runtestcase.py", line 52, in run_only_test
    pytest.main(["uiplatform/utils/business/test_check_web.py"])
  File "E:\Auto_test\flask\erybjp\venv\lib\site-packages\_pytest\config\__init__.py", line 163, in main
    config=config
  File "E:\Auto_test\flask\erybjp\venv\lib\site-packages\pluggy\hooks.py", line 286, in __call__
    return self._hookexec(self, self.get_hookimpls(), kwargs)
  File "E:\Auto_test\flask\erybjp\venv\lib\site-packages\pluggy\manager.py", line 93, in _hookexec
    return self._inner_hookexec(hook, methods, kwargs)
  File "E:\Auto_test\flask\erybjp\venv\lib\site-packages\pluggy\manager.py", line 87, in <lambda>
    firstresult=hook.spec.opts.get("firstresult") if hook.spec else False,
  File "E:\Auto_test\flask\erybjp\venv\lib\site-packages\pluggy\callers.py", line 208, in _multicall
    return outcome.get_result()
  File "E:\Auto_test\flask\erybjp\venv\lib\site-packages\pluggy\callers.py", line 80, in get_result
    raise ex[1].with_traceback(ex[2])
  File "E:\Auto_test\flask\erybjp\venv\lib\site-packages\pluggy\callers.py", line 187, in _multicall
    res = hook_impl.function(*args)
  File "E:\Auto_test\flask\erybjp\venv\lib\site-packages\_pytest\main.py", line 316, in pytest_cmdline_main
    return wrap_session(config, _main)
  File "E:\Auto_test\flask\erybjp\venv\lib\site-packages\_pytest\main.py", line 305, in wrap_session
    session=session, exitstatus=session.exitstatus
  File "E:\Auto_test\flask\erybjp\venv\lib\site-packages\pluggy\hooks.py", line 286, in __call__
    return self._hookexec(self, self.get_hookimpls(), kwargs)
  File "E:\Auto_test\flask\erybjp\venv\lib\site-packages\pluggy\manager.py", line 93, in _hookexec
    return self._inner_hookexec(hook, methods, kwargs)
  File "E:\Auto_test\flask\erybjp\venv\lib\site-packages\pluggy\manager.py", line 87, in <lambda>
    firstresult=hook.spec.opts.get("firstresult") if hook.spec else False,
  File "E:\Auto_test\flask\erybjp\venv\lib\site-packages\pluggy\callers.py", line 203, in _multicall
    gen.send(outcome)
  File "E:\Auto_test\flask\erybjp\venv\lib\site-packages\_pytest\terminal.py", line 804, in pytest_sessionfinish
    self._tw.line("")
  File "E:\Auto_test\flask\erybjp\venv\lib\site-packages\_pytest\_io\terminalwriter.py", line 171, in line
    self.write("\n")
  File "E:\Auto_test\flask\erybjp\venv\lib\site-packages\_pytest\_io\terminalwriter.py", line 155, in write
    self._file.write(msg)
ValueError: I/O operation on closed file.

During handling of the above exception, another exception occurred:

Traceback (most recent call last):
  File "E:\Auto_test\flask\erybjp\venv\lib\site-packages\werkzeug\serving.py", line 319, in run_wsgi
    execute(self.server.app)
  File "E:\Auto_test\flask\erybjp\venv\lib\site-packages\werkzeug\serving.py", line 310, in execute
    for data in application_iter:
  File "E:\Auto_test\flask\erybjp\venv\lib\site-packages\werkzeug\debug\__init__.py", line 351, in debug_application
    traceback.log(environ["wsgi.errors"])
  File "E:\Auto_test\flask\erybjp\venv\lib\site-packages\werkzeug\debug\tbtools.py", line 267, in log
    logfile.write(tb)
ValueError: I/O operation on closed file.
2021-05-30 09:24:30,714 [werkzeug] [11756:Thread-45] _internal.py:_internal:_log in 225] [INFO]: 192.168.31.7 - - [30/May/2021 09:24:30] "GET /auth/ui_test/test?__debugger__=yes&cmd=resource&f=console.png HTTP/1.1" 200 -
2021-05-30 09:24:30,733 [werkzeug] [5116:Thread-46] _internal.py:_internal:_log in 225] [INFO]: 192.168.31.7 - - [30/May/2021 09:24:30] "GET /auth/ui_test/test?__debugger__=yes&cmd=resource&f=ubuntu.ttf HTTP/1.1" 200 -
2021-05-30 09:24:30,839 [werkzeug] [15468:Thread-47] _internal.py:_internal:_log in 225] [INFO]: 192.168.31.7 - - [30/May/2021 09:24:30] "GET /auth/ui_test/test?__debugger__=yes&cmd=resource&f=console.png HTTP/1.1" 200 -
2021-05-30 09:26:01,777 [werkzeug] [14824:Thread-49] _internal.py:_internal:_log in 225] [INFO]: 192.168.31.7 - - [30/May/2021 09:26:01] "GET /auth/ui_test/t HTTP/1.1" 200 -
2021-05-30 09:26:08,508 [werkzeug] [16596:Thread-48] _internal.py:_internal:_log in 225] [INFO]: 192.168.31.7 - - [30/May/2021 09:26:08] "GET /auth/ui_test/test HTTP/1.1" 200 -
2021-05-30 09:26:32,758 [werkzeug] [8104:Thread-50] _internal.py:_internal:_log in 225] [INFO]: 192.168.31.7 - - [30/May/2021 09:26:32] "GET /auth/ui_test/test HTTP/1.1" 200 -
2021-05-30 09:29:29,902 [werkzeug] [1780:MainThread] _internal.py:_internal:_log in 225] [INFO]:  * Detected change in 'E:\\Auto_test\\flask\\erybjp\\uiplatform\\utils\\business\\test_check_web.py', reloading
2021-05-30 09:29:30,001 [werkzeug] [17792:MainThread] _internal.py:_internal:_log in 225] [INFO]:  * Restarting with stat
2021-05-30 09:29:31,943 [werkzeug] [2608:MainThread] _internal.py:_internal:_log in 225] [WARNING]:  * Debugger is active!
2021-05-30 09:29:31,952 [werkzeug] [2608:MainThread] _internal.py:_internal:_log in 225] [INFO]:  * Debugger PIN: 182-435-572
2021-05-30 09:29:32,071 [werkzeug] [20112:Thread-1] _internal.py:_internal:_log in 225] [WARNING]:  * Running on all addresses.
   WARNING: This is a development server. Do not use it in a production deployment.
2021-05-30 09:29:32,072 [werkzeug] [20112:Thread-1] _internal.py:_internal:_log in 225] [INFO]:  * Running on http://192.168.31.7:6851/ (Press CTRL+C to quit)
2021-05-30 09:30:10,873 [werkzeug] [2608:MainThread] _internal.py:_internal:_log in 225] [INFO]:  * Detected change in 'E:\\Auto_test\\flask\\erybjp\\uiplatform\\utils\\logicobject\\H5NormalPage.py', reloading
2021-05-30 09:30:10,942 [werkzeug] [17792:MainThread] _internal.py:_internal:_log in 225] [INFO]:  * Restarting with stat
2021-05-30 09:30:14,537 [werkzeug] [7856:MainThread] _internal.py:_internal:_log in 225] [WARNING]:  * Debugger is active!
2021-05-30 09:30:14,548 [werkzeug] [7856:MainThread] _internal.py:_internal:_log in 225] [INFO]:  * Debugger PIN: 182-435-572
2021-05-30 09:30:14,700 [werkzeug] [5720:Thread-1] _internal.py:_internal:_log in 225] [WARNING]:  * Running on all addresses.
   WARNING: This is a development server. Do not use it in a production deployment.
2021-05-30 09:30:14,700 [werkzeug] [5720:Thread-1] _internal.py:_internal:_log in 225] [INFO]:  * Running on http://192.168.31.7:6851/ (Press CTRL+C to quit)
2021-05-30 09:35:06,376 [werkzeug] [13668:MainThread] _internal.py:_internal:_log in 225] [INFO]:  * Restarting with stat
2021-05-30 09:35:08,252 [werkzeug] [16088:MainThread] _internal.py:_internal:_log in 225] [WARNING]:  * Debugger is active!
2021-05-30 09:35:08,261 [werkzeug] [16088:MainThread] _internal.py:_internal:_log in 225] [INFO]:  * Debugger PIN: 182-435-572
2021-05-30 09:35:08,390 [werkzeug] [4592:Thread-1] _internal.py:_internal:_log in 225] [WARNING]:  * Running on all addresses.
   WARNING: This is a development server. Do not use it in a production deployment.
2021-05-30 09:35:08,390 [werkzeug] [4592:Thread-1] _internal.py:_internal:_log in 225] [INFO]:  * Running on http://192.168.31.7:6851/ (Press CTRL+C to quit)
2021-05-30 09:35:50,543 [werkzeug] [13856:Thread-3] _internal.py:_internal:_log in 225] [INFO]: 192.168.31.7 - - [30/May/2021 09:35:50] "GET /auth/ui_test/test1 HTTP/1.1" 200 -
2021-05-30 09:35:50,840 [werkzeug] [13376:Thread-2] _internal.py:_internal:_log in 225] [INFO]: 192.168.31.7 - - [30/May/2021 09:35:50] "GET /auth/ui_test/test HTTP/1.1" 200 -
2021-05-30 09:36:34,410 [werkzeug] [15548:MainThread] _internal.py:_internal:_log in 225] [INFO]:  * Restarting with stat
2021-05-30 09:36:36,342 [werkzeug] [12476:MainThread] _internal.py:_internal:_log in 225] [WARNING]:  * Debugger is active!
2021-05-30 09:36:36,352 [werkzeug] [12476:MainThread] _internal.py:_internal:_log in 225] [INFO]:  * Debugger PIN: 182-435-572
2021-05-30 09:36:36,473 [werkzeug] [5720:Thread-1] _internal.py:_internal:_log in 225] [WARNING]:  * Running on all addresses.
   WARNING: This is a development server. Do not use it in a production deployment.
2021-05-30 09:36:36,474 [werkzeug] [5720:Thread-1] _internal.py:_internal:_log in 225] [INFO]:  * Running on http://192.168.31.7:6851/ (Press CTRL+C to quit)
2021-05-30 09:37:29,869 [werkzeug] [21248:Thread-3] _internal.py:_internal:_log in 225] [INFO]: 192.168.31.7 - - [30/May/2021 09:37:29] "GET /auth/ui_test/test1 HTTP/1.1" 200 -
2021-05-30 09:37:44,689 [werkzeug] [3052:Thread-2] _internal.py:_internal:_log in 225] [INFO]: 192.168.31.7 - - [30/May/2021 09:37:44] "GET /auth/ui_test/test HTTP/1.1" 200 -
2021-05-30 09:38:51,761 [werkzeug] [6284:Thread-33] _internal.py:_internal:_log in 225] [INFO]: 192.168.31.7 - - [30/May/2021 09:38:51] "GET /auth/ui_test/test1 HTTP/1.1" 200 -
2021-05-30 09:40:04,702 [werkzeug] [14608:MainThread] _internal.py:_internal:_log in 225] [INFO]:  * Restarting with stat
2021-05-30 09:40:06,739 [werkzeug] [4708:MainThread] _internal.py:_internal:_log in 225] [WARNING]:  * Debugger is active!
2021-05-30 09:40:06,748 [werkzeug] [4708:MainThread] _internal.py:_internal:_log in 225] [INFO]:  * Debugger PIN: 182-435-572
2021-05-30 09:40:06,872 [werkzeug] [17844:Thread-1] _internal.py:_internal:_log in 225] [WARNING]:  * Running on all addresses.
   WARNING: This is a development server. Do not use it in a production deployment.
2021-05-30 09:40:06,872 [werkzeug] [17844:Thread-1] _internal.py:_internal:_log in 225] [INFO]:  * Running on http://192.168.31.7:6851/ (Press CTRL+C to quit)
2021-05-30 09:40:39,580 [werkzeug] [9008:Thread-2] _internal.py:_internal:_log in 225] [INFO]: 192.168.31.7 - - [30/May/2021 09:40:39] "GET /auth/ui_test/test1 HTTP/1.1" 200 -
2021-05-30 09:45:36,950 [werkzeug] [11724:MainThread] _internal.py:_internal:_log in 225] [INFO]:  * Restarting with stat
2021-05-30 09:45:38,851 [werkzeug] [10412:MainThread] _internal.py:_internal:_log in 225] [WARNING]:  * Debugger is active!
2021-05-30 09:45:38,862 [werkzeug] [10412:MainThread] _internal.py:_internal:_log in 225] [INFO]:  * Debugger PIN: 182-435-572
2021-05-30 09:45:38,986 [werkzeug] [17508:Thread-1] _internal.py:_internal:_log in 225] [WARNING]:  * Running on all addresses.
   WARNING: This is a development server. Do not use it in a production deployment.
2021-05-30 09:45:38,986 [werkzeug] [17508:Thread-1] _internal.py:_internal:_log in 225] [INFO]:  * Running on http://192.168.31.7:6851/ (Press CTRL+C to quit)
2021-05-30 09:45:52,120 [werkzeug] [9872:Thread-2] _internal.py:_internal:_log in 225] [INFO]: 192.168.31.7 - - [30/May/2021 09:45:52] "GET /auth/ui_test/test1 HTTP/1.1" 200 -
2021-05-30 09:46:27,520 [werkzeug] [16552:MainThread] _internal.py:_internal:_log in 225] [INFO]:  * Restarting with stat
2021-05-30 09:46:29,476 [werkzeug] [12904:MainThread] _internal.py:_internal:_log in 225] [WARNING]:  * Debugger is active!
2021-05-30 09:46:29,486 [werkzeug] [12904:MainThread] _internal.py:_internal:_log in 225] [INFO]:  * Debugger PIN: 182-435-572
2021-05-30 09:46:29,609 [werkzeug] [16596:Thread-1] _internal.py:_internal:_log in 225] [WARNING]:  * Running on all addresses.
   WARNING: This is a development server. Do not use it in a production deployment.
2021-05-30 09:46:29,609 [werkzeug] [16596:Thread-1] _internal.py:_internal:_log in 225] [INFO]:  * Running on http://192.168.31.7:6851/ (Press CTRL+C to quit)
2021-05-30 09:47:01,192 [werkzeug] [5436:Thread-2] _internal.py:_internal:_log in 225] [INFO]: 192.168.31.7 - - [30/May/2021 09:47:01] "GET /auth/ui_test/test1 HTTP/1.1" 200 -
2021-05-30 09:47:49,839 [werkzeug] [7868:MainThread] _internal.py:_internal:_log in 225] [INFO]:  * Restarting with stat
2021-05-30 09:47:52,386 [werkzeug] [18636:MainThread] _internal.py:_internal:_log in 225] [WARNING]:  * Debugger is active!
2021-05-30 09:47:52,399 [werkzeug] [18636:MainThread] _internal.py:_internal:_log in 225] [INFO]:  * Debugger PIN: 182-435-572
2021-05-30 09:47:52,600 [werkzeug] [18524:Thread-6] _internal.py:_internal:_log in 225] [WARNING]:  * Running on all addresses.
   WARNING: This is a development server. Do not use it in a production deployment.
2021-05-30 09:47:52,602 [werkzeug] [18524:Thread-6] _internal.py:_internal:_log in 225] [INFO]:  * Running on http://192.168.31.7:6851/ (Press CTRL+C to quit)
2021-05-30 09:49:54,719 [werkzeug] [9192:MainThread] _internal.py:_internal:_log in 225] [INFO]:  * Restarting with stat
2021-05-30 09:49:57,957 [werkzeug] [4368:MainThread] _internal.py:_internal:_log in 225] [WARNING]:  * Debugger is active!
2021-05-30 09:49:57,967 [werkzeug] [4368:MainThread] _internal.py:_internal:_log in 225] [INFO]:  * Debugger PIN: 182-435-572
2021-05-30 09:49:58,089 [werkzeug] [13472:Thread-1] _internal.py:_internal:_log in 225] [WARNING]:  * Running on all addresses.
   WARNING: This is a development server. Do not use it in a production deployment.
2021-05-30 09:49:58,089 [werkzeug] [13472:Thread-1] _internal.py:_internal:_log in 225] [INFO]:  * Running on http://192.168.31.7:6851/ (Press CTRL+C to quit)
2021-05-30 09:49:58,668 [werkzeug] [18404:Thread-3] _internal.py:_internal:_log in 225] [INFO]: 192.168.31.7 - - [30/May/2021 09:49:58] "GET /auth/ui_test/test1 HTTP/1.1" 200 -
2021-05-30 09:49:58,669 [werkzeug] [3384:Thread-2] _internal.py:_internal:_log in 225] [INFO]: 192.168.31.7 - - [30/May/2021 09:49:58] "GET /auth/ui_test/test1 HTTP/1.1" 200 -
2021-05-30 09:50:45,956 [werkzeug] [18528:MainThread] _internal.py:_internal:_log in 225] [INFO]:  * Restarting with stat
2021-05-30 09:50:47,892 [werkzeug] [10620:MainThread] _internal.py:_internal:_log in 225] [WARNING]:  * Debugger is active!
2021-05-30 09:50:47,901 [werkzeug] [10620:MainThread] _internal.py:_internal:_log in 225] [INFO]:  * Debugger PIN: 182-435-572
2021-05-30 09:50:48,022 [werkzeug] [7164:Thread-1] _internal.py:_internal:_log in 225] [WARNING]:  * Running on all addresses.
   WARNING: This is a development server. Do not use it in a production deployment.
2021-05-30 09:50:48,022 [werkzeug] [7164:Thread-1] _internal.py:_internal:_log in 225] [INFO]:  * Running on http://192.168.31.7:6851/ (Press CTRL+C to quit)
2021-05-30 09:51:04,969 [werkzeug] [3384:Thread-2] _internal.py:_internal:_log in 225] [INFO]: 192.168.31.7 - - [30/May/2021 09:51:04] "GET /auth/ui_test/test1 HTTP/1.1" 200 -
2021-05-30 09:52:57,677 [werkzeug] [16172:MainThread] _internal.py:_internal:_log in 225] [INFO]:  * Restarting with stat
2021-05-30 09:52:59,610 [werkzeug] [9028:MainThread] _internal.py:_internal:_log in 225] [WARNING]:  * Debugger is active!
2021-05-30 09:52:59,620 [werkzeug] [9028:MainThread] _internal.py:_internal:_log in 225] [INFO]:  * Debugger PIN: 182-435-572
2021-05-30 09:52:59,742 [werkzeug] [13824:Thread-1] _internal.py:_internal:_log in 225] [WARNING]:  * Running on all addresses.
   WARNING: This is a development server. Do not use it in a production deployment.
2021-05-30 09:52:59,742 [werkzeug] [13824:Thread-1] _internal.py:_internal:_log in 225] [INFO]:  * Running on http://192.168.31.7:6851/ (Press CTRL+C to quit)
2021-05-30 09:53:04,652 [werkzeug] [12476:Thread-2] _internal.py:_internal:_log in 225] [INFO]: 192.168.31.7 - - [30/May/2021 09:53:04] "GET /auth/ui_test/test HTTP/1.1" 200 -
2021-05-30 09:53:20,468 [werkzeug] [5028:Thread-3] _internal.py:_internal:_log in 225] [INFO]: 192.168.31.7 - - [30/May/2021 09:53:20] "GET /auth/ui_test/test1 HTTP/1.1" 200 -
2021-05-30 09:54:02,361 [werkzeug] [16148:MainThread] _internal.py:_internal:_log in 225] [INFO]:  * Restarting with stat
2021-05-30 09:54:04,524 [werkzeug] [20304:MainThread] _internal.py:_internal:_log in 225] [WARNING]:  * Debugger is active!
2021-05-30 09:54:04,533 [werkzeug] [20304:MainThread] _internal.py:_internal:_log in 225] [INFO]:  * Debugger PIN: 182-435-572
2021-05-30 09:54:04,656 [werkzeug] [20596:Thread-1] _internal.py:_internal:_log in 225] [WARNING]:  * Running on all addresses.
   WARNING: This is a development server. Do not use it in a production deployment.
2021-05-30 09:54:04,656 [werkzeug] [20596:Thread-1] _internal.py:_internal:_log in 225] [INFO]:  * Running on http://192.168.31.7:6851/ (Press CTRL+C to quit)
2021-05-30 09:54:10,141 [werkzeug] [20560:Thread-3] _internal.py:_internal:_log in 225] [INFO]: 192.168.31.7 - - [30/May/2021 09:54:10] "GET /auth/ui_test/test HTTP/1.1" 200 -
2021-05-30 09:54:26,196 [werkzeug] [14716:Thread-4] _internal.py:_internal:_log in 225] [INFO]: 192.168.31.7 - - [30/May/2021 09:54:26] "GET /auth/ui_test/test HTTP/1.1" 200 -
2021-05-30 09:54:45,521 [werkzeug] [10704:Thread-2] _internal.py:_internal:_log in 225] [INFO]: 192.168.31.7 - - [30/May/2021 09:54:45] "GET /auth/ui_test/test1 HTTP/1.1" 200 -
2021-05-30 09:55:16,216 [werkzeug] [19084:MainThread] _internal.py:_internal:_log in 225] [INFO]:  * Restarting with stat
2021-05-30 09:55:22,240 [werkzeug] [19788:MainThread] _internal.py:_internal:_log in 225] [INFO]:  * Restarting with stat
2021-05-30 09:55:24,862 [werkzeug] [15268:MainThread] _internal.py:_internal:_log in 225] [WARNING]:  * Debugger is active!
2021-05-30 09:55:24,875 [werkzeug] [15268:MainThread] _internal.py:_internal:_log in 225] [INFO]:  * Debugger PIN: 182-435-572
2021-05-30 09:55:25,064 [werkzeug] [18880:Thread-6] _internal.py:_internal:_log in 225] [WARNING]:  * Running on all addresses.
   WARNING: This is a development server. Do not use it in a production deployment.
2021-05-30 09:55:25,065 [werkzeug] [18880:Thread-6] _internal.py:_internal:_log in 225] [INFO]:  * Running on http://192.168.31.7:6851/ (Press CTRL+C to quit)
2021-05-30 09:59:52,556 [werkzeug] [3912:MainThread] _internal.py:_internal:_log in 225] [INFO]:  * Restarting with stat
2021-05-30 09:59:56,928 [werkzeug] [12992:MainThread] _internal.py:_internal:_log in 225] [WARNING]:  * Debugger is active!
2021-05-30 09:59:56,940 [werkzeug] [12992:MainThread] _internal.py:_internal:_log in 225] [INFO]:  * Debugger PIN: 182-435-572
2021-05-30 09:59:57,133 [werkzeug] [6424:Thread-6] _internal.py:_internal:_log in 225] [WARNING]:  * Running on all addresses.
   WARNING: This is a development server. Do not use it in a production deployment.
2021-05-30 09:59:57,135 [werkzeug] [6424:Thread-6] _internal.py:_internal:_log in 225] [INFO]:  * Running on http://192.168.31.7:6851/ (Press CTRL+C to quit)
2021-05-30 10:00:43,061 [werkzeug] [13668:MainThread] _internal.py:_internal:_log in 225] [INFO]:  * Restarting with stat
2021-05-30 10:00:46,222 [werkzeug] [17268:MainThread] _internal.py:_internal:_log in 225] [WARNING]:  * Debugger is active!
2021-05-30 10:00:46,235 [werkzeug] [17268:MainThread] _internal.py:_internal:_log in 225] [INFO]:  * Debugger PIN: 182-435-572
2021-05-30 10:00:46,423 [werkzeug] [17216:Thread-6] _internal.py:_internal:_log in 225] [WARNING]:  * Running on all addresses.
   WARNING: This is a development server. Do not use it in a production deployment.
2021-05-30 10:00:46,424 [werkzeug] [17216:Thread-6] _internal.py:_internal:_log in 225] [INFO]:  * Running on http://192.168.31.7:6851/ (Press CTRL+C to quit)
2021-05-30 10:05:43,752 [werkzeug] [15412:MainThread] _internal.py:_internal:_log in 225] [INFO]:  * Restarting with stat
2021-05-30 10:05:45,689 [werkzeug] [10976:MainThread] _internal.py:_internal:_log in 225] [WARNING]:  * Debugger is active!
2021-05-30 10:05:45,699 [werkzeug] [10976:MainThread] _internal.py:_internal:_log in 225] [INFO]:  * Debugger PIN: 182-435-572
2021-05-30 10:05:45,832 [werkzeug] [3536:Thread-1] _internal.py:_internal:_log in 225] [WARNING]:  * Running on all addresses.
   WARNING: This is a development server. Do not use it in a production deployment.
2021-05-30 10:05:45,833 [werkzeug] [3536:Thread-1] _internal.py:_internal:_log in 225] [INFO]:  * Running on http://192.168.31.7:6851/ (Press CTRL+C to quit)
2021-05-30 10:05:54,037 [werkzeug] [10248:Thread-3] _internal.py:_internal:_log in 225] [INFO]: 192.168.31.7 - - [30/May/2021 10:05:54] "GET /auth/ui_test/test HTTP/1.1" 200 -
2021-05-30 10:05:55,556 [werkzeug] [14900:Thread-2] _internal.py:_internal:_log in 225] [INFO]: 192.168.31.7 - - [30/May/2021 10:05:55] "[35m[1mGET /auth/ui_test/test1 HTTP/1.1[0m" 500 -
2021-05-30 10:05:55,577 [werkzeug] [19808:Thread-4] _internal.py:_internal:_log in 225] [INFO]: 192.168.31.7 - - [30/May/2021 10:05:55] "GET /auth/ui_test/test1?__debugger__=yes&cmd=resource&f=style.css HTTP/1.1" 200 -
2021-05-30 10:05:55,577 [werkzeug] [16912:Thread-5] _internal.py:_internal:_log in 225] [INFO]: 192.168.31.7 - - [30/May/2021 10:05:55] "GET /auth/ui_test/test1?__debugger__=yes&cmd=resource&f=debugger.js HTTP/1.1" 200 -
2021-05-30 10:05:55,598 [werkzeug] [14900:Thread-2] _internal.py:_internal:_log in 225] [ERROR]: Error on request:
Traceback (most recent call last):
  File "E:\Auto_test\flask\erybjp\venv\lib\site-packages\_pytest\main.py", line 269, in wrap_session
    session.exitstatus = doit(config, session) or 0
  File "E:\Auto_test\flask\erybjp\venv\lib\site-packages\_pytest\main.py", line 323, in _main
    config.hook.pytest_runtestloop(session=session)
  File "E:\Auto_test\flask\erybjp\venv\lib\site-packages\pluggy\hooks.py", line 286, in __call__
    return self._hookexec(self, self.get_hookimpls(), kwargs)
  File "E:\Auto_test\flask\erybjp\venv\lib\site-packages\pluggy\manager.py", line 93, in _hookexec
    return self._inner_hookexec(hook, methods, kwargs)
  File "E:\Auto_test\flask\erybjp\venv\lib\site-packages\pluggy\manager.py", line 87, in <lambda>
    firstresult=hook.spec.opts.get("firstresult") if hook.spec else False,
  File "E:\Auto_test\flask\erybjp\venv\lib\site-packages\pluggy\callers.py", line 208, in _multicall
    return outcome.get_result()
  File "E:\Auto_test\flask\erybjp\venv\lib\site-packages\pluggy\callers.py", line 80, in get_result
    raise ex[1].with_traceback(ex[2])
  File "E:\Auto_test\flask\erybjp\venv\lib\site-packages\pluggy\callers.py", line 187, in _multicall
    res = hook_impl.function(*args)
  File "E:\Auto_test\flask\erybjp\venv\lib\site-packages\_pytest\main.py", line 348, in pytest_runtestloop
    item.config.hook.pytest_runtest_protocol(item=item, nextitem=nextitem)
  File "E:\Auto_test\flask\erybjp\venv\lib\site-packages\pluggy\hooks.py", line 286, in __call__
    return self._hookexec(self, self.get_hookimpls(), kwargs)
  File "E:\Auto_test\flask\erybjp\venv\lib\site-packages\pluggy\manager.py", line 93, in _hookexec
    return self._inner_hookexec(hook, methods, kwargs)
  File "E:\Auto_test\flask\erybjp\venv\lib\site-packages\pluggy\manager.py", line 87, in <lambda>
    firstresult=hook.spec.opts.get("firstresult") if hook.spec else False,
  File "E:\Auto_test\flask\erybjp\venv\lib\site-packages\pluggy\callers.py", line 208, in _multicall
    return outcome.get_result()
  File "E:\Auto_test\flask\erybjp\venv\lib\site-packages\pluggy\callers.py", line 80, in get_result
    raise ex[1].with_traceback(ex[2])
  File "E:\Auto_test\flask\erybjp\venv\lib\site-packages\pluggy\callers.py", line 187, in _multicall
    res = hook_impl.function(*args)
  File "E:\Auto_test\flask\erybjp\venv\lib\site-packages\_pytest\runner.py", line 109, in pytest_runtest_protocol
    runtestprotocol(item, nextitem=nextitem)
  File "E:\Auto_test\flask\erybjp\venv\lib\site-packages\_pytest\runner.py", line 120, in runtestprotocol
    rep = call_and_report(item, "setup", log)
  File "E:\Auto_test\flask\erybjp\venv\lib\site-packages\_pytest\runner.py", line 217, in call_and_report
    report: TestReport = hook.pytest_runtest_makereport(item=item, call=call)
  File "E:\Auto_test\flask\erybjp\venv\lib\site-packages\pluggy\hooks.py", line 286, in __call__
    return self._hookexec(self, self.get_hookimpls(), kwargs)
  File "E:\Auto_test\flask\erybjp\venv\lib\site-packages\pluggy\manager.py", line 93, in _hookexec
    return self._inner_hookexec(hook, methods, kwargs)
  File "E:\Auto_test\flask\erybjp\venv\lib\site-packages\pluggy\manager.py", line 87, in <lambda>
    firstresult=hook.spec.opts.get("firstresult") if hook.spec else False,
  File "E:\Auto_test\flask\erybjp\venv\lib\site-packages\pluggy\callers.py", line 203, in _multicall
    gen.send(outcome)
  File "E:\Auto_test\flask\erybjp\uiplatform\utils\business\conftest.py", line 56, in pytest_runtest_makereport
    print('测试报告：%s' % report)
ValueError: I/O operation on closed file.

During handling of the above exception, another exception occurred:

Traceback (most recent call last):
  File "E:\Auto_test\flask\erybjp\venv\lib\site-packages\_pytest\main.py", line 289, in wrap_session
    config.notify_exception(excinfo, config.option)
  File "E:\Auto_test\flask\erybjp\venv\lib\site-packages\_pytest\config\__init__.py", line 1037, in notify_exception
    res = self.hook.pytest_internalerror(excrepr=excrepr, excinfo=excinfo)
  File "E:\Auto_test\flask\erybjp\venv\lib\site-packages\pluggy\hooks.py", line 286, in __call__
    return self._hookexec(self, self.get_hookimpls(), kwargs)
  File "E:\Auto_test\flask\erybjp\venv\lib\site-packages\pluggy\manager.py", line 93, in _hookexec
    return self._inner_hookexec(hook, methods, kwargs)
  File "E:\Auto_test\flask\erybjp\venv\lib\site-packages\pluggy\manager.py", line 87, in <lambda>
    firstresult=hook.spec.opts.get("firstresult") if hook.spec else False,
  File "E:\Auto_test\flask\erybjp\venv\lib\site-packages\pluggy\callers.py", line 208, in _multicall
    return outcome.get_result()
  File "E:\Auto_test\flask\erybjp\venv\lib\site-packages\pluggy\callers.py", line 80, in get_result
    raise ex[1].with_traceback(ex[2])
  File "E:\Auto_test\flask\erybjp\venv\lib\site-packages\pluggy\callers.py", line 187, in _multicall
    res = hook_impl.function(*args)
  File "E:\Auto_test\flask\erybjp\venv\lib\site-packages\_pytest\terminal.py", line 474, in pytest_internalerror
    self.write_line("INTERNALERROR> " + line)
  File "E:\Auto_test\flask\erybjp\venv\lib\site-packages\_pytest\terminal.py", line 429, in write_line
    self.ensure_newline()
  File "E:\Auto_test\flask\erybjp\venv\lib\site-packages\_pytest\terminal.py", line 417, in ensure_newline
    self._tw.line()
  File "E:\Auto_test\flask\erybjp\venv\lib\site-packages\_pytest\_io\terminalwriter.py", line 171, in line
    self.write("\n")
  File "E:\Auto_test\flask\erybjp\venv\lib\site-packages\_pytest\_io\terminalwriter.py", line 155, in write
    self._file.write(msg)
ValueError: I/O operation on closed file.

During handling of the above exception, another exception occurred:

Traceback (most recent call last):
  File "E:\Auto_test\flask\erybjp\venv\lib\site-packages\werkzeug\debug\__init__.py", line 309, in debug_application
    app_iter = self.app(environ, start_response)
  File "E:\Auto_test\flask\erybjp\venv\lib\site-packages\flask\app.py", line 2069, in __call__
    return self.wsgi_app(environ, start_response)
  File "E:\Auto_test\flask\erybjp\venv\lib\site-packages\flask\app.py", line 2054, in wsgi_app
    response = self.handle_exception(e)
  File "E:\Auto_test\flask\erybjp\venv\lib\site-packages\flask_cors\extension.py", line 165, in wrapped_function
    return cors_after_request(app.make_response(f(*args, **kwargs)))
  File "E:\Auto_test\flask\erybjp\venv\lib\site-packages\flask\app.py", line 2051, in wsgi_app
    response = self.full_dispatch_request()
  File "E:\Auto_test\flask\erybjp\venv\lib\site-packages\flask\app.py", line 1501, in full_dispatch_request
    rv = self.handle_user_exception(e)
  File "E:\Auto_test\flask\erybjp\venv\lib\site-packages\flask_cors\extension.py", line 165, in wrapped_function
    return cors_after_request(app.make_response(f(*args, **kwargs)))
  File "E:\Auto_test\flask\erybjp\venv\lib\site-packages\flask\app.py", line 1499, in full_dispatch_request
    rv = self.dispatch_request()
  File "E:\Auto_test\flask\erybjp\venv\lib\site-packages\flask\app.py", line 1485, in dispatch_request
    return self.ensure_sync(self.view_functions[rule.endpoint])(**req.view_args)
  File "E:\Auto_test\flask\erybjp\uiplatform\router\runtestcase.py", line 57, in run_only_test01
    pytest.main(["uiplatform/utils/business/test_check_web.py::TestHinfo1"])
  File "E:\Auto_test\flask\erybjp\venv\lib\site-packages\_pytest\config\__init__.py", line 163, in main
    config=config
  File "E:\Auto_test\flask\erybjp\venv\lib\site-packages\pluggy\hooks.py", line 286, in __call__
    return self._hookexec(self, self.get_hookimpls(), kwargs)
  File "E:\Auto_test\flask\erybjp\venv\lib\site-packages\pluggy\manager.py", line 93, in _hookexec
    return self._inner_hookexec(hook, methods, kwargs)
  File "E:\Auto_test\flask\erybjp\venv\lib\site-packages\pluggy\manager.py", line 87, in <lambda>
    firstresult=hook.spec.opts.get("firstresult") if hook.spec else False,
  File "E:\Auto_test\flask\erybjp\venv\lib\site-packages\pluggy\callers.py", line 208, in _multicall
    return outcome.get_result()
  File "E:\Auto_test\flask\erybjp\venv\lib\site-packages\pluggy\callers.py", line 80, in get_result
    raise ex[1].with_traceback(ex[2])
  File "E:\Auto_test\flask\erybjp\venv\lib\site-packages\pluggy\callers.py", line 187, in _multicall
    res = hook_impl.function(*args)
  File "E:\Auto_test\flask\erybjp\venv\lib\site-packages\_pytest\main.py", line 316, in pytest_cmdline_main
    return wrap_session(config, _main)
  File "E:\Auto_test\flask\erybjp\venv\lib\site-packages\_pytest\main.py", line 305, in wrap_session
    session=session, exitstatus=session.exitstatus
  File "E:\Auto_test\flask\erybjp\venv\lib\site-packages\pluggy\hooks.py", line 286, in __call__
    return self._hookexec(self, self.get_hookimpls(), kwargs)
  File "E:\Auto_test\flask\erybjp\venv\lib\site-packages\pluggy\manager.py", line 93, in _hookexec
    return self._inner_hookexec(hook, methods, kwargs)
  File "E:\Auto_test\flask\erybjp\venv\lib\site-packages\pluggy\manager.py", line 87, in <lambda>
    firstresult=hook.spec.opts.get("firstresult") if hook.spec else False,
  File "E:\Auto_test\flask\erybjp\venv\lib\site-packages\pluggy\callers.py", line 203, in _multicall
    gen.send(outcome)
  File "E:\Auto_test\flask\erybjp\venv\lib\site-packages\_pytest\terminal.py", line 804, in pytest_sessionfinish
    self._tw.line("")
  File "E:\Auto_test\flask\erybjp\venv\lib\site-packages\_pytest\_io\terminalwriter.py", line 171, in line
    self.write("\n")
  File "E:\Auto_test\flask\erybjp\venv\lib\site-packages\_pytest\_io\terminalwriter.py", line 155, in write
    self._file.write(msg)
ValueError: I/O operation on closed file.

During handling of the above exception, another exception occurred:

Traceback (most recent call last):
  File "E:\Auto_test\flask\erybjp\venv\lib\site-packages\werkzeug\serving.py", line 319, in run_wsgi
    execute(self.server.app)
  File "E:\Auto_test\flask\erybjp\venv\lib\site-packages\werkzeug\serving.py", line 310, in execute
    for data in application_iter:
  File "E:\Auto_test\flask\erybjp\venv\lib\site-packages\werkzeug\debug\__init__.py", line 351, in debug_application
    traceback.log(environ["wsgi.errors"])
  File "E:\Auto_test\flask\erybjp\venv\lib\site-packages\werkzeug\debug\tbtools.py", line 267, in log
    logfile.write(tb)
ValueError: I/O operation on closed file.
2021-05-30 10:05:55,891 [werkzeug] [1748:Thread-6] _internal.py:_internal:_log in 225] [INFO]: 192.168.31.7 - - [30/May/2021 10:05:55] "GET /auth/ui_test/test1?__debugger__=yes&cmd=resource&f=console.png HTTP/1.1" 200 -
2021-05-30 10:05:55,919 [werkzeug] [8272:Thread-7] _internal.py:_internal:_log in 225] [INFO]: 192.168.31.7 - - [30/May/2021 10:05:55] "GET /auth/ui_test/test1?__debugger__=yes&cmd=resource&f=ubuntu.ttf HTTP/1.1" 200 -
2021-05-30 10:05:56,048 [werkzeug] [13316:Thread-8] _internal.py:_internal:_log in 225] [INFO]: 192.168.31.7 - - [30/May/2021 10:05:56] "GET /auth/ui_test/test1?__debugger__=yes&cmd=resource&f=console.png HTTP/1.1" 200 -
2021-05-30 10:07:10,183 [werkzeug] [16212:MainThread] _internal.py:_internal:_log in 225] [INFO]:  * Restarting with stat
2021-05-30 10:07:12,122 [werkzeug] [18100:MainThread] _internal.py:_internal:_log in 225] [WARNING]:  * Debugger is active!
2021-05-30 10:07:12,132 [werkzeug] [18100:MainThread] _internal.py:_internal:_log in 225] [INFO]:  * Debugger PIN: 182-435-572
2021-05-30 10:07:12,254 [werkzeug] [12892:Thread-1] _internal.py:_internal:_log in 225] [WARNING]:  * Running on all addresses.
   WARNING: This is a development server. Do not use it in a production deployment.
2021-05-30 10:07:12,255 [werkzeug] [12892:Thread-1] _internal.py:_internal:_log in 225] [INFO]:  * Running on http://192.168.31.7:6851/ (Press CTRL+C to quit)
2021-05-30 10:07:54,434 [werkzeug] [12484:Thread-3] _internal.py:_internal:_log in 225] [INFO]: 192.168.31.7 - - [30/May/2021 10:07:54] "GET /auth/ui_test/test HTTP/1.1" 200 -
2021-05-30 10:07:59,984 [werkzeug] [17916:Thread-2] _internal.py:_internal:_log in 225] [INFO]: 192.168.31.7 - - [30/May/2021 10:07:59] "GET /auth/ui_test/test1 HTTP/1.1" 200 -
2021-05-30 10:10:07,339 [werkzeug] [8632:Thread-6] _internal.py:_internal:_log in 225] [INFO]: 192.168.31.7 - - [30/May/2021 10:10:07] "GET /auth/ui_test/test HTTP/1.1" 200 -
2021-05-30 10:10:34,224 [werkzeug] [22420:Thread-7] _internal.py:_internal:_log in 225] [INFO]: 192.168.31.7 - - [30/May/2021 10:10:34] "GET /auth/ui_test/test1 HTTP/1.1" 200 -
2021-05-30 10:15:15,275 [werkzeug] [14564:MainThread] _internal.py:_internal:_log in 225] [INFO]:  * Restarting with stat
2021-05-30 10:15:17,367 [werkzeug] [3472:MainThread] _internal.py:_internal:_log in 225] [WARNING]:  * Debugger is active!
2021-05-30 10:15:17,377 [werkzeug] [3472:MainThread] _internal.py:_internal:_log in 225] [INFO]:  * Debugger PIN: 182-435-572
2021-05-30 10:15:17,515 [werkzeug] [5412:Thread-1] _internal.py:_internal:_log in 225] [WARNING]:  * Running on all addresses.
   WARNING: This is a development server. Do not use it in a production deployment.
2021-05-30 10:15:17,515 [werkzeug] [5412:Thread-1] _internal.py:_internal:_log in 225] [INFO]:  * Running on http://192.168.31.7:6851/ (Press CTRL+C to quit)
2021-05-30 10:15:27,438 [werkzeug] [1736:Thread-2] _internal.py:_internal:_log in 225] [INFO]: 192.168.31.7 - - [30/May/2021 10:15:27] "GET /auth/ui_test/t HTTP/1.1" 200 -
2021-05-30 10:15:39,352 [werkzeug] [14844:Thread-3] _internal.py:_internal:_log in 225] [INFO]: 192.168.31.7 - - [30/May/2021 10:15:39] "GET /auth/ui_test/t HTTP/1.1" 200 -
2021-05-30 10:16:30,443 [werkzeug] [3192:Thread-4] _internal.py:_internal:_log in 225] [INFO]: 192.168.31.7 - - [30/May/2021 10:16:30] "GET /auth/ui_test/test HTTP/1.1" 200 -
2021-05-30 10:17:57,613 [werkzeug] [11604:Thread-7] _internal.py:_internal:_log in 225] [INFO]: 192.168.31.7 - - [30/May/2021 10:17:57] "GET /auth/ui_test/test1 HTTP/1.1" 200 -
2021-05-30 10:21:12,909 [werkzeug] [5112:MainThread] _internal.py:_internal:_log in 225] [INFO]:  * Restarting with stat
2021-05-30 10:21:14,834 [werkzeug] [17572:MainThread] _internal.py:_internal:_log in 225] [WARNING]:  * Debugger is active!
2021-05-30 10:21:14,843 [werkzeug] [17572:MainThread] _internal.py:_internal:_log in 225] [INFO]:  * Debugger PIN: 182-435-572
2021-05-30 10:21:14,966 [werkzeug] [15560:Thread-1] _internal.py:_internal:_log in 225] [WARNING]:  * Running on all addresses.
   WARNING: This is a development server. Do not use it in a production deployment.
2021-05-30 10:21:14,966 [werkzeug] [15560:Thread-1] _internal.py:_internal:_log in 225] [INFO]:  * Running on http://192.168.31.7:6851/ (Press CTRL+C to quit)
2021-05-30 10:21:48,239 [werkzeug] [14404:Thread-2] _internal.py:_internal:_log in 225] [INFO]: 192.168.31.7 - - [30/May/2021 10:21:48] "GET /auth/ui_test/test1 HTTP/1.1" 200 -
2021-05-30 10:23:57,948 [werkzeug] [22176:MainThread] _internal.py:_internal:_log in 225] [INFO]:  * Restarting with stat
2021-05-30 10:24:00,481 [werkzeug] [21864:MainThread] _internal.py:_internal:_log in 225] [WARNING]:  * Debugger is active!
2021-05-30 10:24:00,493 [werkzeug] [21864:MainThread] _internal.py:_internal:_log in 225] [INFO]:  * Debugger PIN: 182-435-572
2021-05-30 10:24:00,694 [werkzeug] [4844:Thread-6] _internal.py:_internal:_log in 225] [WARNING]:  * Running on all addresses.
   WARNING: This is a development server. Do not use it in a production deployment.
2021-05-30 10:24:00,695 [werkzeug] [4844:Thread-6] _internal.py:_internal:_log in 225] [INFO]:  * Running on http://192.168.31.7:6851/ (Press CTRL+C to quit)
