2021-06-13 17:17:12,619 [werkzeug] [16400:MainThread] _internal.py:_internal:_log in 225] [INFO]:  * Restarting with stat
2021-06-13 17:35:19,433 [werkzeug] [16176:Thread-3] _internal.py:_internal:_log in 225] [INFO]: 127.0.0.1 - - [13/Jun/2021 17:35:19] "[33mGET / HTTP/1.1[0m" 404 -
2021-06-13 17:36:49,590 [werkzeug] [1364:Thread-4] _internal.py:_internal:_log in 225] [INFO]: 127.0.0.1 - - [13/Jun/2021 17:36:49] "GET /element/ui_test/test1 HTTP/1.1" 200 -
2021-06-13 17:43:11,217 [werkzeug] [16188:Thread-3] _internal.py:_internal:_log in 225] [INFO]: 127.0.0.1 - - [13/Jun/2021 17:43:11] "GET /element/ui_test/test1 HTTP/1.1" 200 -
2021-06-13 17:43:50,747 [werkzeug] [15064:Thread-4] _internal.py:_internal:_log in 225] [INFO]: 127.0.0.1 - - [13/Jun/2021 17:43:50] "[35m[1mGET /element/ui_test/test1 HTTP/1.1[0m" 500 -
2021-06-13 17:43:50,803 [werkzeug] [15064:Thread-4] _internal.py:_internal:_log in 225] [ERROR]: Error on request:
Traceback (most recent call last):
  File "E:\Auto_test\flask\erybjp\venv\lib\site-packages\_pytest\main.py", line 269, in wrap_session
    session.exitstatus = doit(config, session) or 0
  File "E:\Auto_test\flask\erybjp\venv\lib\site-packages\_pytest\main.py", line 323, in _main
    config.hook.pytest_runtestloop(session=session)
  File "E:\Auto_test\flask\erybjp\venv\lib\site-packages\pluggy\hooks.py", line 286, in __call__
    return self._hookexec(self, self.get_hookimpls(), kwargs)
  File "E:\Auto_test\flask\erybjp\venv\lib\site-packages\pluggy\manager.py", line 93, in _hookexec
    return self._inner_hookexec(hook, methods, kwargs)
  File "E:\Auto_test\flask\erybjp\venv\lib\site-packages\pluggy\manager.py", line 87, in <lambda>
    firstresult=hook.spec.opts.get("firstresult") if hook.spec else False,
  File "E:\Auto_test\flask\erybjp\venv\lib\site-packages\pluggy\callers.py", line 208, in _multicall
    return outcome.get_result()
  File "E:\Auto_test\flask\erybjp\venv\lib\site-packages\pluggy\callers.py", line 80, in get_result
    raise ex[1].with_traceback(ex[2])
  File "E:\Auto_test\flask\erybjp\venv\lib\site-packages\pluggy\callers.py", line 187, in _multicall
    res = hook_impl.function(*args)
  File "E:\Auto_test\flask\erybjp\venv\lib\site-packages\_pytest\main.py", line 348, in pytest_runtestloop
    item.config.hook.pytest_runtest_protocol(item=item, nextitem=nextitem)
  File "E:\Auto_test\flask\erybjp\venv\lib\site-packages\pluggy\hooks.py", line 286, in __call__
    return self._hookexec(self, self.get_hookimpls(), kwargs)
  File "E:\Auto_test\flask\erybjp\venv\lib\site-packages\pluggy\manager.py", line 93, in _hookexec
    return self._inner_hookexec(hook, methods, kwargs)
  File "E:\Auto_test\flask\erybjp\venv\lib\site-packages\pluggy\manager.py", line 87, in <lambda>
    firstresult=hook.spec.opts.get("firstresult") if hook.spec else False,
  File "E:\Auto_test\flask\erybjp\venv\lib\site-packages\pluggy\callers.py", line 208, in _multicall
    return outcome.get_result()
  File "E:\Auto_test\flask\erybjp\venv\lib\site-packages\pluggy\callers.py", line 80, in get_result
    raise ex[1].with_traceback(ex[2])
  File "E:\Auto_test\flask\erybjp\venv\lib\site-packages\pluggy\callers.py", line 187, in _multicall
    res = hook_impl.function(*args)
  File "E:\Auto_test\flask\erybjp\venv\lib\site-packages\_pytest\runner.py", line 109, in pytest_runtest_protocol
    runtestprotocol(item, nextitem=nextitem)
  File "E:\Auto_test\flask\erybjp\venv\lib\site-packages\_pytest\runner.py", line 120, in runtestprotocol
    rep = call_and_report(item, "setup", log)
  File "E:\Auto_test\flask\erybjp\venv\lib\site-packages\_pytest\runner.py", line 217, in call_and_report
    report: TestReport = hook.pytest_runtest_makereport(item=item, call=call)
  File "E:\Auto_test\flask\erybjp\venv\lib\site-packages\pluggy\hooks.py", line 286, in __call__
    return self._hookexec(self, self.get_hookimpls(), kwargs)
  File "E:\Auto_test\flask\erybjp\venv\lib\site-packages\pluggy\manager.py", line 93, in _hookexec
    return self._inner_hookexec(hook, methods, kwargs)
  File "E:\Auto_test\flask\erybjp\venv\lib\site-packages\pluggy\manager.py", line 87, in <lambda>
    firstresult=hook.spec.opts.get("firstresult") if hook.spec else False,
  File "E:\Auto_test\flask\erybjp\venv\lib\site-packages\pluggy\callers.py", line 203, in _multicall
    gen.send(outcome)
  File "E:\Auto_test\flask\erybjp\uiplatform\utils\business\conftest.py", line 54, in pytest_runtest_makereport
    fail_pic = _capture_screenshot(path="uiplatform/utils/data/picture")
  File "E:\Auto_test\flask\erybjp\uiplatform\utils\common\Driver.py", line 63, in _capture_screenshot
    driver.save_screenshot(file_path)
AttributeError: 'NoneType' object has no attribute 'save_screenshot'

During handling of the above exception, another exception occurred:

Traceback (most recent call last):
  File "E:\Auto_test\flask\erybjp\venv\lib\site-packages\_pytest\main.py", line 289, in wrap_session
    config.notify_exception(excinfo, config.option)
  File "E:\Auto_test\flask\erybjp\venv\lib\site-packages\_pytest\config\__init__.py", line 1037, in notify_exception
    res = self.hook.pytest_internalerror(excrepr=excrepr, excinfo=excinfo)
  File "E:\Auto_test\flask\erybjp\venv\lib\site-packages\pluggy\hooks.py", line 286, in __call__
    return self._hookexec(self, self.get_hookimpls(), kwargs)
  File "E:\Auto_test\flask\erybjp\venv\lib\site-packages\pluggy\manager.py", line 93, in _hookexec
    return self._inner_hookexec(hook, methods, kwargs)
  File "E:\Auto_test\flask\erybjp\venv\lib\site-packages\pluggy\manager.py", line 87, in <lambda>
    firstresult=hook.spec.opts.get("firstresult") if hook.spec else False,
  File "E:\Auto_test\flask\erybjp\venv\lib\site-packages\pluggy\callers.py", line 208, in _multicall
    return outcome.get_result()
  File "E:\Auto_test\flask\erybjp\venv\lib\site-packages\pluggy\callers.py", line 80, in get_result
    raise ex[1].with_traceback(ex[2])
  File "E:\Auto_test\flask\erybjp\venv\lib\site-packages\pluggy\callers.py", line 187, in _multicall
    res = hook_impl.function(*args)
  File "E:\Auto_test\flask\erybjp\venv\lib\site-packages\_pytest\terminal.py", line 474, in pytest_internalerror
    self.write_line("INTERNALERROR> " + line)
  File "E:\Auto_test\flask\erybjp\venv\lib\site-packages\_pytest\terminal.py", line 429, in write_line
    self.ensure_newline()
  File "E:\Auto_test\flask\erybjp\venv\lib\site-packages\_pytest\terminal.py", line 417, in ensure_newline
    self._tw.line()
  File "E:\Auto_test\flask\erybjp\venv\lib\site-packages\_pytest\_io\terminalwriter.py", line 171, in line
    self.write("\n")
  File "E:\Auto_test\flask\erybjp\venv\lib\site-packages\_pytest\_io\terminalwriter.py", line 155, in write
    self._file.write(msg)
ValueError: I/O operation on closed file.

During handling of the above exception, another exception occurred:

Traceback (most recent call last):
  File "E:\Auto_test\flask\erybjp\venv\lib\site-packages\werkzeug\debug\__init__.py", line 309, in debug_application
    app_iter = self.app(environ, start_response)
  File "E:\Auto_test\flask\erybjp\venv\lib\site-packages\flask\app.py", line 2464, in __call__
    return self.wsgi_app(environ, start_response)
  File "E:\Auto_test\flask\erybjp\venv\lib\site-packages\flask\app.py", line 2450, in wsgi_app
    response = self.handle_exception(e)
  File "E:\Auto_test\flask\erybjp\venv\lib\site-packages\flask_restful\__init__.py", line 271, in error_router
    return original_handler(e)
  File "E:\Auto_test\flask\erybjp\venv\lib\site-packages\flask_cors\extension.py", line 165, in wrapped_function
    return cors_after_request(app.make_response(f(*args, **kwargs)))
  File "E:\Auto_test\flask\erybjp\venv\lib\site-packages\flask\app.py", line 1867, in handle_exception
    reraise(exc_type, exc_value, tb)
  File "E:\Auto_test\flask\erybjp\venv\lib\site-packages\flask\_compat.py", line 39, in reraise
    raise value
  File "E:\Auto_test\flask\erybjp\venv\lib\site-packages\flask\app.py", line 2447, in wsgi_app
    response = self.full_dispatch_request()
  File "E:\Auto_test\flask\erybjp\venv\lib\site-packages\flask\app.py", line 1952, in full_dispatch_request
    rv = self.handle_user_exception(e)
  File "E:\Auto_test\flask\erybjp\venv\lib\site-packages\flask_restful\__init__.py", line 271, in error_router
    return original_handler(e)
  File "E:\Auto_test\flask\erybjp\venv\lib\site-packages\flask_cors\extension.py", line 165, in wrapped_function
    return cors_after_request(app.make_response(f(*args, **kwargs)))
  File "E:\Auto_test\flask\erybjp\venv\lib\site-packages\flask\app.py", line 1821, in handle_user_exception
    reraise(exc_type, exc_value, tb)
  File "E:\Auto_test\flask\erybjp\venv\lib\site-packages\flask\_compat.py", line 39, in reraise
    raise value
  File "E:\Auto_test\flask\erybjp\venv\lib\site-packages\flask\app.py", line 1950, in full_dispatch_request
    rv = self.dispatch_request()
  File "E:\Auto_test\flask\erybjp\venv\lib\site-packages\flask\app.py", line 1936, in dispatch_request
    return self.view_functions[rule.endpoint](**req.view_args)
  File "E:\Auto_test\flask\erybjp\uiplatform\router\runtestcase.py", line 37, in run_only_test01
    pytest.main(lista)
  File "E:\Auto_test\flask\erybjp\venv\lib\site-packages\_pytest\config\__init__.py", line 163, in main
    config=config
  File "E:\Auto_test\flask\erybjp\venv\lib\site-packages\pluggy\hooks.py", line 286, in __call__
    return self._hookexec(self, self.get_hookimpls(), kwargs)
  File "E:\Auto_test\flask\erybjp\venv\lib\site-packages\pluggy\manager.py", line 93, in _hookexec
    return self._inner_hookexec(hook, methods, kwargs)
  File "E:\Auto_test\flask\erybjp\venv\lib\site-packages\pluggy\manager.py", line 87, in <lambda>
    firstresult=hook.spec.opts.get("firstresult") if hook.spec else False,
  File "E:\Auto_test\flask\erybjp\venv\lib\site-packages\pluggy\callers.py", line 208, in _multicall
    return outcome.get_result()
  File "E:\Auto_test\flask\erybjp\venv\lib\site-packages\pluggy\callers.py", line 80, in get_result
    raise ex[1].with_traceback(ex[2])
  File "E:\Auto_test\flask\erybjp\venv\lib\site-packages\pluggy\callers.py", line 187, in _multicall
    res = hook_impl.function(*args)
  File "E:\Auto_test\flask\erybjp\venv\lib\site-packages\_pytest\main.py", line 316, in pytest_cmdline_main
    return wrap_session(config, _main)
  File "E:\Auto_test\flask\erybjp\venv\lib\site-packages\_pytest\main.py", line 305, in wrap_session
    session=session, exitstatus=session.exitstatus
  File "E:\Auto_test\flask\erybjp\venv\lib\site-packages\pluggy\hooks.py", line 286, in __call__
    return self._hookexec(self, self.get_hookimpls(), kwargs)
  File "E:\Auto_test\flask\erybjp\venv\lib\site-packages\pluggy\manager.py", line 93, in _hookexec
    return self._inner_hookexec(hook, methods, kwargs)
  File "E:\Auto_test\flask\erybjp\venv\lib\site-packages\pluggy\manager.py", line 87, in <lambda>
    firstresult=hook.spec.opts.get("firstresult") if hook.spec else False,
  File "E:\Auto_test\flask\erybjp\venv\lib\site-packages\pluggy\callers.py", line 203, in _multicall
    gen.send(outcome)
  File "E:\Auto_test\flask\erybjp\venv\lib\site-packages\_pytest\terminal.py", line 804, in pytest_sessionfinish
    self._tw.line("")
  File "E:\Auto_test\flask\erybjp\venv\lib\site-packages\_pytest\_io\terminalwriter.py", line 171, in line
    self.write("\n")
  File "E:\Auto_test\flask\erybjp\venv\lib\site-packages\_pytest\_io\terminalwriter.py", line 155, in write
    self._file.write(msg)
ValueError: I/O operation on closed file.

During handling of the above exception, another exception occurred:

Traceback (most recent call last):
  File "E:\Auto_test\flask\erybjp\venv\lib\site-packages\werkzeug\serving.py", line 319, in run_wsgi
    execute(self.server.app)
  File "E:\Auto_test\flask\erybjp\venv\lib\site-packages\werkzeug\serving.py", line 310, in execute
    for data in application_iter:
  File "E:\Auto_test\flask\erybjp\venv\lib\site-packages\werkzeug\debug\__init__.py", line 351, in debug_application
    traceback.log(environ["wsgi.errors"])
  File "E:\Auto_test\flask\erybjp\venv\lib\site-packages\werkzeug\debug\tbtools.py", line 267, in log
    logfile.write(tb)
ValueError: I/O operation on closed file.
2021-06-13 17:43:50,835 [werkzeug] [8168:Thread-5] _internal.py:_internal:_log in 225] [INFO]: 127.0.0.1 - - [13/Jun/2021 17:43:50] "GET /element/ui_test/test1?__debugger__=yes&cmd=resource&f=style.css HTTP/1.1" 200 -
2021-06-13 17:43:50,844 [werkzeug] [1380:Thread-6] _internal.py:_internal:_log in 225] [INFO]: 127.0.0.1 - - [13/Jun/2021 17:43:50] "GET /element/ui_test/test1?__debugger__=yes&cmd=resource&f=debugger.js HTTP/1.1" 200 -
2021-06-13 17:43:51,134 [werkzeug] [10764:Thread-7] _internal.py:_internal:_log in 225] [INFO]: 127.0.0.1 - - [13/Jun/2021 17:43:51] "GET /element/ui_test/test1?__debugger__=yes&cmd=resource&f=console.png HTTP/1.1" 200 -
2021-06-13 17:43:51,165 [werkzeug] [2692:Thread-8] _internal.py:_internal:_log in 225] [INFO]: 127.0.0.1 - - [13/Jun/2021 17:43:51] "GET /element/ui_test/test1?__debugger__=yes&cmd=resource&f=ubuntu.ttf HTTP/1.1" 200 -
2021-06-13 17:43:51,262 [werkzeug] [17092:Thread-9] _internal.py:_internal:_log in 225] [INFO]: 127.0.0.1 - - [13/Jun/2021 17:43:51] "GET /element/ui_test/test1?__debugger__=yes&cmd=resource&f=console.png HTTP/1.1" 200 -
2021-06-13 18:25:07,166 [werkzeug] [11764:Thread-3] _internal.py:_internal:_log in 225] [INFO]: 127.0.0.1 - - [13/Jun/2021 18:25:07] "[33mGET / HTTP/1.1[0m" 404 -
2021-06-13 18:26:36,140 [werkzeug] [16232:Thread-4] _internal.py:_internal:_log in 225] [INFO]: 127.0.0.1 - - [13/Jun/2021 18:26:36] "GET /element/ui_test/test1 HTTP/1.1" 200 -
2021-06-13 18:58:01,894 [werkzeug] [2896:Thread-3] _internal.py:_internal:_log in 225] [INFO]: 127.0.0.1 - - [13/Jun/2021 18:58:01] "[33mGET / HTTP/1.1[0m" 404 -
2021-06-13 18:59:31,663 [werkzeug] [14100:Thread-4] _internal.py:_internal:_log in 225] [INFO]: 127.0.0.1 - - [13/Jun/2021 18:59:31] "GET /element/ui_test/test HTTP/1.1" 200 -
2021-06-13 19:00:33,752 [werkzeug] [17200:Thread-5] _internal.py:_internal:_log in 225] [INFO]: 127.0.0.1 - - [13/Jun/2021 19:00:33] "[35m[1mGET /element/ui_test/test HTTP/1.1[0m" 500 -
2021-06-13 19:00:33,784 [werkzeug] [17200:Thread-5] _internal.py:_internal:_log in 225] [ERROR]: Error on request:
Traceback (most recent call last):
  File "E:\Auto_test\flask\erybjp\venv\lib\site-packages\_pytest\main.py", line 269, in wrap_session
    session.exitstatus = doit(config, session) or 0
  File "E:\Auto_test\flask\erybjp\venv\lib\site-packages\_pytest\main.py", line 323, in _main
    config.hook.pytest_runtestloop(session=session)
  File "E:\Auto_test\flask\erybjp\venv\lib\site-packages\pluggy\hooks.py", line 286, in __call__
    return self._hookexec(self, self.get_hookimpls(), kwargs)
  File "E:\Auto_test\flask\erybjp\venv\lib\site-packages\pluggy\manager.py", line 93, in _hookexec
    return self._inner_hookexec(hook, methods, kwargs)
  File "E:\Auto_test\flask\erybjp\venv\lib\site-packages\pluggy\manager.py", line 87, in <lambda>
    firstresult=hook.spec.opts.get("firstresult") if hook.spec else False,
  File "E:\Auto_test\flask\erybjp\venv\lib\site-packages\pluggy\callers.py", line 208, in _multicall
    return outcome.get_result()
  File "E:\Auto_test\flask\erybjp\venv\lib\site-packages\pluggy\callers.py", line 80, in get_result
    raise ex[1].with_traceback(ex[2])
  File "E:\Auto_test\flask\erybjp\venv\lib\site-packages\pluggy\callers.py", line 187, in _multicall
    res = hook_impl.function(*args)
  File "E:\Auto_test\flask\erybjp\venv\lib\site-packages\_pytest\main.py", line 348, in pytest_runtestloop
    item.config.hook.pytest_runtest_protocol(item=item, nextitem=nextitem)
  File "E:\Auto_test\flask\erybjp\venv\lib\site-packages\pluggy\hooks.py", line 286, in __call__
    return self._hookexec(self, self.get_hookimpls(), kwargs)
  File "E:\Auto_test\flask\erybjp\venv\lib\site-packages\pluggy\manager.py", line 93, in _hookexec
    return self._inner_hookexec(hook, methods, kwargs)
  File "E:\Auto_test\flask\erybjp\venv\lib\site-packages\pluggy\manager.py", line 87, in <lambda>
    firstresult=hook.spec.opts.get("firstresult") if hook.spec else False,
  File "E:\Auto_test\flask\erybjp\venv\lib\site-packages\pluggy\callers.py", line 208, in _multicall
    return outcome.get_result()
  File "E:\Auto_test\flask\erybjp\venv\lib\site-packages\pluggy\callers.py", line 80, in get_result
    raise ex[1].with_traceback(ex[2])
  File "E:\Auto_test\flask\erybjp\venv\lib\site-packages\pluggy\callers.py", line 187, in _multicall
    res = hook_impl.function(*args)
  File "E:\Auto_test\flask\erybjp\venv\lib\site-packages\_pytest\runner.py", line 109, in pytest_runtest_protocol
    runtestprotocol(item, nextitem=nextitem)
  File "E:\Auto_test\flask\erybjp\venv\lib\site-packages\_pytest\runner.py", line 120, in runtestprotocol
    rep = call_and_report(item, "setup", log)
  File "E:\Auto_test\flask\erybjp\venv\lib\site-packages\_pytest\runner.py", line 217, in call_and_report
    report: TestReport = hook.pytest_runtest_makereport(item=item, call=call)
  File "E:\Auto_test\flask\erybjp\venv\lib\site-packages\pluggy\hooks.py", line 286, in __call__
    return self._hookexec(self, self.get_hookimpls(), kwargs)
  File "E:\Auto_test\flask\erybjp\venv\lib\site-packages\pluggy\manager.py", line 93, in _hookexec
    return self._inner_hookexec(hook, methods, kwargs)
  File "E:\Auto_test\flask\erybjp\venv\lib\site-packages\pluggy\manager.py", line 87, in <lambda>
    firstresult=hook.spec.opts.get("firstresult") if hook.spec else False,
  File "E:\Auto_test\flask\erybjp\venv\lib\site-packages\pluggy\callers.py", line 203, in _multicall
    gen.send(outcome)
  File "E:\Auto_test\flask\erybjp\uiplatform\utils\business\conftest.py", line 54, in pytest_runtest_makereport
    fail_pic = _capture_screenshot(path="uiplatform/utils/data/picture")
  File "E:\Auto_test\flask\erybjp\uiplatform\utils\common\Driver.py", line 63, in _capture_screenshot
    driver.save_screenshot(file_path)
AttributeError: 'NoneType' object has no attribute 'save_screenshot'

During handling of the above exception, another exception occurred:

Traceback (most recent call last):
  File "E:\Auto_test\flask\erybjp\venv\lib\site-packages\_pytest\main.py", line 289, in wrap_session
    config.notify_exception(excinfo, config.option)
  File "E:\Auto_test\flask\erybjp\venv\lib\site-packages\_pytest\config\__init__.py", line 1037, in notify_exception
    res = self.hook.pytest_internalerror(excrepr=excrepr, excinfo=excinfo)
  File "E:\Auto_test\flask\erybjp\venv\lib\site-packages\pluggy\hooks.py", line 286, in __call__
    return self._hookexec(self, self.get_hookimpls(), kwargs)
  File "E:\Auto_test\flask\erybjp\venv\lib\site-packages\pluggy\manager.py", line 93, in _hookexec
    return self._inner_hookexec(hook, methods, kwargs)
  File "E:\Auto_test\flask\erybjp\venv\lib\site-packages\pluggy\manager.py", line 87, in <lambda>
    firstresult=hook.spec.opts.get("firstresult") if hook.spec else False,
  File "E:\Auto_test\flask\erybjp\venv\lib\site-packages\pluggy\callers.py", line 208, in _multicall
    return outcome.get_result()
  File "E:\Auto_test\flask\erybjp\venv\lib\site-packages\pluggy\callers.py", line 80, in get_result
    raise ex[1].with_traceback(ex[2])
  File "E:\Auto_test\flask\erybjp\venv\lib\site-packages\pluggy\callers.py", line 187, in _multicall
    res = hook_impl.function(*args)
  File "E:\Auto_test\flask\erybjp\venv\lib\site-packages\_pytest\terminal.py", line 474, in pytest_internalerror
    self.write_line("INTERNALERROR> " + line)
  File "E:\Auto_test\flask\erybjp\venv\lib\site-packages\_pytest\terminal.py", line 429, in write_line
    self.ensure_newline()
  File "E:\Auto_test\flask\erybjp\venv\lib\site-packages\_pytest\terminal.py", line 417, in ensure_newline
    self._tw.line()
  File "E:\Auto_test\flask\erybjp\venv\lib\site-packages\_pytest\_io\terminalwriter.py", line 171, in line
    self.write("\n")
  File "E:\Auto_test\flask\erybjp\venv\lib\site-packages\_pytest\_io\terminalwriter.py", line 155, in write
    self._file.write(msg)
ValueError: I/O operation on closed file.

During handling of the above exception, another exception occurred:

Traceback (most recent call last):
  File "E:\Auto_test\flask\erybjp\venv\lib\site-packages\werkzeug\debug\__init__.py", line 309, in debug_application
    app_iter = self.app(environ, start_response)
  File "E:\Auto_test\flask\erybjp\venv\lib\site-packages\flask\app.py", line 2464, in __call__
    return self.wsgi_app(environ, start_response)
  File "E:\Auto_test\flask\erybjp\venv\lib\site-packages\flask\app.py", line 2450, in wsgi_app
    response = self.handle_exception(e)
  File "E:\Auto_test\flask\erybjp\venv\lib\site-packages\flask_restful\__init__.py", line 271, in error_router
    return original_handler(e)
  File "E:\Auto_test\flask\erybjp\venv\lib\site-packages\flask_cors\extension.py", line 165, in wrapped_function
    return cors_after_request(app.make_response(f(*args, **kwargs)))
  File "E:\Auto_test\flask\erybjp\venv\lib\site-packages\flask\app.py", line 1867, in handle_exception
    reraise(exc_type, exc_value, tb)
  File "E:\Auto_test\flask\erybjp\venv\lib\site-packages\flask\_compat.py", line 39, in reraise
    raise value
  File "E:\Auto_test\flask\erybjp\venv\lib\site-packages\flask\app.py", line 2447, in wsgi_app
    response = self.full_dispatch_request()
  File "E:\Auto_test\flask\erybjp\venv\lib\site-packages\flask\app.py", line 1952, in full_dispatch_request
    rv = self.handle_user_exception(e)
  File "E:\Auto_test\flask\erybjp\venv\lib\site-packages\flask_restful\__init__.py", line 271, in error_router
    return original_handler(e)
  File "E:\Auto_test\flask\erybjp\venv\lib\site-packages\flask_cors\extension.py", line 165, in wrapped_function
    return cors_after_request(app.make_response(f(*args, **kwargs)))
  File "E:\Auto_test\flask\erybjp\venv\lib\site-packages\flask\app.py", line 1821, in handle_user_exception
    reraise(exc_type, exc_value, tb)
  File "E:\Auto_test\flask\erybjp\venv\lib\site-packages\flask\_compat.py", line 39, in reraise
    raise value
  File "E:\Auto_test\flask\erybjp\venv\lib\site-packages\flask\app.py", line 1950, in full_dispatch_request
    rv = self.dispatch_request()
  File "E:\Auto_test\flask\erybjp\venv\lib\site-packages\flask\app.py", line 1936, in dispatch_request
    return self.view_functions[rule.endpoint](**req.view_args)
  File "E:\Auto_test\flask\erybjp\uiplatform\router\runtestcase.py", line 27, in run_only_test
    pytest.main(lista)
  File "E:\Auto_test\flask\erybjp\venv\lib\site-packages\_pytest\config\__init__.py", line 163, in main
    config=config
  File "E:\Auto_test\flask\erybjp\venv\lib\site-packages\pluggy\hooks.py", line 286, in __call__
    return self._hookexec(self, self.get_hookimpls(), kwargs)
  File "E:\Auto_test\flask\erybjp\venv\lib\site-packages\pluggy\manager.py", line 93, in _hookexec
    return self._inner_hookexec(hook, methods, kwargs)
  File "E:\Auto_test\flask\erybjp\venv\lib\site-packages\pluggy\manager.py", line 87, in <lambda>
    firstresult=hook.spec.opts.get("firstresult") if hook.spec else False,
  File "E:\Auto_test\flask\erybjp\venv\lib\site-packages\pluggy\callers.py", line 208, in _multicall
    return outcome.get_result()
  File "E:\Auto_test\flask\erybjp\venv\lib\site-packages\pluggy\callers.py", line 80, in get_result
    raise ex[1].with_traceback(ex[2])
  File "E:\Auto_test\flask\erybjp\venv\lib\site-packages\pluggy\callers.py", line 187, in _multicall
    res = hook_impl.function(*args)
  File "E:\Auto_test\flask\erybjp\venv\lib\site-packages\_pytest\main.py", line 316, in pytest_cmdline_main
    return wrap_session(config, _main)
  File "E:\Auto_test\flask\erybjp\venv\lib\site-packages\_pytest\main.py", line 305, in wrap_session
    session=session, exitstatus=session.exitstatus
  File "E:\Auto_test\flask\erybjp\venv\lib\site-packages\pluggy\hooks.py", line 286, in __call__
    return self._hookexec(self, self.get_hookimpls(), kwargs)
  File "E:\Auto_test\flask\erybjp\venv\lib\site-packages\pluggy\manager.py", line 93, in _hookexec
    return self._inner_hookexec(hook, methods, kwargs)
  File "E:\Auto_test\flask\erybjp\venv\lib\site-packages\pluggy\manager.py", line 87, in <lambda>
    firstresult=hook.spec.opts.get("firstresult") if hook.spec else False,
  File "E:\Auto_test\flask\erybjp\venv\lib\site-packages\pluggy\callers.py", line 203, in _multicall
    gen.send(outcome)
  File "E:\Auto_test\flask\erybjp\venv\lib\site-packages\_pytest\terminal.py", line 804, in pytest_sessionfinish
    self._tw.line("")
  File "E:\Auto_test\flask\erybjp\venv\lib\site-packages\_pytest\_io\terminalwriter.py", line 171, in line
    self.write("\n")
  File "E:\Auto_test\flask\erybjp\venv\lib\site-packages\_pytest\_io\terminalwriter.py", line 155, in write
    self._file.write(msg)
ValueError: I/O operation on closed file.

During handling of the above exception, another exception occurred:

Traceback (most recent call last):
  File "E:\Auto_test\flask\erybjp\venv\lib\site-packages\werkzeug\serving.py", line 319, in run_wsgi
    execute(self.server.app)
  File "E:\Auto_test\flask\erybjp\venv\lib\site-packages\werkzeug\serving.py", line 310, in execute
    for data in application_iter:
  File "E:\Auto_test\flask\erybjp\venv\lib\site-packages\werkzeug\debug\__init__.py", line 351, in debug_application
    traceback.log(environ["wsgi.errors"])
  File "E:\Auto_test\flask\erybjp\venv\lib\site-packages\werkzeug\debug\tbtools.py", line 267, in log
    logfile.write(tb)
ValueError: I/O operation on closed file.
2021-06-13 19:00:33,811 [werkzeug] [16012:Thread-6] _internal.py:_internal:_log in 225] [INFO]: 127.0.0.1 - - [13/Jun/2021 19:00:33] "GET /element/ui_test/test?__debugger__=yes&cmd=resource&f=style.css HTTP/1.1" 200 -
2021-06-13 19:00:33,811 [werkzeug] [1944:Thread-7] _internal.py:_internal:_log in 225] [INFO]: 127.0.0.1 - - [13/Jun/2021 19:00:33] "GET /element/ui_test/test?__debugger__=yes&cmd=resource&f=debugger.js HTTP/1.1" 200 -
2021-06-13 19:00:33,897 [werkzeug] [18300:Thread-8] _internal.py:_internal:_log in 225] [INFO]: 127.0.0.1 - - [13/Jun/2021 19:00:33] "GET /element/ui_test/test?__debugger__=yes&cmd=resource&f=console.png HTTP/1.1" 200 -
2021-06-13 19:00:33,938 [werkzeug] [17744:Thread-9] _internal.py:_internal:_log in 225] [INFO]: 127.0.0.1 - - [13/Jun/2021 19:00:33] "GET /element/ui_test/test?__debugger__=yes&cmd=resource&f=ubuntu.ttf HTTP/1.1" 200 -
2021-06-13 19:00:34,024 [werkzeug] [17816:Thread-10] _internal.py:_internal:_log in 225] [INFO]: 127.0.0.1 - - [13/Jun/2021 19:00:34] "GET /element/ui_test/test?__debugger__=yes&cmd=resource&f=console.png HTTP/1.1" 200 -
2021-06-13 20:20:20,539 [werkzeug] [17620:Thread-3] _internal.py:_internal:_log in 225] [INFO]: 127.0.0.1 - - [13/Jun/2021 20:20:20] "GET /element/ui_test/test HTTP/1.1" 200 -
2021-06-13 20:21:14,524 [werkzeug] [17436:Thread-4] _internal.py:_internal:_log in 225] [INFO]: 127.0.0.1 - - [13/Jun/2021 20:21:14] "[35m[1mGET /element/ui_test/test HTTP/1.1[0m" 500 -
2021-06-13 20:21:14,558 [werkzeug] [17436:Thread-4] _internal.py:_internal:_log in 225] [ERROR]: Error on request:
Traceback (most recent call last):
  File "E:\Auto_test\flask\erybjp\venv\lib\site-packages\_pytest\main.py", line 269, in wrap_session
    session.exitstatus = doit(config, session) or 0
  File "E:\Auto_test\flask\erybjp\venv\lib\site-packages\_pytest\main.py", line 323, in _main
    config.hook.pytest_runtestloop(session=session)
  File "E:\Auto_test\flask\erybjp\venv\lib\site-packages\pluggy\hooks.py", line 286, in __call__
    return self._hookexec(self, self.get_hookimpls(), kwargs)
  File "E:\Auto_test\flask\erybjp\venv\lib\site-packages\pluggy\manager.py", line 93, in _hookexec
    return self._inner_hookexec(hook, methods, kwargs)
  File "E:\Auto_test\flask\erybjp\venv\lib\site-packages\pluggy\manager.py", line 87, in <lambda>
    firstresult=hook.spec.opts.get("firstresult") if hook.spec else False,
  File "E:\Auto_test\flask\erybjp\venv\lib\site-packages\pluggy\callers.py", line 208, in _multicall
    return outcome.get_result()
  File "E:\Auto_test\flask\erybjp\venv\lib\site-packages\pluggy\callers.py", line 80, in get_result
    raise ex[1].with_traceback(ex[2])
  File "E:\Auto_test\flask\erybjp\venv\lib\site-packages\pluggy\callers.py", line 187, in _multicall
    res = hook_impl.function(*args)
  File "E:\Auto_test\flask\erybjp\venv\lib\site-packages\_pytest\main.py", line 348, in pytest_runtestloop
    item.config.hook.pytest_runtest_protocol(item=item, nextitem=nextitem)
  File "E:\Auto_test\flask\erybjp\venv\lib\site-packages\pluggy\hooks.py", line 286, in __call__
    return self._hookexec(self, self.get_hookimpls(), kwargs)
  File "E:\Auto_test\flask\erybjp\venv\lib\site-packages\pluggy\manager.py", line 93, in _hookexec
    return self._inner_hookexec(hook, methods, kwargs)
  File "E:\Auto_test\flask\erybjp\venv\lib\site-packages\pluggy\manager.py", line 87, in <lambda>
    firstresult=hook.spec.opts.get("firstresult") if hook.spec else False,
  File "E:\Auto_test\flask\erybjp\venv\lib\site-packages\pluggy\callers.py", line 208, in _multicall
    return outcome.get_result()
  File "E:\Auto_test\flask\erybjp\venv\lib\site-packages\pluggy\callers.py", line 80, in get_result
    raise ex[1].with_traceback(ex[2])
  File "E:\Auto_test\flask\erybjp\venv\lib\site-packages\pluggy\callers.py", line 187, in _multicall
    res = hook_impl.function(*args)
  File "E:\Auto_test\flask\erybjp\venv\lib\site-packages\_pytest\runner.py", line 109, in pytest_runtest_protocol
    runtestprotocol(item, nextitem=nextitem)
  File "E:\Auto_test\flask\erybjp\venv\lib\site-packages\_pytest\runner.py", line 120, in runtestprotocol
    rep = call_and_report(item, "setup", log)
  File "E:\Auto_test\flask\erybjp\venv\lib\site-packages\_pytest\runner.py", line 217, in call_and_report
    report: TestReport = hook.pytest_runtest_makereport(item=item, call=call)
  File "E:\Auto_test\flask\erybjp\venv\lib\site-packages\pluggy\hooks.py", line 286, in __call__
    return self._hookexec(self, self.get_hookimpls(), kwargs)
  File "E:\Auto_test\flask\erybjp\venv\lib\site-packages\pluggy\manager.py", line 93, in _hookexec
    return self._inner_hookexec(hook, methods, kwargs)
  File "E:\Auto_test\flask\erybjp\venv\lib\site-packages\pluggy\manager.py", line 87, in <lambda>
    firstresult=hook.spec.opts.get("firstresult") if hook.spec else False,
  File "E:\Auto_test\flask\erybjp\venv\lib\site-packages\pluggy\callers.py", line 203, in _multicall
    gen.send(outcome)
  File "E:\Auto_test\flask\erybjp\uiplatform\utils\business\conftest.py", line 54, in pytest_runtest_makereport
    fail_pic = _capture_screenshot(path="uiplatform/utils/data/picture")
  File "E:\Auto_test\flask\erybjp\uiplatform\utils\common\Driver.py", line 63, in _capture_screenshot
    driver.save_screenshot(file_path)
AttributeError: 'NoneType' object has no attribute 'save_screenshot'

During handling of the above exception, another exception occurred:

Traceback (most recent call last):
  File "E:\Auto_test\flask\erybjp\venv\lib\site-packages\_pytest\main.py", line 289, in wrap_session
    config.notify_exception(excinfo, config.option)
  File "E:\Auto_test\flask\erybjp\venv\lib\site-packages\_pytest\config\__init__.py", line 1037, in notify_exception
    res = self.hook.pytest_internalerror(excrepr=excrepr, excinfo=excinfo)
  File "E:\Auto_test\flask\erybjp\venv\lib\site-packages\pluggy\hooks.py", line 286, in __call__
    return self._hookexec(self, self.get_hookimpls(), kwargs)
  File "E:\Auto_test\flask\erybjp\venv\lib\site-packages\pluggy\manager.py", line 93, in _hookexec
    return self._inner_hookexec(hook, methods, kwargs)
  File "E:\Auto_test\flask\erybjp\venv\lib\site-packages\pluggy\manager.py", line 87, in <lambda>
    firstresult=hook.spec.opts.get("firstresult") if hook.spec else False,
  File "E:\Auto_test\flask\erybjp\venv\lib\site-packages\pluggy\callers.py", line 208, in _multicall
    return outcome.get_result()
  File "E:\Auto_test\flask\erybjp\venv\lib\site-packages\pluggy\callers.py", line 80, in get_result
    raise ex[1].with_traceback(ex[2])
  File "E:\Auto_test\flask\erybjp\venv\lib\site-packages\pluggy\callers.py", line 187, in _multicall
    res = hook_impl.function(*args)
  File "E:\Auto_test\flask\erybjp\venv\lib\site-packages\_pytest\terminal.py", line 474, in pytest_internalerror
    self.write_line("INTERNALERROR> " + line)
  File "E:\Auto_test\flask\erybjp\venv\lib\site-packages\_pytest\terminal.py", line 429, in write_line
    self.ensure_newline()
  File "E:\Auto_test\flask\erybjp\venv\lib\site-packages\_pytest\terminal.py", line 417, in ensure_newline
    self._tw.line()
  File "E:\Auto_test\flask\erybjp\venv\lib\site-packages\_pytest\_io\terminalwriter.py", line 171, in line
    self.write("\n")
  File "E:\Auto_test\flask\erybjp\venv\lib\site-packages\_pytest\_io\terminalwriter.py", line 155, in write
    self._file.write(msg)
ValueError: I/O operation on closed file.

During handling of the above exception, another exception occurred:

Traceback (most recent call last):
  File "E:\Auto_test\flask\erybjp\venv\lib\site-packages\werkzeug\debug\__init__.py", line 309, in debug_application
    app_iter = self.app(environ, start_response)
  File "E:\Auto_test\flask\erybjp\venv\lib\site-packages\flask\app.py", line 2464, in __call__
    return self.wsgi_app(environ, start_response)
  File "E:\Auto_test\flask\erybjp\venv\lib\site-packages\flask\app.py", line 2450, in wsgi_app
    response = self.handle_exception(e)
  File "E:\Auto_test\flask\erybjp\venv\lib\site-packages\flask_restful\__init__.py", line 271, in error_router
    return original_handler(e)
  File "E:\Auto_test\flask\erybjp\venv\lib\site-packages\flask_cors\extension.py", line 165, in wrapped_function
    return cors_after_request(app.make_response(f(*args, **kwargs)))
  File "E:\Auto_test\flask\erybjp\venv\lib\site-packages\flask\app.py", line 1867, in handle_exception
    reraise(exc_type, exc_value, tb)
  File "E:\Auto_test\flask\erybjp\venv\lib\site-packages\flask\_compat.py", line 39, in reraise
    raise value
  File "E:\Auto_test\flask\erybjp\venv\lib\site-packages\flask\app.py", line 2447, in wsgi_app
    response = self.full_dispatch_request()
  File "E:\Auto_test\flask\erybjp\venv\lib\site-packages\flask\app.py", line 1952, in full_dispatch_request
    rv = self.handle_user_exception(e)
  File "E:\Auto_test\flask\erybjp\venv\lib\site-packages\flask_restful\__init__.py", line 271, in error_router
    return original_handler(e)
  File "E:\Auto_test\flask\erybjp\venv\lib\site-packages\flask_cors\extension.py", line 165, in wrapped_function
    return cors_after_request(app.make_response(f(*args, **kwargs)))
  File "E:\Auto_test\flask\erybjp\venv\lib\site-packages\flask\app.py", line 1821, in handle_user_exception
    reraise(exc_type, exc_value, tb)
  File "E:\Auto_test\flask\erybjp\venv\lib\site-packages\flask\_compat.py", line 39, in reraise
    raise value
  File "E:\Auto_test\flask\erybjp\venv\lib\site-packages\flask\app.py", line 1950, in full_dispatch_request
    rv = self.dispatch_request()
  File "E:\Auto_test\flask\erybjp\venv\lib\site-packages\flask\app.py", line 1936, in dispatch_request
    return self.view_functions[rule.endpoint](**req.view_args)
  File "E:\Auto_test\flask\erybjp\uiplatform\router\runtestcase.py", line 27, in run_only_test
    pytest.main(lista)
  File "E:\Auto_test\flask\erybjp\venv\lib\site-packages\_pytest\config\__init__.py", line 163, in main
    config=config
  File "E:\Auto_test\flask\erybjp\venv\lib\site-packages\pluggy\hooks.py", line 286, in __call__
    return self._hookexec(self, self.get_hookimpls(), kwargs)
  File "E:\Auto_test\flask\erybjp\venv\lib\site-packages\pluggy\manager.py", line 93, in _hookexec
    return self._inner_hookexec(hook, methods, kwargs)
  File "E:\Auto_test\flask\erybjp\venv\lib\site-packages\pluggy\manager.py", line 87, in <lambda>
    firstresult=hook.spec.opts.get("firstresult") if hook.spec else False,
  File "E:\Auto_test\flask\erybjp\venv\lib\site-packages\pluggy\callers.py", line 208, in _multicall
    return outcome.get_result()
  File "E:\Auto_test\flask\erybjp\venv\lib\site-packages\pluggy\callers.py", line 80, in get_result
    raise ex[1].with_traceback(ex[2])
  File "E:\Auto_test\flask\erybjp\venv\lib\site-packages\pluggy\callers.py", line 187, in _multicall
    res = hook_impl.function(*args)
  File "E:\Auto_test\flask\erybjp\venv\lib\site-packages\_pytest\main.py", line 316, in pytest_cmdline_main
    return wrap_session(config, _main)
  File "E:\Auto_test\flask\erybjp\venv\lib\site-packages\_pytest\main.py", line 305, in wrap_session
    session=session, exitstatus=session.exitstatus
  File "E:\Auto_test\flask\erybjp\venv\lib\site-packages\pluggy\hooks.py", line 286, in __call__
    return self._hookexec(self, self.get_hookimpls(), kwargs)
  File "E:\Auto_test\flask\erybjp\venv\lib\site-packages\pluggy\manager.py", line 93, in _hookexec
    return self._inner_hookexec(hook, methods, kwargs)
  File "E:\Auto_test\flask\erybjp\venv\lib\site-packages\pluggy\manager.py", line 87, in <lambda>
    firstresult=hook.spec.opts.get("firstresult") if hook.spec else False,
  File "E:\Auto_test\flask\erybjp\venv\lib\site-packages\pluggy\callers.py", line 203, in _multicall
    gen.send(outcome)
  File "E:\Auto_test\flask\erybjp\venv\lib\site-packages\_pytest\terminal.py", line 804, in pytest_sessionfinish
    self._tw.line("")
  File "E:\Auto_test\flask\erybjp\venv\lib\site-packages\_pytest\_io\terminalwriter.py", line 171, in line
    self.write("\n")
  File "E:\Auto_test\flask\erybjp\venv\lib\site-packages\_pytest\_io\terminalwriter.py", line 155, in write
    self._file.write(msg)
ValueError: I/O operation on closed file.

During handling of the above exception, another exception occurred:

Traceback (most recent call last):
  File "E:\Auto_test\flask\erybjp\venv\lib\site-packages\werkzeug\serving.py", line 319, in run_wsgi
    execute(self.server.app)
  File "E:\Auto_test\flask\erybjp\venv\lib\site-packages\werkzeug\serving.py", line 310, in execute
    for data in application_iter:
  File "E:\Auto_test\flask\erybjp\venv\lib\site-packages\werkzeug\debug\__init__.py", line 351, in debug_application
    traceback.log(environ["wsgi.errors"])
  File "E:\Auto_test\flask\erybjp\venv\lib\site-packages\werkzeug\debug\tbtools.py", line 267, in log
    logfile.write(tb)
ValueError: I/O operation on closed file.
2021-06-13 20:21:14,594 [werkzeug] [6660:Thread-5] _internal.py:_internal:_log in 225] [INFO]: 127.0.0.1 - - [13/Jun/2021 20:21:14] "GET /element/ui_test/test?__debugger__=yes&cmd=resource&f=debugger.js HTTP/1.1" 200 -
2021-06-13 20:21:14,594 [werkzeug] [896:Thread-6] _internal.py:_internal:_log in 225] [INFO]: 127.0.0.1 - - [13/Jun/2021 20:21:14] "GET /element/ui_test/test?__debugger__=yes&cmd=resource&f=style.css HTTP/1.1" 200 -
2021-06-13 20:21:14,876 [werkzeug] [15148:Thread-7] _internal.py:_internal:_log in 225] [INFO]: 127.0.0.1 - - [13/Jun/2021 20:21:14] "GET /element/ui_test/test?__debugger__=yes&cmd=resource&f=console.png HTTP/1.1" 200 -
2021-06-13 20:21:14,904 [werkzeug] [6900:Thread-8] _internal.py:_internal:_log in 225] [INFO]: 127.0.0.1 - - [13/Jun/2021 20:21:14] "GET /element/ui_test/test?__debugger__=yes&cmd=resource&f=ubuntu.ttf HTTP/1.1" 200 -
2021-06-13 20:21:15,395 [werkzeug] [7252:Thread-9] _internal.py:_internal:_log in 225] [INFO]: 127.0.0.1 - - [13/Jun/2021 20:21:15] "GET /element/ui_test/test?__debugger__=yes&cmd=resource&f=console.png HTTP/1.1" 200 -
2021-06-13 20:49:12,659 [werkzeug] [6900:Thread-3] _internal.py:_internal:_log in 225] [INFO]: 127.0.0.1 - - [13/Jun/2021 20:49:12] "[35m[1mGET / HTTP/1.1[0m" 500 -
2021-06-13 20:49:12,659 [werkzeug] [6900:Thread-3] _internal.py:_internal:_log in 225] [INFO]: 127.0.0.1 - - [13/Jun/2021 20:49:12] "[35m[1mGET / HTTP/1.1[0m" 500 -
2021-06-13 20:49:12,676 [werkzeug] [15484:Thread-4] _internal.py:_internal:_log in 225] [INFO]: 127.0.0.1 - - [13/Jun/2021 20:49:12] "GET /?__debugger__=yes&cmd=resource&f=style.css HTTP/1.1" 200 -
2021-06-13 20:49:12,676 [werkzeug] [15484:Thread-4] _internal.py:_internal:_log in 225] [INFO]: 127.0.0.1 - - [13/Jun/2021 20:49:12] "GET /?__debugger__=yes&cmd=resource&f=style.css HTTP/1.1" 200 -
2021-06-13 20:49:12,677 [werkzeug] [14900:Thread-5] _internal.py:_internal:_log in 225] [INFO]: 127.0.0.1 - - [13/Jun/2021 20:49:12] "GET /?__debugger__=yes&cmd=resource&f=debugger.js HTTP/1.1" 200 -
2021-06-13 20:49:12,677 [werkzeug] [14900:Thread-5] _internal.py:_internal:_log in 225] [INFO]: 127.0.0.1 - - [13/Jun/2021 20:49:12] "GET /?__debugger__=yes&cmd=resource&f=debugger.js HTTP/1.1" 200 -
2021-06-13 20:49:12,959 [werkzeug] [8464:Thread-6] _internal.py:_internal:_log in 225] [INFO]: 127.0.0.1 - - [13/Jun/2021 20:49:12] "GET /?__debugger__=yes&cmd=resource&f=console.png HTTP/1.1" 200 -
2021-06-13 20:49:12,959 [werkzeug] [8464:Thread-6] _internal.py:_internal:_log in 225] [INFO]: 127.0.0.1 - - [13/Jun/2021 20:49:12] "GET /?__debugger__=yes&cmd=resource&f=console.png HTTP/1.1" 200 -
2021-06-13 20:49:12,982 [werkzeug] [3132:Thread-7] _internal.py:_internal:_log in 225] [INFO]: 127.0.0.1 - - [13/Jun/2021 20:49:12] "GET /?__debugger__=yes&cmd=resource&f=ubuntu.ttf HTTP/1.1" 200 -
2021-06-13 20:49:12,982 [werkzeug] [3132:Thread-7] _internal.py:_internal:_log in 225] [INFO]: 127.0.0.1 - - [13/Jun/2021 20:49:12] "GET /?__debugger__=yes&cmd=resource&f=ubuntu.ttf HTTP/1.1" 200 -
2021-06-13 20:49:13,416 [werkzeug] [6656:Thread-8] _internal.py:_internal:_log in 225] [INFO]: 127.0.0.1 - - [13/Jun/2021 20:49:13] "GET /?__debugger__=yes&cmd=resource&f=console.png HTTP/1.1" 200 -
2021-06-13 20:49:13,416 [werkzeug] [6656:Thread-8] _internal.py:_internal:_log in 225] [INFO]: 127.0.0.1 - - [13/Jun/2021 20:49:13] "GET /?__debugger__=yes&cmd=resource&f=console.png HTTP/1.1" 200 -
2021-06-13 20:49:18,022 [werkzeug] [6696:Thread-9] _internal.py:_internal:_log in 225] [INFO]: 127.0.0.1 - - [13/Jun/2021 20:49:18] "[35m[1mGET /ui_test/test HTTP/1.1[0m" 500 -
2021-06-13 20:49:18,022 [werkzeug] [6696:Thread-9] _internal.py:_internal:_log in 225] [INFO]: 127.0.0.1 - - [13/Jun/2021 20:49:18] "[35m[1mGET /ui_test/test HTTP/1.1[0m" 500 -
2021-06-13 20:49:18,050 [werkzeug] [12844:Thread-10] _internal.py:_internal:_log in 225] [INFO]: 127.0.0.1 - - [13/Jun/2021 20:49:18] "GET /ui_test/test?__debugger__=yes&cmd=resource&f=style.css HTTP/1.1" 200 -
2021-06-13 20:49:18,050 [werkzeug] [12844:Thread-10] _internal.py:_internal:_log in 225] [INFO]: 127.0.0.1 - - [13/Jun/2021 20:49:18] "GET /ui_test/test?__debugger__=yes&cmd=resource&f=style.css HTTP/1.1" 200 -
2021-06-13 20:49:18,051 [werkzeug] [2368:Thread-11] _internal.py:_internal:_log in 225] [INFO]: 127.0.0.1 - - [13/Jun/2021 20:49:18] "GET /ui_test/test?__debugger__=yes&cmd=resource&f=debugger.js HTTP/1.1" 200 -
2021-06-13 20:49:18,051 [werkzeug] [2368:Thread-11] _internal.py:_internal:_log in 225] [INFO]: 127.0.0.1 - - [13/Jun/2021 20:49:18] "GET /ui_test/test?__debugger__=yes&cmd=resource&f=debugger.js HTTP/1.1" 200 -
2021-06-13 20:49:18,176 [werkzeug] [4328:Thread-12] _internal.py:_internal:_log in 225] [INFO]: 127.0.0.1 - - [13/Jun/2021 20:49:18] "GET /ui_test/test?__debugger__=yes&cmd=resource&f=console.png HTTP/1.1" 200 -
2021-06-13 20:49:18,176 [werkzeug] [4328:Thread-12] _internal.py:_internal:_log in 225] [INFO]: 127.0.0.1 - - [13/Jun/2021 20:49:18] "GET /ui_test/test?__debugger__=yes&cmd=resource&f=console.png HTTP/1.1" 200 -
2021-06-13 20:49:18,203 [werkzeug] [12884:Thread-13] _internal.py:_internal:_log in 225] [INFO]: 127.0.0.1 - - [13/Jun/2021 20:49:18] "GET /ui_test/test?__debugger__=yes&cmd=resource&f=ubuntu.ttf HTTP/1.1" 200 -
2021-06-13 20:49:18,203 [werkzeug] [12884:Thread-13] _internal.py:_internal:_log in 225] [INFO]: 127.0.0.1 - - [13/Jun/2021 20:49:18] "GET /ui_test/test?__debugger__=yes&cmd=resource&f=ubuntu.ttf HTTP/1.1" 200 -
2021-06-13 20:49:18,277 [werkzeug] [7684:Thread-14] _internal.py:_internal:_log in 225] [INFO]: 127.0.0.1 - - [13/Jun/2021 20:49:18] "GET /ui_test/test?__debugger__=yes&cmd=resource&f=console.png HTTP/1.1" 200 -
2021-06-13 20:49:18,277 [werkzeug] [7684:Thread-14] _internal.py:_internal:_log in 225] [INFO]: 127.0.0.1 - - [13/Jun/2021 20:49:18] "GET /ui_test/test?__debugger__=yes&cmd=resource&f=console.png HTTP/1.1" 200 -
