2021-07-07 17:58:31,939 [werkzeug] [28712:MainThread] _internal.py:_internal:_log in 113] [INFO]:  * Running on http://127.0.0.1:5000/ (Press CTRL+C to quit)
2021-07-07 18:00:38,690 [werkzeug] [4056:MainThread] _internal.py:_internal:_log in 113] [INFO]:  * Running on http://127.0.0.1:5000/ (Press CTRL+C to quit)
2021-07-07 18:00:42,594 [werkzeug] [27408:Thread-1] _internal.py:_internal:_log in 113] [INFO]: 127.0.0.1 - - [07/Jul/2021 18:00:42] "[33mGET / HTTP/1.1[0m" 404 -
2021-07-07 18:00:42,755 [werkzeug] [2412:Thread-2] _internal.py:_internal:_log in 113] [INFO]: 127.0.0.1 - - [07/Jul/2021 18:00:42] "[33mGET /favicon.ico HTTP/1.1[0m" 404 -
2021-07-07 18:02:43,754 [werkzeug] [30196:Thread-3] _internal.py:_internal:_log in 113] [INFO]: 127.0.0.1 - - [07/Jul/2021 18:02:43] "[31m[1mPOST /element/henkins/check HTTP/1.1[0m" 405 -
2021-07-07 18:03:00,737 [werkzeug] [30688:MainThread] _internal.py:_internal:_log in 113] [INFO]:  * Running on http://127.0.0.1:5000/ (Press CTRL+C to quit)
2021-07-07 18:03:33,448 [werkzeug] [28832:MainThread] _internal.py:_internal:_log in 113] [INFO]:  * Running on http://127.0.0.1:5000/ (Press CTRL+C to quit)
2021-07-07 18:05:01,453 [werkzeug] [11912:MainThread] _internal.py:_internal:_log in 113] [INFO]:  * Running on http://127.0.0.1:5000/ (Press CTRL+C to quit)
2021-07-07 18:05:56,114 [werkzeug] [23896:MainThread] _internal.py:_internal:_log in 113] [INFO]:  * Running on http://127.0.0.1:5000/ (Press CTRL+C to quit)
2021-07-07 18:08:46,792 [erybjp] [29260:Thread-1] app.py:app:log_exception in 1891] [ERROR]: Exception on /element/henkins/check [GET]
Traceback (most recent call last):
  File "D:\AutoTest\erybjp\venv\lib\site-packages\flask\app.py", line 2447, in wsgi_app
    response = self.full_dispatch_request()
  File "D:\AutoTest\erybjp\venv\lib\site-packages\flask\app.py", line 1952, in full_dispatch_request
    rv = self.handle_user_exception(e)
  File "D:\AutoTest\erybjp\venv\lib\site-packages\flask_restful\__init__.py", line 271, in error_router
    return original_handler(e)
  File "D:\AutoTest\erybjp\venv\lib\site-packages\flask_cors\extension.py", line 165, in wrapped_function
    return cors_after_request(app.make_response(f(*args, **kwargs)))
  File "D:\AutoTest\erybjp\venv\lib\site-packages\flask\app.py", line 1821, in handle_user_exception
    reraise(exc_type, exc_value, tb)
  File "D:\AutoTest\erybjp\venv\lib\site-packages\flask\_compat.py", line 39, in reraise
    raise value
  File "D:\AutoTest\erybjp\venv\lib\site-packages\flask\app.py", line 1950, in full_dispatch_request
    rv = self.dispatch_request()
  File "D:\AutoTest\erybjp\venv\lib\site-packages\flask\app.py", line 1936, in dispatch_request
    return self.view_functions[rule.endpoint](**req.view_args)
  File "D:\AutoTest\erybjp\uiplatform\router\runtestcase.py", line 87, in jenkins_check
    jen.aliding_jenkins(arg, num)
  File "D:\AutoTest\erybjp\uiplatform\utils\business\cycle_check\test_jenkins_stage_production.py", line 91, in aliding_jenkins
    DingtalkRobot().send_markdown("jenkinsÊúçÂä°Âç†Áî®Ê£ÄÊµãÁªìÊûúÈÄöÁü•", text, [])
  File "D:\AutoTest\erybjp\uiplatform\services\ali_dingtalk.py", line 87, in send_markdown
    return self.__post(data)
  File "D:\AutoTest\erybjp\uiplatform\services\ali_dingtalk.py", line 104, in __post
    response = requests.post(self.__spliceUrl(), headers=self.headers, data=post_data)
  File "D:\AutoTest\erybjp\venv\lib\site-packages\requests\api.py", line 119, in post
    return request('post', url, data=data, json=json, **kwargs)
  File "D:\AutoTest\erybjp\venv\lib\site-packages\requests\api.py", line 61, in request
    return session.request(method=method, url=url, **kwargs)
  File "D:\AutoTest\erybjp\venv\lib\site-packages\requests\sessions.py", line 542, in request
    resp = self.send(prep, **send_kwargs)
  File "D:\AutoTest\erybjp\venv\lib\site-packages\requests\sessions.py", line 655, in send
    r = adapter.send(request, **kwargs)
  File "D:\AutoTest\erybjp\venv\lib\site-packages\requests\adapters.py", line 439, in send
    resp = conn.urlopen(
  File "D:\AutoTest\erybjp\venv\lib\site-packages\urllib3\connectionpool.py", line 696, in urlopen
    self._prepare_proxy(conn)
  File "D:\AutoTest\erybjp\venv\lib\site-packages\urllib3\connectionpool.py", line 964, in _prepare_proxy
    conn.connect()
  File "D:\AutoTest\erybjp\venv\lib\site-packages\urllib3\connection.py", line 359, in connect
    conn = self._connect_tls_proxy(hostname, conn)
  File "D:\AutoTest\erybjp\venv\lib\site-packages\urllib3\connection.py", line 500, in _connect_tls_proxy
    return ssl_wrap_socket(
  File "D:\AutoTest\erybjp\venv\lib\site-packages\urllib3\util\ssl_.py", line 432, in ssl_wrap_socket
    ssl_sock = _ssl_wrap_socket_impl(sock, context, tls_in_tls)
  File "D:\AutoTest\erybjp\venv\lib\site-packages\urllib3\util\ssl_.py", line 474, in _ssl_wrap_socket_impl
    return ssl_context.wrap_socket(sock)
  File "C:\Users\yuanbaojun\AppData\Local\Programs\Python\Python38\lib\ssl.py", line 500, in wrap_socket
    return self.sslsocket_class._create(
  File "C:\Users\yuanbaojun\AppData\Local\Programs\Python\Python38\lib\ssl.py", line 997, in _create
    raise ValueError("check_hostname requires server_hostname")
ValueError: check_hostname requires server_hostname
2021-07-07 18:08:46,810 [werkzeug] [29260:Thread-1] _internal.py:_internal:_log in 113] [INFO]: 127.0.0.1 - - [07/Jul/2021 18:08:46] "[35m[1mGET /element/henkins/check?servername_list=["lbk_activity"] HTTP/1.1[0m" 500 -
2021-07-07 19:16:07,671 [werkzeug] [2412:MainThread] _internal.py:_internal:_log in 113] [INFO]:  * Running on http://127.0.0.1:5000/ (Press CTRL+C to quit)
2021-07-07 19:17:31,799 [werkzeug] [30284:MainThread] _internal.py:_internal:_log in 113] [INFO]:  * Running on http://127.0.0.1:5000/ (Press CTRL+C to quit)
2021-07-07 19:19:25,812 [werkzeug] [6336:MainThread] _internal.py:_internal:_log in 113] [INFO]:  * Running on http://127.0.0.1:5000/ (Press CTRL+C to quit)
2021-07-07 19:19:30,416 [werkzeug] [13580:Thread-6] _internal.py:_internal:_log in 113] [INFO]: 127.0.0.1 - - [07/Jul/2021 19:19:30] "[31m[1mGET /element/henkins/check?servername_list=["lbk_activity","lbk_web_common"] HTTP/1.1[0m" 405 -
2021-07-07 19:19:41,884 [erybjp] [29888:Thread-7] app.py:app:log_exception in 1891] [ERROR]: Exception on /element/henkins/check [POST]
Traceback (most recent call last):
  File "D:\AutoTest\erybjp\venv\lib\site-packages\werkzeug\wrappers\json.py", line 119, in get_json
    rv = self.json_module.loads(data)
  File "D:\AutoTest\erybjp\venv\lib\site-packages\flask\json\__init__.py", line 253, in loads
    return _json.loads(s, **kwargs)
  File "C:\Users\yuanbaojun\AppData\Local\Programs\Python\Python38\lib\json\__init__.py", line 370, in loads
    return cls(**kw).decode(s)
  File "C:\Users\yuanbaojun\AppData\Local\Programs\Python\Python38\lib\json\decoder.py", line 337, in decode
    obj, end = self.raw_decode(s, idx=_w(s, 0).end())
  File "C:\Users\yuanbaojun\AppData\Local\Programs\Python\Python38\lib\json\decoder.py", line 355, in raw_decode
    raise JSONDecodeError("Expecting value", s, err.value) from None
json.decoder.JSONDecodeError: Expecting value: line 1 column 1 (char 0)

During handling of the above exception, another exception occurred:

Traceback (most recent call last):
  File "D:\AutoTest\erybjp\venv\lib\site-packages\flask\app.py", line 1950, in full_dispatch_request
    rv = self.dispatch_request()
  File "D:\AutoTest\erybjp\venv\lib\site-packages\flask\app.py", line 1936, in dispatch_request
    return self.view_functions[rule.endpoint](**req.view_args)
  File "D:\AutoTest\erybjp\uiplatform\router\runtestcase.py", line 84, in jenkins_check
    arg = request.get_json()
  File "D:\AutoTest\erybjp\venv\lib\site-packages\werkzeug\wrappers\json.py", line 128, in get_json
    rv = self.on_json_loading_failed(e)
  File "D:\AutoTest\erybjp\venv\lib\site-packages\flask\wrappers.py", line 27, in on_json_loading_failed
    raise BadRequest()
werkzeug.exceptions.BadRequest: 400 Bad Request: The browser (or proxy) sent a request that this server could not understand.

During handling of the above exception, another exception occurred:

Traceback (most recent call last):
  File "D:\AutoTest\erybjp\venv\lib\site-packages\flask\app.py", line 2447, in wsgi_app
    response = self.full_dispatch_request()
  File "D:\AutoTest\erybjp\venv\lib\site-packages\flask\app.py", line 1952, in full_dispatch_request
    rv = self.handle_user_exception(e)
  File "D:\AutoTest\erybjp\venv\lib\site-packages\flask_restful\__init__.py", line 271, in error_router
    return original_handler(e)
  File "D:\AutoTest\erybjp\venv\lib\site-packages\flask_cors\extension.py", line 165, in wrapped_function
    return cors_after_request(app.make_response(f(*args, **kwargs)))
  File "D:\AutoTest\erybjp\venv\lib\site-packages\flask\app.py", line 2097, in make_response
    raise TypeError(
TypeError: The view function did not return a valid response. The function either returned None or ended without a return statement.
2021-07-07 19:19:41,900 [werkzeug] [29888:Thread-7] _internal.py:_internal:_log in 113] [INFO]: 127.0.0.1 - - [07/Jul/2021 19:19:41] "[35m[1mPOST /element/henkins/check HTTP/1.1[0m" 500 -
2021-07-07 19:20:09,365 [werkzeug] [27520:MainThread] _internal.py:_internal:_log in 113] [INFO]:  * Running on http://127.0.0.1:5000/ (Press CTRL+C to quit)
2021-07-07 19:23:43,104 [werkzeug] [21596:MainThread] _internal.py:_internal:_log in 113] [INFO]:  * Running on http://127.0.0.1:5000/ (Press CTRL+C to quit)
2021-07-07 19:24:43,434 [erybjp] [23660:Thread-1] app.py:app:log_exception in 1891] [ERROR]: Exception on /element/henkins/check [POST]
Traceback (most recent call last):
  File "D:\AutoTest\erybjp\venv\lib\site-packages\flask\app.py", line 2447, in wsgi_app
    response = self.full_dispatch_request()
  File "D:\AutoTest\erybjp\venv\lib\site-packages\flask\app.py", line 1952, in full_dispatch_request
    rv = self.handle_user_exception(e)
  File "D:\AutoTest\erybjp\venv\lib\site-packages\flask_restful\__init__.py", line 271, in error_router
    return original_handler(e)
  File "D:\AutoTest\erybjp\venv\lib\site-packages\flask_cors\extension.py", line 165, in wrapped_function
    return cors_after_request(app.make_response(f(*args, **kwargs)))
  File "D:\AutoTest\erybjp\venv\lib\site-packages\flask\app.py", line 1821, in handle_user_exception
    reraise(exc_type, exc_value, tb)
  File "D:\AutoTest\erybjp\venv\lib\site-packages\flask\_compat.py", line 39, in reraise
    raise value
  File "D:\AutoTest\erybjp\venv\lib\site-packages\flask\app.py", line 1950, in full_dispatch_request
    rv = self.dispatch_request()
  File "D:\AutoTest\erybjp\venv\lib\site-packages\flask\app.py", line 1936, in dispatch_request
    return self.view_functions[rule.endpoint](**req.view_args)
  File "D:\AutoTest\erybjp\uiplatform\router\runtestcase.py", line 88, in jenkins_check
    jen.aliding_jenkins(arg.get("servername_list"), num)
  File "D:\AutoTest\erybjp\uiplatform\utils\business\cycle_check\test_jenkins_stage_production.py", line 89, in aliding_jenkins
    data = jen.test_staging_production_compare(servername_list)
  File "D:\AutoTest\erybjp\uiplatform\utils\business\cycle_check\test_jenkins_stage_production.py", line 76, in test_staging_production_compare
    production_num = self.test_production_server(servername)
  File "D:\AutoTest\erybjp\uiplatform\utils\business\cycle_check\test_jenkins_stage_production.py", line 64, in test_production_server
    self.page.product_para_element.click()
  File "D:\AutoTest\erybjp\uiplatform\utils\common\BasePage.py", line 261, in click
    elem = self.__get_element(self.k, self.v)
  File "D:\AutoTest\erybjp\uiplatform\utils\common\BasePage.py", line 185, in __get_element
    self.__find_element((By.CSS_SELECTOR, value))
  File "D:\AutoTest\erybjp\uiplatform\utils\common\BasePage.py", line 155, in __find_element
    raise NoSuchElementException(error_msg)
selenium.common.exceptions.NoSuchElementException: Message: ‚ùå Find 0 elements through: css selector=a[title='Parameters']

2021-07-07 19:24:43,454 [werkzeug] [23660:Thread-1] _internal.py:_internal:_log in 113] [INFO]: 127.0.0.1 - - [07/Jul/2021 19:24:43] "[35m[1mPOST /element/henkins/check HTTP/1.1[0m" 500 -
2021-07-07 19:43:57,329 [werkzeug] [29016:MainThread] _internal.py:_internal:_log in 113] [INFO]:  * Running on http://127.0.0.1:5000/ (Press CTRL+C to quit)
2021-07-07 19:44:40,566 [erybjp] [31496:Thread-1] app.py:app:log_exception in 1891] [ERROR]: Exception on /element/henkins/check [POST]
Traceback (most recent call last):
  File "D:\AutoTest\erybjp\venv\lib\site-packages\flask\app.py", line 2447, in wsgi_app
    response = self.full_dispatch_request()
  File "D:\AutoTest\erybjp\venv\lib\site-packages\flask\app.py", line 1952, in full_dispatch_request
    rv = self.handle_user_exception(e)
  File "D:\AutoTest\erybjp\venv\lib\site-packages\flask_restful\__init__.py", line 271, in error_router
    return original_handler(e)
  File "D:\AutoTest\erybjp\venv\lib\site-packages\flask_cors\extension.py", line 165, in wrapped_function
    return cors_after_request(app.make_response(f(*args, **kwargs)))
  File "D:\AutoTest\erybjp\venv\lib\site-packages\flask\app.py", line 1821, in handle_user_exception
    reraise(exc_type, exc_value, tb)
  File "D:\AutoTest\erybjp\venv\lib\site-packages\flask\_compat.py", line 39, in reraise
    raise value
  File "D:\AutoTest\erybjp\venv\lib\site-packages\flask\app.py", line 1950, in full_dispatch_request
    rv = self.dispatch_request()
  File "D:\AutoTest\erybjp\venv\lib\site-packages\flask\app.py", line 1936, in dispatch_request
    return self.view_functions[rule.endpoint](**req.view_args)
  File "D:\AutoTest\erybjp\uiplatform\router\runtestcase.py", line 88, in jenkins_check
    jen.aliding_jenkins(arg.get("servername_list"), num)
  File "D:\AutoTest\erybjp\uiplatform\utils\business\cycle_check\test_jenkins_stage_production.py", line 92, in aliding_jenkins
    DingtalkRobot().send_markdown("jenkinsÊúçÂä°Âç†Áî®Ê£ÄÊµãÁªìÊûúÈÄöÁü•", text, [])
  File "D:\AutoTest\erybjp\uiplatform\services\ali_dingtalk.py", line 87, in send_markdown
    return self.__post(data)
  File "D:\AutoTest\erybjp\uiplatform\services\ali_dingtalk.py", line 104, in __post
    response = requests.post(self.__spliceUrl(), headers=self.headers, data=post_data)
  File "D:\AutoTest\erybjp\venv\lib\site-packages\requests\api.py", line 119, in post
    return request('post', url, data=data, json=json, **kwargs)
  File "D:\AutoTest\erybjp\venv\lib\site-packages\requests\api.py", line 61, in request
    return session.request(method=method, url=url, **kwargs)
  File "D:\AutoTest\erybjp\venv\lib\site-packages\requests\sessions.py", line 542, in request
    resp = self.send(prep, **send_kwargs)
  File "D:\AutoTest\erybjp\venv\lib\site-packages\requests\sessions.py", line 655, in send
    r = adapter.send(request, **kwargs)
  File "D:\AutoTest\erybjp\venv\lib\site-packages\requests\adapters.py", line 439, in send
    resp = conn.urlopen(
  File "D:\AutoTest\erybjp\venv\lib\site-packages\urllib3\connectionpool.py", line 696, in urlopen
    self._prepare_proxy(conn)
  File "D:\AutoTest\erybjp\venv\lib\site-packages\urllib3\connectionpool.py", line 964, in _prepare_proxy
    conn.connect()
  File "D:\AutoTest\erybjp\venv\lib\site-packages\urllib3\connection.py", line 359, in connect
    conn = self._connect_tls_proxy(hostname, conn)
  File "D:\AutoTest\erybjp\venv\lib\site-packages\urllib3\connection.py", line 500, in _connect_tls_proxy
    return ssl_wrap_socket(
  File "D:\AutoTest\erybjp\venv\lib\site-packages\urllib3\util\ssl_.py", line 432, in ssl_wrap_socket
    ssl_sock = _ssl_wrap_socket_impl(sock, context, tls_in_tls)
  File "D:\AutoTest\erybjp\venv\lib\site-packages\urllib3\util\ssl_.py", line 474, in _ssl_wrap_socket_impl
    return ssl_context.wrap_socket(sock)
  File "C:\Users\yuanbaojun\AppData\Local\Programs\Python\Python38\lib\ssl.py", line 500, in wrap_socket
    return self.sslsocket_class._create(
  File "C:\Users\yuanbaojun\AppData\Local\Programs\Python\Python38\lib\ssl.py", line 997, in _create
    raise ValueError("check_hostname requires server_hostname")
ValueError: check_hostname requires server_hostname
2021-07-07 19:44:40,577 [werkzeug] [31496:Thread-1] _internal.py:_internal:_log in 113] [INFO]: 127.0.0.1 - - [07/Jul/2021 19:44:40] "[35m[1mPOST /element/henkins/check HTTP/1.1[0m" 500 -
2021-07-07 19:47:54,903 [werkzeug] [27436:Thread-14] _internal.py:_internal:_log in 113] [INFO]: 127.0.0.1 - - [07/Jul/2021 19:47:54] "[37mPOST /element/henkins/check HTTP/1.1[0m" 200 -
2021-07-07 20:21:45,959 [werkzeug] [32708:MainThread] _internal.py:_internal:_log in 113] [INFO]:  * Running on http://127.0.0.1:5000/ (Press CTRL+C to quit)
2021-07-07 20:22:03,808 [werkzeug] [29188:Thread-1] _internal.py:_internal:_log in 113] [INFO]: 127.0.0.1 - - [07/Jul/2021 20:22:03] "[37mPOST /element/henkins/check HTTP/1.1[0m" 200 -
2021-07-07 20:22:39,056 [werkzeug] [27520:Thread-3] _internal.py:_internal:_log in 113] [INFO]: 127.0.0.1 - - [07/Jul/2021 20:22:39] "[37mPOST /element/henkins/check HTTP/1.1[0m" 200 -
2021-07-07 20:25:31,001 [werkzeug] [32604:Thread-5] _internal.py:_internal:_log in 113] [INFO]: 127.0.0.1 - - [07/Jul/2021 20:25:31] "[37mPOST /element/henkins/check HTTP/1.1[0m" 200 -
2021-07-07 20:27:52,658 [werkzeug] [20320:MainThread] _internal.py:_internal:_log in 113] [INFO]:  * Running on http://127.0.0.1:5000/ (Press CTRL+C to quit)
2021-07-07 20:27:56,009 [werkzeug] [20288:Thread-1] _internal.py:_internal:_log in 113] [INFO]: 127.0.0.1 - - [07/Jul/2021 20:27:56] "[37mPOST /element/henkins/check HTTP/1.1[0m" 200 -
2021-07-09 12:01:53,258 [werkzeug] [3208:MainThread] _internal.py:_internal:_log in 113] [INFO]:  * Running on http://127.0.0.1:6851/ (Press CTRL+C to quit)
2021-07-09 13:41:57,236 [werkzeug] [10956:Thread-1] _internal.py:_internal:_log in 113] [INFO]: 127.0.0.1 - - [09/Jul/2021 13:41:57] "[33mPOST /jenkins/check HTTP/1.1[0m" 404 -
2021-07-09 13:42:41,102 [werkzeug] [5980:Thread-2] _internal.py:_internal:_log in 113] [INFO]: 127.0.0.1 - - [09/Jul/2021 13:42:41] "[33mPOST /jenkins/check HTTP/1.1[0m" 404 -
2021-07-09 13:42:42,969 [werkzeug] [13012:Thread-3] _internal.py:_internal:_log in 113] [INFO]: 127.0.0.1 - - [09/Jul/2021 13:42:42] "[33mPOST /jenkins/check HTTP/1.1[0m" 404 -
2021-07-09 13:43:30,920 [werkzeug] [8336:MainThread] _internal.py:_internal:_log in 113] [INFO]:  * Running on http://127.0.0.1:6851/ (Press CTRL+C to quit)
2021-07-09 13:43:46,136 [werkzeug] [15152:Thread-1] _internal.py:_internal:_log in 113] [INFO]: 127.0.0.1 - - [09/Jul/2021 13:43:46] "[33mPOST /jenkins/check HTTP/1.1[0m" 404 -
2021-07-09 13:44:25,651 [erybjp] [4888:Thread-2] app.py:app:log_exception in 1891] [ERROR]: Exception on /element/jenkins/check [POST]
Traceback (most recent call last):
  File "C:\Users\lx\AppData\Local\Programs\Python\Python38\lib\site-packages\werkzeug\wrappers\json.py", line 119, in get_json
    rv = self.json_module.loads(data)
  File "C:\Users\lx\AppData\Local\Programs\Python\Python38\lib\site-packages\flask\json\__init__.py", line 253, in loads
    return _json.loads(s, **kwargs)
  File "C:\Users\lx\AppData\Local\Programs\Python\Python38\lib\json\__init__.py", line 370, in loads
    return cls(**kw).decode(s)
  File "C:\Users\lx\AppData\Local\Programs\Python\Python38\lib\json\decoder.py", line 337, in decode
    obj, end = self.raw_decode(s, idx=_w(s, 0).end())
  File "C:\Users\lx\AppData\Local\Programs\Python\Python38\lib\json\decoder.py", line 355, in raw_decode
    raise JSONDecodeError("Expecting value", s, err.value) from None
json.decoder.JSONDecodeError: Expecting value: line 1 column 1 (char 0)

During handling of the above exception, another exception occurred:

Traceback (most recent call last):
  File "C:\Users\lx\AppData\Local\Programs\Python\Python38\lib\site-packages\flask\app.py", line 1950, in full_dispatch_request
    rv = self.dispatch_request()
  File "C:\Users\lx\AppData\Local\Programs\Python\Python38\lib\site-packages\flask\app.py", line 1936, in dispatch_request
    return self.view_functions[rule.endpoint](**req.view_args)
  File "D:\ÊµãËØïÂ≠¶‰π†ÊñáÊ°£\erybjp-master\uiplatform\router\runtestcase.py", line 83, in jenkins_check
    arg = request.get_json()
  File "C:\Users\lx\AppData\Local\Programs\Python\Python38\lib\site-packages\werkzeug\wrappers\json.py", line 128, in get_json
    rv = self.on_json_loading_failed(e)
  File "C:\Users\lx\AppData\Local\Programs\Python\Python38\lib\site-packages\flask\wrappers.py", line 27, in on_json_loading_failed
    raise BadRequest()
werkzeug.exceptions.BadRequest: 400 Bad Request: The browser (or proxy) sent a request that this server could not understand.

During handling of the above exception, another exception occurred:

Traceback (most recent call last):
  File "C:\Users\lx\AppData\Local\Programs\Python\Python38\lib\site-packages\flask\app.py", line 2447, in wsgi_app
    response = self.full_dispatch_request()
  File "C:\Users\lx\AppData\Local\Programs\Python\Python38\lib\site-packages\flask\app.py", line 1952, in full_dispatch_request
    rv = self.handle_user_exception(e)
  File "C:\Users\lx\AppData\Local\Programs\Python\Python38\lib\site-packages\flask_restful\__init__.py", line 271, in error_router
    return original_handler(e)
  File "C:\Users\lx\AppData\Local\Programs\Python\Python38\lib\site-packages\flask_cors\extension.py", line 165, in wrapped_function
    return cors_after_request(app.make_response(f(*args, **kwargs)))
  File "C:\Users\lx\AppData\Local\Programs\Python\Python38\lib\site-packages\flask\app.py", line 2097, in make_response
    raise TypeError(
TypeError: The view function did not return a valid response. The function either returned None or ended without a return statement.
2021-07-09 13:44:25,735 [werkzeug] [4888:Thread-2] _internal.py:_internal:_log in 113] [INFO]: 127.0.0.1 - - [09/Jul/2021 13:44:25] "[35m[1mPOST /element/jenkins/check HTTP/1.1[0m" 500 -
2021-07-09 13:45:13,930 [erybjp] [2020:Thread-3] app.py:app:log_exception in 1891] [ERROR]: Exception on /element/jenkins/check [POST]
Traceback (most recent call last):
  File "C:\Users\lx\AppData\Local\Programs\Python\Python38\lib\site-packages\werkzeug\wrappers\json.py", line 119, in get_json
    rv = self.json_module.loads(data)
  File "C:\Users\lx\AppData\Local\Programs\Python\Python38\lib\site-packages\flask\json\__init__.py", line 253, in loads
    return _json.loads(s, **kwargs)
  File "C:\Users\lx\AppData\Local\Programs\Python\Python38\lib\json\__init__.py", line 370, in loads
    return cls(**kw).decode(s)
  File "C:\Users\lx\AppData\Local\Programs\Python\Python38\lib\json\decoder.py", line 337, in decode
    obj, end = self.raw_decode(s, idx=_w(s, 0).end())
  File "C:\Users\lx\AppData\Local\Programs\Python\Python38\lib\json\decoder.py", line 355, in raw_decode
    raise JSONDecodeError("Expecting value", s, err.value) from None
json.decoder.JSONDecodeError: Expecting value: line 1 column 1 (char 0)

During handling of the above exception, another exception occurred:

Traceback (most recent call last):
  File "C:\Users\lx\AppData\Local\Programs\Python\Python38\lib\site-packages\flask\app.py", line 1950, in full_dispatch_request
    rv = self.dispatch_request()
  File "C:\Users\lx\AppData\Local\Programs\Python\Python38\lib\site-packages\flask\app.py", line 1936, in dispatch_request
    return self.view_functions[rule.endpoint](**req.view_args)
  File "D:\ÊµãËØïÂ≠¶‰π†ÊñáÊ°£\erybjp-master\uiplatform\router\runtestcase.py", line 83, in jenkins_check
    arg = request.get_json()
  File "C:\Users\lx\AppData\Local\Programs\Python\Python38\lib\site-packages\werkzeug\wrappers\json.py", line 128, in get_json
    rv = self.on_json_loading_failed(e)
  File "C:\Users\lx\AppData\Local\Programs\Python\Python38\lib\site-packages\flask\wrappers.py", line 27, in on_json_loading_failed
    raise BadRequest()
werkzeug.exceptions.BadRequest: 400 Bad Request: The browser (or proxy) sent a request that this server could not understand.

During handling of the above exception, another exception occurred:

Traceback (most recent call last):
  File "C:\Users\lx\AppData\Local\Programs\Python\Python38\lib\site-packages\flask\app.py", line 2447, in wsgi_app
    response = self.full_dispatch_request()
  File "C:\Users\lx\AppData\Local\Programs\Python\Python38\lib\site-packages\flask\app.py", line 1952, in full_dispatch_request
    rv = self.handle_user_exception(e)
  File "C:\Users\lx\AppData\Local\Programs\Python\Python38\lib\site-packages\flask_restful\__init__.py", line 271, in error_router
    return original_handler(e)
  File "C:\Users\lx\AppData\Local\Programs\Python\Python38\lib\site-packages\flask_cors\extension.py", line 165, in wrapped_function
    return cors_after_request(app.make_response(f(*args, **kwargs)))
  File "C:\Users\lx\AppData\Local\Programs\Python\Python38\lib\site-packages\flask\app.py", line 2097, in make_response
    raise TypeError(
TypeError: The view function did not return a valid response. The function either returned None or ended without a return statement.
2021-07-09 13:45:13,931 [werkzeug] [2020:Thread-3] _internal.py:_internal:_log in 113] [INFO]: 127.0.0.1 - - [09/Jul/2021 13:45:13] "[35m[1mPOST /element/jenkins/check HTTP/1.1[0m" 500 -
2021-07-09 13:45:45,457 [werkzeug] [3220:MainThread] _internal.py:_internal:_log in 113] [INFO]:  * Running on http://127.0.0.1:6851/ (Press CTRL+C to quit)
2021-07-09 13:45:49,755 [erybjp] [10108:Thread-1] app.py:app:log_exception in 1891] [ERROR]: Exception on /element/jenkins/check [POST]
Traceback (most recent call last):
  File "C:\Users\lx\AppData\Local\Programs\Python\Python38\lib\site-packages\werkzeug\wrappers\json.py", line 119, in get_json
    rv = self.json_module.loads(data)
  File "C:\Users\lx\AppData\Local\Programs\Python\Python38\lib\site-packages\flask\json\__init__.py", line 253, in loads
    return _json.loads(s, **kwargs)
  File "C:\Users\lx\AppData\Local\Programs\Python\Python38\lib\json\__init__.py", line 370, in loads
    return cls(**kw).decode(s)
  File "C:\Users\lx\AppData\Local\Programs\Python\Python38\lib\json\decoder.py", line 337, in decode
    obj, end = self.raw_decode(s, idx=_w(s, 0).end())
  File "C:\Users\lx\AppData\Local\Programs\Python\Python38\lib\json\decoder.py", line 355, in raw_decode
    raise JSONDecodeError("Expecting value", s, err.value) from None
json.decoder.JSONDecodeError: Expecting value: line 1 column 1 (char 0)

During handling of the above exception, another exception occurred:

Traceback (most recent call last):
  File "C:\Users\lx\AppData\Local\Programs\Python\Python38\lib\site-packages\flask\app.py", line 1950, in full_dispatch_request
    rv = self.dispatch_request()
  File "C:\Users\lx\AppData\Local\Programs\Python\Python38\lib\site-packages\flask\app.py", line 1936, in dispatch_request
    return self.view_functions[rule.endpoint](**req.view_args)
  File "D:\ÊµãËØïÂ≠¶‰π†ÊñáÊ°£\erybjp-master\uiplatform\router\runtestcase.py", line 83, in jenkins_check
    arg = request.get_json()
  File "C:\Users\lx\AppData\Local\Programs\Python\Python38\lib\site-packages\werkzeug\wrappers\json.py", line 128, in get_json
    rv = self.on_json_loading_failed(e)
  File "C:\Users\lx\AppData\Local\Programs\Python\Python38\lib\site-packages\flask\wrappers.py", line 27, in on_json_loading_failed
    raise BadRequest()
werkzeug.exceptions.BadRequest: 400 Bad Request: The browser (or proxy) sent a request that this server could not understand.

During handling of the above exception, another exception occurred:

Traceback (most recent call last):
  File "C:\Users\lx\AppData\Local\Programs\Python\Python38\lib\site-packages\flask\app.py", line 2447, in wsgi_app
    response = self.full_dispatch_request()
  File "C:\Users\lx\AppData\Local\Programs\Python\Python38\lib\site-packages\flask\app.py", line 1952, in full_dispatch_request
    rv = self.handle_user_exception(e)
  File "C:\Users\lx\AppData\Local\Programs\Python\Python38\lib\site-packages\flask_restful\__init__.py", line 271, in error_router
    return original_handler(e)
  File "C:\Users\lx\AppData\Local\Programs\Python\Python38\lib\site-packages\flask_cors\extension.py", line 165, in wrapped_function
    return cors_after_request(app.make_response(f(*args, **kwargs)))
  File "C:\Users\lx\AppData\Local\Programs\Python\Python38\lib\site-packages\flask\app.py", line 2097, in make_response
    raise TypeError(
TypeError: The view function did not return a valid response. The function either returned None or ended without a return statement.
2021-07-09 13:45:49,773 [werkzeug] [10108:Thread-1] _internal.py:_internal:_log in 113] [INFO]: 127.0.0.1 - - [09/Jul/2021 13:45:49] "[35m[1mPOST /element/jenkins/check HTTP/1.1[0m" 500 -
2021-07-09 13:47:38,545 [erybjp] [14308:Thread-2] app.py:app:log_exception in 1891] [ERROR]: Exception on /element/jenkins/check [POST]
Traceback (most recent call last):
  File "C:\Users\lx\AppData\Local\Programs\Python\Python38\lib\site-packages\werkzeug\wrappers\json.py", line 119, in get_json
    rv = self.json_module.loads(data)
  File "C:\Users\lx\AppData\Local\Programs\Python\Python38\lib\site-packages\flask\json\__init__.py", line 253, in loads
    return _json.loads(s, **kwargs)
  File "C:\Users\lx\AppData\Local\Programs\Python\Python38\lib\json\__init__.py", line 370, in loads
    return cls(**kw).decode(s)
  File "C:\Users\lx\AppData\Local\Programs\Python\Python38\lib\json\decoder.py", line 337, in decode
    obj, end = self.raw_decode(s, idx=_w(s, 0).end())
  File "C:\Users\lx\AppData\Local\Programs\Python\Python38\lib\json\decoder.py", line 355, in raw_decode
    raise JSONDecodeError("Expecting value", s, err.value) from None
json.decoder.JSONDecodeError: Expecting value: line 1 column 1 (char 0)

During handling of the above exception, another exception occurred:

Traceback (most recent call last):
  File "C:\Users\lx\AppData\Local\Programs\Python\Python38\lib\site-packages\flask\app.py", line 1950, in full_dispatch_request
    rv = self.dispatch_request()
  File "C:\Users\lx\AppData\Local\Programs\Python\Python38\lib\site-packages\flask\app.py", line 1936, in dispatch_request
    return self.view_functions[rule.endpoint](**req.view_args)
  File "D:\ÊµãËØïÂ≠¶‰π†ÊñáÊ°£\erybjp-master\uiplatform\router\runtestcase.py", line 83, in jenkins_check
    arg = request.get_json()
  File "C:\Users\lx\AppData\Local\Programs\Python\Python38\lib\site-packages\werkzeug\wrappers\json.py", line 128, in get_json
    rv = self.on_json_loading_failed(e)
  File "C:\Users\lx\AppData\Local\Programs\Python\Python38\lib\site-packages\flask\wrappers.py", line 27, in on_json_loading_failed
    raise BadRequest()
werkzeug.exceptions.BadRequest: 400 Bad Request: The browser (or proxy) sent a request that this server could not understand.

During handling of the above exception, another exception occurred:

Traceback (most recent call last):
  File "C:\Users\lx\AppData\Local\Programs\Python\Python38\lib\site-packages\flask\app.py", line 2447, in wsgi_app
    response = self.full_dispatch_request()
  File "C:\Users\lx\AppData\Local\Programs\Python\Python38\lib\site-packages\flask\app.py", line 1952, in full_dispatch_request
    rv = self.handle_user_exception(e)
  File "C:\Users\lx\AppData\Local\Programs\Python\Python38\lib\site-packages\flask_restful\__init__.py", line 271, in error_router
    return original_handler(e)
  File "C:\Users\lx\AppData\Local\Programs\Python\Python38\lib\site-packages\flask_cors\extension.py", line 165, in wrapped_function
    return cors_after_request(app.make_response(f(*args, **kwargs)))
  File "C:\Users\lx\AppData\Local\Programs\Python\Python38\lib\site-packages\flask\app.py", line 2097, in make_response
    raise TypeError(
TypeError: The view function did not return a valid response. The function either returned None or ended without a return statement.
2021-07-09 13:47:38,559 [werkzeug] [14308:Thread-2] _internal.py:_internal:_log in 113] [INFO]: 127.0.0.1 - - [09/Jul/2021 13:47:38] "[35m[1mPOST /element/jenkins/check HTTP/1.1[0m" 500 -
2021-07-09 13:47:48,067 [werkzeug] [7476:MainThread] _internal.py:_internal:_log in 113] [INFO]:  * Running on http://127.0.0.1:6851/ (Press CTRL+C to quit)
2021-07-09 13:47:49,857 [erybjp] [13956:Thread-1] app.py:app:log_exception in 1891] [ERROR]: Exception on /element/jenkins/check [POST]
Traceback (most recent call last):
  File "C:\Users\lx\AppData\Local\Programs\Python\Python38\lib\site-packages\werkzeug\wrappers\json.py", line 119, in get_json
    rv = self.json_module.loads(data)
  File "C:\Users\lx\AppData\Local\Programs\Python\Python38\lib\site-packages\flask\json\__init__.py", line 253, in loads
    return _json.loads(s, **kwargs)
  File "C:\Users\lx\AppData\Local\Programs\Python\Python38\lib\json\__init__.py", line 370, in loads
    return cls(**kw).decode(s)
  File "C:\Users\lx\AppData\Local\Programs\Python\Python38\lib\json\decoder.py", line 337, in decode
    obj, end = self.raw_decode(s, idx=_w(s, 0).end())
  File "C:\Users\lx\AppData\Local\Programs\Python\Python38\lib\json\decoder.py", line 355, in raw_decode
    raise JSONDecodeError("Expecting value", s, err.value) from None
json.decoder.JSONDecodeError: Expecting value: line 1 column 1 (char 0)

During handling of the above exception, another exception occurred:

Traceback (most recent call last):
  File "C:\Users\lx\AppData\Local\Programs\Python\Python38\lib\site-packages\flask\app.py", line 1950, in full_dispatch_request
    rv = self.dispatch_request()
  File "C:\Users\lx\AppData\Local\Programs\Python\Python38\lib\site-packages\flask\app.py", line 1936, in dispatch_request
    return self.view_functions[rule.endpoint](**req.view_args)
  File "D:\ÊµãËØïÂ≠¶‰π†ÊñáÊ°£\erybjp-master\uiplatform\router\runtestcase.py", line 83, in jenkins_check
    arg = request.get_json()
  File "C:\Users\lx\AppData\Local\Programs\Python\Python38\lib\site-packages\werkzeug\wrappers\json.py", line 128, in get_json
    rv = self.on_json_loading_failed(e)
  File "C:\Users\lx\AppData\Local\Programs\Python\Python38\lib\site-packages\flask\wrappers.py", line 27, in on_json_loading_failed
    raise BadRequest()
werkzeug.exceptions.BadRequest: 400 Bad Request: The browser (or proxy) sent a request that this server could not understand.

During handling of the above exception, another exception occurred:

Traceback (most recent call last):
  File "C:\Users\lx\AppData\Local\Programs\Python\Python38\lib\site-packages\flask\app.py", line 2447, in wsgi_app
    response = self.full_dispatch_request()
  File "C:\Users\lx\AppData\Local\Programs\Python\Python38\lib\site-packages\flask\app.py", line 1952, in full_dispatch_request
    rv = self.handle_user_exception(e)
  File "C:\Users\lx\AppData\Local\Programs\Python\Python38\lib\site-packages\flask_restful\__init__.py", line 271, in error_router
    return original_handler(e)
  File "C:\Users\lx\AppData\Local\Programs\Python\Python38\lib\site-packages\flask_cors\extension.py", line 165, in wrapped_function
    return cors_after_request(app.make_response(f(*args, **kwargs)))
  File "C:\Users\lx\AppData\Local\Programs\Python\Python38\lib\site-packages\flask\app.py", line 2097, in make_response
    raise TypeError(
TypeError: The view function did not return a valid response. The function either returned None or ended without a return statement.
2021-07-09 13:47:49,862 [werkzeug] [13956:Thread-1] _internal.py:_internal:_log in 113] [INFO]: 127.0.0.1 - - [09/Jul/2021 13:47:49] "[35m[1mPOST /element/jenkins/check HTTP/1.1[0m" 500 -
2021-07-09 13:48:32,725 [werkzeug] [9928:MainThread] _internal.py:_internal:_log in 113] [INFO]:  * Running on http://127.0.0.1:6851/ (Press CTRL+C to quit)
2021-07-09 13:48:34,233 [erybjp] [12868:Thread-1] app.py:app:log_exception in 1891] [ERROR]: Exception on /element/jenkins/check [POST]
Traceback (most recent call last):
  File "C:\Users\lx\AppData\Local\Programs\Python\Python38\lib\site-packages\werkzeug\wrappers\json.py", line 119, in get_json
    rv = self.json_module.loads(data)
  File "C:\Users\lx\AppData\Local\Programs\Python\Python38\lib\site-packages\flask\json\__init__.py", line 253, in loads
    return _json.loads(s, **kwargs)
  File "C:\Users\lx\AppData\Local\Programs\Python\Python38\lib\json\__init__.py", line 370, in loads
    return cls(**kw).decode(s)
  File "C:\Users\lx\AppData\Local\Programs\Python\Python38\lib\json\decoder.py", line 337, in decode
    obj, end = self.raw_decode(s, idx=_w(s, 0).end())
  File "C:\Users\lx\AppData\Local\Programs\Python\Python38\lib\json\decoder.py", line 355, in raw_decode
    raise JSONDecodeError("Expecting value", s, err.value) from None
json.decoder.JSONDecodeError: Expecting value: line 1 column 1 (char 0)

During handling of the above exception, another exception occurred:

Traceback (most recent call last):
  File "C:\Users\lx\AppData\Local\Programs\Python\Python38\lib\site-packages\flask\app.py", line 1950, in full_dispatch_request
    rv = self.dispatch_request()
  File "C:\Users\lx\AppData\Local\Programs\Python\Python38\lib\site-packages\flask\app.py", line 1936, in dispatch_request
    return self.view_functions[rule.endpoint](**req.view_args)
  File "D:\ÊµãËØïÂ≠¶‰π†ÊñáÊ°£\erybjp-master\uiplatform\router\runtestcase.py", line 84, in jenkins_check
    arg = request.get_json()
  File "C:\Users\lx\AppData\Local\Programs\Python\Python38\lib\site-packages\werkzeug\wrappers\json.py", line 128, in get_json
    rv = self.on_json_loading_failed(e)
  File "C:\Users\lx\AppData\Local\Programs\Python\Python38\lib\site-packages\flask\wrappers.py", line 27, in on_json_loading_failed
    raise BadRequest()
werkzeug.exceptions.BadRequest: 400 Bad Request: The browser (or proxy) sent a request that this server could not understand.

During handling of the above exception, another exception occurred:

Traceback (most recent call last):
  File "C:\Users\lx\AppData\Local\Programs\Python\Python38\lib\site-packages\flask\app.py", line 2447, in wsgi_app
    response = self.full_dispatch_request()
  File "C:\Users\lx\AppData\Local\Programs\Python\Python38\lib\site-packages\flask\app.py", line 1952, in full_dispatch_request
    rv = self.handle_user_exception(e)
  File "C:\Users\lx\AppData\Local\Programs\Python\Python38\lib\site-packages\flask_restful\__init__.py", line 271, in error_router
    return original_handler(e)
  File "C:\Users\lx\AppData\Local\Programs\Python\Python38\lib\site-packages\flask_cors\extension.py", line 165, in wrapped_function
    return cors_after_request(app.make_response(f(*args, **kwargs)))
  File "C:\Users\lx\AppData\Local\Programs\Python\Python38\lib\site-packages\flask\app.py", line 2097, in make_response
    raise TypeError(
TypeError: The view function did not return a valid response. The function either returned None or ended without a return statement.
2021-07-09 13:48:34,247 [werkzeug] [12868:Thread-1] _internal.py:_internal:_log in 113] [INFO]: 127.0.0.1 - - [09/Jul/2021 13:48:34] "[35m[1mPOST /element/jenkins/check HTTP/1.1[0m" 500 -
2021-07-09 13:50:03,462 [werkzeug] [7032:MainThread] _internal.py:_internal:_log in 113] [INFO]:  * Running on http://127.0.0.1:6851/ (Press CTRL+C to quit)
2021-07-09 13:50:10,103 [werkzeug] [10120:Thread-1] _internal.py:_internal:_log in 113] [INFO]: 127.0.0.1 - - [09/Jul/2021 13:50:10] "[33mPOST /element/jenkins/check HTTP/1.1[0m" 404 -
2021-07-09 13:50:42,538 [erybjp] [16212:Thread-2] app.py:app:log_exception in 1891] [ERROR]: Exception on /element/henkins/check [POST]
Traceback (most recent call last):
  File "C:\Users\lx\AppData\Local\Programs\Python\Python38\lib\site-packages\werkzeug\wrappers\json.py", line 119, in get_json
    rv = self.json_module.loads(data)
  File "C:\Users\lx\AppData\Local\Programs\Python\Python38\lib\site-packages\flask\json\__init__.py", line 253, in loads
    return _json.loads(s, **kwargs)
  File "C:\Users\lx\AppData\Local\Programs\Python\Python38\lib\json\__init__.py", line 370, in loads
    return cls(**kw).decode(s)
  File "C:\Users\lx\AppData\Local\Programs\Python\Python38\lib\json\decoder.py", line 337, in decode
    obj, end = self.raw_decode(s, idx=_w(s, 0).end())
  File "C:\Users\lx\AppData\Local\Programs\Python\Python38\lib\json\decoder.py", line 355, in raw_decode
    raise JSONDecodeError("Expecting value", s, err.value) from None
json.decoder.JSONDecodeError: Expecting value: line 1 column 1 (char 0)

During handling of the above exception, another exception occurred:

Traceback (most recent call last):
  File "C:\Users\lx\AppData\Local\Programs\Python\Python38\lib\site-packages\flask\app.py", line 1950, in full_dispatch_request
    rv = self.dispatch_request()
  File "C:\Users\lx\AppData\Local\Programs\Python\Python38\lib\site-packages\flask\app.py", line 1936, in dispatch_request
    return self.view_functions[rule.endpoint](**req.view_args)
  File "D:\ÊµãËØïÂ≠¶‰π†ÊñáÊ°£\erybjp-master\uiplatform\router\runtestcase.py", line 83, in jenkins_check
    arg = request.get_json()
  File "C:\Users\lx\AppData\Local\Programs\Python\Python38\lib\site-packages\werkzeug\wrappers\json.py", line 128, in get_json
    rv = self.on_json_loading_failed(e)
  File "C:\Users\lx\AppData\Local\Programs\Python\Python38\lib\site-packages\flask\wrappers.py", line 27, in on_json_loading_failed
    raise BadRequest()
werkzeug.exceptions.BadRequest: 400 Bad Request: The browser (or proxy) sent a request that this server could not understand.

During handling of the above exception, another exception occurred:

Traceback (most recent call last):
  File "C:\Users\lx\AppData\Local\Programs\Python\Python38\lib\site-packages\flask\app.py", line 2447, in wsgi_app
    response = self.full_dispatch_request()
  File "C:\Users\lx\AppData\Local\Programs\Python\Python38\lib\site-packages\flask\app.py", line 1952, in full_dispatch_request
    rv = self.handle_user_exception(e)
  File "C:\Users\lx\AppData\Local\Programs\Python\Python38\lib\site-packages\flask_restful\__init__.py", line 271, in error_router
    return original_handler(e)
  File "C:\Users\lx\AppData\Local\Programs\Python\Python38\lib\site-packages\flask_cors\extension.py", line 165, in wrapped_function
    return cors_after_request(app.make_response(f(*args, **kwargs)))
  File "C:\Users\lx\AppData\Local\Programs\Python\Python38\lib\site-packages\flask\app.py", line 2097, in make_response
    raise TypeError(
TypeError: The view function did not return a valid response. The function either returned None or ended without a return statement.
2021-07-09 13:50:42,543 [werkzeug] [16212:Thread-2] _internal.py:_internal:_log in 113] [INFO]: 127.0.0.1 - - [09/Jul/2021 13:50:42] "[35m[1mPOST //element/henkins/check HTTP/1.1[0m" 500 -
2021-07-09 13:51:07,780 [erybjp] [5176:Thread-3] app.py:app:log_exception in 1891] [ERROR]: Exception on /element/henkins/check [POST]
Traceback (most recent call last):
  File "C:\Users\lx\AppData\Local\Programs\Python\Python38\lib\site-packages\werkzeug\wrappers\json.py", line 119, in get_json
    rv = self.json_module.loads(data)
  File "C:\Users\lx\AppData\Local\Programs\Python\Python38\lib\site-packages\flask\json\__init__.py", line 253, in loads
    return _json.loads(s, **kwargs)
  File "C:\Users\lx\AppData\Local\Programs\Python\Python38\lib\json\__init__.py", line 370, in loads
    return cls(**kw).decode(s)
  File "C:\Users\lx\AppData\Local\Programs\Python\Python38\lib\json\decoder.py", line 337, in decode
    obj, end = self.raw_decode(s, idx=_w(s, 0).end())
  File "C:\Users\lx\AppData\Local\Programs\Python\Python38\lib\json\decoder.py", line 355, in raw_decode
    raise JSONDecodeError("Expecting value", s, err.value) from None
json.decoder.JSONDecodeError: Expecting value: line 1 column 1 (char 0)

During handling of the above exception, another exception occurred:

Traceback (most recent call last):
  File "C:\Users\lx\AppData\Local\Programs\Python\Python38\lib\site-packages\flask\app.py", line 1950, in full_dispatch_request
    rv = self.dispatch_request()
  File "C:\Users\lx\AppData\Local\Programs\Python\Python38\lib\site-packages\flask\app.py", line 1936, in dispatch_request
    return self.view_functions[rule.endpoint](**req.view_args)
  File "D:\ÊµãËØïÂ≠¶‰π†ÊñáÊ°£\erybjp-master\uiplatform\router\runtestcase.py", line 83, in jenkins_check
    arg = request.get_json()
  File "C:\Users\lx\AppData\Local\Programs\Python\Python38\lib\site-packages\werkzeug\wrappers\json.py", line 128, in get_json
    rv = self.on_json_loading_failed(e)
  File "C:\Users\lx\AppData\Local\Programs\Python\Python38\lib\site-packages\flask\wrappers.py", line 27, in on_json_loading_failed
    raise BadRequest()
werkzeug.exceptions.BadRequest: 400 Bad Request: The browser (or proxy) sent a request that this server could not understand.

During handling of the above exception, another exception occurred:

Traceback (most recent call last):
  File "C:\Users\lx\AppData\Local\Programs\Python\Python38\lib\site-packages\flask\app.py", line 2447, in wsgi_app
    response = self.full_dispatch_request()
  File "C:\Users\lx\AppData\Local\Programs\Python\Python38\lib\site-packages\flask\app.py", line 1952, in full_dispatch_request
    rv = self.handle_user_exception(e)
  File "C:\Users\lx\AppData\Local\Programs\Python\Python38\lib\site-packages\flask_restful\__init__.py", line 271, in error_router
    return original_handler(e)
  File "C:\Users\lx\AppData\Local\Programs\Python\Python38\lib\site-packages\flask_cors\extension.py", line 165, in wrapped_function
    return cors_after_request(app.make_response(f(*args, **kwargs)))
  File "C:\Users\lx\AppData\Local\Programs\Python\Python38\lib\site-packages\flask\app.py", line 2097, in make_response
    raise TypeError(
TypeError: The view function did not return a valid response. The function either returned None or ended without a return statement.
2021-07-09 13:51:07,786 [werkzeug] [5176:Thread-3] _internal.py:_internal:_log in 113] [INFO]: 127.0.0.1 - - [09/Jul/2021 13:51:07] "[35m[1mPOST /element/henkins/check HTTP/1.1[0m" 500 -
2021-07-09 13:55:33,050 [werkzeug] [13788:Thread-4] _internal.py:_internal:_log in 113] [INFO]: 127.0.0.1 - - [09/Jul/2021 13:55:33] "[37mOPTIONS /element/henkins/check HTTP/1.1[0m" 200 -
2021-07-09 13:55:37,540 [erybjp] [9320:Thread-5] app.py:app:log_exception in 1891] [ERROR]: Exception on /element/henkins/check [POST]
Traceback (most recent call last):
  File "C:\Users\lx\AppData\Local\Programs\Python\Python38\lib\site-packages\werkzeug\wrappers\json.py", line 119, in get_json
    rv = self.json_module.loads(data)
  File "C:\Users\lx\AppData\Local\Programs\Python\Python38\lib\site-packages\flask\json\__init__.py", line 253, in loads
    return _json.loads(s, **kwargs)
  File "C:\Users\lx\AppData\Local\Programs\Python\Python38\lib\json\__init__.py", line 370, in loads
    return cls(**kw).decode(s)
  File "C:\Users\lx\AppData\Local\Programs\Python\Python38\lib\json\decoder.py", line 337, in decode
    obj, end = self.raw_decode(s, idx=_w(s, 0).end())
  File "C:\Users\lx\AppData\Local\Programs\Python\Python38\lib\json\decoder.py", line 355, in raw_decode
    raise JSONDecodeError("Expecting value", s, err.value) from None
json.decoder.JSONDecodeError: Expecting value: line 1 column 1 (char 0)

During handling of the above exception, another exception occurred:

Traceback (most recent call last):
  File "C:\Users\lx\AppData\Local\Programs\Python\Python38\lib\site-packages\flask\app.py", line 1950, in full_dispatch_request
    rv = self.dispatch_request()
  File "C:\Users\lx\AppData\Local\Programs\Python\Python38\lib\site-packages\flask\app.py", line 1936, in dispatch_request
    return self.view_functions[rule.endpoint](**req.view_args)
  File "D:\ÊµãËØïÂ≠¶‰π†ÊñáÊ°£\erybjp-master\uiplatform\router\runtestcase.py", line 83, in jenkins_check
    arg = request.get_json()
  File "C:\Users\lx\AppData\Local\Programs\Python\Python38\lib\site-packages\werkzeug\wrappers\json.py", line 128, in get_json
    rv = self.on_json_loading_failed(e)
  File "C:\Users\lx\AppData\Local\Programs\Python\Python38\lib\site-packages\flask\wrappers.py", line 27, in on_json_loading_failed
    raise BadRequest()
werkzeug.exceptions.BadRequest: 400 Bad Request: The browser (or proxy) sent a request that this server could not understand.

During handling of the above exception, another exception occurred:

Traceback (most recent call last):
  File "C:\Users\lx\AppData\Local\Programs\Python\Python38\lib\site-packages\flask\app.py", line 2447, in wsgi_app
    response = self.full_dispatch_request()
  File "C:\Users\lx\AppData\Local\Programs\Python\Python38\lib\site-packages\flask\app.py", line 1952, in full_dispatch_request
    rv = self.handle_user_exception(e)
  File "C:\Users\lx\AppData\Local\Programs\Python\Python38\lib\site-packages\flask_restful\__init__.py", line 271, in error_router
    return original_handler(e)
  File "C:\Users\lx\AppData\Local\Programs\Python\Python38\lib\site-packages\flask_cors\extension.py", line 165, in wrapped_function
    return cors_after_request(app.make_response(f(*args, **kwargs)))
  File "C:\Users\lx\AppData\Local\Programs\Python\Python38\lib\site-packages\flask\app.py", line 2097, in make_response
    raise TypeError(
TypeError: The view function did not return a valid response. The function either returned None or ended without a return statement.
2021-07-09 13:55:37,554 [werkzeug] [9320:Thread-5] _internal.py:_internal:_log in 113] [INFO]: 127.0.0.1 - - [09/Jul/2021 13:55:37] "[35m[1mPOST /element/henkins/check HTTP/1.1[0m" 500 -
2021-07-09 13:56:59,528 [werkzeug] [3708:Thread-6] _internal.py:_internal:_log in 113] [INFO]: 127.0.0.1 - - [09/Jul/2021 13:56:59] "[37mGET /element/auto/run HTTP/1.1[0m" 200 -
2021-07-09 13:57:52,355 [erybjp] [9268:Thread-7] app.py:app:log_exception in 1891] [ERROR]: Exception on /element/henkins/check [POST]
Traceback (most recent call last):
  File "C:\Users\lx\AppData\Local\Programs\Python\Python38\lib\site-packages\werkzeug\wrappers\json.py", line 119, in get_json
    rv = self.json_module.loads(data)
  File "C:\Users\lx\AppData\Local\Programs\Python\Python38\lib\site-packages\flask\json\__init__.py", line 253, in loads
    return _json.loads(s, **kwargs)
  File "C:\Users\lx\AppData\Local\Programs\Python\Python38\lib\json\__init__.py", line 370, in loads
    return cls(**kw).decode(s)
  File "C:\Users\lx\AppData\Local\Programs\Python\Python38\lib\json\decoder.py", line 337, in decode
    obj, end = self.raw_decode(s, idx=_w(s, 0).end())
  File "C:\Users\lx\AppData\Local\Programs\Python\Python38\lib\json\decoder.py", line 355, in raw_decode
    raise JSONDecodeError("Expecting value", s, err.value) from None
json.decoder.JSONDecodeError: Expecting value: line 1 column 1 (char 0)

During handling of the above exception, another exception occurred:

Traceback (most recent call last):
  File "C:\Users\lx\AppData\Local\Programs\Python\Python38\lib\site-packages\flask\app.py", line 1950, in full_dispatch_request
    rv = self.dispatch_request()
  File "C:\Users\lx\AppData\Local\Programs\Python\Python38\lib\site-packages\flask\app.py", line 1936, in dispatch_request
    return self.view_functions[rule.endpoint](**req.view_args)
  File "D:\ÊµãËØïÂ≠¶‰π†ÊñáÊ°£\erybjp-master\uiplatform\router\runtestcase.py", line 83, in jenkins_check
    arg = request.get_json()
  File "C:\Users\lx\AppData\Local\Programs\Python\Python38\lib\site-packages\werkzeug\wrappers\json.py", line 128, in get_json
    rv = self.on_json_loading_failed(e)
  File "C:\Users\lx\AppData\Local\Programs\Python\Python38\lib\site-packages\flask\wrappers.py", line 27, in on_json_loading_failed
    raise BadRequest()
werkzeug.exceptions.BadRequest: 400 Bad Request: The browser (or proxy) sent a request that this server could not understand.

During handling of the above exception, another exception occurred:

Traceback (most recent call last):
  File "C:\Users\lx\AppData\Local\Programs\Python\Python38\lib\site-packages\flask\app.py", line 2447, in wsgi_app
    response = self.full_dispatch_request()
  File "C:\Users\lx\AppData\Local\Programs\Python\Python38\lib\site-packages\flask\app.py", line 1952, in full_dispatch_request
    rv = self.handle_user_exception(e)
  File "C:\Users\lx\AppData\Local\Programs\Python\Python38\lib\site-packages\flask_restful\__init__.py", line 271, in error_router
    return original_handler(e)
  File "C:\Users\lx\AppData\Local\Programs\Python\Python38\lib\site-packages\flask_cors\extension.py", line 165, in wrapped_function
    return cors_after_request(app.make_response(f(*args, **kwargs)))
  File "C:\Users\lx\AppData\Local\Programs\Python\Python38\lib\site-packages\flask\app.py", line 2097, in make_response
    raise TypeError(
TypeError: The view function did not return a valid response. The function either returned None or ended without a return statement.
2021-07-09 13:57:52,368 [werkzeug] [9268:Thread-7] _internal.py:_internal:_log in 113] [INFO]: 127.0.0.1 - - [09/Jul/2021 13:57:52] "[35m[1mPOST /element/henkins/check HTTP/1.1[0m" 500 -
2021-07-09 13:58:03,066 [erybjp] [15976:Thread-8] app.py:app:log_exception in 1891] [ERROR]: Exception on /element/henkins/check [POST]
Traceback (most recent call last):
  File "C:\Users\lx\AppData\Local\Programs\Python\Python38\lib\site-packages\werkzeug\wrappers\json.py", line 119, in get_json
    rv = self.json_module.loads(data)
  File "C:\Users\lx\AppData\Local\Programs\Python\Python38\lib\site-packages\flask\json\__init__.py", line 253, in loads
    return _json.loads(s, **kwargs)
  File "C:\Users\lx\AppData\Local\Programs\Python\Python38\lib\json\__init__.py", line 370, in loads
    return cls(**kw).decode(s)
  File "C:\Users\lx\AppData\Local\Programs\Python\Python38\lib\json\decoder.py", line 337, in decode
    obj, end = self.raw_decode(s, idx=_w(s, 0).end())
  File "C:\Users\lx\AppData\Local\Programs\Python\Python38\lib\json\decoder.py", line 355, in raw_decode
    raise JSONDecodeError("Expecting value", s, err.value) from None
json.decoder.JSONDecodeError: Expecting value: line 1 column 1 (char 0)

During handling of the above exception, another exception occurred:

Traceback (most recent call last):
  File "C:\Users\lx\AppData\Local\Programs\Python\Python38\lib\site-packages\flask\app.py", line 1950, in full_dispatch_request
    rv = self.dispatch_request()
  File "C:\Users\lx\AppData\Local\Programs\Python\Python38\lib\site-packages\flask\app.py", line 1936, in dispatch_request
    return self.view_functions[rule.endpoint](**req.view_args)
  File "D:\ÊµãËØïÂ≠¶‰π†ÊñáÊ°£\erybjp-master\uiplatform\router\runtestcase.py", line 83, in jenkins_check
    arg = request.get_json()
  File "C:\Users\lx\AppData\Local\Programs\Python\Python38\lib\site-packages\werkzeug\wrappers\json.py", line 128, in get_json
    rv = self.on_json_loading_failed(e)
  File "C:\Users\lx\AppData\Local\Programs\Python\Python38\lib\site-packages\flask\wrappers.py", line 27, in on_json_loading_failed
    raise BadRequest()
werkzeug.exceptions.BadRequest: 400 Bad Request: The browser (or proxy) sent a request that this server could not understand.

During handling of the above exception, another exception occurred:

Traceback (most recent call last):
  File "C:\Users\lx\AppData\Local\Programs\Python\Python38\lib\site-packages\flask\app.py", line 2447, in wsgi_app
    response = self.full_dispatch_request()
  File "C:\Users\lx\AppData\Local\Programs\Python\Python38\lib\site-packages\flask\app.py", line 1952, in full_dispatch_request
    rv = self.handle_user_exception(e)
  File "C:\Users\lx\AppData\Local\Programs\Python\Python38\lib\site-packages\flask_restful\__init__.py", line 271, in error_router
    return original_handler(e)
  File "C:\Users\lx\AppData\Local\Programs\Python\Python38\lib\site-packages\flask_cors\extension.py", line 165, in wrapped_function
    return cors_after_request(app.make_response(f(*args, **kwargs)))
  File "C:\Users\lx\AppData\Local\Programs\Python\Python38\lib\site-packages\flask\app.py", line 2097, in make_response
    raise TypeError(
TypeError: The view function did not return a valid response. The function either returned None or ended without a return statement.
2021-07-09 13:58:03,072 [werkzeug] [15976:Thread-8] _internal.py:_internal:_log in 113] [INFO]: 127.0.0.1 - - [09/Jul/2021 13:58:03] "[35m[1mPOST /element/henkins/check HTTP/1.1[0m" 500 -
2021-07-09 13:58:03,971 [erybjp] [1920:Thread-9] app.py:app:log_exception in 1891] [ERROR]: Exception on /element/henkins/check [POST]
Traceback (most recent call last):
  File "C:\Users\lx\AppData\Local\Programs\Python\Python38\lib\site-packages\werkzeug\wrappers\json.py", line 119, in get_json
    rv = self.json_module.loads(data)
  File "C:\Users\lx\AppData\Local\Programs\Python\Python38\lib\site-packages\flask\json\__init__.py", line 253, in loads
    return _json.loads(s, **kwargs)
  File "C:\Users\lx\AppData\Local\Programs\Python\Python38\lib\json\__init__.py", line 370, in loads
    return cls(**kw).decode(s)
  File "C:\Users\lx\AppData\Local\Programs\Python\Python38\lib\json\decoder.py", line 337, in decode
    obj, end = self.raw_decode(s, idx=_w(s, 0).end())
  File "C:\Users\lx\AppData\Local\Programs\Python\Python38\lib\json\decoder.py", line 355, in raw_decode
    raise JSONDecodeError("Expecting value", s, err.value) from None
json.decoder.JSONDecodeError: Expecting value: line 1 column 1 (char 0)

During handling of the above exception, another exception occurred:

Traceback (most recent call last):
  File "C:\Users\lx\AppData\Local\Programs\Python\Python38\lib\site-packages\flask\app.py", line 1950, in full_dispatch_request
    rv = self.dispatch_request()
  File "C:\Users\lx\AppData\Local\Programs\Python\Python38\lib\site-packages\flask\app.py", line 1936, in dispatch_request
    return self.view_functions[rule.endpoint](**req.view_args)
  File "D:\ÊµãËØïÂ≠¶‰π†ÊñáÊ°£\erybjp-master\uiplatform\router\runtestcase.py", line 83, in jenkins_check
    arg = request.get_json()
  File "C:\Users\lx\AppData\Local\Programs\Python\Python38\lib\site-packages\werkzeug\wrappers\json.py", line 128, in get_json
    rv = self.on_json_loading_failed(e)
  File "C:\Users\lx\AppData\Local\Programs\Python\Python38\lib\site-packages\flask\wrappers.py", line 27, in on_json_loading_failed
    raise BadRequest()
werkzeug.exceptions.BadRequest: 400 Bad Request: The browser (or proxy) sent a request that this server could not understand.

During handling of the above exception, another exception occurred:

Traceback (most recent call last):
  File "C:\Users\lx\AppData\Local\Programs\Python\Python38\lib\site-packages\flask\app.py", line 2447, in wsgi_app
    response = self.full_dispatch_request()
  File "C:\Users\lx\AppData\Local\Programs\Python\Python38\lib\site-packages\flask\app.py", line 1952, in full_dispatch_request
    rv = self.handle_user_exception(e)
  File "C:\Users\lx\AppData\Local\Programs\Python\Python38\lib\site-packages\flask_restful\__init__.py", line 271, in error_router
    return original_handler(e)
  File "C:\Users\lx\AppData\Local\Programs\Python\Python38\lib\site-packages\flask_cors\extension.py", line 165, in wrapped_function
    return cors_after_request(app.make_response(f(*args, **kwargs)))
  File "C:\Users\lx\AppData\Local\Programs\Python\Python38\lib\site-packages\flask\app.py", line 2097, in make_response
    raise TypeError(
TypeError: The view function did not return a valid response. The function either returned None or ended without a return statement.
2021-07-09 13:58:03,984 [werkzeug] [1920:Thread-9] _internal.py:_internal:_log in 113] [INFO]: 127.0.0.1 - - [09/Jul/2021 13:58:03] "[35m[1mPOST /element/henkins/check HTTP/1.1[0m" 500 -
2021-07-09 13:58:08,585 [erybjp] [9040:Thread-10] app.py:app:log_exception in 1891] [ERROR]: Exception on /element/henkins/check [POST]
Traceback (most recent call last):
  File "C:\Users\lx\AppData\Local\Programs\Python\Python38\lib\site-packages\werkzeug\wrappers\json.py", line 119, in get_json
    rv = self.json_module.loads(data)
  File "C:\Users\lx\AppData\Local\Programs\Python\Python38\lib\site-packages\flask\json\__init__.py", line 253, in loads
    return _json.loads(s, **kwargs)
  File "C:\Users\lx\AppData\Local\Programs\Python\Python38\lib\json\__init__.py", line 370, in loads
    return cls(**kw).decode(s)
  File "C:\Users\lx\AppData\Local\Programs\Python\Python38\lib\json\decoder.py", line 337, in decode
    obj, end = self.raw_decode(s, idx=_w(s, 0).end())
  File "C:\Users\lx\AppData\Local\Programs\Python\Python38\lib\json\decoder.py", line 355, in raw_decode
    raise JSONDecodeError("Expecting value", s, err.value) from None
json.decoder.JSONDecodeError: Expecting value: line 1 column 1 (char 0)

During handling of the above exception, another exception occurred:

Traceback (most recent call last):
  File "C:\Users\lx\AppData\Local\Programs\Python\Python38\lib\site-packages\flask\app.py", line 1950, in full_dispatch_request
    rv = self.dispatch_request()
  File "C:\Users\lx\AppData\Local\Programs\Python\Python38\lib\site-packages\flask\app.py", line 1936, in dispatch_request
    return self.view_functions[rule.endpoint](**req.view_args)
  File "D:\ÊµãËØïÂ≠¶‰π†ÊñáÊ°£\erybjp-master\uiplatform\router\runtestcase.py", line 83, in jenkins_check
    arg = request.get_json()
  File "C:\Users\lx\AppData\Local\Programs\Python\Python38\lib\site-packages\werkzeug\wrappers\json.py", line 128, in get_json
    rv = self.on_json_loading_failed(e)
  File "C:\Users\lx\AppData\Local\Programs\Python\Python38\lib\site-packages\flask\wrappers.py", line 27, in on_json_loading_failed
    raise BadRequest()
werkzeug.exceptions.BadRequest: 400 Bad Request: The browser (or proxy) sent a request that this server could not understand.

During handling of the above exception, another exception occurred:

Traceback (most recent call last):
  File "C:\Users\lx\AppData\Local\Programs\Python\Python38\lib\site-packages\flask\app.py", line 2447, in wsgi_app
    response = self.full_dispatch_request()
  File "C:\Users\lx\AppData\Local\Programs\Python\Python38\lib\site-packages\flask\app.py", line 1952, in full_dispatch_request
    rv = self.handle_user_exception(e)
  File "C:\Users\lx\AppData\Local\Programs\Python\Python38\lib\site-packages\flask_restful\__init__.py", line 271, in error_router
    return original_handler(e)
  File "C:\Users\lx\AppData\Local\Programs\Python\Python38\lib\site-packages\flask_cors\extension.py", line 165, in wrapped_function
    return cors_after_request(app.make_response(f(*args, **kwargs)))
  File "C:\Users\lx\AppData\Local\Programs\Python\Python38\lib\site-packages\flask\app.py", line 2097, in make_response
    raise TypeError(
TypeError: The view function did not return a valid response. The function either returned None or ended without a return statement.
2021-07-09 13:58:08,590 [werkzeug] [9040:Thread-10] _internal.py:_internal:_log in 113] [INFO]: 127.0.0.1 - - [09/Jul/2021 13:58:08] "[35m[1mPOST /element/henkins/check HTTP/1.1[0m" 500 -
2021-07-09 13:58:34,440 [erybjp] [4524:Thread-11] app.py:app:log_exception in 1891] [ERROR]: Exception on /element/henkins/check [POST]
Traceback (most recent call last):
  File "C:\Users\lx\AppData\Local\Programs\Python\Python38\lib\site-packages\werkzeug\wrappers\json.py", line 119, in get_json
    rv = self.json_module.loads(data)
  File "C:\Users\lx\AppData\Local\Programs\Python\Python38\lib\site-packages\flask\json\__init__.py", line 253, in loads
    return _json.loads(s, **kwargs)
  File "C:\Users\lx\AppData\Local\Programs\Python\Python38\lib\json\__init__.py", line 370, in loads
    return cls(**kw).decode(s)
  File "C:\Users\lx\AppData\Local\Programs\Python\Python38\lib\json\decoder.py", line 337, in decode
    obj, end = self.raw_decode(s, idx=_w(s, 0).end())
  File "C:\Users\lx\AppData\Local\Programs\Python\Python38\lib\json\decoder.py", line 355, in raw_decode
    raise JSONDecodeError("Expecting value", s, err.value) from None
json.decoder.JSONDecodeError: Expecting value: line 1 column 1 (char 0)

During handling of the above exception, another exception occurred:

Traceback (most recent call last):
  File "C:\Users\lx\AppData\Local\Programs\Python\Python38\lib\site-packages\flask\app.py", line 1950, in full_dispatch_request
    rv = self.dispatch_request()
  File "C:\Users\lx\AppData\Local\Programs\Python\Python38\lib\site-packages\flask\app.py", line 1936, in dispatch_request
    return self.view_functions[rule.endpoint](**req.view_args)
  File "D:\ÊµãËØïÂ≠¶‰π†ÊñáÊ°£\erybjp-master\uiplatform\router\runtestcase.py", line 83, in jenkins_check
    arg = request.get_json()
  File "C:\Users\lx\AppData\Local\Programs\Python\Python38\lib\site-packages\werkzeug\wrappers\json.py", line 128, in get_json
    rv = self.on_json_loading_failed(e)
  File "C:\Users\lx\AppData\Local\Programs\Python\Python38\lib\site-packages\flask\wrappers.py", line 27, in on_json_loading_failed
    raise BadRequest()
werkzeug.exceptions.BadRequest: 400 Bad Request: The browser (or proxy) sent a request that this server could not understand.

During handling of the above exception, another exception occurred:

Traceback (most recent call last):
  File "C:\Users\lx\AppData\Local\Programs\Python\Python38\lib\site-packages\flask\app.py", line 2447, in wsgi_app
    response = self.full_dispatch_request()
  File "C:\Users\lx\AppData\Local\Programs\Python\Python38\lib\site-packages\flask\app.py", line 1952, in full_dispatch_request
    rv = self.handle_user_exception(e)
  File "C:\Users\lx\AppData\Local\Programs\Python\Python38\lib\site-packages\flask_restful\__init__.py", line 271, in error_router
    return original_handler(e)
  File "C:\Users\lx\AppData\Local\Programs\Python\Python38\lib\site-packages\flask_cors\extension.py", line 165, in wrapped_function
    return cors_after_request(app.make_response(f(*args, **kwargs)))
  File "C:\Users\lx\AppData\Local\Programs\Python\Python38\lib\site-packages\flask\app.py", line 2097, in make_response
    raise TypeError(
TypeError: The view function did not return a valid response. The function either returned None or ended without a return statement.
2021-07-09 13:58:34,451 [werkzeug] [4524:Thread-11] _internal.py:_internal:_log in 113] [INFO]: 127.0.0.1 - - [09/Jul/2021 13:58:34] "[35m[1mPOST /element/henkins/check HTTP/1.1[0m" 500 -
2021-07-09 13:58:57,018 [werkzeug] [6840:MainThread] _internal.py:_internal:_log in 113] [INFO]:  * Running on http://127.0.0.1:6851/ (Press CTRL+C to quit)
2021-07-09 14:00:17,249 [werkzeug] [15312:Thread-1] _internal.py:_internal:_log in 113] [INFO]: 127.0.0.1 - - [09/Jul/2021 14:00:17] "[37mGET /scheduler/jobs HTTP/1.1[0m" 200 -
2021-07-09 14:00:24,762 [erybjp] [15100:Thread-2] app.py:app:log_exception in 1891] [ERROR]: Exception on /element/henkins/check [POST]
Traceback (most recent call last):
  File "C:\Users\lx\AppData\Local\Programs\Python\Python38\lib\site-packages\werkzeug\wrappers\json.py", line 119, in get_json
    rv = self.json_module.loads(data)
  File "C:\Users\lx\AppData\Local\Programs\Python\Python38\lib\site-packages\flask\json\__init__.py", line 253, in loads
    return _json.loads(s, **kwargs)
  File "C:\Users\lx\AppData\Local\Programs\Python\Python38\lib\json\__init__.py", line 370, in loads
    return cls(**kw).decode(s)
  File "C:\Users\lx\AppData\Local\Programs\Python\Python38\lib\json\decoder.py", line 337, in decode
    obj, end = self.raw_decode(s, idx=_w(s, 0).end())
  File "C:\Users\lx\AppData\Local\Programs\Python\Python38\lib\json\decoder.py", line 355, in raw_decode
    raise JSONDecodeError("Expecting value", s, err.value) from None
json.decoder.JSONDecodeError: Expecting value: line 1 column 1 (char 0)

During handling of the above exception, another exception occurred:

Traceback (most recent call last):
  File "C:\Users\lx\AppData\Local\Programs\Python\Python38\lib\site-packages\flask\app.py", line 1950, in full_dispatch_request
    rv = self.dispatch_request()
  File "C:\Users\lx\AppData\Local\Programs\Python\Python38\lib\site-packages\flask\app.py", line 1936, in dispatch_request
    return self.view_functions[rule.endpoint](**req.view_args)
  File "D:\ÊµãËØïÂ≠¶‰π†ÊñáÊ°£\erybjp-master\uiplatform\router\runtestcase.py", line 83, in jenkins_check
    arg = request.get_json()
  File "C:\Users\lx\AppData\Local\Programs\Python\Python38\lib\site-packages\werkzeug\wrappers\json.py", line 128, in get_json
    rv = self.on_json_loading_failed(e)
  File "C:\Users\lx\AppData\Local\Programs\Python\Python38\lib\site-packages\flask\wrappers.py", line 27, in on_json_loading_failed
    raise BadRequest()
werkzeug.exceptions.BadRequest: 400 Bad Request: The browser (or proxy) sent a request that this server could not understand.

During handling of the above exception, another exception occurred:

Traceback (most recent call last):
  File "C:\Users\lx\AppData\Local\Programs\Python\Python38\lib\site-packages\flask\app.py", line 2447, in wsgi_app
    response = self.full_dispatch_request()
  File "C:\Users\lx\AppData\Local\Programs\Python\Python38\lib\site-packages\flask\app.py", line 1952, in full_dispatch_request
    rv = self.handle_user_exception(e)
  File "C:\Users\lx\AppData\Local\Programs\Python\Python38\lib\site-packages\flask_restful\__init__.py", line 271, in error_router
    return original_handler(e)
  File "C:\Users\lx\AppData\Local\Programs\Python\Python38\lib\site-packages\flask_cors\extension.py", line 165, in wrapped_function
    return cors_after_request(app.make_response(f(*args, **kwargs)))
  File "C:\Users\lx\AppData\Local\Programs\Python\Python38\lib\site-packages\flask\app.py", line 2097, in make_response
    raise TypeError(
TypeError: The view function did not return a valid response. The function either returned None or ended without a return statement.
2021-07-09 14:00:24,773 [werkzeug] [15100:Thread-2] _internal.py:_internal:_log in 113] [INFO]: 127.0.0.1 - - [09/Jul/2021 14:00:24] "[35m[1mPOST /element/henkins/check HTTP/1.1[0m" 500 -
2021-07-09 14:00:47,754 [erybjp] [3708:Thread-3] app.py:app:log_exception in 1891] [ERROR]: Exception on /element/henkins/check [POST]
Traceback (most recent call last):
  File "C:\Users\lx\AppData\Local\Programs\Python\Python38\lib\site-packages\werkzeug\wrappers\json.py", line 119, in get_json
    rv = self.json_module.loads(data)
  File "C:\Users\lx\AppData\Local\Programs\Python\Python38\lib\site-packages\flask\json\__init__.py", line 253, in loads
    return _json.loads(s, **kwargs)
  File "C:\Users\lx\AppData\Local\Programs\Python\Python38\lib\json\__init__.py", line 370, in loads
    return cls(**kw).decode(s)
  File "C:\Users\lx\AppData\Local\Programs\Python\Python38\lib\json\decoder.py", line 337, in decode
    obj, end = self.raw_decode(s, idx=_w(s, 0).end())
  File "C:\Users\lx\AppData\Local\Programs\Python\Python38\lib\json\decoder.py", line 355, in raw_decode
    raise JSONDecodeError("Expecting value", s, err.value) from None
json.decoder.JSONDecodeError: Expecting value: line 1 column 1 (char 0)

During handling of the above exception, another exception occurred:

Traceback (most recent call last):
  File "C:\Users\lx\AppData\Local\Programs\Python\Python38\lib\site-packages\flask\app.py", line 1950, in full_dispatch_request
    rv = self.dispatch_request()
  File "C:\Users\lx\AppData\Local\Programs\Python\Python38\lib\site-packages\flask\app.py", line 1936, in dispatch_request
    return self.view_functions[rule.endpoint](**req.view_args)
  File "D:\ÊµãËØïÂ≠¶‰π†ÊñáÊ°£\erybjp-master\uiplatform\router\runtestcase.py", line 83, in jenkins_check
    arg = request.get_json()
  File "C:\Users\lx\AppData\Local\Programs\Python\Python38\lib\site-packages\werkzeug\wrappers\json.py", line 128, in get_json
    rv = self.on_json_loading_failed(e)
  File "C:\Users\lx\AppData\Local\Programs\Python\Python38\lib\site-packages\flask\wrappers.py", line 27, in on_json_loading_failed
    raise BadRequest()
werkzeug.exceptions.BadRequest: 400 Bad Request: The browser (or proxy) sent a request that this server could not understand.

During handling of the above exception, another exception occurred:

Traceback (most recent call last):
  File "C:\Users\lx\AppData\Local\Programs\Python\Python38\lib\site-packages\flask\app.py", line 2447, in wsgi_app
    response = self.full_dispatch_request()
  File "C:\Users\lx\AppData\Local\Programs\Python\Python38\lib\site-packages\flask\app.py", line 1952, in full_dispatch_request
    rv = self.handle_user_exception(e)
  File "C:\Users\lx\AppData\Local\Programs\Python\Python38\lib\site-packages\flask_restful\__init__.py", line 271, in error_router
    return original_handler(e)
  File "C:\Users\lx\AppData\Local\Programs\Python\Python38\lib\site-packages\flask_cors\extension.py", line 165, in wrapped_function
    return cors_after_request(app.make_response(f(*args, **kwargs)))
  File "C:\Users\lx\AppData\Local\Programs\Python\Python38\lib\site-packages\flask\app.py", line 2097, in make_response
    raise TypeError(
TypeError: The view function did not return a valid response. The function either returned None or ended without a return statement.
2021-07-09 14:00:47,761 [werkzeug] [3708:Thread-3] _internal.py:_internal:_log in 113] [INFO]: 127.0.0.1 - - [09/Jul/2021 14:00:47] "[35m[1mPOST /element/henkins/check HTTP/1.1[0m" 500 -
2021-07-09 15:17:02,000 [werkzeug] [14784:MainThread] _internal.py:_internal:_log in 113] [INFO]:  * Running on http://127.0.0.1:6851/ (Press CTRL+C to quit)
2021-07-09 15:17:18,850 [werkzeug] [10056:MainThread] _internal.py:_internal:_log in 113] [INFO]:  * Running on http://127.0.0.1:6851/ (Press CTRL+C to quit)
2021-07-09 15:17:43,771 [erybjp] [15688:Thread-6] app.py:app:log_exception in 1891] [ERROR]: Exception on /element/henkins/check [POST]
Traceback (most recent call last):
  File "C:\Users\lx\AppData\Local\Programs\Python\Python38\lib\site-packages\werkzeug\wrappers\json.py", line 119, in get_json
    rv = self.json_module.loads(data)
  File "C:\Users\lx\AppData\Local\Programs\Python\Python38\lib\site-packages\flask\json\__init__.py", line 253, in loads
    return _json.loads(s, **kwargs)
  File "C:\Users\lx\AppData\Local\Programs\Python\Python38\lib\json\__init__.py", line 370, in loads
    return cls(**kw).decode(s)
  File "C:\Users\lx\AppData\Local\Programs\Python\Python38\lib\json\decoder.py", line 337, in decode
    obj, end = self.raw_decode(s, idx=_w(s, 0).end())
  File "C:\Users\lx\AppData\Local\Programs\Python\Python38\lib\json\decoder.py", line 355, in raw_decode
    raise JSONDecodeError("Expecting value", s, err.value) from None
json.decoder.JSONDecodeError: Expecting value: line 1 column 1 (char 0)

During handling of the above exception, another exception occurred:

Traceback (most recent call last):
  File "C:\Users\lx\AppData\Local\Programs\Python\Python38\lib\site-packages\flask\app.py", line 1950, in full_dispatch_request
    rv = self.dispatch_request()
  File "C:\Users\lx\AppData\Local\Programs\Python\Python38\lib\site-packages\flask\app.py", line 1936, in dispatch_request
    return self.view_functions[rule.endpoint](**req.view_args)
  File "D:\ÊµãËØïÂ≠¶‰π†ÊñáÊ°£\erybjp-master\uiplatform\router\runtestcase.py", line 83, in jenkins_check
    arg = request.get_json()
  File "C:\Users\lx\AppData\Local\Programs\Python\Python38\lib\site-packages\werkzeug\wrappers\json.py", line 128, in get_json
    rv = self.on_json_loading_failed(e)
  File "C:\Users\lx\AppData\Local\Programs\Python\Python38\lib\site-packages\flask\wrappers.py", line 27, in on_json_loading_failed
    raise BadRequest()
werkzeug.exceptions.BadRequest: 400 Bad Request: The browser (or proxy) sent a request that this server could not understand.

During handling of the above exception, another exception occurred:

Traceback (most recent call last):
  File "C:\Users\lx\AppData\Local\Programs\Python\Python38\lib\site-packages\flask\app.py", line 2447, in wsgi_app
    response = self.full_dispatch_request()
  File "C:\Users\lx\AppData\Local\Programs\Python\Python38\lib\site-packages\flask\app.py", line 1952, in full_dispatch_request
    rv = self.handle_user_exception(e)
  File "C:\Users\lx\AppData\Local\Programs\Python\Python38\lib\site-packages\flask_restful\__init__.py", line 271, in error_router
    return original_handler(e)
  File "C:\Users\lx\AppData\Local\Programs\Python\Python38\lib\site-packages\flask_cors\extension.py", line 165, in wrapped_function
    return cors_after_request(app.make_response(f(*args, **kwargs)))
  File "C:\Users\lx\AppData\Local\Programs\Python\Python38\lib\site-packages\flask\app.py", line 2097, in make_response
    raise TypeError(
TypeError: The view function did not return a valid response. The function either returned None or ended without a return statement.
2021-07-09 15:17:43,792 [werkzeug] [15688:Thread-6] _internal.py:_internal:_log in 113] [INFO]: 127.0.0.1 - - [09/Jul/2021 15:17:43] "[35m[1mPOST /element/henkins/check HTTP/1.1[0m" 500 -
2021-07-09 15:18:28,341 [werkzeug] [15240:MainThread] _internal.py:_internal:_log in 113] [INFO]:  * Running on http://127.0.0.1:6851/ (Press CTRL+C to quit)
2021-07-09 15:19:21,745 [werkzeug] [8148:MainThread] _internal.py:_internal:_log in 113] [INFO]:  * Running on http://127.0.0.1:6851/ (Press CTRL+C to quit)
2021-07-09 15:23:26,738 [werkzeug] [16192:MainThread] _internal.py:_internal:_log in 113] [INFO]:  * Running on http://127.0.0.1:6851/ (Press CTRL+C to quit)
2021-07-09 15:23:30,857 [werkzeug] [15320:Thread-1] _internal.py:_internal:_log in 113] [INFO]: 127.0.0.1 - - [09/Jul/2021 15:23:30] "[33mPOST /element/jenkins/check HTTP/1.1[0m" 404 -
2021-07-09 15:24:20,660 [werkzeug] [12836:Thread-2] _internal.py:_internal:_log in 113] [INFO]: 127.0.0.1 - - [09/Jul/2021 15:24:20] "[37mPOST /element/henkins/check HTTP/1.1[0m" 200 -
2021-07-09 15:26:09,976 [werkzeug] [7580:Thread-18] _internal.py:_internal:_log in 113] [INFO]: 127.0.0.1 - - [09/Jul/2021 15:26:09] "[37mPOST /element/henkins/check HTTP/1.1[0m" 200 -
2021-07-09 15:31:17,679 [werkzeug] [7328:MainThread] _internal.py:_internal:_log in 113] [INFO]:  * Running on http://127.0.0.1:6851/ (Press CTRL+C to quit)
2021-07-09 15:31:36,454 [werkzeug] [10232:Thread-1] _internal.py:_internal:_log in 113] [INFO]: 127.0.0.1 - - [09/Jul/2021 15:31:36] "[37mPOST /element/henkins/check HTTP/1.1[0m" 200 -
2021-07-09 15:32:40,542 [werkzeug] [6088:Thread-6] _internal.py:_internal:_log in 113] [INFO]: 127.0.0.1 - - [09/Jul/2021 15:32:40] "[37mPOST /element/henkins/check HTTP/1.1[0m" 200 -
2021-07-26 16:12:00,780 [werkzeug] [13004:MainThread] _internal.py:_internal:_log in 113] [INFO]:  * Running on http://127.0.0.1:6851/ (Press CTRL+C to quit)
2021-07-26 16:12:57,921 [werkzeug] [8128:Thread-1] _internal.py:_internal:_log in 113] [INFO]: 127.0.0.1 - - [26/Jul/2021 16:12:57] "[33mGET /ui_test/test1 HTTP/1.1[0m" 404 -
2021-07-26 16:13:50,067 [werkzeug] [23372:Thread-2] _internal.py:_internal:_log in 113] [INFO]: 127.0.0.1 - - [26/Jul/2021 16:13:50] "[37mGET /element/ui_test/test1 HTTP/1.1[0m" 200 -
2021-07-26 16:21:28,801 [werkzeug] [27476:MainThread] _internal.py:_internal:_log in 113] [INFO]:  * Running on http://127.0.0.1:6851/ (Press CTRL+C to quit)
2021-07-26 16:22:23,045 [erybjp] [2968:Thread-1] app.py:app:log_exception in 1891] [ERROR]: Exception on /element/buy/testpacket [GET]
Traceback (most recent call last):
  File "C:\Users\lx\AppData\Local\Programs\Python\Python38\lib\site-packages\flask\app.py", line 2447, in wsgi_app
    response = self.full_dispatch_request()
  File "C:\Users\lx\AppData\Local\Programs\Python\Python38\lib\site-packages\flask\app.py", line 1952, in full_dispatch_request
    rv = self.handle_user_exception(e)
  File "C:\Users\lx\AppData\Local\Programs\Python\Python38\lib\site-packages\flask_restful\__init__.py", line 271, in error_router
    return original_handler(e)
  File "C:\Users\lx\AppData\Local\Programs\Python\Python38\lib\site-packages\flask_cors\extension.py", line 165, in wrapped_function
    return cors_after_request(app.make_response(f(*args, **kwargs)))
  File "C:\Users\lx\AppData\Local\Programs\Python\Python38\lib\site-packages\flask\app.py", line 1821, in handle_user_exception
    reraise(exc_type, exc_value, tb)
  File "C:\Users\lx\AppData\Local\Programs\Python\Python38\lib\site-packages\flask\_compat.py", line 39, in reraise
    raise value
  File "C:\Users\lx\AppData\Local\Programs\Python\Python38\lib\site-packages\flask\app.py", line 1950, in full_dispatch_request
    rv = self.dispatch_request()
  File "C:\Users\lx\AppData\Local\Programs\Python\Python38\lib\site-packages\flask\app.py", line 1936, in dispatch_request
    return self.view_functions[rule.endpoint](**req.view_args)
  File "D:\ÊµãËØïÂ≠¶‰π†ÊñáÊ°£\erybjp-master\uiplatform\utils\business\lbk_operational_package\runtestcase.py", line 99, in test_purchase_packet
    message = buy.purse_price_not_zero()
  File "D:\ÊµãËØïÂ≠¶‰π†ÊñáÊ°£\erybjp-master\uiplatform\utils\business\ttest_course_puchase_h5_web.py", line 109, in purse_price_not_zero
    course.code_ele = self.get_phone_code()
  File "D:\ÊµãËØïÂ≠¶‰π†ÊñáÊ°£\erybjp-master\uiplatform\utils\common\BasePage.py", line 124, in __set__
    self.send_keys(value)
  File "D:\ÊµãËØïÂ≠¶‰π†ÊñáÊ°£\erybjp-master\uiplatform\utils\common\BasePage.py", line 254, in send_keys
    elem = self.__get_element(self.k, self.v)
  File "D:\ÊµãËØïÂ≠¶‰π†ÊñáÊ°£\erybjp-master\uiplatform\utils\common\BasePage.py", line 185, in __get_element
    self.__find_element((By.CSS_SELECTOR, value))
  File "D:\ÊµãËØïÂ≠¶‰π†ÊñáÊ°£\erybjp-master\uiplatform\utils\common\BasePage.py", line 155, in __find_element
    raise NoSuchElementException(error_msg)
selenium.common.exceptions.NoSuchElementException: Message: ‚ùå Find 0 elements through: css selector=input[placeholder="ËØ∑ËæìÂÖ•È™åËØÅÁ†Å"]

2021-07-26 16:22:23,091 [werkzeug] [2968:Thread-1] _internal.py:_internal:_log in 113] [INFO]: 127.0.0.1 - - [26/Jul/2021 16:22:23] "[35m[1mGET /element/buy/testpacket HTTP/1.1[0m" 500 -
2021-07-26 16:25:51,213 [erybjp] [28232:Thread-14] app.py:app:log_exception in 1891] [ERROR]: Exception on /element/buy/testpacket [GET]
Traceback (most recent call last):
  File "C:\Users\lx\AppData\Local\Programs\Python\Python38\lib\site-packages\flask\app.py", line 2447, in wsgi_app
    response = self.full_dispatch_request()
  File "C:\Users\lx\AppData\Local\Programs\Python\Python38\lib\site-packages\flask\app.py", line 1952, in full_dispatch_request
    rv = self.handle_user_exception(e)
  File "C:\Users\lx\AppData\Local\Programs\Python\Python38\lib\site-packages\flask_restful\__init__.py", line 271, in error_router
    return original_handler(e)
  File "C:\Users\lx\AppData\Local\Programs\Python\Python38\lib\site-packages\flask_cors\extension.py", line 165, in wrapped_function
    return cors_after_request(app.make_response(f(*args, **kwargs)))
  File "C:\Users\lx\AppData\Local\Programs\Python\Python38\lib\site-packages\flask\app.py", line 1821, in handle_user_exception
    reraise(exc_type, exc_value, tb)
  File "C:\Users\lx\AppData\Local\Programs\Python\Python38\lib\site-packages\flask\_compat.py", line 39, in reraise
    raise value
  File "C:\Users\lx\AppData\Local\Programs\Python\Python38\lib\site-packages\flask\app.py", line 1950, in full_dispatch_request
    rv = self.dispatch_request()
  File "C:\Users\lx\AppData\Local\Programs\Python\Python38\lib\site-packages\flask\app.py", line 1936, in dispatch_request
    return self.view_functions[rule.endpoint](**req.view_args)
  File "D:\ÊµãËØïÂ≠¶‰π†ÊñáÊ°£\erybjp-master\uiplatform\utils\business\lbk_operational_package\runtestcase.py", line 99, in test_purchase_packet
    message = buy.purse_price_not_zero()
  File "D:\ÊµãËØïÂ≠¶‰π†ÊñáÊ°£\erybjp-master\uiplatform\utils\business\ttest_course_puchase_h5_web.py", line 109, in purse_price_not_zero
    course.pay_button_ele.click()
  File "D:\ÊµãËØïÂ≠¶‰π†ÊñáÊ°£\erybjp-master\uiplatform\utils\common\BasePage.py", line 124, in __set__
    self.send_keys(value)
  File "D:\ÊµãËØïÂ≠¶‰π†ÊñáÊ°£\erybjp-master\uiplatform\utils\common\BasePage.py", line 254, in send_keys
    elem = self.__get_element(self.k, self.v)
  File "D:\ÊµãËØïÂ≠¶‰π†ÊñáÊ°£\erybjp-master\uiplatform\utils\common\BasePage.py", line 185, in __get_element
    self.__find_element((By.CSS_SELECTOR, value))
  File "D:\ÊµãËØïÂ≠¶‰π†ÊñáÊ°£\erybjp-master\uiplatform\utils\common\BasePage.py", line 155, in __find_element
    raise NoSuchElementException(error_msg)
selenium.common.exceptions.NoSuchElementException: Message: ‚ùå Find 0 elements through: css selector=input[placeholder="ËØ∑ËæìÂÖ•È™åËØÅÁ†Å"]

2021-07-26 16:25:51,228 [werkzeug] [28232:Thread-14] _internal.py:_internal:_log in 113] [INFO]: 127.0.0.1 - - [26/Jul/2021 16:25:51] "[35m[1mGET /element/buy/testpacket HTTP/1.1[0m" 500 -
2021-07-26 16:35:57,347 [werkzeug] [26848:MainThread] _internal.py:_internal:_log in 113] [INFO]:  * Running on http://127.0.0.1:6851/ (Press CTRL+C to quit)
2021-07-26 16:36:11,884 [werkzeug] [784:Thread-1] _internal.py:_internal:_log in 113] [INFO]: 127.0.0.1 - - [26/Jul/2021 16:36:11] "[37mGET /element/buy/testpacket HTTP/1.1[0m" 200 -
2021-07-26 16:43:56,710 [werkzeug] [14660:Thread-4] _internal.py:_internal:_log in 113] [INFO]: 127.0.0.1 - - [26/Jul/2021 16:43:56] "[37mGET /element/buy/testpacket HTTP/1.1[0m" 200 -
2021-07-26 19:16:47,197 [werkzeug] [18972:MainThread] _internal.py:_internal:_log in 113] [INFO]:  * Running on http://127.0.0.1:6851/ (Press CTRL+C to quit)
2021-07-26 19:17:31,086 [erybjp] [9760:Thread-1] app.py:app:log_exception in 1891] [ERROR]: Exception on /element/upload/picture [POST]
Traceback (most recent call last):
  File "C:\Users\lx\AppData\Local\Programs\Python\Python38\lib\site-packages\flask\app.py", line 2447, in wsgi_app
    response = self.full_dispatch_request()
  File "C:\Users\lx\AppData\Local\Programs\Python\Python38\lib\site-packages\flask\app.py", line 1952, in full_dispatch_request
    rv = self.handle_user_exception(e)
  File "C:\Users\lx\AppData\Local\Programs\Python\Python38\lib\site-packages\flask_restful\__init__.py", line 271, in error_router
    return original_handler(e)
  File "C:\Users\lx\AppData\Local\Programs\Python\Python38\lib\site-packages\flask_cors\extension.py", line 165, in wrapped_function
    return cors_after_request(app.make_response(f(*args, **kwargs)))
  File "C:\Users\lx\AppData\Local\Programs\Python\Python38\lib\site-packages\flask\app.py", line 1821, in handle_user_exception
    reraise(exc_type, exc_value, tb)
  File "C:\Users\lx\AppData\Local\Programs\Python\Python38\lib\site-packages\flask\_compat.py", line 39, in reraise
    raise value
  File "C:\Users\lx\AppData\Local\Programs\Python\Python38\lib\site-packages\flask\app.py", line 1950, in full_dispatch_request
    rv = self.dispatch_request()
  File "C:\Users\lx\AppData\Local\Programs\Python\Python38\lib\site-packages\flask\app.py", line 1936, in dispatch_request
    return self.view_functions[rule.endpoint](**req.view_args)
  File "D:\ÊµãËØïÂ≠¶‰π†ÊñáÊ°£\erybjp-master\uiplatform\router\runtestcase.py", line 115, in upload_picture
    pictureName = arg.get("picturename")
AttributeError: 'NoneType' object has no attribute 'get'
2021-07-26 19:17:31,092 [werkzeug] [9760:Thread-1] _internal.py:_internal:_log in 113] [INFO]: 127.0.0.1 - - [26/Jul/2021 19:17:31] "[35m[1mPOST /element/upload/picture HTTP/1.1[0m" 500 -
2021-07-26 19:18:13,882 [erybjp] [17252:Thread-2] app.py:app:log_exception in 1891] [ERROR]: Exception on /element/upload/picture [POST]
Traceback (most recent call last):
  File "C:\Users\lx\AppData\Local\Programs\Python\Python38\lib\site-packages\flask\app.py", line 2447, in wsgi_app
    response = self.full_dispatch_request()
  File "C:\Users\lx\AppData\Local\Programs\Python\Python38\lib\site-packages\flask\app.py", line 1953, in full_dispatch_request
    return self.finalize_request(rv)
  File "C:\Users\lx\AppData\Local\Programs\Python\Python38\lib\site-packages\flask\app.py", line 1968, in finalize_request
    response = self.make_response(rv)
  File "C:\Users\lx\AppData\Local\Programs\Python\Python38\lib\site-packages\flask\app.py", line 2097, in make_response
    raise TypeError(
TypeError: The view function did not return a valid response. The function either returned None or ended without a return statement.
2021-07-26 19:18:13,883 [werkzeug] [17252:Thread-2] _internal.py:_internal:_log in 113] [INFO]: 127.0.0.1 - - [26/Jul/2021 19:18:13] "[35m[1mPOST /element/upload/picture HTTP/1.1[0m" 500 -
2021-07-26 19:18:20,269 [erybjp] [12884:Thread-3] app.py:app:log_exception in 1891] [ERROR]: Exception on /element/upload/picture [POST]
Traceback (most recent call last):
  File "C:\Users\lx\AppData\Local\Programs\Python\Python38\lib\site-packages\flask\app.py", line 2447, in wsgi_app
    response = self.full_dispatch_request()
  File "C:\Users\lx\AppData\Local\Programs\Python\Python38\lib\site-packages\flask\app.py", line 1953, in full_dispatch_request
    return self.finalize_request(rv)
  File "C:\Users\lx\AppData\Local\Programs\Python\Python38\lib\site-packages\flask\app.py", line 1968, in finalize_request
    response = self.make_response(rv)
  File "C:\Users\lx\AppData\Local\Programs\Python\Python38\lib\site-packages\flask\app.py", line 2097, in make_response
    raise TypeError(
TypeError: The view function did not return a valid response. The function either returned None or ended without a return statement.
2021-07-26 19:18:20,270 [werkzeug] [12884:Thread-3] _internal.py:_internal:_log in 113] [INFO]: 127.0.0.1 - - [26/Jul/2021 19:18:20] "[35m[1mPOST /element/upload/picture HTTP/1.1[0m" 500 -
2021-07-26 19:19:35,136 [erybjp] [3668:Thread-4] app.py:app:log_exception in 1891] [ERROR]: Exception on /element/upload/picture [POST]
Traceback (most recent call last):
  File "C:\Users\lx\AppData\Local\Programs\Python\Python38\lib\site-packages\flask\app.py", line 2447, in wsgi_app
    response = self.full_dispatch_request()
  File "C:\Users\lx\AppData\Local\Programs\Python\Python38\lib\site-packages\flask\app.py", line 1953, in full_dispatch_request
    return self.finalize_request(rv)
  File "C:\Users\lx\AppData\Local\Programs\Python\Python38\lib\site-packages\flask\app.py", line 1968, in finalize_request
    response = self.make_response(rv)
  File "C:\Users\lx\AppData\Local\Programs\Python\Python38\lib\site-packages\flask\app.py", line 2097, in make_response
    raise TypeError(
TypeError: The view function did not return a valid response. The function either returned None or ended without a return statement.
2021-07-26 19:19:35,137 [werkzeug] [3668:Thread-4] _internal.py:_internal:_log in 113] [INFO]: 127.0.0.1 - - [26/Jul/2021 19:19:35] "[35m[1mPOST /element/upload/picture HTTP/1.1[0m" 500 -
2021-07-26 19:20:37,085 [erybjp] [7020:Thread-5] app.py:app:log_exception in 1891] [ERROR]: Exception on /element/upload/picture [POST]
Traceback (most recent call last):
  File "C:\Users\lx\AppData\Local\Programs\Python\Python38\lib\site-packages\flask\app.py", line 2447, in wsgi_app
    response = self.full_dispatch_request()
  File "C:\Users\lx\AppData\Local\Programs\Python\Python38\lib\site-packages\flask\app.py", line 1953, in full_dispatch_request
    return self.finalize_request(rv)
  File "C:\Users\lx\AppData\Local\Programs\Python\Python38\lib\site-packages\flask\app.py", line 1968, in finalize_request
    response = self.make_response(rv)
  File "C:\Users\lx\AppData\Local\Programs\Python\Python38\lib\site-packages\flask\app.py", line 2097, in make_response
    raise TypeError(
TypeError: The view function did not return a valid response. The function either returned None or ended without a return statement.
2021-07-26 19:20:37,085 [werkzeug] [7020:Thread-5] _internal.py:_internal:_log in 113] [INFO]: 127.0.0.1 - - [26/Jul/2021 19:20:37] "[35m[1mPOST /element/upload/picture HTTP/1.1[0m" 500 -
2021-07-26 19:20:44,908 [werkzeug] [29140:MainThread] _internal.py:_internal:_log in 113] [INFO]:  * Running on http://127.0.0.1:6851/ (Press CTRL+C to quit)
2021-07-26 19:20:53,103 [erybjp] [5844:Thread-1] app.py:app:log_exception in 1891] [ERROR]: Exception on /element/upload/picture [POST]
Traceback (most recent call last):
  File "C:\Users\lx\AppData\Local\Programs\Python\Python38\lib\site-packages\flask\app.py", line 2447, in wsgi_app
    response = self.full_dispatch_request()
  File "C:\Users\lx\AppData\Local\Programs\Python\Python38\lib\site-packages\flask\app.py", line 1953, in full_dispatch_request
    return self.finalize_request(rv)
  File "C:\Users\lx\AppData\Local\Programs\Python\Python38\lib\site-packages\flask\app.py", line 1968, in finalize_request
    response = self.make_response(rv)
  File "C:\Users\lx\AppData\Local\Programs\Python\Python38\lib\site-packages\flask\app.py", line 2097, in make_response
    raise TypeError(
TypeError: The view function did not return a valid response. The function either returned None or ended without a return statement.
2021-07-26 19:20:53,105 [werkzeug] [5844:Thread-1] _internal.py:_internal:_log in 113] [INFO]: 127.0.0.1 - - [26/Jul/2021 19:20:53] "[35m[1mPOST /element/upload/picture HTTP/1.1[0m" 500 -
2021-07-26 19:21:39,811 [erybjp] [3176:Thread-2] app.py:app:log_exception in 1891] [ERROR]: Exception on /element/upload/picture [POST]
Traceback (most recent call last):
  File "C:\Users\lx\AppData\Local\Programs\Python\Python38\lib\site-packages\flask\app.py", line 2447, in wsgi_app
    response = self.full_dispatch_request()
  File "C:\Users\lx\AppData\Local\Programs\Python\Python38\lib\site-packages\flask\app.py", line 1953, in full_dispatch_request
    return self.finalize_request(rv)
  File "C:\Users\lx\AppData\Local\Programs\Python\Python38\lib\site-packages\flask\app.py", line 1968, in finalize_request
    response = self.make_response(rv)
  File "C:\Users\lx\AppData\Local\Programs\Python\Python38\lib\site-packages\flask\app.py", line 2097, in make_response
    raise TypeError(
TypeError: The view function did not return a valid response. The function either returned None or ended without a return statement.
2021-07-26 19:21:39,812 [werkzeug] [3176:Thread-2] _internal.py:_internal:_log in 113] [INFO]: 127.0.0.1 - - [26/Jul/2021 19:21:39] "[35m[1mPOST /element/upload/picture HTTP/1.1[0m" 500 -
2021-07-26 19:22:09,514 [erybjp] [13984:Thread-3] app.py:app:log_exception in 1891] [ERROR]: Exception on /element/upload/picture [POST]
Traceback (most recent call last):
  File "C:\Users\lx\AppData\Local\Programs\Python\Python38\lib\site-packages\flask\app.py", line 2447, in wsgi_app
    response = self.full_dispatch_request()
  File "C:\Users\lx\AppData\Local\Programs\Python\Python38\lib\site-packages\flask\app.py", line 1953, in full_dispatch_request
    return self.finalize_request(rv)
  File "C:\Users\lx\AppData\Local\Programs\Python\Python38\lib\site-packages\flask\app.py", line 1968, in finalize_request
    response = self.make_response(rv)
  File "C:\Users\lx\AppData\Local\Programs\Python\Python38\lib\site-packages\flask\app.py", line 2097, in make_response
    raise TypeError(
TypeError: The view function did not return a valid response. The function either returned None or ended without a return statement.
2021-07-26 19:22:09,515 [werkzeug] [13984:Thread-3] _internal.py:_internal:_log in 113] [INFO]: 127.0.0.1 - - [26/Jul/2021 19:22:09] "[35m[1mPOST /element/upload/picture HTTP/1.1[0m" 500 -
2021-07-26 19:22:23,334 [werkzeug] [22748:MainThread] _internal.py:_internal:_log in 113] [INFO]:  * Running on http://127.0.0.1:6851/ (Press CTRL+C to quit)
2021-07-26 19:22:27,055 [werkzeug] [27100:Thread-1] _internal.py:_internal:_log in 113] [INFO]: 127.0.0.1 - - [26/Jul/2021 19:22:27] "[37mPOST /element/upload/picture HTTP/1.1[0m" 200 -
2021-07-26 19:22:42,582 [erybjp] [25456:Thread-2] app.py:app:log_exception in 1891] [ERROR]: Exception on /element/upload/picture [POST]
Traceback (most recent call last):
  File "C:\Users\lx\AppData\Local\Programs\Python\Python38\lib\site-packages\flask\app.py", line 2447, in wsgi_app
    response = self.full_dispatch_request()
  File "C:\Users\lx\AppData\Local\Programs\Python\Python38\lib\site-packages\flask\app.py", line 1952, in full_dispatch_request
    rv = self.handle_user_exception(e)
  File "C:\Users\lx\AppData\Local\Programs\Python\Python38\lib\site-packages\flask_restful\__init__.py", line 271, in error_router
    return original_handler(e)
  File "C:\Users\lx\AppData\Local\Programs\Python\Python38\lib\site-packages\flask_cors\extension.py", line 165, in wrapped_function
    return cors_after_request(app.make_response(f(*args, **kwargs)))
  File "C:\Users\lx\AppData\Local\Programs\Python\Python38\lib\site-packages\flask\app.py", line 1821, in handle_user_exception
    reraise(exc_type, exc_value, tb)
  File "C:\Users\lx\AppData\Local\Programs\Python\Python38\lib\site-packages\flask\_compat.py", line 39, in reraise
    raise value
  File "C:\Users\lx\AppData\Local\Programs\Python\Python38\lib\site-packages\flask\app.py", line 1950, in full_dispatch_request
    rv = self.dispatch_request()
  File "C:\Users\lx\AppData\Local\Programs\Python\Python38\lib\site-packages\flask\app.py", line 1936, in dispatch_request
    return self.view_functions[rule.endpoint](**req.view_args)
  File "D:\ÊµãËØïÂ≠¶‰π†ÊñáÊ°£\erybjp-master\uiplatform\router\runtestcase.py", line 117, in upload_picture
    if pictureName in result:
TypeError: unhashable type: 'list'
2021-07-26 19:22:42,584 [werkzeug] [25456:Thread-2] _internal.py:_internal:_log in 113] [INFO]: 127.0.0.1 - - [26/Jul/2021 19:22:42] "[35m[1mPOST /element/upload/picture HTTP/1.1[0m" 500 -
2021-07-26 19:28:22,863 [erybjp] [17112:Thread-3] app.py:app:log_exception in 1891] [ERROR]: Exception on /element/upload/picture [POST]
Traceback (most recent call last):
  File "C:\Users\lx\AppData\Local\Programs\Python\Python38\lib\site-packages\flask\app.py", line 2447, in wsgi_app
    response = self.full_dispatch_request()
  File "C:\Users\lx\AppData\Local\Programs\Python\Python38\lib\site-packages\flask\app.py", line 1952, in full_dispatch_request
    rv = self.handle_user_exception(e)
  File "C:\Users\lx\AppData\Local\Programs\Python\Python38\lib\site-packages\flask_restful\__init__.py", line 271, in error_router
    return original_handler(e)
  File "C:\Users\lx\AppData\Local\Programs\Python\Python38\lib\site-packages\flask_cors\extension.py", line 165, in wrapped_function
    return cors_after_request(app.make_response(f(*args, **kwargs)))
  File "C:\Users\lx\AppData\Local\Programs\Python\Python38\lib\site-packages\flask\app.py", line 1821, in handle_user_exception
    reraise(exc_type, exc_value, tb)
  File "C:\Users\lx\AppData\Local\Programs\Python\Python38\lib\site-packages\flask\_compat.py", line 39, in reraise
    raise value
  File "C:\Users\lx\AppData\Local\Programs\Python\Python38\lib\site-packages\flask\app.py", line 1950, in full_dispatch_request
    rv = self.dispatch_request()
  File "C:\Users\lx\AppData\Local\Programs\Python\Python38\lib\site-packages\flask\app.py", line 1936, in dispatch_request
    return self.view_functions[rule.endpoint](**req.view_args)
  File "D:\ÊµãËØïÂ≠¶‰π†ÊñáÊ°£\erybjp-master\uiplatform\router\runtestcase.py", line 117, in upload_picture
    if pictureName in result:
TypeError: unhashable type: 'list'
2021-07-26 19:28:22,864 [werkzeug] [17112:Thread-3] _internal.py:_internal:_log in 113] [INFO]: 127.0.0.1 - - [26/Jul/2021 19:28:22] "[35m[1mPOST /element/upload/picture HTTP/1.1[0m" 500 -
2021-07-26 19:28:32,404 [werkzeug] [18576:MainThread] _internal.py:_internal:_log in 113] [INFO]:  * Running on http://127.0.0.1:6851/ (Press CTRL+C to quit)
2021-07-26 19:28:34,667 [erybjp] [15600:Thread-1] app.py:app:log_exception in 1891] [ERROR]: Exception on /element/upload/picture [POST]
Traceback (most recent call last):
  File "C:\Users\lx\AppData\Local\Programs\Python\Python38\lib\site-packages\flask\app.py", line 2447, in wsgi_app
    response = self.full_dispatch_request()
  File "C:\Users\lx\AppData\Local\Programs\Python\Python38\lib\site-packages\flask\app.py", line 1952, in full_dispatch_request
    rv = self.handle_user_exception(e)
  File "C:\Users\lx\AppData\Local\Programs\Python\Python38\lib\site-packages\flask_restful\__init__.py", line 271, in error_router
    return original_handler(e)
  File "C:\Users\lx\AppData\Local\Programs\Python\Python38\lib\site-packages\flask_cors\extension.py", line 165, in wrapped_function
    return cors_after_request(app.make_response(f(*args, **kwargs)))
  File "C:\Users\lx\AppData\Local\Programs\Python\Python38\lib\site-packages\flask\app.py", line 1821, in handle_user_exception
    reraise(exc_type, exc_value, tb)
  File "C:\Users\lx\AppData\Local\Programs\Python\Python38\lib\site-packages\flask\_compat.py", line 39, in reraise
    raise value
  File "C:\Users\lx\AppData\Local\Programs\Python\Python38\lib\site-packages\flask\app.py", line 1950, in full_dispatch_request
    rv = self.dispatch_request()
  File "C:\Users\lx\AppData\Local\Programs\Python\Python38\lib\site-packages\flask\app.py", line 1936, in dispatch_request
    return self.view_functions[rule.endpoint](**req.view_args)
  File "D:\ÊµãËØïÂ≠¶‰π†ÊñáÊ°£\erybjp-master\uiplatform\router\runtestcase.py", line 117, in upload_picture
    if pictureName in result:
TypeError: unhashable type: 'list'
2021-07-26 19:28:34,671 [werkzeug] [15600:Thread-1] _internal.py:_internal:_log in 113] [INFO]: 127.0.0.1 - - [26/Jul/2021 19:28:34] "[35m[1mPOST /element/upload/picture HTTP/1.1[0m" 500 -
2021-07-26 19:29:35,578 [erybjp] [24232:Thread-2] app.py:app:log_exception in 1891] [ERROR]: Exception on /element/upload/picture [POST]
Traceback (most recent call last):
  File "C:\Users\lx\AppData\Local\Programs\Python\Python38\lib\site-packages\flask\app.py", line 2447, in wsgi_app
    response = self.full_dispatch_request()
  File "C:\Users\lx\AppData\Local\Programs\Python\Python38\lib\site-packages\flask\app.py", line 1952, in full_dispatch_request
    rv = self.handle_user_exception(e)
  File "C:\Users\lx\AppData\Local\Programs\Python\Python38\lib\site-packages\flask_restful\__init__.py", line 271, in error_router
    return original_handler(e)
  File "C:\Users\lx\AppData\Local\Programs\Python\Python38\lib\site-packages\flask_cors\extension.py", line 165, in wrapped_function
    return cors_after_request(app.make_response(f(*args, **kwargs)))
  File "C:\Users\lx\AppData\Local\Programs\Python\Python38\lib\site-packages\flask\app.py", line 1821, in handle_user_exception
    reraise(exc_type, exc_value, tb)
  File "C:\Users\lx\AppData\Local\Programs\Python\Python38\lib\site-packages\flask\_compat.py", line 39, in reraise
    raise value
  File "C:\Users\lx\AppData\Local\Programs\Python\Python38\lib\site-packages\flask\app.py", line 1950, in full_dispatch_request
    rv = self.dispatch_request()
  File "C:\Users\lx\AppData\Local\Programs\Python\Python38\lib\site-packages\flask\app.py", line 1936, in dispatch_request
    return self.view_functions[rule.endpoint](**req.view_args)
  File "D:\ÊµãËØïÂ≠¶‰π†ÊñáÊ°£\erybjp-master\uiplatform\router\runtestcase.py", line 117, in upload_picture
    result = upload.upload_one_picture(pictureName)
TypeError: unhashable type: 'list'
2021-07-26 19:29:35,579 [werkzeug] [24232:Thread-2] _internal.py:_internal:_log in 113] [INFO]: 127.0.0.1 - - [26/Jul/2021 19:29:35] "[35m[1mPOST /element/upload/picture HTTP/1.1[0m" 500 -
2021-07-26 19:30:20,633 [werkzeug] [10788:MainThread] _internal.py:_internal:_log in 113] [INFO]:  * Running on http://127.0.0.1:6851/ (Press CTRL+C to quit)
2021-07-26 19:30:23,710 [erybjp] [29604:Thread-1] app.py:app:log_exception in 1891] [ERROR]: Exception on /element/upload/picture [POST]
Traceback (most recent call last):
  File "C:\Users\lx\AppData\Local\Programs\Python\Python38\lib\site-packages\flask\app.py", line 2447, in wsgi_app
    response = self.full_dispatch_request()
  File "C:\Users\lx\AppData\Local\Programs\Python\Python38\lib\site-packages\flask\app.py", line 1952, in full_dispatch_request
    rv = self.handle_user_exception(e)
  File "C:\Users\lx\AppData\Local\Programs\Python\Python38\lib\site-packages\flask_restful\__init__.py", line 271, in error_router
    return original_handler(e)
  File "C:\Users\lx\AppData\Local\Programs\Python\Python38\lib\site-packages\flask_cors\extension.py", line 165, in wrapped_function
    return cors_after_request(app.make_response(f(*args, **kwargs)))
  File "C:\Users\lx\AppData\Local\Programs\Python\Python38\lib\site-packages\flask\app.py", line 1821, in handle_user_exception
    reraise(exc_type, exc_value, tb)
  File "C:\Users\lx\AppData\Local\Programs\Python\Python38\lib\site-packages\flask\_compat.py", line 39, in reraise
    raise value
  File "C:\Users\lx\AppData\Local\Programs\Python\Python38\lib\site-packages\flask\app.py", line 1950, in full_dispatch_request
    rv = self.dispatch_request()
  File "C:\Users\lx\AppData\Local\Programs\Python\Python38\lib\site-packages\flask\app.py", line 1936, in dispatch_request
    return self.view_functions[rule.endpoint](**req.view_args)
  File "D:\ÊµãËØïÂ≠¶‰π†ÊñáÊ°£\erybjp-master\uiplatform\router\runtestcase.py", line 118, in upload_picture
    if pictureName in result:
TypeError: unhashable type: 'list'
2021-07-26 19:30:23,726 [werkzeug] [29604:Thread-1] _internal.py:_internal:_log in 113] [INFO]: 127.0.0.1 - - [26/Jul/2021 19:30:23] "[35m[1mPOST /element/upload/picture HTTP/1.1[0m" 500 -
2021-07-26 19:32:59,189 [werkzeug] [15548:Thread-2] _internal.py:_internal:_log in 113] [INFO]: 127.0.0.1 - - [26/Jul/2021 19:32:59] "[37mPOST /element/upload/picture HTTP/1.1[0m" 200 -
2021-07-26 19:35:17,251 [werkzeug] [19184:MainThread] _internal.py:_internal:_log in 113] [INFO]:  * Running on http://127.0.0.1:6851/ (Press CTRL+C to quit)
2021-07-26 19:35:23,481 [werkzeug] [22436:Thread-1] _internal.py:_internal:_log in 113] [INFO]: 127.0.0.1 - - [26/Jul/2021 19:35:23] "[37mPOST /element/upload/picture HTTP/1.1[0m" 200 -
2021-07-26 19:35:27,535 [werkzeug] [20608:Thread-2] _internal.py:_internal:_log in 113] [INFO]: 127.0.0.1 - - [26/Jul/2021 19:35:27] "[37mPOST /element/upload/picture HTTP/1.1[0m" 200 -
2021-07-26 19:37:03,135 [werkzeug] [9544:MainThread] _internal.py:_internal:_log in 113] [INFO]:  * Running on http://127.0.0.1:6851/ (Press CTRL+C to quit)
2021-07-26 19:37:05,681 [werkzeug] [30300:Thread-1] _internal.py:_internal:_log in 113] [INFO]: 127.0.0.1 - - [26/Jul/2021 19:37:05] "[37mPOST /element/upload/picture HTTP/1.1[0m" 200 -
2021-07-26 19:37:45,732 [werkzeug] [9404:Thread-2] _internal.py:_internal:_log in 113] [INFO]: 127.0.0.1 - - [26/Jul/2021 19:37:45] "[37mPOST /element/upload/picture HTTP/1.1[0m" 200 -
2021-07-26 19:38:54,334 [werkzeug] [24252:Thread-3] _internal.py:_internal:_log in 113] [INFO]: 127.0.0.1 - - [26/Jul/2021 19:38:54] "[37mPOST /element/upload/picture HTTP/1.1[0m" 200 -
2021-07-26 19:39:04,386 [werkzeug] [24972:MainThread] _internal.py:_internal:_log in 113] [INFO]:  * Running on http://127.0.0.1:6851/ (Press CTRL+C to quit)
2021-07-26 19:39:06,833 [werkzeug] [21812:Thread-1] _internal.py:_internal:_log in 113] [INFO]: 127.0.0.1 - - [26/Jul/2021 19:39:06] "[37mPOST /element/upload/picture HTTP/1.1[0m" 200 -
2021-07-26 19:44:59,531 [werkzeug] [14132:MainThread] _internal.py:_internal:_log in 113] [INFO]:  * Running on http://127.0.0.1:6851/ (Press CTRL+C to quit)
2021-07-26 19:45:35,173 [werkzeug] [26996:Thread-1] _internal.py:_internal:_log in 113] [INFO]: 127.0.0.1 - - [26/Jul/2021 19:45:35] "[37mPOST /element/upload/picture HTTP/1.1[0m" 200 -
2021-07-26 19:45:43,269 [werkzeug] [22468:MainThread] _internal.py:_internal:_log in 113] [INFO]:  * Running on http://127.0.0.1:6851/ (Press CTRL+C to quit)
2021-07-26 19:45:47,679 [werkzeug] [23972:Thread-1] _internal.py:_internal:_log in 113] [INFO]: 127.0.0.1 - - [26/Jul/2021 19:45:47] "[37mPOST /element/upload/picture HTTP/1.1[0m" 200 -
2021-07-26 19:46:28,504 [werkzeug] [6228:Thread-2] _internal.py:_internal:_log in 113] [INFO]: 127.0.0.1 - - [26/Jul/2021 19:46:28] "[37mPOST /element/upload/picture HTTP/1.1[0m" 200 -
2021-07-26 19:46:40,876 [werkzeug] [21664:MainThread] _internal.py:_internal:_log in 113] [INFO]:  * Running on http://127.0.0.1:6851/ (Press CTRL+C to quit)
2021-07-26 19:46:42,198 [werkzeug] [19948:Thread-1] _internal.py:_internal:_log in 113] [INFO]: 127.0.0.1 - - [26/Jul/2021 19:46:42] "[37mPOST /element/upload/picture HTTP/1.1[0m" 200 -
2021-07-26 19:52:26,191 [werkzeug] [30124:MainThread] _internal.py:_internal:_log in 113] [INFO]:  * Running on http://127.0.0.1:6851/ (Press CTRL+C to quit)
2021-07-26 19:52:28,762 [werkzeug] [21116:Thread-1] _internal.py:_internal:_log in 113] [INFO]: 127.0.0.1 - - [26/Jul/2021 19:52:28] "[37mPOST /element/upload/picture HTTP/1.1[0m" 200 -
2021-07-26 19:52:45,057 [werkzeug] [30516:MainThread] _internal.py:_internal:_log in 113] [INFO]:  * Running on http://127.0.0.1:6851/ (Press CTRL+C to quit)
2021-07-26 19:54:04,317 [werkzeug] [14284:MainThread] _internal.py:_internal:_log in 113] [INFO]:  * Running on http://127.0.0.1:6851/ (Press CTRL+C to quit)
2021-07-26 19:54:06,218 [werkzeug] [3392:Thread-1] _internal.py:_internal:_log in 113] [INFO]: 127.0.0.1 - - [26/Jul/2021 19:54:06] "[37mPOST /element/upload/picture HTTP/1.1[0m" 200 -
2021-07-26 19:55:41,921 [werkzeug] [20408:MainThread] _internal.py:_internal:_log in 113] [INFO]:  * Running on http://127.0.0.1:6851/ (Press CTRL+C to quit)
2021-07-26 19:55:44,351 [werkzeug] [26272:Thread-1] _internal.py:_internal:_log in 113] [INFO]: 127.0.0.1 - - [26/Jul/2021 19:55:44] "[37mPOST /element/upload/picture HTTP/1.1[0m" 200 -
2021-07-26 19:57:19,065 [werkzeug] [1400:Thread-2] _internal.py:_internal:_log in 113] [INFO]: 127.0.0.1 - - [26/Jul/2021 19:57:19] "[37mPOST /element/upload/picture HTTP/1.1[0m" 200 -
2021-07-26 20:05:33,106 [werkzeug] [13812:Thread-3] _internal.py:_internal:_log in 113] [INFO]: 127.0.0.1 - - [26/Jul/2021 20:05:33] "[37mPOST /element/upload/picture HTTP/1.1[0m" 200 -
2021-07-26 20:09:03,115 [werkzeug] [22832:MainThread] _internal.py:_internal:_log in 113] [INFO]:  * Running on http://127.0.0.1:6851/ (Press CTRL+C to quit)
2021-07-26 20:09:05,706 [werkzeug] [7008:Thread-1] _internal.py:_internal:_log in 113] [INFO]: 127.0.0.1 - - [26/Jul/2021 20:09:05] "[37mPOST /element/upload/picture HTTP/1.1[0m" 200 -
2021-07-26 20:11:22,444 [werkzeug] [21568:MainThread] _internal.py:_internal:_log in 113] [INFO]:  * Running on http://127.0.0.1:6851/ (Press CTRL+C to quit)
2021-07-26 20:12:33,136 [werkzeug] [3616:MainThread] _internal.py:_internal:_log in 113] [INFO]:  * Running on http://127.0.0.1:6851/ (Press CTRL+C to quit)
2021-07-26 20:13:09,446 [werkzeug] [5284:MainThread] _internal.py:_internal:_log in 113] [INFO]:  * Running on http://127.0.0.1:6851/ (Press CTRL+C to quit)
2021-07-26 20:13:11,916 [werkzeug] [13820:Thread-1] _internal.py:_internal:_log in 113] [INFO]: 127.0.0.1 - - [26/Jul/2021 20:13:11] "[37mPOST /element/upload/picture HTTP/1.1[0m" 200 -
2021-07-26 20:15:02,973 [werkzeug] [2468:MainThread] _internal.py:_internal:_log in 113] [INFO]:  * Running on http://127.0.0.1:6851/ (Press CTRL+C to quit)
2021-07-26 20:17:55,722 [werkzeug] [29916:Thread-1] _internal.py:_internal:_log in 113] [INFO]: 127.0.0.1 - - [26/Jul/2021 20:17:55] "[37mPOST /element/upload/picture HTTP/1.1[0m" 200 -
2021-07-26 20:18:01,680 [werkzeug] [24492:MainThread] _internal.py:_internal:_log in 113] [INFO]:  * Running on http://127.0.0.1:6851/ (Press CTRL+C to quit)
2021-07-26 20:18:31,944 [werkzeug] [27972:MainThread] _internal.py:_internal:_log in 113] [INFO]:  * Running on http://127.0.0.1:6851/ (Press CTRL+C to quit)
2021-07-26 20:18:44,576 [werkzeug] [13352:Thread-1] _internal.py:_internal:_log in 113] [INFO]: 127.0.0.1 - - [26/Jul/2021 20:18:44] "[37mPOST /element/upload/picture HTTP/1.1[0m" 200 -
2021-07-26 20:20:32,203 [werkzeug] [21132:Thread-2] _internal.py:_internal:_log in 113] [INFO]: 127.0.0.1 - - [26/Jul/2021 20:20:32] "[37mPOST /element/upload/picture HTTP/1.1[0m" 200 -
2021-07-26 20:20:44,267 [werkzeug] [25140:MainThread] _internal.py:_internal:_log in 113] [INFO]:  * Running on http://127.0.0.1:6851/ (Press CTRL+C to quit)
2021-07-26 20:20:47,410 [werkzeug] [30036:Thread-1] _internal.py:_internal:_log in 113] [INFO]: 127.0.0.1 - - [26/Jul/2021 20:20:47] "[37mPOST /element/upload/picture HTTP/1.1[0m" 200 -
2021-07-26 20:22:56,133 [werkzeug] [28420:Thread-2] _internal.py:_internal:_log in 113] [INFO]: 127.0.0.1 - - [26/Jul/2021 20:22:56] "[37mPOST /element/upload/picture HTTP/1.1[0m" 200 -
2021-07-26 20:26:14,672 [werkzeug] [1452:Thread-3] _internal.py:_internal:_log in 113] [INFO]: 127.0.0.1 - - [26/Jul/2021 20:26:14] "[37mPOST /element/upload/picture HTTP/1.1[0m" 200 -
2021-07-26 20:27:15,375 [werkzeug] [9080:MainThread] _internal.py:_internal:_log in 113] [INFO]:  * Running on http://127.0.0.1:6851/ (Press CTRL+C to quit)
2021-07-26 20:27:17,665 [werkzeug] [29788:Thread-1] _internal.py:_internal:_log in 113] [INFO]: 127.0.0.1 - - [26/Jul/2021 20:27:17] "[37mPOST /element/upload/picture HTTP/1.1[0m" 200 -
2021-07-26 20:28:47,671 [werkzeug] [13940:Thread-2] _internal.py:_internal:_log in 113] [INFO]: 127.0.0.1 - - [26/Jul/2021 20:28:47] "[37mPOST /element/upload/picture HTTP/1.1[0m" 200 -
2021-07-26 20:28:49,027 [werkzeug] [14088:Thread-3] _internal.py:_internal:_log in 113] [INFO]: 127.0.0.1 - - [26/Jul/2021 20:28:49] "[37mPOST /element/upload/picture HTTP/1.1[0m" 200 -
2021-07-26 20:29:19,120 [werkzeug] [28052:MainThread] _internal.py:_internal:_log in 113] [INFO]:  * Running on http://127.0.0.1:6851/ (Press CTRL+C to quit)
2021-07-26 20:29:21,537 [werkzeug] [340:Thread-1] _internal.py:_internal:_log in 113] [INFO]: 127.0.0.1 - - [26/Jul/2021 20:29:21] "[37mPOST /element/upload/picture HTTP/1.1[0m" 200 -
2021-07-26 20:29:24,430 [werkzeug] [468:Thread-2] _internal.py:_internal:_log in 113] [INFO]: 127.0.0.1 - - [26/Jul/2021 20:29:24] "[37mPOST /element/upload/picture HTTP/1.1[0m" 200 -
2021-07-26 20:29:31,607 [werkzeug] [21840:Thread-3] _internal.py:_internal:_log in 113] [INFO]: 127.0.0.1 - - [26/Jul/2021 20:29:31] "[37mPOST /element/upload/picture HTTP/1.1[0m" 200 -
2021-07-26 20:29:38,488 [werkzeug] [17204:Thread-4] _internal.py:_internal:_log in 113] [INFO]: 127.0.0.1 - - [26/Jul/2021 20:29:38] "[37mPOST /element/upload/picture HTTP/1.1[0m" 200 -
2021-07-26 20:29:48,179 [werkzeug] [16980:Thread-5] _internal.py:_internal:_log in 113] [INFO]: 127.0.0.1 - - [26/Jul/2021 20:29:48] "[37mPOST /element/upload/picture HTTP/1.1[0m" 200 -
2021-07-26 20:30:22,911 [werkzeug] [10320:Thread-6] _internal.py:_internal:_log in 113] [INFO]: 127.0.0.1 - - [26/Jul/2021 20:30:22] "[37mPOST /element/upload/picture HTTP/1.1[0m" 200 -
2021-07-26 20:30:33,946 [werkzeug] [26188:Thread-7] _internal.py:_internal:_log in 113] [INFO]: 127.0.0.1 - - [26/Jul/2021 20:30:33] "[37mPOST /element/upload/picture HTTP/1.1[0m" 200 -
2021-07-26 20:33:09,912 [werkzeug] [19996:MainThread] _internal.py:_internal:_log in 113] [INFO]:  * Running on http://127.0.0.1:6851/ (Press CTRL+C to quit)
2021-07-26 20:33:21,506 [werkzeug] [8080:Thread-1] _internal.py:_internal:_log in 113] [INFO]: 127.0.0.1 - - [26/Jul/2021 20:33:21] "[37mPOST /element/upload/picture HTTP/1.1[0m" 200 -
2021-07-26 20:33:40,217 [werkzeug] [29468:MainThread] _internal.py:_internal:_log in 113] [INFO]:  * Running on http://127.0.0.1:6851/ (Press CTRL+C to quit)
2021-07-26 20:33:54,868 [werkzeug] [25132:Thread-1] _internal.py:_internal:_log in 113] [INFO]: 127.0.0.1 - - [26/Jul/2021 20:33:54] "[37mPOST /element/upload/picture HTTP/1.1[0m" 200 -
2021-07-26 20:35:09,599 [werkzeug] [2088:MainThread] _internal.py:_internal:_log in 113] [INFO]:  * Running on http://127.0.0.1:6851/ (Press CTRL+C to quit)
2021-07-26 20:35:11,723 [erybjp] [4328:Thread-1] app.py:app:log_exception in 1891] [ERROR]: Exception on /element/upload/picture [POST]
Traceback (most recent call last):
  File "C:\Users\lx\AppData\Local\Programs\Python\Python38\lib\site-packages\flask\app.py", line 2447, in wsgi_app
    response = self.full_dispatch_request()
  File "C:\Users\lx\AppData\Local\Programs\Python\Python38\lib\site-packages\flask\app.py", line 1952, in full_dispatch_request
    rv = self.handle_user_exception(e)
  File "C:\Users\lx\AppData\Local\Programs\Python\Python38\lib\site-packages\flask_restful\__init__.py", line 271, in error_router
    return original_handler(e)
  File "C:\Users\lx\AppData\Local\Programs\Python\Python38\lib\site-packages\flask_cors\extension.py", line 165, in wrapped_function
    return cors_after_request(app.make_response(f(*args, **kwargs)))
  File "C:\Users\lx\AppData\Local\Programs\Python\Python38\lib\site-packages\flask\app.py", line 1821, in handle_user_exception
    reraise(exc_type, exc_value, tb)
  File "C:\Users\lx\AppData\Local\Programs\Python\Python38\lib\site-packages\flask\_compat.py", line 39, in reraise
    raise value
  File "C:\Users\lx\AppData\Local\Programs\Python\Python38\lib\site-packages\flask\app.py", line 1950, in full_dispatch_request
    rv = self.dispatch_request()
  File "C:\Users\lx\AppData\Local\Programs\Python\Python38\lib\site-packages\flask\app.py", line 1936, in dispatch_request
    return self.view_functions[rule.endpoint](**req.view_args)
  File "D:\ÊµãËØïÂ≠¶‰π†ÊñáÊ°£\erybjp-master\uiplatform\router\runtestcase.py", line 122, in upload_picture
    return jsonify(code=500,success=False,message=result["message"])
TypeError: string indices must be integers
2021-07-26 20:35:11,730 [werkzeug] [4328:Thread-1] _internal.py:_internal:_log in 113] [INFO]: 127.0.0.1 - - [26/Jul/2021 20:35:11] "[35m[1mPOST /element/upload/picture HTTP/1.1[0m" 500 -
2021-07-26 20:37:41,802 [werkzeug] [18932:MainThread] _internal.py:_internal:_log in 113] [INFO]:  * Running on http://127.0.0.1:6851/ (Press CTRL+C to quit)
2021-07-26 20:37:48,993 [erybjp] [9128:Thread-1] app.py:app:log_exception in 1891] [ERROR]: Exception on /element/upload/picture [POST]
Traceback (most recent call last):
  File "C:\Users\lx\AppData\Local\Programs\Python\Python38\lib\site-packages\flask\app.py", line 2447, in wsgi_app
    response = self.full_dispatch_request()
  File "C:\Users\lx\AppData\Local\Programs\Python\Python38\lib\site-packages\flask\app.py", line 1952, in full_dispatch_request
    rv = self.handle_user_exception(e)
  File "C:\Users\lx\AppData\Local\Programs\Python\Python38\lib\site-packages\flask_restful\__init__.py", line 271, in error_router
    return original_handler(e)
  File "C:\Users\lx\AppData\Local\Programs\Python\Python38\lib\site-packages\flask_cors\extension.py", line 165, in wrapped_function
    return cors_after_request(app.make_response(f(*args, **kwargs)))
  File "C:\Users\lx\AppData\Local\Programs\Python\Python38\lib\site-packages\flask\app.py", line 1821, in handle_user_exception
    reraise(exc_type, exc_value, tb)
  File "C:\Users\lx\AppData\Local\Programs\Python\Python38\lib\site-packages\flask\_compat.py", line 39, in reraise
    raise value
  File "C:\Users\lx\AppData\Local\Programs\Python\Python38\lib\site-packages\flask\app.py", line 1950, in full_dispatch_request
    rv = self.dispatch_request()
  File "C:\Users\lx\AppData\Local\Programs\Python\Python38\lib\site-packages\flask\app.py", line 1936, in dispatch_request
    return self.view_functions[rule.endpoint](**req.view_args)
  File "D:\ÊµãËØïÂ≠¶‰π†ÊñáÊ°£\erybjp-master\uiplatform\router\runtestcase.py", line 122, in upload_picture
    return jsonify(code=500,success=False,message=result["message"])
TypeError: string indices must be integers
2021-07-26 20:37:48,996 [werkzeug] [9128:Thread-1] _internal.py:_internal:_log in 113] [INFO]: 127.0.0.1 - - [26/Jul/2021 20:37:48] "[35m[1mPOST /element/upload/picture HTTP/1.1[0m" 500 -
2021-07-26 20:40:04,575 [werkzeug] [14116:MainThread] _internal.py:_internal:_log in 113] [INFO]:  * Running on http://127.0.0.1:6851/ (Press CTRL+C to quit)
2021-07-26 20:40:07,308 [werkzeug] [15340:Thread-1] _internal.py:_internal:_log in 113] [INFO]: 127.0.0.1 - - [26/Jul/2021 20:40:07] "[37mPOST /element/upload/picture HTTP/1.1[0m" 200 -
2021-07-26 20:40:47,632 [werkzeug] [16588:MainThread] _internal.py:_internal:_log in 113] [INFO]:  * Running on http://127.0.0.1:6851/ (Press CTRL+C to quit)
2021-07-26 20:40:52,359 [werkzeug] [16432:Thread-1] _internal.py:_internal:_log in 113] [INFO]: 127.0.0.1 - - [26/Jul/2021 20:40:52] "[37mPOST /element/upload/picture HTTP/1.1[0m" 200 -
2021-07-26 20:40:54,713 [werkzeug] [10024:Thread-2] _internal.py:_internal:_log in 113] [INFO]: 127.0.0.1 - - [26/Jul/2021 20:40:54] "[37mPOST /element/upload/picture HTTP/1.1[0m" 200 -
2021-07-26 20:40:56,592 [werkzeug] [14724:Thread-3] _internal.py:_internal:_log in 113] [INFO]: 127.0.0.1 - - [26/Jul/2021 20:40:56] "[37mPOST /element/upload/picture HTTP/1.1[0m" 200 -
2021-07-26 20:40:57,340 [werkzeug] [4248:Thread-4] _internal.py:_internal:_log in 113] [INFO]: 127.0.0.1 - - [26/Jul/2021 20:40:57] "[37mPOST /element/upload/picture HTTP/1.1[0m" 200 -
2021-07-26 20:41:37,281 [werkzeug] [16288:Thread-5] _internal.py:_internal:_log in 113] [INFO]: 127.0.0.1 - - [26/Jul/2021 20:41:37] "[37mPOST /element/upload/picture HTTP/1.1[0m" 200 -
2021-07-26 20:41:49,373 [werkzeug] [29444:Thread-6] _internal.py:_internal:_log in 113] [INFO]: 127.0.0.1 - - [26/Jul/2021 20:41:49] "[37mPOST /element/upload/picture HTTP/1.1[0m" 200 -
2021-07-26 20:41:54,975 [werkzeug] [24600:Thread-7] _internal.py:_internal:_log in 113] [INFO]: 127.0.0.1 - - [26/Jul/2021 20:41:54] "[37mPOST /element/upload/picture HTTP/1.1[0m" 200 -
2021-07-26 20:42:04,466 [werkzeug] [10636:Thread-8] _internal.py:_internal:_log in 113] [INFO]: 127.0.0.1 - - [26/Jul/2021 20:42:04] "[37mPOST /element/upload/picture HTTP/1.1[0m" 200 -
2021-07-26 20:42:19,908 [werkzeug] [15408:Thread-9] _internal.py:_internal:_log in 113] [INFO]: 127.0.0.1 - - [26/Jul/2021 20:42:19] "[37mPOST /element/upload/picture HTTP/1.1[0m" 200 -
2021-07-26 20:42:24,703 [werkzeug] [13636:Thread-10] _internal.py:_internal:_log in 113] [INFO]: 127.0.0.1 - - [26/Jul/2021 20:42:24] "[37mPOST /element/upload/picture HTTP/1.1[0m" 200 -
2021-07-26 20:42:30,274 [werkzeug] [2428:Thread-11] _internal.py:_internal:_log in 113] [INFO]: 127.0.0.1 - - [26/Jul/2021 20:42:30] "[37mPOST /element/upload/picture HTTP/1.1[0m" 200 -
2021-07-26 20:42:33,710 [werkzeug] [6348:Thread-12] _internal.py:_internal:_log in 113] [INFO]: 127.0.0.1 - - [26/Jul/2021 20:42:33] "[37mPOST /element/upload/picture HTTP/1.1[0m" 200 -
